{
  "version": 8,
  "blockIdVersion": 11,
  "anchorX": 0,
  "anchorY": 0,
  "anchorZ": 0,
  "blocks": [
    {
      "x": -9,
      "y": 0,
      "z": -9,
      "name": "BO_Parking_Blacktop",
      "rotation": 4
    },
    {
      "x": -9,
      "y": 1,
      "z": -9,
      "name": "BO_Parking_Blacktop",
      "rotation": 4
    },
    {
      "x": -9,
      "y": 2,
      "z": -9,
      "name": "BO_Parking_Blacktop",
      "rotation": 4
    },
    {
      "x": -9,
      "y": 3,
      "z": -9,
      "name": "BO_Parking_Blacktop",
      "rotation": 4
    },
    {
      "x": -9,
      "y": 4,
      "z": -9,
      "name": "BO_Parking_Wall00"
    },
    {
      "x": -9,
      "y": 5,
      "z": -9,
      "name": "BO_Parking_Wall02"
    },
    {
      "x": -9,
      "y": 6,
      "z": -9,
      "name": "BO_Parking_Wall00"
    },
    {
      "x": -9,
      "y": 7,
      "z": -9,
      "name": "BO_Parking_Wall00"
    },
    {
      "x": -9,
      "y": 8,
      "z": -9,
      "name": "BO_Parking_Wall00"
    },
    {
      "x": -9,
      "y": 9,
      "z": -9,
      "name": "BO_Parking_Wall00"
    },
    {
      "x": -9,
      "y": 10,
      "z": -9,
      "name": "BO_Parking_Wall00"
    },
    {
      "x": -9,
      "y": 0,
      "z": -8,
      "name": "BO_Parking_Blacktop",
      "rotation": 4
    },
    {
      "x": -9,
      "y": 1,
      "z": -8,
      "name": "BO_Parking_Blacktop",
      "rotation": 4
    },
    {
      "x": -9,
      "y": 2,
      "z": -8,
      "name": "BO_Parking_Blacktop",
      "rotation": 4
    },
    {
      "x": -9,
      "y": 3,
      "z": -8,
      "name": "BO_Parking_Blacktop",
      "rotation": 4
    },
    {
      "x": -9,
      "y": 4,
      "z": -8,
      "name": "BO_Parking_Bollard",
      "support": 15,
      "rotation": 1
    },
    {
      "x": -9,
      "y": 5,
      "z": -8,
      "name": "BO_Parking_Bollard",
      "filler": 1024,
      "rotation": 1
    },
    {
      "x": -9,
      "y": 9,
      "z": -8,
      "name": "Prototype_Rock_Concrete_Brick_Half"
    },
    {
      "x": -9,
      "y": 10,
      "z": -8,
      "name": "BO_Parking_Wall00"
    },
    {
      "x": -9,
      "y": 11,
      "z": -8,
      "name": "Build_Black_Cube"
    },
    {
      "x": -9,
      "y": 0,
      "z": -7,
      "name": "BO_Parking_Blacktop",
      "rotation": 4
    },
    {
      "x": -9,
      "y": 1,
      "z": -7,
      "name": "BO_Parking_Blacktop",
      "rotation": 4
    },
    {
      "x": -9,
      "y": 2,
      "z": -7,
      "name": "BO_Parking_Blacktop",
      "rotation": 4
    },
    {
      "x": -9,
      "y": 3,
      "z": -7,
      "name": "BO_Parking_Blacktop",
      "rotation": 4
    },
    {
      "x": -9,
      "y": 9,
      "z": -7,
      "name": "Prototype_Rock_Concrete_Brick_Half"
    },
    {
      "x": -9,
      "y": 10,
      "z": -7,
      "name": "BO_Parking_Wall00"
    },
    {
      "x": -9,
      "y": 0,
      "z": -6,
      "name": "BO_Parking_Blacktop",
      "rotation": 4
    },
    {
      "x": -9,
      "y": 1,
      "z": -6,
      "name": "BO_Parking_Blacktop",
      "rotation": 4
    },
    {
      "x": -9,
      "y": 2,
      "z": -6,
      "name": "BO_Parking_Blacktop",
      "rotation": 4
    },
    {
      "x": -9,
      "y": 3,
      "z": -6,
      "name": "BO_Parking_Blacktop",
      "rotation": 4
    },
    {
      "x": -9,
      "y": 9,
      "z": -6,
      "name": "Prototype_Rock_Concrete_Brick_Half"
    },
    {
      "x": -9,
      "y": 10,
      "z": -6,
      "name": "BO_Parking_Wall00"
    },
    {
      "x": -9,
      "y": 0,
      "z": -5,
      "name": "BO_Parking_Blacktop",
      "rotation": 4
    },
    {
      "x": -9,
      "y": 1,
      "z": -5,
      "name": "BO_Parking_Blacktop",
      "rotation": 4
    },
    {
      "x": -9,
      "y": 2,
      "z": -5,
      "name": "BO_Parking_Blacktop",
      "rotation": 4
    },
    {
      "x": -9,
      "y": 3,
      "z": -5,
      "name": "BO_Parking_Blacktop",
      "rotation": 4
    },
    {
      "x": -9,
      "y": 9,
      "z": -5,
      "name": "Prototype_Rock_Concrete_Brick_Half"
    },
    {
      "x": -9,
      "y": 10,
      "z": -5,
      "name": "BO_Parking_Wall00"
    },
    {
      "x": -9,
      "y": 0,
      "z": -4,
      "name": "BO_Parking_Blacktop",
      "rotation": 4
    },
    {
      "x": -9,
      "y": 1,
      "z": -4,
      "name": "BO_Parking_Blacktop",
      "rotation": 4
    },
    {
      "x": -9,
      "y": 2,
      "z": -4,
      "name": "BO_Parking_Blacktop",
      "rotation": 4
    },
    {
      "x": -9,
      "y": 3,
      "z": -4,
      "name": "BO_Parking_Blacktop",
      "rotation": 4
    },
    {
      "x": -9,
      "y": 9,
      "z": -4,
      "name": "Prototype_Rock_Concrete_Brick_Half"
    },
    {
      "x": -9,
      "y": 10,
      "z": -4,
      "name": "BO_Parking_Wall00"
    },
    {
      "x": -9,
      "y": 0,
      "z": -3,
      "name": "BO_Parking_Blacktop",
      "rotation": 4
    },
    {
      "x": -9,
      "y": 1,
      "z": -3,
      "name": "BO_Parking_Blacktop",
      "rotation": 4
    },
    {
      "x": -9,
      "y": 2,
      "z": -3,
      "name": "BO_Parking_Blacktop",
      "rotation": 4
    },
    {
      "x": -9,
      "y": 3,
      "z": -3,
      "name": "BO_Parking_Blacktop",
      "rotation": 4
    },
    {
      "x": -9,
      "y": 9,
      "z": -3,
      "name": "Prototype_Rock_Concrete_Brick_Half"
    },
    {
      "x": -9,
      "y": 10,
      "z": -3,
      "name": "BO_Parking_Wall00"
    },
    {
      "x": -9,
      "y": 0,
      "z": -2,
      "name": "BO_Parking_Blacktop",
      "rotation": 4
    },
    {
      "x": -9,
      "y": 1,
      "z": -2,
      "name": "BO_Parking_Blacktop",
      "rotation": 4
    },
    {
      "x": -9,
      "y": 2,
      "z": -2,
      "name": "BO_Parking_Blacktop",
      "rotation": 4
    },
    {
      "x": -9,
      "y": 3,
      "z": -2,
      "name": "BO_Parking_Blacktop",
      "rotation": 4
    },
    {
      "x": -9,
      "y": 9,
      "z": -2,
      "name": "Prototype_Rock_Concrete_Brick_Half"
    },
    {
      "x": -9,
      "y": 10,
      "z": -2,
      "name": "BO_Parking_Wall00"
    },
    {
      "x": -9,
      "y": 0,
      "z": -1,
      "name": "BO_Parking_Blacktop",
      "rotation": 4
    },
    {
      "x": -9,
      "y": 1,
      "z": -1,
      "name": "BO_Parking_Blacktop",
      "rotation": 4
    },
    {
      "x": -9,
      "y": 2,
      "z": -1,
      "name": "BO_Parking_Blacktop",
      "rotation": 4
    },
    {
      "x": -9,
      "y": 3,
      "z": -1,
      "name": "BO_Parking_Blacktop",
      "rotation": 4
    },
    {
      "x": -9,
      "y": 4,
      "z": -1,
      "name": "BO_Parking_Bumper",
      "support": 15,
      "rotation": 2
    },
    {
      "x": -9,
      "y": 5,
      "z": -1,
      "name": "BO_Parking_Bumper",
      "filler": 1024,
      "rotation": 2
    },
    {
      "x": -9,
      "y": 9,
      "z": -1,
      "name": "Prototype_Rock_Concrete_Brick_Half"
    },
    {
      "x": -9,
      "y": 10,
      "z": -1,
      "name": "BO_Parking_Wall00"
    },
    {
      "x": -9,
      "y": 11,
      "z": -1,
      "name": "Build_Black_Cube"
    },
    {
      "x": -9,
      "y": 0,
      "z": 0,
      "name": "BO_Parking_Blacktop",
      "rotation": 4
    },
    {
      "x": -9,
      "y": 1,
      "z": 0,
      "name": "BO_Parking_Blacktop",
      "rotation": 4
    },
    {
      "x": -9,
      "y": 2,
      "z": 0,
      "name": "BO_Parking_Blacktop",
      "rotation": 4
    },
    {
      "x": -9,
      "y": 3,
      "z": 0,
      "name": "BO_Parking_Blacktop",
      "rotation": 4
    },
    {
      "x": -9,
      "y": 4,
      "z": 0,
      "name": "BO_Parking_Wall00"
    },
    {
      "x": -9,
      "y": 5,
      "z": 0,
      "name": "BO_Parking_Wall02"
    },
    {
      "x": -9,
      "y": 6,
      "z": 0,
      "name": "BO_Parking_Wall00"
    },
    {
      "x": -9,
      "y": 7,
      "z": 0,
      "name": "BO_Parking_Wall00"
    },
    {
      "x": -9,
      "y": 8,
      "z": 0,
      "name": "BO_Parking_Wall00"
    },
    {
      "x": -9,
      "y": 9,
      "z": 0,
      "name": "BO_Parking_Wall00",
      "rotation": 1
    },
    {
      "x": -9,
      "y": 10,
      "z": 0,
      "name": "BO_Parking_Wall00"
    },
    {
      "x": -9,
      "y": 0,
      "z": 1,
      "name": "BO_Parking_Blacktop",
      "rotation": 4
    },
    {
      "x": -9,
      "y": 1,
      "z": 1,
      "name": "BO_Parking_Blacktop",
      "rotation": 4
    },
    {
      "x": -9,
      "y": 2,
      "z": 1,
      "name": "BO_Parking_Blacktop",
      "rotation": 4
    },
    {
      "x": -9,
      "y": 3,
      "z": 1,
      "name": "BO_Parking_Blacktop",
      "rotation": 4
    },
    {
      "x": -9,
      "y": 4,
      "z": 1,
      "name": "BO_Parking_Wall00"
    },
    {
      "x": -9,
      "y": 5,
      "z": 1,
      "name": "BO_Parking_Wall02"
    },
    {
      "x": -9,
      "y": 6,
      "z": 1,
      "name": "BO_Parking_Wall00"
    },
    {
      "x": -9,
      "y": 7,
      "z": 1,
      "name": "BO_Parking_Wall00"
    },
    {
      "x": -9,
      "y": 8,
      "z": 1,
      "name": "BO_Parking_Wall00"
    },
    {
      "x": -9,
      "y": 9,
      "z": 1,
      "name": "BO_Parking_Wall00",
      "rotation": 1
    },
    {
      "x": -9,
      "y": 10,
      "z": 1,
      "name": "BO_Parking_Wall00"
    },
    {
      "x": -9,
      "y": 0,
      "z": 2,
      "name": "BO_Parking_Blacktop",
      "rotation": 4
    },
    {
      "x": -9,
      "y": 1,
      "z": 2,
      "name": "BO_Parking_Blacktop",
      "rotation": 4
    },
    {
      "x": -9,
      "y": 2,
      "z": 2,
      "name": "BO_Parking_Blacktop",
      "rotation": 4
    },
    {
      "x": -9,
      "y": 3,
      "z": 2,
      "name": "BO_Parking_Blacktop",
      "rotation": 4
    },
    {
      "x": -9,
      "y": 4,
      "z": 2,
      "name": "BO_Parking_Bumper",
      "support": 15
    },
    {
      "x": -9,
      "y": 5,
      "z": 2,
      "name": "BO_Parking_Bumper",
      "filler": 1024
    },
    {
      "x": -9,
      "y": 9,
      "z": 2,
      "name": "BO_Parking_Wall03"
    },
    {
      "x": -9,
      "y": 10,
      "z": 2,
      "name": "BO_Parking_Wall00"
    },
    {
      "x": -9,
      "y": 11,
      "z": 2,
      "name": "Build_Black_Cube"
    },
    {
      "x": -9,
      "y": 0,
      "z": 3,
      "name": "BO_Parking_Blacktop",
      "rotation": 4
    },
    {
      "x": -9,
      "y": 1,
      "z": 3,
      "name": "BO_Parking_Blacktop",
      "rotation": 4
    },
    {
      "x": -9,
      "y": 2,
      "z": 3,
      "name": "BO_Parking_Blacktop",
      "rotation": 4
    },
    {
      "x": -9,
      "y": 3,
      "z": 3,
      "name": "BO_Parking_Blacktop",
      "rotation": 4
    },
    {
      "x": -9,
      "y": 9,
      "z": 3,
      "name": "BO_Parking_Wall03"
    },
    {
      "x": -9,
      "y": 10,
      "z": 3,
      "name": "BO_Parking_Wall00"
    },
    {
      "x": -9,
      "y": 0,
      "z": 4,
      "name": "BO_Parking_Blacktop",
      "rotation": 4
    },
    {
      "x": -9,
      "y": 1,
      "z": 4,
      "name": "BO_Parking_Blacktop",
      "rotation": 4
    },
    {
      "x": -9,
      "y": 2,
      "z": 4,
      "name": "BO_Parking_Blacktop",
      "rotation": 4
    },
    {
      "x": -9,
      "y": 3,
      "z": 4,
      "name": "BO_Parking_Blacktop",
      "rotation": 4
    },
    {
      "x": -9,
      "y": 9,
      "z": 4,
      "name": "Prototype_Rock_Concrete_Brick_Half"
    },
    {
      "x": -9,
      "y": 10,
      "z": 4,
      "name": "BO_Parking_Wall00"
    },
    {
      "x": -9,
      "y": 0,
      "z": 5,
      "name": "BO_Parking_Blacktop",
      "rotation": 4
    },
    {
      "x": -9,
      "y": 1,
      "z": 5,
      "name": "BO_Parking_Blacktop",
      "rotation": 4
    },
    {
      "x": -9,
      "y": 2,
      "z": 5,
      "name": "BO_Parking_Blacktop",
      "rotation": 4
    },
    {
      "x": -9,
      "y": 3,
      "z": 5,
      "name": "BO_Parking_Blacktop",
      "rotation": 4
    },
    {
      "x": -9,
      "y": 9,
      "z": 5,
      "name": "Prototype_Rock_Concrete_Brick_Half"
    },
    {
      "x": -9,
      "y": 10,
      "z": 5,
      "name": "BO_Parking_Wall00"
    },
    {
      "x": -9,
      "y": 0,
      "z": 6,
      "name": "BO_Parking_Blacktop",
      "rotation": 4
    },
    {
      "x": -9,
      "y": 1,
      "z": 6,
      "name": "BO_Parking_Blacktop",
      "rotation": 4
    },
    {
      "x": -9,
      "y": 2,
      "z": 6,
      "name": "BO_Parking_Blacktop",
      "rotation": 4
    },
    {
      "x": -9,
      "y": 3,
      "z": 6,
      "name": "BO_Parking_Blacktop",
      "rotation": 4
    },
    {
      "x": -9,
      "y": 9,
      "z": 6,
      "name": "Prototype_Rock_Concrete_Brick_Half"
    },
    {
      "x": -9,
      "y": 10,
      "z": 6,
      "name": "BO_Parking_Wall00"
    },
    {
      "x": -9,
      "y": 0,
      "z": 7,
      "name": "BO_Parking_Blacktop",
      "rotation": 4
    },
    {
      "x": -9,
      "y": 1,
      "z": 7,
      "name": "BO_Parking_Blacktop",
      "rotation": 4
    },
    {
      "x": -9,
      "y": 2,
      "z": 7,
      "name": "BO_Parking_Blacktop",
      "rotation": 4
    },
    {
      "x": -9,
      "y": 3,
      "z": 7,
      "name": "BO_Parking_Blacktop",
      "rotation": 4
    },
    {
      "x": -9,
      "y": 9,
      "z": 7,
      "name": "Prototype_Rock_Concrete_Brick_Half"
    },
    {
      "x": -9,
      "y": 10,
      "z": 7,
      "name": "BO_Parking_Wall00"
    },
    {
      "x": -9,
      "y": 0,
      "z": 8,
      "name": "BO_Parking_Blacktop",
      "rotation": 4
    },
    {
      "x": -9,
      "y": 1,
      "z": 8,
      "name": "BO_Parking_Blacktop",
      "rotation": 4
    },
    {
      "x": -9,
      "y": 2,
      "z": 8,
      "name": "BO_Parking_Blacktop",
      "rotation": 4
    },
    {
      "x": -9,
      "y": 3,
      "z": 8,
      "name": "BO_Parking_Blacktop",
      "rotation": 4
    },
    {
      "x": -9,
      "y": 9,
      "z": 8,
      "name": "Prototype_Rock_Concrete_Brick_Half"
    },
    {
      "x": -9,
      "y": 10,
      "z": 8,
      "name": "BO_Parking_Wall00"
    },
    {
      "x": -9,
      "y": 0,
      "z": 9,
      "name": "BO_Parking_Blacktop",
      "rotation": 4
    },
    {
      "x": -9,
      "y": 1,
      "z": 9,
      "name": "BO_Parking_Blacktop",
      "rotation": 4
    },
    {
      "x": -9,
      "y": 2,
      "z": 9,
      "name": "BO_Parking_Blacktop",
      "rotation": 4
    },
    {
      "x": -9,
      "y": 3,
      "z": 9,
      "name": "BO_Parking_Blacktop",
      "rotation": 4
    },
    {
      "x": -9,
      "y": 9,
      "z": 9,
      "name": "Prototype_Rock_Concrete_Brick_Half"
    },
    {
      "x": -9,
      "y": 10,
      "z": 9,
      "name": "BO_Parking_Wall00"
    },
    {
      "x": -9,
      "y": 11,
      "z": 9,
      "name": "Build_Black_Cube"
    },
    {
      "x": -9,
      "y": 0,
      "z": 10,
      "name": "BO_Parking_Blacktop",
      "rotation": 4
    },
    {
      "x": -9,
      "y": 1,
      "z": 10,
      "name": "BO_Parking_Blacktop",
      "rotation": 4
    },
    {
      "x": -9,
      "y": 2,
      "z": 10,
      "name": "BO_Parking_Blacktop",
      "rotation": 4
    },
    {
      "x": -9,
      "y": 3,
      "z": 10,
      "name": "BO_Parking_Blacktop",
      "rotation": 4
    },
    {
      "x": -9,
      "y": 4,
      "z": 10,
      "name": "BO_Parking_Wall00"
    },
    {
      "x": -9,
      "y": 5,
      "z": 10,
      "name": "BO_Parking_Wall02"
    },
    {
      "x": -9,
      "y": 6,
      "z": 10,
      "name": "BO_Parking_Wall00"
    },
    {
      "x": -9,
      "y": 7,
      "z": 10,
      "name": "BO_Parking_Wall00"
    },
    {
      "x": -9,
      "y": 8,
      "z": 10,
      "name": "BO_Parking_Wall00"
    },
    {
      "x": -9,
      "y": 9,
      "z": 10,
      "name": "BO_Parking_Wall00"
    },
    {
      "x": -9,
      "y": 10,
      "z": 10,
      "name": "BO_Parking_Wall00"
    },
    {
      "x": -8,
      "y": 0,
      "z": -9,
      "name": "BO_Parking_Blacktop",
      "rotation": 4
    },
    {
      "x": -8,
      "y": 1,
      "z": -9,
      "name": "BO_Parking_Blacktop",
      "rotation": 4
    },
    {
      "x": -8,
      "y": 2,
      "z": -9,
      "name": "BO_Parking_Blacktop",
      "rotation": 4
    },
    {
      "x": -8,
      "y": 3,
      "z": -9,
      "name": "BO_Parking_Blacktop",
      "rotation": 4
    },
    {
      "x": -8,
      "y": 4,
      "z": -9,
      "name": "BO_Parking_Bollard",
      "support": 15
    },
    {
      "x": -8,
      "y": 5,
      "z": -9,
      "name": "BO_Parking_Bollard",
      "filler": 1024
    },
    {
      "x": -8,
      "y": 9,
      "z": -9,
      "name": "BO_Parking_Wall03"
    },
    {
      "x": -8,
      "y": 10,
      "z": -9,
      "name": "BO_Parking_Wall00"
    },
    {
      "x": -8,
      "y": 11,
      "z": -9,
      "name": "Build_Black_Cube"
    },
    {
      "x": -8,
      "y": 0,
      "z": -8,
      "name": "BO_Parking_Blacktop",
      "rotation": 4
    },
    {
      "x": -8,
      "y": 1,
      "z": -8,
      "name": "BO_Parking_Blacktop",
      "rotation": 4
    },
    {
      "x": -8,
      "y": 2,
      "z": -8,
      "name": "BO_Parking_Blacktop",
      "rotation": 4
    },
    {
      "x": -8,
      "y": 3,
      "z": -8,
      "name": "BO_Parking_Blacktop",
      "rotation": 4
    },
    {
      "x": -8,
      "y": 9,
      "z": -8,
      "name": "BO_Parking_Wall_Half",
      "rotation": 8
    },
    {
      "x": -8,
      "y": 10,
      "z": -8,
      "name": "BO_Parking_Wall00"
    },
    {
      "x": -8,
      "y": 11,
      "z": -8,
      "name": "Build_Black_Cube"
    },
    {
      "x": -8,
      "y": 0,
      "z": -7,
      "name": "BO_Parking_Blacktop",
      "rotation": 4
    },
    {
      "x": -8,
      "y": 1,
      "z": -7,
      "name": "BO_Parking_Blacktop",
      "rotation": 4
    },
    {
      "x": -8,
      "y": 2,
      "z": -7,
      "name": "BO_Parking_Blacktop",
      "rotation": 4
    },
    {
      "x": -8,
      "y": 3,
      "z": -7,
      "name": "BO_Parking_Blacktop",
      "rotation": 4
    },
    {
      "x": -8,
      "y": 9,
      "z": -7,
      "name": "BO_Parking_Wall_Half",
      "rotation": 8
    },
    {
      "x": -8,
      "y": 10,
      "z": -7,
      "name": "BO_Parking_Wall00"
    },
    {
      "x": -8,
      "y": 0,
      "z": -6,
      "name": "BO_Parking_Blacktop",
      "rotation": 4
    },
    {
      "x": -8,
      "y": 1,
      "z": -6,
      "name": "BO_Parking_Blacktop",
      "rotation": 4
    },
    {
      "x": -8,
      "y": 2,
      "z": -6,
      "name": "BO_Parking_Blacktop",
      "rotation": 4
    },
    {
      "x": -8,
      "y": 3,
      "z": -6,
      "name": "BO_Parking_Blacktop",
      "rotation": 4
    },
    {
      "x": -8,
      "y": 9,
      "z": -6,
      "name": "BO_Parking_Wall_Half",
      "rotation": 8
    },
    {
      "x": -8,
      "y": 10,
      "z": -6,
      "name": "BO_Parking_Wall00"
    },
    {
      "x": -8,
      "y": 0,
      "z": -5,
      "name": "BO_Parking_Blacktop",
      "rotation": 4
    },
    {
      "x": -8,
      "y": 1,
      "z": -5,
      "name": "BO_Parking_Blacktop",
      "rotation": 4
    },
    {
      "x": -8,
      "y": 2,
      "z": -5,
      "name": "BO_Parking_Blacktop",
      "rotation": 4
    },
    {
      "x": -8,
      "y": 3,
      "z": -5,
      "name": "BO_Parking_Blacktop",
      "rotation": 4
    },
    {
      "x": -8,
      "y": 9,
      "z": -5,
      "name": "BO_Parking_Wall_Half",
      "rotation": 8
    },
    {
      "x": -8,
      "y": 10,
      "z": -5,
      "name": "BO_Parking_Wall00"
    },
    {
      "x": -8,
      "y": 0,
      "z": -4,
      "name": "BO_Parking_Blacktop",
      "rotation": 4
    },
    {
      "x": -8,
      "y": 1,
      "z": -4,
      "name": "BO_Parking_Blacktop",
      "rotation": 4
    },
    {
      "x": -8,
      "y": 2,
      "z": -4,
      "name": "BO_Parking_Blacktop",
      "rotation": 4
    },
    {
      "x": -8,
      "y": 3,
      "z": -4,
      "name": "BO_Parking_Blacktop",
      "rotation": 4
    },
    {
      "x": -8,
      "y": 9,
      "z": -4,
      "name": "BO_Parking_Wall_Half",
      "rotation": 8
    },
    {
      "x": -8,
      "y": 10,
      "z": -4,
      "name": "BO_Parking_Wall00"
    },
    {
      "x": -8,
      "y": 0,
      "z": -3,
      "name": "BO_Parking_Blacktop",
      "rotation": 4
    },
    {
      "x": -8,
      "y": 1,
      "z": -3,
      "name": "BO_Parking_Blacktop",
      "rotation": 4
    },
    {
      "x": -8,
      "y": 2,
      "z": -3,
      "name": "BO_Parking_Blacktop",
      "rotation": 4
    },
    {
      "x": -8,
      "y": 3,
      "z": -3,
      "name": "BO_Parking_Blacktop01",
      "support": 15,
      "rotation": 1
    },
    {
      "x": -8,
      "y": 9,
      "z": -3,
      "name": "BO_Parking_Wall_Half",
      "rotation": 8
    },
    {
      "x": -8,
      "y": 10,
      "z": -3,
      "name": "BO_Parking_Wall00"
    },
    {
      "x": -8,
      "y": 0,
      "z": -2,
      "name": "BO_Parking_Blacktop",
      "rotation": 4
    },
    {
      "x": -8,
      "y": 1,
      "z": -2,
      "name": "BO_Parking_Blacktop",
      "rotation": 4
    },
    {
      "x": -8,
      "y": 2,
      "z": -2,
      "name": "BO_Parking_Blacktop",
      "rotation": 4
    },
    {
      "x": -8,
      "y": 3,
      "z": -2,
      "name": "BO_Parking_Blacktop01",
      "support": 15,
      "rotation": 3
    },
    {
      "x": -8,
      "y": 9,
      "z": -2,
      "name": "BO_Parking_Wall_Half",
      "rotation": 8
    },
    {
      "x": -8,
      "y": 10,
      "z": -2,
      "name": "BO_Parking_Wall00"
    },
    {
      "x": -8,
      "y": 0,
      "z": -1,
      "name": "BO_Parking_Blacktop",
      "rotation": 4
    },
    {
      "x": -8,
      "y": 1,
      "z": -1,
      "name": "BO_Parking_Blacktop",
      "rotation": 4
    },
    {
      "x": -8,
      "y": 2,
      "z": -1,
      "name": "BO_Parking_Blacktop",
      "rotation": 4
    },
    {
      "x": -8,
      "y": 3,
      "z": -1,
      "name": "BO_Parking_Blacktop01",
      "support": 15,
      "rotation": 3
    },
    {
      "x": -8,
      "y": 9,
      "z": -1,
      "name": "*BO_Garage_Overhead_Lights_State_Definitions_Inactive",
      "components": {
        "Components": {
          "BlackoutCycleState": {
            "OnState": "Inactive",
            "OffState": "Active",
            "OnSound": "Garage_Alarm_Disable"
          },
          "PlacedByInteraction": {
            "WhoPlacedUuid": {
              "$binary": "KMPE5JWxSQGC8WI/IkVLQQ==",
              "$type": "04"
            }
          }
        }
      },
      "rotation": 5
    },
    {
      "x": -8,
      "y": 10,
      "z": -1,
      "name": "BO_Parking_Wall00"
    },
    {
      "x": -8,
      "y": 11,
      "z": -1,
      "name": "Build_Black_Cube"
    },
    {
      "x": -8,
      "y": 0,
      "z": 0,
      "name": "BO_Parking_Blacktop",
      "rotation": 4
    },
    {
      "x": -8,
      "y": 1,
      "z": 0,
      "name": "BO_Parking_Blacktop",
      "rotation": 4
    },
    {
      "x": -8,
      "y": 2,
      "z": 0,
      "name": "BO_Parking_Blacktop",
      "rotation": 4
    },
    {
      "x": -8,
      "y": 3,
      "z": 0,
      "name": "BO_Parking_Blacktop01",
      "support": 15,
      "rotation": 3
    },
    {
      "x": -8,
      "y": 4,
      "z": 0,
      "name": "BO_Parking_Curb",
      "filler": 31,
      "rotation": 1
    },
    {
      "x": -8,
      "y": 9,
      "z": 0,
      "name": "BO_Parking_Wall03",
      "rotation": 1
    },
    {
      "x": -8,
      "y": 10,
      "z": 0,
      "name": "BO_Parking_Wall00"
    },
    {
      "x": -8,
      "y": 11,
      "z": 0,
      "name": "Build_Black_Cube"
    },
    {
      "x": -8,
      "y": 0,
      "z": 1,
      "name": "BO_Parking_Blacktop",
      "rotation": 4
    },
    {
      "x": -8,
      "y": 1,
      "z": 1,
      "name": "BO_Parking_Blacktop",
      "rotation": 4
    },
    {
      "x": -8,
      "y": 2,
      "z": 1,
      "name": "BO_Parking_Blacktop",
      "rotation": 4
    },
    {
      "x": -8,
      "y": 3,
      "z": 1,
      "name": "BO_Parking_Blacktop01",
      "support": 15,
      "rotation": 3
    },
    {
      "x": -8,
      "y": 9,
      "z": 1,
      "name": "BO_Parking_Wall03",
      "rotation": 1
    },
    {
      "x": -8,
      "y": 10,
      "z": 1,
      "name": "BO_Parking_Wall00"
    },
    {
      "x": -8,
      "y": 11,
      "z": 1,
      "name": "Build_Black_Cube"
    },
    {
      "x": -8,
      "y": 0,
      "z": 2,
      "name": "BO_Parking_Blacktop",
      "rotation": 4
    },
    {
      "x": -8,
      "y": 1,
      "z": 2,
      "name": "BO_Parking_Blacktop",
      "rotation": 4
    },
    {
      "x": -8,
      "y": 2,
      "z": 2,
      "name": "BO_Parking_Blacktop",
      "rotation": 4
    },
    {
      "x": -8,
      "y": 3,
      "z": 2,
      "name": "BO_Parking_Blacktop01",
      "support": 15,
      "rotation": 3
    },
    {
      "x": -8,
      "y": 9,
      "z": 2,
      "name": "BO_Parking_Wall_Half",
      "rotation": 8
    },
    {
      "x": -8,
      "y": 10,
      "z": 2,
      "name": "BO_Parking_Wall00"
    },
    {
      "x": -8,
      "y": 11,
      "z": 2,
      "name": "Build_Black_Cube"
    },
    {
      "x": -8,
      "y": 0,
      "z": 3,
      "name": "BO_Parking_Blacktop",
      "rotation": 4
    },
    {
      "x": -8,
      "y": 1,
      "z": 3,
      "name": "BO_Parking_Blacktop",
      "rotation": 4
    },
    {
      "x": -8,
      "y": 2,
      "z": 3,
      "name": "BO_Parking_Blacktop",
      "rotation": 4
    },
    {
      "x": -8,
      "y": 3,
      "z": 3,
      "name": "BO_Parking_Blacktop01",
      "support": 15,
      "rotation": 3
    },
    {
      "x": -8,
      "y": 9,
      "z": 3,
      "name": "BO_Parking_Wall_Half",
      "rotation": 8
    },
    {
      "x": -8,
      "y": 10,
      "z": 3,
      "name": "BO_Parking_Wall00"
    },
    {
      "x": -8,
      "y": 0,
      "z": 4,
      "name": "BO_Parking_Blacktop",
      "rotation": 4
    },
    {
      "x": -8,
      "y": 1,
      "z": 4,
      "name": "BO_Parking_Blacktop",
      "rotation": 4
    },
    {
      "x": -8,
      "y": 2,
      "z": 4,
      "name": "BO_Parking_Blacktop",
      "rotation": 4
    },
    {
      "x": -8,
      "y": 3,
      "z": 4,
      "name": "BO_Parking_Blacktop01",
      "support": 15,
      "rotation": 3
    },
    {
      "x": -8,
      "y": 9,
      "z": 4,
      "name": "BO_Parking_Wall_Half",
      "rotation": 8
    },
    {
      "x": -8,
      "y": 10,
      "z": 4,
      "name": "BO_Parking_Wall00"
    },
    {
      "x": -8,
      "y": 0,
      "z": 5,
      "name": "BO_Parking_Blacktop",
      "rotation": 4
    },
    {
      "x": -8,
      "y": 1,
      "z": 5,
      "name": "BO_Parking_Blacktop",
      "rotation": 4
    },
    {
      "x": -8,
      "y": 2,
      "z": 5,
      "name": "BO_Parking_Blacktop",
      "rotation": 4
    },
    {
      "x": -8,
      "y": 3,
      "z": 5,
      "name": "BO_Parking_Blacktop",
      "rotation": 4
    },
    {
      "x": -8,
      "y": 9,
      "z": 5,
      "name": "BO_Parking_Wall_Half",
      "rotation": 8
    },
    {
      "x": -8,
      "y": 10,
      "z": 5,
      "name": "BO_Parking_Wall00"
    },
    {
      "x": -8,
      "y": 0,
      "z": 6,
      "name": "BO_Parking_Blacktop",
      "rotation": 4
    },
    {
      "x": -8,
      "y": 1,
      "z": 6,
      "name": "BO_Parking_Blacktop",
      "rotation": 4
    },
    {
      "x": -8,
      "y": 2,
      "z": 6,
      "name": "BO_Parking_Blacktop",
      "rotation": 4
    },
    {
      "x": -8,
      "y": 3,
      "z": 6,
      "name": "BO_Parking_Blacktop",
      "rotation": 4
    },
    {
      "x": -8,
      "y": 9,
      "z": 6,
      "name": "BO_Parking_Wall_Half",
      "rotation": 8
    },
    {
      "x": -8,
      "y": 10,
      "z": 6,
      "name": "BO_Parking_Wall00"
    },
    {
      "x": -8,
      "y": 0,
      "z": 7,
      "name": "BO_Parking_Blacktop",
      "rotation": 4
    },
    {
      "x": -8,
      "y": 1,
      "z": 7,
      "name": "BO_Parking_Blacktop",
      "rotation": 4
    },
    {
      "x": -8,
      "y": 2,
      "z": 7,
      "name": "BO_Parking_Blacktop",
      "rotation": 4
    },
    {
      "x": -8,
      "y": 3,
      "z": 7,
      "name": "BO_Parking_Blacktop",
      "rotation": 4
    },
    {
      "x": -8,
      "y": 9,
      "z": 7,
      "name": "BO_Parking_Wall_Half",
      "rotation": 8
    },
    {
      "x": -8,
      "y": 10,
      "z": 7,
      "name": "BO_Parking_Wall00"
    },
    {
      "x": -8,
      "y": 0,
      "z": 8,
      "name": "BO_Parking_Blacktop",
      "rotation": 4
    },
    {
      "x": -8,
      "y": 1,
      "z": 8,
      "name": "BO_Parking_Blacktop",
      "rotation": 4
    },
    {
      "x": -8,
      "y": 2,
      "z": 8,
      "name": "BO_Parking_Blacktop",
      "rotation": 4
    },
    {
      "x": -8,
      "y": 3,
      "z": 8,
      "name": "BO_Parking_Blacktop",
      "rotation": 4
    },
    {
      "x": -8,
      "y": 9,
      "z": 8,
      "name": "BO_Parking_Wall_Half",
      "rotation": 8
    },
    {
      "x": -8,
      "y": 10,
      "z": 8,
      "name": "BO_Parking_Wall00"
    },
    {
      "x": -8,
      "y": 0,
      "z": 9,
      "name": "BO_Parking_Blacktop",
      "rotation": 4
    },
    {
      "x": -8,
      "y": 1,
      "z": 9,
      "name": "BO_Parking_Blacktop",
      "rotation": 4
    },
    {
      "x": -8,
      "y": 2,
      "z": 9,
      "name": "BO_Parking_Blacktop",
      "rotation": 4
    },
    {
      "x": -8,
      "y": 3,
      "z": 9,
      "name": "BO_Parking_Blacktop",
      "rotation": 4
    },
    {
      "x": -8,
      "y": 9,
      "z": 9,
      "name": "*BO_Garage_Overhead_Lights_State_Definitions_Inactive",
      "components": {
        "Components": {
          "BlackoutCycleState": {
            "OnState": "Inactive",
            "OffState": "Active",
            "OnSound": "Garage_Alarm_Disable"
          },
          "PlacedByInteraction": {
            "WhoPlacedUuid": {
              "$binary": "KMPE5JWxSQGC8WI/IkVLQQ==",
              "$type": "04"
            }
          }
        }
      },
      "rotation": 5
    },
    {
      "x": -8,
      "y": 10,
      "z": 9,
      "name": "BO_Parking_Wall00"
    },
    {
      "x": -8,
      "y": 11,
      "z": 9,
      "name": "Build_Black_Cube"
    },
    {
      "x": -8,
      "y": 0,
      "z": 10,
      "name": "BO_Parking_Blacktop",
      "rotation": 4
    },
    {
      "x": -8,
      "y": 1,
      "z": 10,
      "name": "BO_Parking_Blacktop",
      "rotation": 4
    },
    {
      "x": -8,
      "y": 2,
      "z": 10,
      "name": "BO_Parking_Blacktop",
      "rotation": 4
    },
    {
      "x": -8,
      "y": 3,
      "z": 10,
      "name": "BO_Parking_Blacktop",
      "rotation": 4
    },
    {
      "x": -8,
      "y": 9,
      "z": 10,
      "name": "BO_Parking_Wall03"
    },
    {
      "x": -8,
      "y": 10,
      "z": 10,
      "name": "BO_Parking_Wall00"
    },
    {
      "x": -8,
      "y": 11,
      "z": 10,
      "name": "Build_Black_Cube"
    },
    {
      "x": -7,
      "y": 0,
      "z": -9,
      "name": "BO_Parking_Blacktop",
      "rotation": 4
    },
    {
      "x": -7,
      "y": 1,
      "z": -9,
      "name": "BO_Parking_Blacktop",
      "rotation": 4
    },
    {
      "x": -7,
      "y": 2,
      "z": -9,
      "name": "BO_Parking_Blacktop",
      "rotation": 4
    },
    {
      "x": -7,
      "y": 3,
      "z": -9,
      "name": "BO_Parking_Blacktop",
      "rotation": 4
    },
    {
      "x": -7,
      "y": 9,
      "z": -9,
      "name": "BO_Parking_Wall03"
    },
    {
      "x": -7,
      "y": 10,
      "z": -9,
      "name": "BO_Parking_Wall00"
    },
    {
      "x": -7,
      "y": 0,
      "z": -8,
      "name": "BO_Parking_Blacktop",
      "rotation": 4
    },
    {
      "x": -7,
      "y": 1,
      "z": -8,
      "name": "BO_Parking_Blacktop",
      "rotation": 4
    },
    {
      "x": -7,
      "y": 2,
      "z": -8,
      "name": "BO_Parking_Blacktop",
      "rotation": 4
    },
    {
      "x": -7,
      "y": 3,
      "z": -8,
      "name": "BO_Parking_Blacktop",
      "rotation": 4
    },
    {
      "x": -7,
      "y": 9,
      "z": -8,
      "name": "BO_Parking_Wall_Half",
      "rotation": 8
    },
    {
      "x": -7,
      "y": 10,
      "z": -8,
      "name": "BO_Parking_Wall00"
    },
    {
      "x": -7,
      "y": 0,
      "z": -7,
      "name": "BO_Parking_Blacktop",
      "rotation": 4
    },
    {
      "x": -7,
      "y": 1,
      "z": -7,
      "name": "BO_Parking_Blacktop",
      "rotation": 4
    },
    {
      "x": -7,
      "y": 2,
      "z": -7,
      "name": "BO_Parking_Blacktop",
      "rotation": 4
    },
    {
      "x": -7,
      "y": 3,
      "z": -7,
      "name": "BO_Parking_Blacktop",
      "rotation": 4
    },
    {
      "x": -7,
      "y": 9,
      "z": -7,
      "name": "BO_Parking_Wall_Half",
      "rotation": 8
    },
    {
      "x": -7,
      "y": 10,
      "z": -7,
      "name": "BO_Parking_Wall00"
    },
    {
      "x": -7,
      "y": 0,
      "z": -6,
      "name": "BO_Parking_Blacktop",
      "rotation": 4
    },
    {
      "x": -7,
      "y": 1,
      "z": -6,
      "name": "BO_Parking_Blacktop",
      "rotation": 4
    },
    {
      "x": -7,
      "y": 2,
      "z": -6,
      "name": "BO_Parking_Blacktop",
      "rotation": 4
    },
    {
      "x": -7,
      "y": 3,
      "z": -6,
      "name": "BO_Parking_Blacktop",
      "rotation": 4
    },
    {
      "x": -7,
      "y": 9,
      "z": -6,
      "name": "BO_Parking_Wall_Half",
      "rotation": 8
    },
    {
      "x": -7,
      "y": 10,
      "z": -6,
      "name": "BO_Parking_Wall00"
    },
    {
      "x": -7,
      "y": 0,
      "z": -5,
      "name": "BO_Parking_Blacktop",
      "rotation": 4
    },
    {
      "x": -7,
      "y": 1,
      "z": -5,
      "name": "BO_Parking_Blacktop",
      "rotation": 4
    },
    {
      "x": -7,
      "y": 2,
      "z": -5,
      "name": "BO_Parking_Blacktop",
      "rotation": 4
    },
    {
      "x": -7,
      "y": 3,
      "z": -5,
      "name": "BO_Parking_Blacktop",
      "rotation": 4
    },
    {
      "x": -7,
      "y": 9,
      "z": -5,
      "name": "BO_Parking_Wall_Half",
      "rotation": 8
    },
    {
      "x": -7,
      "y": 10,
      "z": -5,
      "name": "BO_Parking_Wall00"
    },
    {
      "x": -7,
      "y": 0,
      "z": -4,
      "name": "BO_Parking_Blacktop",
      "rotation": 4
    },
    {
      "x": -7,
      "y": 1,
      "z": -4,
      "name": "BO_Parking_Blacktop",
      "rotation": 4
    },
    {
      "x": -7,
      "y": 2,
      "z": -4,
      "name": "BO_Parking_Blacktop",
      "rotation": 4
    },
    {
      "x": -7,
      "y": 3,
      "z": -4,
      "name": "BO_Parking_Blacktop",
      "rotation": 4
    },
    {
      "x": -7,
      "y": 9,
      "z": -4,
      "name": "BO_Parking_Wall_Half",
      "rotation": 8
    },
    {
      "x": -7,
      "y": 10,
      "z": -4,
      "name": "BO_Parking_Wall00"
    },
    {
      "x": -7,
      "y": 0,
      "z": -3,
      "name": "BO_Parking_Blacktop",
      "rotation": 4
    },
    {
      "x": -7,
      "y": 1,
      "z": -3,
      "name": "BO_Parking_Blacktop",
      "rotation": 4
    },
    {
      "x": -7,
      "y": 2,
      "z": -3,
      "name": "BO_Parking_Blacktop",
      "rotation": 4
    },
    {
      "x": -7,
      "y": 3,
      "z": -3,
      "name": "BO_Parking_Blacktop",
      "rotation": 4
    },
    {
      "x": -7,
      "y": 9,
      "z": -3,
      "name": "BO_Parking_Wall_Half",
      "rotation": 8
    },
    {
      "x": -7,
      "y": 10,
      "z": -3,
      "name": "BO_Parking_Wall00"
    },
    {
      "x": -7,
      "y": 0,
      "z": -2,
      "name": "BO_Parking_Blacktop",
      "rotation": 4
    },
    {
      "x": -7,
      "y": 1,
      "z": -2,
      "name": "BO_Parking_Blacktop",
      "rotation": 4
    },
    {
      "x": -7,
      "y": 2,
      "z": -2,
      "name": "BO_Parking_Blacktop",
      "rotation": 4
    },
    {
      "x": -7,
      "y": 3,
      "z": -2,
      "name": "BO_Parking_Blacktop",
      "rotation": 4
    },
    {
      "x": -7,
      "y": 9,
      "z": -2,
      "name": "BO_Parking_Wall_Half",
      "rotation": 8
    },
    {
      "x": -7,
      "y": 10,
      "z": -2,
      "name": "BO_Parking_Wall00"
    },
    {
      "x": -7,
      "y": 0,
      "z": -1,
      "name": "BO_Parking_Blacktop",
      "rotation": 4
    },
    {
      "x": -7,
      "y": 1,
      "z": -1,
      "name": "BO_Parking_Blacktop",
      "rotation": 4
    },
    {
      "x": -7,
      "y": 2,
      "z": -1,
      "name": "BO_Parking_Blacktop",
      "rotation": 4
    },
    {
      "x": -7,
      "y": 3,
      "z": -1,
      "name": "BO_Parking_Blacktop",
      "rotation": 4
    },
    {
      "x": -7,
      "y": 9,
      "z": -1,
      "name": "*BO_Garage_Overhead_Lights_State_Definitions_Inactive",
      "components": {
        "Components": {
          "BlackoutCycleState": {
            "OnState": "Inactive",
            "OffState": "Active",
            "OnSound": "Garage_Alarm_Disable"
          },
          "PlacedByInteraction": {
            "WhoPlacedUuid": {
              "$binary": "KMPE5JWxSQGC8WI/IkVLQQ==",
              "$type": "04"
            }
          }
        }
      },
      "rotation": 5
    },
    {
      "x": -7,
      "y": 10,
      "z": -1,
      "name": "BO_Parking_Wall00"
    },
    {
      "x": -7,
      "y": 0,
      "z": 0,
      "name": "BO_Parking_Blacktop",
      "rotation": 4
    },
    {
      "x": -7,
      "y": 1,
      "z": 0,
      "name": "BO_Parking_Blacktop",
      "rotation": 4
    },
    {
      "x": -7,
      "y": 2,
      "z": 0,
      "name": "BO_Parking_Blacktop",
      "rotation": 4
    },
    {
      "x": -7,
      "y": 3,
      "z": 0,
      "name": "BO_Parking_Blacktop",
      "rotation": 4
    },
    {
      "x": -7,
      "y": 4,
      "z": 0,
      "name": "BO_Parking_Curb",
      "support": 15,
      "rotation": 1
    },
    {
      "x": -7,
      "y": 9,
      "z": 0,
      "name": "BO_Parking_Wall03",
      "rotation": 1
    },
    {
      "x": -7,
      "y": 10,
      "z": 0,
      "name": "BO_Parking_Wall00"
    },
    {
      "x": -7,
      "y": 0,
      "z": 1,
      "name": "BO_Parking_Blacktop",
      "rotation": 4
    },
    {
      "x": -7,
      "y": 1,
      "z": 1,
      "name": "BO_Parking_Blacktop",
      "rotation": 4
    },
    {
      "x": -7,
      "y": 2,
      "z": 1,
      "name": "BO_Parking_Blacktop",
      "rotation": 4
    },
    {
      "x": -7,
      "y": 3,
      "z": 1,
      "name": "BO_Parking_Blacktop",
      "rotation": 4
    },
    {
      "x": -7,
      "y": 4,
      "z": 1,
      "name": "BO_Parking_Curb",
      "filler": 31,
      "rotation": 1
    },
    {
      "x": -7,
      "y": 9,
      "z": 1,
      "name": "BO_Parking_Wall03",
      "rotation": 1
    },
    {
      "x": -7,
      "y": 10,
      "z": 1,
      "name": "BO_Parking_Wall00"
    },
    {
      "x": -7,
      "y": 0,
      "z": 2,
      "name": "BO_Parking_Blacktop",
      "rotation": 4
    },
    {
      "x": -7,
      "y": 1,
      "z": 2,
      "name": "BO_Parking_Blacktop",
      "rotation": 4
    },
    {
      "x": -7,
      "y": 2,
      "z": 2,
      "name": "BO_Parking_Blacktop",
      "rotation": 4
    },
    {
      "x": -7,
      "y": 3,
      "z": 2,
      "name": "BO_Parking_Blacktop",
      "rotation": 4
    },
    {
      "x": -7,
      "y": 9,
      "z": 2,
      "name": "BO_Parking_Wall_Half",
      "rotation": 8
    },
    {
      "x": -7,
      "y": 10,
      "z": 2,
      "name": "BO_Parking_Wall00"
    },
    {
      "x": -7,
      "y": 0,
      "z": 3,
      "name": "BO_Parking_Blacktop",
      "rotation": 4
    },
    {
      "x": -7,
      "y": 1,
      "z": 3,
      "name": "BO_Parking_Blacktop",
      "rotation": 4
    },
    {
      "x": -7,
      "y": 2,
      "z": 3,
      "name": "BO_Parking_Blacktop",
      "rotation": 4
    },
    {
      "x": -7,
      "y": 3,
      "z": 3,
      "name": "BO_Parking_Blacktop",
      "rotation": 4
    },
    {
      "x": -7,
      "y": 9,
      "z": 3,
      "name": "BO_Parking_Wall_Half",
      "rotation": 8
    },
    {
      "x": -7,
      "y": 10,
      "z": 3,
      "name": "BO_Parking_Wall00"
    },
    {
      "x": -7,
      "y": 0,
      "z": 4,
      "name": "BO_Parking_Blacktop",
      "rotation": 4
    },
    {
      "x": -7,
      "y": 1,
      "z": 4,
      "name": "BO_Parking_Blacktop",
      "rotation": 4
    },
    {
      "x": -7,
      "y": 2,
      "z": 4,
      "name": "BO_Parking_Blacktop",
      "rotation": 4
    },
    {
      "x": -7,
      "y": 3,
      "z": 4,
      "name": "BO_Parking_Blacktop",
      "rotation": 4
    },
    {
      "x": -7,
      "y": 9,
      "z": 4,
      "name": "BO_Parking_Wall_Half",
      "rotation": 8
    },
    {
      "x": -7,
      "y": 10,
      "z": 4,
      "name": "BO_Parking_Wall00"
    },
    {
      "x": -7,
      "y": 0,
      "z": 5,
      "name": "BO_Parking_Blacktop",
      "rotation": 4
    },
    {
      "x": -7,
      "y": 1,
      "z": 5,
      "name": "BO_Parking_Blacktop",
      "rotation": 4
    },
    {
      "x": -7,
      "y": 2,
      "z": 5,
      "name": "BO_Parking_Blacktop",
      "rotation": 4
    },
    {
      "x": -7,
      "y": 3,
      "z": 5,
      "name": "BO_Parking_Blacktop",
      "rotation": 4
    },
    {
      "x": -7,
      "y": 9,
      "z": 5,
      "name": "BO_Parking_Wall_Half",
      "rotation": 8
    },
    {
      "x": -7,
      "y": 10,
      "z": 5,
      "name": "BO_Parking_Wall00"
    },
    {
      "x": -7,
      "y": 0,
      "z": 6,
      "name": "BO_Parking_Blacktop",
      "rotation": 4
    },
    {
      "x": -7,
      "y": 1,
      "z": 6,
      "name": "BO_Parking_Blacktop",
      "rotation": 4
    },
    {
      "x": -7,
      "y": 2,
      "z": 6,
      "name": "BO_Parking_Blacktop",
      "rotation": 4
    },
    {
      "x": -7,
      "y": 3,
      "z": 6,
      "name": "BO_Parking_Blacktop",
      "rotation": 4
    },
    {
      "x": -7,
      "y": 9,
      "z": 6,
      "name": "BO_Parking_Wall_Half",
      "rotation": 8
    },
    {
      "x": -7,
      "y": 10,
      "z": 6,
      "name": "BO_Parking_Wall00"
    },
    {
      "x": -7,
      "y": 0,
      "z": 7,
      "name": "BO_Parking_Blacktop",
      "rotation": 4
    },
    {
      "x": -7,
      "y": 1,
      "z": 7,
      "name": "BO_Parking_Blacktop",
      "rotation": 4
    },
    {
      "x": -7,
      "y": 2,
      "z": 7,
      "name": "BO_Parking_Blacktop",
      "rotation": 4
    },
    {
      "x": -7,
      "y": 3,
      "z": 7,
      "name": "BO_Parking_Blacktop",
      "rotation": 4
    },
    {
      "x": -7,
      "y": 9,
      "z": 7,
      "name": "BO_Parking_Wall_Half",
      "rotation": 8
    },
    {
      "x": -7,
      "y": 10,
      "z": 7,
      "name": "BO_Parking_Wall00"
    },
    {
      "x": -7,
      "y": 0,
      "z": 8,
      "name": "BO_Parking_Blacktop",
      "rotation": 4
    },
    {
      "x": -7,
      "y": 1,
      "z": 8,
      "name": "BO_Parking_Blacktop",
      "rotation": 4
    },
    {
      "x": -7,
      "y": 2,
      "z": 8,
      "name": "BO_Parking_Blacktop",
      "rotation": 4
    },
    {
      "x": -7,
      "y": 3,
      "z": 8,
      "name": "BO_Parking_Blacktop",
      "rotation": 4
    },
    {
      "x": -7,
      "y": 9,
      "z": 8,
      "name": "BO_Parking_Wall_Half",
      "rotation": 8
    },
    {
      "x": -7,
      "y": 10,
      "z": 8,
      "name": "BO_Parking_Wall00"
    },
    {
      "x": -7,
      "y": 0,
      "z": 9,
      "name": "BO_Parking_Blacktop",
      "rotation": 4
    },
    {
      "x": -7,
      "y": 1,
      "z": 9,
      "name": "BO_Parking_Blacktop",
      "rotation": 4
    },
    {
      "x": -7,
      "y": 2,
      "z": 9,
      "name": "BO_Parking_Blacktop",
      "rotation": 4
    },
    {
      "x": -7,
      "y": 3,
      "z": 9,
      "name": "BO_Parking_Blacktop",
      "rotation": 4
    },
    {
      "x": -7,
      "y": 9,
      "z": 9,
      "name": "*BO_Garage_Overhead_Lights_State_Definitions_Inactive",
      "components": {
        "Components": {
          "BlackoutCycleState": {
            "OnState": "Inactive",
            "OffState": "Active",
            "OnSound": "Garage_Alarm_Disable"
          },
          "PlacedByInteraction": {
            "WhoPlacedUuid": {
              "$binary": "KMPE5JWxSQGC8WI/IkVLQQ==",
              "$type": "04"
            }
          }
        }
      },
      "rotation": 5
    },
    {
      "x": -7,
      "y": 10,
      "z": 9,
      "name": "BO_Parking_Wall00"
    },
    {
      "x": -7,
      "y": 0,
      "z": 10,
      "name": "BO_Parking_Blacktop",
      "rotation": 4
    },
    {
      "x": -7,
      "y": 1,
      "z": 10,
      "name": "BO_Parking_Blacktop",
      "rotation": 4
    },
    {
      "x": -7,
      "y": 2,
      "z": 10,
      "name": "BO_Parking_Blacktop",
      "rotation": 4
    },
    {
      "x": -7,
      "y": 3,
      "z": 10,
      "name": "BO_Parking_Blacktop",
      "rotation": 4
    },
    {
      "x": -7,
      "y": 9,
      "z": 10,
      "name": "BO_Parking_Wall03"
    },
    {
      "x": -7,
      "y": 10,
      "z": 10,
      "name": "BO_Parking_Wall00"
    },
    {
      "x": -6,
      "y": 0,
      "z": -9,
      "name": "BO_Parking_Blacktop",
      "rotation": 4
    },
    {
      "x": -6,
      "y": 1,
      "z": -9,
      "name": "BO_Parking_Blacktop",
      "rotation": 4
    },
    {
      "x": -6,
      "y": 2,
      "z": -9,
      "name": "BO_Parking_Blacktop",
      "rotation": 4
    },
    {
      "x": -6,
      "y": 3,
      "z": -9,
      "name": "BO_Parking_Blacktop",
      "rotation": 4
    },
    {
      "x": -6,
      "y": 9,
      "z": -9,
      "name": "BO_Parking_Wall03"
    },
    {
      "x": -6,
      "y": 10,
      "z": -9,
      "name": "BO_Parking_Wall00"
    },
    {
      "x": -6,
      "y": 0,
      "z": -8,
      "name": "BO_Parking_Blacktop",
      "rotation": 4
    },
    {
      "x": -6,
      "y": 1,
      "z": -8,
      "name": "BO_Parking_Blacktop",
      "rotation": 4
    },
    {
      "x": -6,
      "y": 2,
      "z": -8,
      "name": "BO_Parking_Blacktop",
      "rotation": 4
    },
    {
      "x": -6,
      "y": 3,
      "z": -8,
      "name": "BO_Parking_Blacktop",
      "rotation": 4
    },
    {
      "x": -6,
      "y": 9,
      "z": -8,
      "name": "BO_Parking_Wall_Half",
      "rotation": 8
    },
    {
      "x": -6,
      "y": 10,
      "z": -8,
      "name": "BO_Parking_Wall00"
    },
    {
      "x": -6,
      "y": 0,
      "z": -7,
      "name": "BO_Parking_Blacktop",
      "rotation": 4
    },
    {
      "x": -6,
      "y": 1,
      "z": -7,
      "name": "BO_Parking_Blacktop",
      "rotation": 4
    },
    {
      "x": -6,
      "y": 2,
      "z": -7,
      "name": "BO_Parking_Blacktop",
      "rotation": 4
    },
    {
      "x": -6,
      "y": 3,
      "z": -7,
      "name": "BO_Parking_Blacktop",
      "rotation": 4
    },
    {
      "x": -6,
      "y": 9,
      "z": -7,
      "name": "BO_Parking_Wall_Half",
      "rotation": 8
    },
    {
      "x": -6,
      "y": 10,
      "z": -7,
      "name": "BO_Parking_Wall00"
    },
    {
      "x": -6,
      "y": 0,
      "z": -6,
      "name": "BO_Parking_Blacktop",
      "rotation": 4
    },
    {
      "x": -6,
      "y": 1,
      "z": -6,
      "name": "BO_Parking_Blacktop",
      "rotation": 4
    },
    {
      "x": -6,
      "y": 2,
      "z": -6,
      "name": "BO_Parking_Blacktop",
      "rotation": 4
    },
    {
      "x": -6,
      "y": 3,
      "z": -6,
      "name": "BO_Parking_Blacktop",
      "rotation": 4
    },
    {
      "x": -6,
      "y": 9,
      "z": -6,
      "name": "BO_Parking_Wall_Half",
      "rotation": 8
    },
    {
      "x": -6,
      "y": 10,
      "z": -6,
      "name": "BO_Parking_Wall00"
    },
    {
      "x": -6,
      "y": 0,
      "z": -5,
      "name": "BO_Parking_Blacktop",
      "rotation": 4
    },
    {
      "x": -6,
      "y": 1,
      "z": -5,
      "name": "BO_Parking_Blacktop",
      "rotation": 4
    },
    {
      "x": -6,
      "y": 2,
      "z": -5,
      "name": "BO_Parking_Blacktop",
      "rotation": 4
    },
    {
      "x": -6,
      "y": 3,
      "z": -5,
      "name": "BO_Parking_Blacktop",
      "rotation": 4
    },
    {
      "x": -6,
      "y": 9,
      "z": -5,
      "name": "BO_Parking_Wall_Half",
      "rotation": 8
    },
    {
      "x": -6,
      "y": 10,
      "z": -5,
      "name": "BO_Parking_Wall00"
    },
    {
      "x": -6,
      "y": 0,
      "z": -4,
      "name": "BO_Parking_Blacktop",
      "rotation": 4
    },
    {
      "x": -6,
      "y": 1,
      "z": -4,
      "name": "BO_Parking_Blacktop",
      "rotation": 4
    },
    {
      "x": -6,
      "y": 2,
      "z": -4,
      "name": "BO_Parking_Blacktop",
      "rotation": 4
    },
    {
      "x": -6,
      "y": 3,
      "z": -4,
      "name": "BO_Parking_Blacktop",
      "rotation": 4
    },
    {
      "x": -6,
      "y": 9,
      "z": -4,
      "name": "BO_Parking_Wall_Half",
      "rotation": 8
    },
    {
      "x": -6,
      "y": 10,
      "z": -4,
      "name": "BO_Parking_Wall00"
    },
    {
      "x": -6,
      "y": 0,
      "z": -3,
      "name": "BO_Parking_Blacktop",
      "rotation": 4
    },
    {
      "x": -6,
      "y": 1,
      "z": -3,
      "name": "BO_Parking_Blacktop",
      "rotation": 4
    },
    {
      "x": -6,
      "y": 2,
      "z": -3,
      "name": "BO_Parking_Blacktop",
      "rotation": 4
    },
    {
      "x": -6,
      "y": 3,
      "z": -3,
      "name": "BO_Parking_Blacktop",
      "rotation": 4
    },
    {
      "x": -6,
      "y": 9,
      "z": -3,
      "name": "BO_Parking_Wall_Half",
      "rotation": 8
    },
    {
      "x": -6,
      "y": 10,
      "z": -3,
      "name": "BO_Parking_Wall00"
    },
    {
      "x": -6,
      "y": 0,
      "z": -2,
      "name": "BO_Parking_Blacktop",
      "rotation": 4
    },
    {
      "x": -6,
      "y": 1,
      "z": -2,
      "name": "BO_Parking_Blacktop",
      "rotation": 4
    },
    {
      "x": -6,
      "y": 2,
      "z": -2,
      "name": "BO_Parking_Blacktop",
      "rotation": 4
    },
    {
      "x": -6,
      "y": 3,
      "z": -2,
      "name": "BO_Parking_Blacktop",
      "rotation": 4
    },
    {
      "x": -6,
      "y": 9,
      "z": -2,
      "name": "BO_Parking_Wall_Half",
      "rotation": 8
    },
    {
      "x": -6,
      "y": 10,
      "z": -2,
      "name": "BO_Parking_Wall00"
    },
    {
      "x": -6,
      "y": 0,
      "z": -1,
      "name": "BO_Parking_Blacktop",
      "rotation": 4
    },
    {
      "x": -6,
      "y": 1,
      "z": -1,
      "name": "BO_Parking_Blacktop",
      "rotation": 4
    },
    {
      "x": -6,
      "y": 2,
      "z": -1,
      "name": "BO_Parking_Blacktop",
      "rotation": 4
    },
    {
      "x": -6,
      "y": 3,
      "z": -1,
      "name": "BO_Parking_Blacktop"
    },
    {
      "x": -6,
      "y": 9,
      "z": -1,
      "name": "BO_Parking_Wall_Half",
      "rotation": 8
    },
    {
      "x": -6,
      "y": 10,
      "z": -1,
      "name": "BO_Parking_Wall00"
    },
    {
      "x": -6,
      "y": 0,
      "z": 0,
      "name": "BO_Parking_Blacktop",
      "rotation": 4
    },
    {
      "x": -6,
      "y": 1,
      "z": 0,
      "name": "BO_Parking_Blacktop",
      "rotation": 4
    },
    {
      "x": -6,
      "y": 2,
      "z": 0,
      "name": "BO_Parking_Blacktop",
      "rotation": 4
    },
    {
      "x": -6,
      "y": 3,
      "z": 0,
      "name": "BO_Parking_Blacktop",
      "rotation": 4
    },
    {
      "x": -6,
      "y": 4,
      "z": 0,
      "name": "BO_Parking_Curb",
      "filler": 1,
      "rotation": 1
    },
    {
      "x": -6,
      "y": 9,
      "z": 0,
      "name": "BO_Parking_Wall03",
      "rotation": 1
    },
    {
      "x": -6,
      "y": 10,
      "z": 0,
      "name": "BO_Parking_Wall00"
    },
    {
      "x": -6,
      "y": 0,
      "z": 1,
      "name": "BO_Parking_Blacktop",
      "rotation": 4
    },
    {
      "x": -6,
      "y": 1,
      "z": 1,
      "name": "BO_Parking_Blacktop",
      "rotation": 4
    },
    {
      "x": -6,
      "y": 2,
      "z": 1,
      "name": "BO_Parking_Blacktop",
      "rotation": 4
    },
    {
      "x": -6,
      "y": 3,
      "z": 1,
      "name": "BO_Parking_Blacktop",
      "rotation": 4
    },
    {
      "x": -6,
      "y": 4,
      "z": 1,
      "name": "BO_Parking_Curb",
      "support": 15,
      "rotation": 1
    },
    {
      "x": -6,
      "y": 9,
      "z": 1,
      "name": "BO_Parking_Wall03",
      "rotation": 1
    },
    {
      "x": -6,
      "y": 10,
      "z": 1,
      "name": "BO_Parking_Wall00"
    },
    {
      "x": -6,
      "y": 0,
      "z": 2,
      "name": "BO_Parking_Blacktop",
      "rotation": 4
    },
    {
      "x": -6,
      "y": 1,
      "z": 2,
      "name": "BO_Parking_Blacktop",
      "rotation": 4
    },
    {
      "x": -6,
      "y": 2,
      "z": 2,
      "name": "BO_Parking_Blacktop",
      "rotation": 4
    },
    {
      "x": -6,
      "y": 3,
      "z": 2,
      "name": "BO_Parking_Blacktop",
      "rotation": 4
    },
    {
      "x": -6,
      "y": 9,
      "z": 2,
      "name": "BO_Parking_Wall_Half",
      "rotation": 8
    },
    {
      "x": -6,
      "y": 10,
      "z": 2,
      "name": "BO_Parking_Wall00"
    },
    {
      "x": -6,
      "y": 0,
      "z": 3,
      "name": "BO_Parking_Blacktop",
      "rotation": 4
    },
    {
      "x": -6,
      "y": 1,
      "z": 3,
      "name": "BO_Parking_Blacktop",
      "rotation": 4
    },
    {
      "x": -6,
      "y": 2,
      "z": 3,
      "name": "BO_Parking_Blacktop",
      "rotation": 4
    },
    {
      "x": -6,
      "y": 3,
      "z": 3,
      "name": "BO_Parking_Blacktop",
      "rotation": 4
    },
    {
      "x": -6,
      "y": 9,
      "z": 3,
      "name": "BO_Parking_Wall_Half",
      "rotation": 8
    },
    {
      "x": -6,
      "y": 10,
      "z": 3,
      "name": "BO_Parking_Wall00"
    },
    {
      "x": -6,
      "y": 0,
      "z": 4,
      "name": "BO_Parking_Blacktop",
      "rotation": 4
    },
    {
      "x": -6,
      "y": 1,
      "z": 4,
      "name": "BO_Parking_Blacktop",
      "rotation": 4
    },
    {
      "x": -6,
      "y": 2,
      "z": 4,
      "name": "BO_Parking_Blacktop",
      "rotation": 4
    },
    {
      "x": -6,
      "y": 3,
      "z": 4,
      "name": "BO_Parking_Blacktop",
      "rotation": 4
    },
    {
      "x": -6,
      "y": 9,
      "z": 4,
      "name": "BO_Parking_Wall_Half",
      "rotation": 8
    },
    {
      "x": -6,
      "y": 10,
      "z": 4,
      "name": "BO_Parking_Wall00"
    },
    {
      "x": -6,
      "y": 0,
      "z": 5,
      "name": "BO_Parking_Blacktop",
      "rotation": 4
    },
    {
      "x": -6,
      "y": 1,
      "z": 5,
      "name": "BO_Parking_Blacktop",
      "rotation": 4
    },
    {
      "x": -6,
      "y": 2,
      "z": 5,
      "name": "BO_Parking_Blacktop",
      "rotation": 4
    },
    {
      "x": -6,
      "y": 3,
      "z": 5,
      "name": "BO_Parking_Blacktop",
      "rotation": 4
    },
    {
      "x": -6,
      "y": 9,
      "z": 5,
      "name": "BO_Parking_Wall_Half",
      "rotation": 8
    },
    {
      "x": -6,
      "y": 10,
      "z": 5,
      "name": "BO_Parking_Wall00"
    },
    {
      "x": -6,
      "y": 0,
      "z": 6,
      "name": "BO_Parking_Blacktop",
      "rotation": 4
    },
    {
      "x": -6,
      "y": 1,
      "z": 6,
      "name": "BO_Parking_Blacktop",
      "rotation": 4
    },
    {
      "x": -6,
      "y": 2,
      "z": 6,
      "name": "BO_Parking_Blacktop",
      "rotation": 4
    },
    {
      "x": -6,
      "y": 3,
      "z": 6,
      "name": "BO_Parking_Blacktop",
      "rotation": 4
    },
    {
      "x": -6,
      "y": 9,
      "z": 6,
      "name": "BO_Parking_Wall_Half",
      "rotation": 8
    },
    {
      "x": -6,
      "y": 10,
      "z": 6,
      "name": "BO_Parking_Wall00"
    },
    {
      "x": -6,
      "y": 0,
      "z": 7,
      "name": "BO_Parking_Blacktop",
      "rotation": 4
    },
    {
      "x": -6,
      "y": 1,
      "z": 7,
      "name": "BO_Parking_Blacktop",
      "rotation": 4
    },
    {
      "x": -6,
      "y": 2,
      "z": 7,
      "name": "BO_Parking_Blacktop",
      "rotation": 4
    },
    {
      "x": -6,
      "y": 3,
      "z": 7,
      "name": "BO_Parking_Blacktop",
      "rotation": 4
    },
    {
      "x": -6,
      "y": 9,
      "z": 7,
      "name": "BO_Parking_Wall_Half",
      "rotation": 8
    },
    {
      "x": -6,
      "y": 10,
      "z": 7,
      "name": "BO_Parking_Wall00"
    },
    {
      "x": -6,
      "y": 0,
      "z": 8,
      "name": "BO_Parking_Blacktop",
      "rotation": 4
    },
    {
      "x": -6,
      "y": 1,
      "z": 8,
      "name": "BO_Parking_Blacktop",
      "rotation": 4
    },
    {
      "x": -6,
      "y": 2,
      "z": 8,
      "name": "BO_Parking_Blacktop",
      "rotation": 4
    },
    {
      "x": -6,
      "y": 3,
      "z": 8,
      "name": "BO_Parking_Blacktop",
      "rotation": 4
    },
    {
      "x": -6,
      "y": 9,
      "z": 8,
      "name": "BO_Parking_Wall_Half",
      "rotation": 8
    },
    {
      "x": -6,
      "y": 10,
      "z": 8,
      "name": "BO_Parking_Wall00"
    },
    {
      "x": -6,
      "y": 0,
      "z": 9,
      "name": "BO_Parking_Blacktop",
      "rotation": 4
    },
    {
      "x": -6,
      "y": 1,
      "z": 9,
      "name": "BO_Parking_Blacktop",
      "rotation": 4
    },
    {
      "x": -6,
      "y": 2,
      "z": 9,
      "name": "BO_Parking_Blacktop",
      "rotation": 4
    },
    {
      "x": -6,
      "y": 3,
      "z": 9,
      "name": "BO_Parking_Blacktop"
    },
    {
      "x": -6,
      "y": 9,
      "z": 9,
      "name": "BO_Parking_Wall_Half",
      "rotation": 8
    },
    {
      "x": -6,
      "y": 10,
      "z": 9,
      "name": "BO_Parking_Wall00"
    },
    {
      "x": -6,
      "y": 0,
      "z": 10,
      "name": "BO_Parking_Blacktop",
      "rotation": 4
    },
    {
      "x": -6,
      "y": 1,
      "z": 10,
      "name": "BO_Parking_Blacktop",
      "rotation": 4
    },
    {
      "x": -6,
      "y": 2,
      "z": 10,
      "name": "BO_Parking_Blacktop",
      "rotation": 4
    },
    {
      "x": -6,
      "y": 3,
      "z": 10,
      "name": "BO_Parking_Blacktop",
      "rotation": 4
    },
    {
      "x": -6,
      "y": 9,
      "z": 10,
      "name": "BO_Parking_Wall03"
    },
    {
      "x": -6,
      "y": 10,
      "z": 10,
      "name": "BO_Parking_Wall00"
    },
    {
      "x": -5,
      "y": 0,
      "z": -9,
      "name": "BO_Parking_Blacktop",
      "rotation": 4
    },
    {
      "x": -5,
      "y": 1,
      "z": -9,
      "name": "BO_Parking_Blacktop",
      "rotation": 4
    },
    {
      "x": -5,
      "y": 2,
      "z": -9,
      "name": "BO_Parking_Blacktop",
      "rotation": 4
    },
    {
      "x": -5,
      "y": 3,
      "z": -9,
      "name": "BO_Parking_Blacktop",
      "rotation": 2
    },
    {
      "x": -5,
      "y": 9,
      "z": -9,
      "name": "BO_Parking_Wall03"
    },
    {
      "x": -5,
      "y": 10,
      "z": -9,
      "name": "BO_Parking_Wall00"
    },
    {
      "x": -5,
      "y": 0,
      "z": -8,
      "name": "BO_Parking_Blacktop",
      "rotation": 4
    },
    {
      "x": -5,
      "y": 1,
      "z": -8,
      "name": "BO_Parking_Blacktop",
      "rotation": 4
    },
    {
      "x": -5,
      "y": 2,
      "z": -8,
      "name": "BO_Parking_Blacktop",
      "rotation": 4
    },
    {
      "x": -5,
      "y": 3,
      "z": -8,
      "name": "BO_Parking_Blacktop",
      "rotation": 4
    },
    {
      "x": -5,
      "y": 9,
      "z": -8,
      "name": "BO_Parking_Wall_Half",
      "rotation": 8
    },
    {
      "x": -5,
      "y": 10,
      "z": -8,
      "name": "BO_Parking_Wall00"
    },
    {
      "x": -5,
      "y": 0,
      "z": -7,
      "name": "BO_Parking_Blacktop",
      "rotation": 4
    },
    {
      "x": -5,
      "y": 1,
      "z": -7,
      "name": "BO_Parking_Blacktop",
      "rotation": 4
    },
    {
      "x": -5,
      "y": 2,
      "z": -7,
      "name": "BO_Parking_Blacktop",
      "rotation": 4
    },
    {
      "x": -5,
      "y": 3,
      "z": -7,
      "name": "BO_Parking_Blacktop",
      "rotation": 4
    },
    {
      "x": -5,
      "y": 9,
      "z": -7,
      "name": "BO_Parking_Wall_Half",
      "rotation": 8
    },
    {
      "x": -5,
      "y": 10,
      "z": -7,
      "name": "BO_Parking_Wall00"
    },
    {
      "x": -5,
      "y": 0,
      "z": -6,
      "name": "Rock_Stone_Brick",
      "rotation": 5
    },
    {
      "x": -5,
      "y": 1,
      "z": -6,
      "name": "Rock_Stone_Brick",
      "rotation": 5
    },
    {
      "x": -5,
      "y": 2,
      "z": -6,
      "name": "Rock_Stone_Brick",
      "rotation": 5
    },
    {
      "x": -5,
      "y": 3,
      "z": -6,
      "name": "BO_Parking_Blacktop"
    },
    {
      "x": -5,
      "y": 9,
      "z": -6,
      "name": "BO_Parking_Wall_Half",
      "rotation": 8
    },
    {
      "x": -5,
      "y": 10,
      "z": -6,
      "name": "BO_Parking_Wall00"
    },
    {
      "x": -5,
      "y": 0,
      "z": -5,
      "name": "Rock_Stone_Brick",
      "rotation": 4
    },
    {
      "x": -5,
      "y": 1,
      "z": -5,
      "name": "Rock_Stone_Brick",
      "rotation": 4
    },
    {
      "x": -5,
      "y": 2,
      "z": -5,
      "name": "Rock_Stone_Brick",
      "rotation": 4
    },
    {
      "x": -5,
      "y": 3,
      "z": -5,
      "name": "BO_Parking_Blacktop",
      "rotation": 4
    },
    {
      "x": -5,
      "y": 9,
      "z": -5,
      "name": "BO_Parking_Wall_Half",
      "rotation": 8
    },
    {
      "x": -5,
      "y": 10,
      "z": -5,
      "name": "BO_Parking_Wall00"
    },
    {
      "x": -5,
      "y": 0,
      "z": -4,
      "name": "Rock_Stone_Brick",
      "rotation": 4
    },
    {
      "x": -5,
      "y": 1,
      "z": -4,
      "name": "Rock_Stone_Brick",
      "rotation": 4
    },
    {
      "x": -5,
      "y": 2,
      "z": -4,
      "name": "Rock_Stone_Brick",
      "rotation": 4
    },
    {
      "x": -5,
      "y": 3,
      "z": -4,
      "name": "BO_Parking_Blacktop",
      "rotation": 4
    },
    {
      "x": -5,
      "y": 9,
      "z": -4,
      "name": "BO_Parking_Wall_Half",
      "rotation": 8
    },
    {
      "x": -5,
      "y": 10,
      "z": -4,
      "name": "BO_Parking_Wall00"
    },
    {
      "x": -5,
      "y": 0,
      "z": -3,
      "name": "BO_Parking_Blacktop",
      "rotation": 4
    },
    {
      "x": -5,
      "y": 1,
      "z": -3,
      "name": "BO_Parking_Blacktop",
      "rotation": 4
    },
    {
      "x": -5,
      "y": 2,
      "z": -3,
      "name": "BO_Parking_Blacktop",
      "rotation": 4
    },
    {
      "x": -5,
      "y": 3,
      "z": -3,
      "name": "BO_Parking_Blacktop01",
      "support": 15,
      "rotation": 1
    },
    {
      "x": -5,
      "y": 9,
      "z": -3,
      "name": "BO_Parking_Wall_Half",
      "rotation": 8
    },
    {
      "x": -5,
      "y": 10,
      "z": -3,
      "name": "BO_Parking_Wall00"
    },
    {
      "x": -5,
      "y": 0,
      "z": -2,
      "name": "BO_Parking_Blacktop",
      "rotation": 4
    },
    {
      "x": -5,
      "y": 1,
      "z": -2,
      "name": "BO_Parking_Blacktop",
      "rotation": 4
    },
    {
      "x": -5,
      "y": 2,
      "z": -2,
      "name": "BO_Parking_Blacktop",
      "rotation": 4
    },
    {
      "x": -5,
      "y": 3,
      "z": -2,
      "name": "BO_Parking_Blacktop01",
      "support": 15,
      "rotation": 3
    },
    {
      "x": -5,
      "y": 9,
      "z": -2,
      "name": "BO_Parking_Wall_Half",
      "rotation": 8
    },
    {
      "x": -5,
      "y": 10,
      "z": -2,
      "name": "BO_Parking_Wall00"
    },
    {
      "x": -5,
      "y": 0,
      "z": -1,
      "name": "BO_Parking_Blacktop",
      "rotation": 4
    },
    {
      "x": -5,
      "y": 1,
      "z": -1,
      "name": "BO_Parking_Blacktop",
      "rotation": 4
    },
    {
      "x": -5,
      "y": 2,
      "z": -1,
      "name": "BO_Parking_Blacktop",
      "rotation": 4
    },
    {
      "x": -5,
      "y": 3,
      "z": -1,
      "name": "BO_Parking_Blacktop01",
      "support": 15,
      "rotation": 3
    },
    {
      "x": -5,
      "y": 9,
      "z": -1,
      "name": "BO_Parking_Wall_Half",
      "rotation": 8
    },
    {
      "x": -5,
      "y": 10,
      "z": -1,
      "name": "BO_Parking_Wall00"
    },
    {
      "x": -5,
      "y": 0,
      "z": 0,
      "name": "BO_Parking_Blacktop",
      "rotation": 4
    },
    {
      "x": -5,
      "y": 1,
      "z": 0,
      "name": "BO_Parking_Blacktop",
      "rotation": 4
    },
    {
      "x": -5,
      "y": 2,
      "z": 0,
      "name": "BO_Parking_Blacktop",
      "rotation": 4
    },
    {
      "x": -5,
      "y": 3,
      "z": 0,
      "name": "BO_Parking_Blacktop01",
      "support": 15,
      "rotation": 3
    },
    {
      "x": -5,
      "y": 4,
      "z": 0,
      "name": "BO_Parking_Curb",
      "filler": 31,
      "rotation": 1
    },
    {
      "x": -5,
      "y": 9,
      "z": 0,
      "name": "BO_Parking_Wall03",
      "rotation": 1
    },
    {
      "x": -5,
      "y": 10,
      "z": 0,
      "name": "BO_Parking_Wall00"
    },
    {
      "x": -5,
      "y": 0,
      "z": 1,
      "name": "BO_Parking_Blacktop",
      "rotation": 4
    },
    {
      "x": -5,
      "y": 1,
      "z": 1,
      "name": "BO_Parking_Blacktop",
      "rotation": 4
    },
    {
      "x": -5,
      "y": 2,
      "z": 1,
      "name": "BO_Parking_Blacktop",
      "rotation": 4
    },
    {
      "x": -5,
      "y": 3,
      "z": 1,
      "name": "BO_Parking_Blacktop01",
      "support": 15,
      "rotation": 3
    },
    {
      "x": -5,
      "y": 4,
      "z": 1,
      "name": "BO_Parking_Curb",
      "filler": 1,
      "rotation": 1
    },
    {
      "x": -5,
      "y": 9,
      "z": 1,
      "name": "BO_Parking_Wall03",
      "rotation": 1
    },
    {
      "x": -5,
      "y": 10,
      "z": 1,
      "name": "BO_Parking_Wall00"
    },
    {
      "x": -5,
      "y": 0,
      "z": 2,
      "name": "BO_Parking_Blacktop",
      "rotation": 4
    },
    {
      "x": -5,
      "y": 1,
      "z": 2,
      "name": "BO_Parking_Blacktop",
      "rotation": 4
    },
    {
      "x": -5,
      "y": 2,
      "z": 2,
      "name": "BO_Parking_Blacktop",
      "rotation": 4
    },
    {
      "x": -5,
      "y": 3,
      "z": 2,
      "name": "BO_Parking_Blacktop01",
      "support": 15,
      "rotation": 3
    },
    {
      "x": -5,
      "y": 9,
      "z": 2,
      "name": "BO_Parking_Wall_Half",
      "rotation": 8
    },
    {
      "x": -5,
      "y": 10,
      "z": 2,
      "name": "BO_Parking_Wall00"
    },
    {
      "x": -5,
      "y": 0,
      "z": 3,
      "name": "BO_Parking_Blacktop",
      "rotation": 4
    },
    {
      "x": -5,
      "y": 1,
      "z": 3,
      "name": "BO_Parking_Blacktop",
      "rotation": 4
    },
    {
      "x": -5,
      "y": 2,
      "z": 3,
      "name": "BO_Parking_Blacktop",
      "rotation": 4
    },
    {
      "x": -5,
      "y": 3,
      "z": 3,
      "name": "BO_Parking_Blacktop01",
      "support": 15,
      "rotation": 3
    },
    {
      "x": -5,
      "y": 9,
      "z": 3,
      "name": "BO_Parking_Wall_Half",
      "rotation": 8
    },
    {
      "x": -5,
      "y": 10,
      "z": 3,
      "name": "BO_Parking_Wall00"
    },
    {
      "x": -5,
      "y": 0,
      "z": 4,
      "name": "Rock_Stone_Brick",
      "rotation": 5
    },
    {
      "x": -5,
      "y": 1,
      "z": 4,
      "name": "Rock_Stone_Brick",
      "rotation": 5
    },
    {
      "x": -5,
      "y": 2,
      "z": 4,
      "name": "Rock_Stone_Brick",
      "rotation": 5
    },
    {
      "x": -5,
      "y": 3,
      "z": 4,
      "name": "BO_Parking_Blacktop01",
      "support": 15,
      "rotation": 3
    },
    {
      "x": -5,
      "y": 9,
      "z": 4,
      "name": "BO_Parking_Wall_Half",
      "rotation": 8
    },
    {
      "x": -5,
      "y": 10,
      "z": 4,
      "name": "BO_Parking_Wall00"
    },
    {
      "x": -5,
      "y": 0,
      "z": 5,
      "name": "Rock_Stone_Brick",
      "rotation": 4
    },
    {
      "x": -5,
      "y": 1,
      "z": 5,
      "name": "Rock_Stone_Brick",
      "rotation": 4
    },
    {
      "x": -5,
      "y": 2,
      "z": 5,
      "name": "Rock_Stone_Brick",
      "rotation": 4
    },
    {
      "x": -5,
      "y": 3,
      "z": 5,
      "name": "BO_Parking_Blacktop",
      "rotation": 4
    },
    {
      "x": -5,
      "y": 9,
      "z": 5,
      "name": "BO_Parking_Wall_Half",
      "rotation": 8
    },
    {
      "x": -5,
      "y": 10,
      "z": 5,
      "name": "BO_Parking_Wall00"
    },
    {
      "x": -5,
      "y": 0,
      "z": 6,
      "name": "Rock_Stone_Brick",
      "rotation": 4
    },
    {
      "x": -5,
      "y": 1,
      "z": 6,
      "name": "Rock_Stone_Brick",
      "rotation": 4
    },
    {
      "x": -5,
      "y": 2,
      "z": 6,
      "name": "Rock_Stone_Brick",
      "rotation": 4
    },
    {
      "x": -5,
      "y": 3,
      "z": 6,
      "name": "BO_Parking_Blacktop",
      "rotation": 4
    },
    {
      "x": -5,
      "y": 9,
      "z": 6,
      "name": "BO_Parking_Wall_Half",
      "rotation": 8
    },
    {
      "x": -5,
      "y": 10,
      "z": 6,
      "name": "BO_Parking_Wall00"
    },
    {
      "x": -5,
      "y": 0,
      "z": 7,
      "name": "BO_Parking_Blacktop",
      "rotation": 4
    },
    {
      "x": -5,
      "y": 1,
      "z": 7,
      "name": "BO_Parking_Blacktop",
      "rotation": 4
    },
    {
      "x": -5,
      "y": 2,
      "z": 7,
      "name": "BO_Parking_Blacktop",
      "rotation": 4
    },
    {
      "x": -5,
      "y": 3,
      "z": 7,
      "name": "BO_Parking_Blacktop",
      "rotation": 4
    },
    {
      "x": -5,
      "y": 9,
      "z": 7,
      "name": "BO_Parking_Wall_Half",
      "rotation": 8
    },
    {
      "x": -5,
      "y": 10,
      "z": 7,
      "name": "BO_Parking_Wall00"
    },
    {
      "x": -5,
      "y": 0,
      "z": 8,
      "name": "BO_Parking_Blacktop",
      "rotation": 4
    },
    {
      "x": -5,
      "y": 1,
      "z": 8,
      "name": "BO_Parking_Blacktop",
      "rotation": 4
    },
    {
      "x": -5,
      "y": 2,
      "z": 8,
      "name": "BO_Parking_Blacktop",
      "rotation": 4
    },
    {
      "x": -5,
      "y": 3,
      "z": 8,
      "name": "BO_Parking_Blacktop",
      "rotation": 4
    },
    {
      "x": -5,
      "y": 9,
      "z": 8,
      "name": "BO_Parking_Wall_Half",
      "rotation": 8
    },
    {
      "x": -5,
      "y": 10,
      "z": 8,
      "name": "BO_Parking_Wall00"
    },
    {
      "x": -5,
      "y": 0,
      "z": 9,
      "name": "BO_Parking_Blacktop",
      "rotation": 4
    },
    {
      "x": -5,
      "y": 1,
      "z": 9,
      "name": "BO_Parking_Blacktop",
      "rotation": 4
    },
    {
      "x": -5,
      "y": 2,
      "z": 9,
      "name": "BO_Parking_Blacktop",
      "rotation": 4
    },
    {
      "x": -5,
      "y": 3,
      "z": 9,
      "name": "BO_Parking_Blacktop"
    },
    {
      "x": -5,
      "y": 9,
      "z": 9,
      "name": "BO_Parking_Wall_Half",
      "rotation": 8
    },
    {
      "x": -5,
      "y": 10,
      "z": 9,
      "name": "BO_Parking_Wall00"
    },
    {
      "x": -5,
      "y": 0,
      "z": 10,
      "name": "BO_Parking_Blacktop",
      "rotation": 4
    },
    {
      "x": -5,
      "y": 1,
      "z": 10,
      "name": "BO_Parking_Blacktop",
      "rotation": 4
    },
    {
      "x": -5,
      "y": 2,
      "z": 10,
      "name": "BO_Parking_Blacktop",
      "rotation": 4
    },
    {
      "x": -5,
      "y": 3,
      "z": 10,
      "name": "BO_Parking_Blacktop"
    },
    {
      "x": -5,
      "y": 9,
      "z": 10,
      "name": "BO_Parking_Wall03"
    },
    {
      "x": -5,
      "y": 10,
      "z": 10,
      "name": "BO_Parking_Wall00"
    },
    {
      "x": -4,
      "y": 0,
      "z": -9,
      "name": "BO_Parking_Blacktop",
      "rotation": 4
    },
    {
      "x": -4,
      "y": 1,
      "z": -9,
      "name": "BO_Parking_Blacktop",
      "rotation": 4
    },
    {
      "x": -4,
      "y": 2,
      "z": -9,
      "name": "BO_Parking_Blacktop",
      "rotation": 4
    },
    {
      "x": -4,
      "y": 3,
      "z": -9,
      "name": "BO_Parking_Blacktop",
      "rotation": 2
    },
    {
      "x": -4,
      "y": 9,
      "z": -9,
      "name": "BO_Parking_Wall03"
    },
    {
      "x": -4,
      "y": 10,
      "z": -9,
      "name": "BO_Parking_Wall00"
    },
    {
      "x": -4,
      "y": 0,
      "z": -8,
      "name": "BO_Parking_Blacktop",
      "rotation": 4
    },
    {
      "x": -4,
      "y": 1,
      "z": -8,
      "name": "BO_Parking_Blacktop",
      "rotation": 4
    },
    {
      "x": -4,
      "y": 2,
      "z": -8,
      "name": "BO_Parking_Blacktop",
      "rotation": 4
    },
    {
      "x": -4,
      "y": 3,
      "z": -8,
      "name": "BO_Parking_Blacktop",
      "rotation": 4
    },
    {
      "x": -4,
      "y": 9,
      "z": -8,
      "name": "BO_Parking_Wall_Half",
      "rotation": 8
    },
    {
      "x": -4,
      "y": 10,
      "z": -8,
      "name": "BO_Parking_Wall00"
    },
    {
      "x": -4,
      "y": 0,
      "z": -7,
      "name": "BO_Parking_Blacktop",
      "rotation": 4
    },
    {
      "x": -4,
      "y": 1,
      "z": -7,
      "name": "BO_Parking_Blacktop",
      "rotation": 4
    },
    {
      "x": -4,
      "y": 2,
      "z": -7,
      "name": "BO_Parking_Blacktop",
      "rotation": 4
    },
    {
      "x": -4,
      "y": 3,
      "z": -7,
      "name": "BO_Parking_Blacktop",
      "rotation": 4
    },
    {
      "x": -4,
      "y": 9,
      "z": -7,
      "name": "BO_Parking_Wall_Half",
      "rotation": 8
    },
    {
      "x": -4,
      "y": 10,
      "z": -7,
      "name": "BO_Parking_Wall00"
    },
    {
      "x": -4,
      "y": 0,
      "z": -6,
      "name": "Rock_Stone_Brick",
      "rotation": 4
    },
    {
      "x": -4,
      "y": 1,
      "z": -6,
      "name": "Rock_Stone_Brick",
      "rotation": 4
    },
    {
      "x": -4,
      "y": 2,
      "z": -6,
      "name": "Rock_Stone_Brick",
      "rotation": 4
    },
    {
      "x": -4,
      "y": 3,
      "z": -6,
      "name": "BO_Parking_Blacktop"
    },
    {
      "x": -4,
      "y": 9,
      "z": -6,
      "name": "BO_Parking_Wall_Half",
      "rotation": 8
    },
    {
      "x": -4,
      "y": 10,
      "z": -6,
      "name": "BO_Parking_Wall00"
    },
    {
      "x": -4,
      "y": 0,
      "z": -5,
      "name": "BO_Parking_Blacktop",
      "rotation": 4
    },
    {
      "x": -4,
      "y": 1,
      "z": -5,
      "name": "BO_Parking_Blacktop",
      "rotation": 4
    },
    {
      "x": -4,
      "y": 2,
      "z": -5,
      "name": "BO_Parking_Blacktop",
      "rotation": 4
    },
    {
      "x": -4,
      "y": 3,
      "z": -5,
      "name": "BO_Parking_Blacktop",
      "rotation": 4
    },
    {
      "x": -4,
      "y": 9,
      "z": -5,
      "name": "BO_Parking_Wall_Half",
      "rotation": 8
    },
    {
      "x": -4,
      "y": 10,
      "z": -5,
      "name": "BO_Parking_Wall00"
    },
    {
      "x": -4,
      "y": 0,
      "z": -4,
      "name": "Rock_Stone_Brick",
      "rotation": 4
    },
    {
      "x": -4,
      "y": 1,
      "z": -4,
      "name": "Rock_Stone_Brick",
      "rotation": 4
    },
    {
      "x": -4,
      "y": 2,
      "z": -4,
      "name": "Rock_Stone_Brick",
      "rotation": 4
    },
    {
      "x": -4,
      "y": 3,
      "z": -4,
      "name": "BO_Parking_Blacktop",
      "rotation": 4
    },
    {
      "x": -4,
      "y": 9,
      "z": -4,
      "name": "BO_Parking_Wall_Half",
      "rotation": 8
    },
    {
      "x": -4,
      "y": 10,
      "z": -4,
      "name": "BO_Parking_Wall00"
    },
    {
      "x": -4,
      "y": 0,
      "z": -3,
      "name": "BO_Parking_Blacktop",
      "rotation": 4
    },
    {
      "x": -4,
      "y": 1,
      "z": -3,
      "name": "BO_Parking_Blacktop",
      "rotation": 4
    },
    {
      "x": -4,
      "y": 2,
      "z": -3,
      "name": "BO_Parking_Blacktop",
      "rotation": 4
    },
    {
      "x": -4,
      "y": 3,
      "z": -3,
      "name": "BO_Parking_Blacktop",
      "rotation": 4
    },
    {
      "x": -4,
      "y": 9,
      "z": -3,
      "name": "BO_Parking_Wall_Half",
      "rotation": 8
    },
    {
      "x": -4,
      "y": 10,
      "z": -3,
      "name": "BO_Parking_Wall00"
    },
    {
      "x": -4,
      "y": 0,
      "z": -2,
      "name": "BO_Parking_Blacktop",
      "rotation": 4
    },
    {
      "x": -4,
      "y": 1,
      "z": -2,
      "name": "BO_Parking_Blacktop",
      "rotation": 4
    },
    {
      "x": -4,
      "y": 2,
      "z": -2,
      "name": "BO_Parking_Blacktop",
      "rotation": 4
    },
    {
      "x": -4,
      "y": 3,
      "z": -2,
      "name": "BO_Parking_Blacktop",
      "rotation": 4
    },
    {
      "x": -4,
      "y": 9,
      "z": -2,
      "name": "BO_Parking_Wall_Half",
      "rotation": 8
    },
    {
      "x": -4,
      "y": 10,
      "z": -2,
      "name": "BO_Parking_Wall00"
    },
    {
      "x": -4,
      "y": 0,
      "z": -1,
      "name": "BO_Parking_Blacktop",
      "rotation": 4
    },
    {
      "x": -4,
      "y": 1,
      "z": -1,
      "name": "BO_Parking_Blacktop",
      "rotation": 4
    },
    {
      "x": -4,
      "y": 2,
      "z": -1,
      "name": "BO_Parking_Blacktop",
      "rotation": 4
    },
    {
      "x": -4,
      "y": 3,
      "z": -1,
      "name": "BO_Parking_Blacktop"
    },
    {
      "x": -4,
      "y": 9,
      "z": -1,
      "name": "BO_Parking_Wall_Half",
      "rotation": 8
    },
    {
      "x": -4,
      "y": 10,
      "z": -1,
      "name": "BO_Parking_Wall00"
    },
    {
      "x": -4,
      "y": 0,
      "z": 0,
      "name": "BO_Parking_Blacktop",
      "rotation": 4
    },
    {
      "x": -4,
      "y": 1,
      "z": 0,
      "name": "BO_Parking_Blacktop",
      "rotation": 4
    },
    {
      "x": -4,
      "y": 2,
      "z": 0,
      "name": "BO_Parking_Blacktop",
      "rotation": 4
    },
    {
      "x": -4,
      "y": 3,
      "z": 0,
      "name": "BO_Parking_Blacktop",
      "rotation": 3
    },
    {
      "x": -4,
      "y": 4,
      "z": 0,
      "name": "BO_Parking_Curb",
      "support": 15,
      "rotation": 1
    },
    {
      "x": -4,
      "y": 9,
      "z": 0,
      "name": "BO_Parking_Wall03",
      "rotation": 1
    },
    {
      "x": -4,
      "y": 10,
      "z": 0,
      "name": "BO_Parking_Wall00"
    },
    {
      "x": -4,
      "y": 0,
      "z": 1,
      "name": "BO_Parking_Blacktop",
      "rotation": 4
    },
    {
      "x": -4,
      "y": 1,
      "z": 1,
      "name": "BO_Parking_Blacktop",
      "rotation": 4
    },
    {
      "x": -4,
      "y": 2,
      "z": 1,
      "name": "BO_Parking_Blacktop",
      "rotation": 4
    },
    {
      "x": -4,
      "y": 3,
      "z": 1,
      "name": "BO_Parking_Blacktop",
      "rotation": 2
    },
    {
      "x": -4,
      "y": 4,
      "z": 1,
      "name": "BO_Parking_Curb",
      "filler": 31,
      "rotation": 1
    },
    {
      "x": -4,
      "y": 9,
      "z": 1,
      "name": "BO_Parking_Wall03",
      "rotation": 1
    },
    {
      "x": -4,
      "y": 10,
      "z": 1,
      "name": "BO_Parking_Wall00"
    },
    {
      "x": -4,
      "y": 0,
      "z": 2,
      "name": "BO_Parking_Blacktop",
      "rotation": 4
    },
    {
      "x": -4,
      "y": 1,
      "z": 2,
      "name": "BO_Parking_Blacktop",
      "rotation": 4
    },
    {
      "x": -4,
      "y": 2,
      "z": 2,
      "name": "BO_Parking_Blacktop",
      "rotation": 4
    },
    {
      "x": -4,
      "y": 3,
      "z": 2,
      "name": "BO_Parking_Blacktop",
      "rotation": 4
    },
    {
      "x": -4,
      "y": 9,
      "z": 2,
      "name": "BO_Parking_Wall_Half",
      "rotation": 8
    },
    {
      "x": -4,
      "y": 10,
      "z": 2,
      "name": "BO_Parking_Wall00"
    },
    {
      "x": -4,
      "y": 0,
      "z": 3,
      "name": "BO_Parking_Blacktop",
      "rotation": 4
    },
    {
      "x": -4,
      "y": 1,
      "z": 3,
      "name": "BO_Parking_Blacktop",
      "rotation": 4
    },
    {
      "x": -4,
      "y": 2,
      "z": 3,
      "name": "BO_Parking_Blacktop",
      "rotation": 4
    },
    {
      "x": -4,
      "y": 3,
      "z": 3,
      "name": "BO_Parking_Blacktop",
      "rotation": 4
    },
    {
      "x": -4,
      "y": 9,
      "z": 3,
      "name": "BO_Parking_Wall_Half",
      "rotation": 8
    },
    {
      "x": -4,
      "y": 10,
      "z": 3,
      "name": "BO_Parking_Wall00"
    },
    {
      "x": -4,
      "y": 0,
      "z": 4,
      "name": "Rock_Stone_Brick",
      "rotation": 4
    },
    {
      "x": -4,
      "y": 1,
      "z": 4,
      "name": "Rock_Stone_Brick",
      "rotation": 4
    },
    {
      "x": -4,
      "y": 2,
      "z": 4,
      "name": "Rock_Stone_Brick",
      "rotation": 4
    },
    {
      "x": -4,
      "y": 3,
      "z": 4,
      "name": "BO_Parking_Blacktop"
    },
    {
      "x": -4,
      "y": 9,
      "z": 4,
      "name": "BO_Parking_Wall_Half",
      "rotation": 8
    },
    {
      "x": -4,
      "y": 10,
      "z": 4,
      "name": "BO_Parking_Wall00"
    },
    {
      "x": -4,
      "y": 0,
      "z": 5,
      "name": "BO_Parking_Blacktop",
      "rotation": 4
    },
    {
      "x": -4,
      "y": 1,
      "z": 5,
      "name": "BO_Parking_Blacktop",
      "rotation": 4
    },
    {
      "x": -4,
      "y": 2,
      "z": 5,
      "name": "BO_Parking_Blacktop",
      "rotation": 4
    },
    {
      "x": -4,
      "y": 3,
      "z": 5,
      "name": "BO_Parking_Blacktop",
      "rotation": 4
    },
    {
      "x": -4,
      "y": 9,
      "z": 5,
      "name": "BO_Parking_Wall_Half",
      "rotation": 8
    },
    {
      "x": -4,
      "y": 10,
      "z": 5,
      "name": "BO_Parking_Wall00"
    },
    {
      "x": -4,
      "y": 0,
      "z": 6,
      "name": "Rock_Stone_Brick",
      "rotation": 4
    },
    {
      "x": -4,
      "y": 1,
      "z": 6,
      "name": "Rock_Stone_Brick",
      "rotation": 4
    },
    {
      "x": -4,
      "y": 2,
      "z": 6,
      "name": "Rock_Stone_Brick",
      "rotation": 4
    },
    {
      "x": -4,
      "y": 3,
      "z": 6,
      "name": "BO_Parking_Blacktop",
      "rotation": 4
    },
    {
      "x": -4,
      "y": 9,
      "z": 6,
      "name": "BO_Parking_Wall_Half",
      "rotation": 8
    },
    {
      "x": -4,
      "y": 10,
      "z": 6,
      "name": "BO_Parking_Wall00"
    },
    {
      "x": -4,
      "y": 0,
      "z": 7,
      "name": "BO_Parking_Blacktop",
      "rotation": 4
    },
    {
      "x": -4,
      "y": 1,
      "z": 7,
      "name": "BO_Parking_Blacktop",
      "rotation": 4
    },
    {
      "x": -4,
      "y": 2,
      "z": 7,
      "name": "BO_Parking_Blacktop",
      "rotation": 4
    },
    {
      "x": -4,
      "y": 3,
      "z": 7,
      "name": "BO_Parking_Blacktop",
      "rotation": 4
    },
    {
      "x": -4,
      "y": 9,
      "z": 7,
      "name": "BO_Parking_Wall_Half",
      "rotation": 8
    },
    {
      "x": -4,
      "y": 10,
      "z": 7,
      "name": "BO_Parking_Wall00"
    },
    {
      "x": -4,
      "y": 0,
      "z": 8,
      "name": "BO_Parking_Blacktop",
      "rotation": 4
    },
    {
      "x": -4,
      "y": 1,
      "z": 8,
      "name": "BO_Parking_Blacktop",
      "rotation": 4
    },
    {
      "x": -4,
      "y": 2,
      "z": 8,
      "name": "BO_Parking_Blacktop",
      "rotation": 4
    },
    {
      "x": -4,
      "y": 3,
      "z": 8,
      "name": "BO_Parking_Blacktop",
      "rotation": 4
    },
    {
      "x": -4,
      "y": 9,
      "z": 8,
      "name": "BO_Parking_Wall_Half",
      "rotation": 8
    },
    {
      "x": -4,
      "y": 10,
      "z": 8,
      "name": "BO_Parking_Wall00"
    },
    {
      "x": -4,
      "y": 0,
      "z": 9,
      "name": "BO_Parking_Blacktop",
      "rotation": 4
    },
    {
      "x": -4,
      "y": 1,
      "z": 9,
      "name": "BO_Parking_Blacktop",
      "rotation": 4
    },
    {
      "x": -4,
      "y": 2,
      "z": 9,
      "name": "BO_Parking_Blacktop",
      "rotation": 4
    },
    {
      "x": -4,
      "y": 3,
      "z": 9,
      "name": "BO_Parking_Blacktop"
    },
    {
      "x": -4,
      "y": 9,
      "z": 9,
      "name": "BO_Parking_Wall_Half",
      "rotation": 8
    },
    {
      "x": -4,
      "y": 10,
      "z": 9,
      "name": "BO_Parking_Wall00"
    },
    {
      "x": -4,
      "y": 0,
      "z": 10,
      "name": "BO_Parking_Blacktop",
      "rotation": 4
    },
    {
      "x": -4,
      "y": 1,
      "z": 10,
      "name": "BO_Parking_Blacktop",
      "rotation": 4
    },
    {
      "x": -4,
      "y": 2,
      "z": 10,
      "name": "BO_Parking_Blacktop",
      "rotation": 4
    },
    {
      "x": -4,
      "y": 3,
      "z": 10,
      "name": "BO_Parking_Blacktop",
      "rotation": 3
    },
    {
      "x": -4,
      "y": 9,
      "z": 10,
      "name": "BO_Parking_Wall03"
    },
    {
      "x": -4,
      "y": 10,
      "z": 10,
      "name": "BO_Parking_Wall00"
    },
    {
      "x": -3,
      "y": 0,
      "z": -9,
      "name": "BO_Parking_Blacktop",
      "rotation": 4
    },
    {
      "x": -3,
      "y": 1,
      "z": -9,
      "name": "BO_Parking_Blacktop",
      "rotation": 4
    },
    {
      "x": -3,
      "y": 2,
      "z": -9,
      "name": "BO_Parking_Blacktop",
      "rotation": 4
    },
    {
      "x": -3,
      "y": 3,
      "z": -9,
      "name": "BO_Parking_Blacktop",
      "rotation": 2
    },
    {
      "x": -3,
      "y": 9,
      "z": -9,
      "name": "BO_Parking_Wall03"
    },
    {
      "x": -3,
      "y": 10,
      "z": -9,
      "name": "BO_Parking_Wall00"
    },
    {
      "x": -3,
      "y": 0,
      "z": -8,
      "name": "BO_Parking_Blacktop",
      "rotation": 4
    },
    {
      "x": -3,
      "y": 1,
      "z": -8,
      "name": "BO_Parking_Blacktop",
      "rotation": 4
    },
    {
      "x": -3,
      "y": 2,
      "z": -8,
      "name": "BO_Parking_Blacktop",
      "rotation": 4
    },
    {
      "x": -3,
      "y": 3,
      "z": -8,
      "name": "BO_Parking_Blacktop",
      "rotation": 4
    },
    {
      "x": -3,
      "y": 9,
      "z": -8,
      "name": "BO_Parking_Wall_Half",
      "rotation": 8
    },
    {
      "x": -3,
      "y": 10,
      "z": -8,
      "name": "BO_Parking_Wall00"
    },
    {
      "x": -3,
      "y": 0,
      "z": -7,
      "name": "BO_Parking_Blacktop",
      "rotation": 4
    },
    {
      "x": -3,
      "y": 1,
      "z": -7,
      "name": "BO_Parking_Blacktop",
      "rotation": 4
    },
    {
      "x": -3,
      "y": 2,
      "z": -7,
      "name": "BO_Parking_Blacktop",
      "rotation": 4
    },
    {
      "x": -3,
      "y": 3,
      "z": -7,
      "name": "BO_Parking_Blacktop",
      "rotation": 4
    },
    {
      "x": -3,
      "y": 9,
      "z": -7,
      "name": "BO_Parking_Wall_Half",
      "rotation": 8
    },
    {
      "x": -3,
      "y": 10,
      "z": -7,
      "name": "BO_Parking_Wall00"
    },
    {
      "x": -3,
      "y": 0,
      "z": -6,
      "name": "Rock_Stone_Brick"
    },
    {
      "x": -3,
      "y": 1,
      "z": -6,
      "name": "Rock_Stone_Brick"
    },
    {
      "x": -3,
      "y": 2,
      "z": -6,
      "name": "Rock_Stone_Brick"
    },
    {
      "x": -3,
      "y": 3,
      "z": -6,
      "name": "BO_Parking_Blacktop"
    },
    {
      "x": -3,
      "y": 9,
      "z": -6,
      "name": "BO_Parking_Wall_Half",
      "rotation": 8
    },
    {
      "x": -3,
      "y": 10,
      "z": -6,
      "name": "BO_Parking_Wall00"
    },
    {
      "x": -3,
      "y": 0,
      "z": -5,
      "name": "Rock_Stone_Brick"
    },
    {
      "x": -3,
      "y": 1,
      "z": -5,
      "name": "Rock_Stone_Brick"
    },
    {
      "x": -3,
      "y": 2,
      "z": -5,
      "name": "Rock_Stone_Brick"
    },
    {
      "x": -3,
      "y": 3,
      "z": -5,
      "name": "BO_Parking_Blacktop"
    },
    {
      "x": -3,
      "y": 9,
      "z": -5,
      "name": "BO_Parking_Wall_Half",
      "rotation": 8
    },
    {
      "x": -3,
      "y": 10,
      "z": -5,
      "name": "BO_Parking_Wall00"
    },
    {
      "x": -3,
      "y": 0,
      "z": -4,
      "name": "Rock_Stone_Brick"
    },
    {
      "x": -3,
      "y": 1,
      "z": -4,
      "name": "Rock_Stone_Brick"
    },
    {
      "x": -3,
      "y": 2,
      "z": -4,
      "name": "Rock_Stone_Brick"
    },
    {
      "x": -3,
      "y": 3,
      "z": -4,
      "name": "BO_Parking_Blacktop"
    },
    {
      "x": -3,
      "y": 9,
      "z": -4,
      "name": "BO_Parking_Wall_Half",
      "rotation": 8
    },
    {
      "x": -3,
      "y": 10,
      "z": -4,
      "name": "BO_Parking_Wall00"
    },
    {
      "x": -3,
      "y": 0,
      "z": -3,
      "name": "BO_Parking_Blacktop",
      "rotation": 4
    },
    {
      "x": -3,
      "y": 1,
      "z": -3,
      "name": "BO_Parking_Blacktop",
      "rotation": 4
    },
    {
      "x": -3,
      "y": 2,
      "z": -3,
      "name": "BO_Parking_Blacktop",
      "rotation": 4
    },
    {
      "x": -3,
      "y": 3,
      "z": -3,
      "name": "BO_Parking_Blacktop",
      "rotation": 4
    },
    {
      "x": -3,
      "y": 9,
      "z": -3,
      "name": "BO_Parking_Wall_Half",
      "rotation": 8
    },
    {
      "x": -3,
      "y": 10,
      "z": -3,
      "name": "BO_Parking_Wall00"
    },
    {
      "x": -3,
      "y": 0,
      "z": -2,
      "name": "BO_Parking_Blacktop",
      "rotation": 4
    },
    {
      "x": -3,
      "y": 1,
      "z": -2,
      "name": "BO_Parking_Blacktop",
      "rotation": 4
    },
    {
      "x": -3,
      "y": 2,
      "z": -2,
      "name": "BO_Parking_Blacktop",
      "rotation": 4
    },
    {
      "x": -3,
      "y": 3,
      "z": -2,
      "name": "BO_Parking_Blacktop",
      "rotation": 4
    },
    {
      "x": -3,
      "y": 9,
      "z": -2,
      "name": "BO_Parking_Wall_Half",
      "rotation": 8
    },
    {
      "x": -3,
      "y": 10,
      "z": -2,
      "name": "BO_Parking_Wall00"
    },
    {
      "x": -3,
      "y": 0,
      "z": -1,
      "name": "BO_Parking_Blacktop",
      "rotation": 4
    },
    {
      "x": -3,
      "y": 1,
      "z": -1,
      "name": "BO_Parking_Blacktop",
      "rotation": 4
    },
    {
      "x": -3,
      "y": 2,
      "z": -1,
      "name": "BO_Parking_Blacktop",
      "rotation": 4
    },
    {
      "x": -3,
      "y": 3,
      "z": -1,
      "name": "BO_Parking_Blacktop"
    },
    {
      "x": -3,
      "y": 9,
      "z": -1,
      "name": "BO_Parking_Wall_Half",
      "rotation": 8
    },
    {
      "x": -3,
      "y": 10,
      "z": -1,
      "name": "BO_Parking_Wall00"
    },
    {
      "x": -3,
      "y": 0,
      "z": 0,
      "name": "BO_Parking_Blacktop",
      "rotation": 4
    },
    {
      "x": -3,
      "y": 1,
      "z": 0,
      "name": "BO_Parking_Blacktop",
      "rotation": 4
    },
    {
      "x": -3,
      "y": 2,
      "z": 0,
      "name": "BO_Parking_Blacktop",
      "rotation": 4
    },
    {
      "x": -3,
      "y": 3,
      "z": 0,
      "name": "BO_Parking_Blacktop",
      "rotation": 3
    },
    {
      "x": -3,
      "y": 4,
      "z": 0,
      "name": "BO_Parking_Curb",
      "filler": 1,
      "rotation": 1
    },
    {
      "x": -3,
      "y": 9,
      "z": 0,
      "name": "BO_Parking_Wall03",
      "rotation": 1
    },
    {
      "x": -3,
      "y": 10,
      "z": 0,
      "name": "BO_Parking_Wall00"
    },
    {
      "x": -3,
      "y": 0,
      "z": 1,
      "name": "BO_Parking_Blacktop",
      "rotation": 4
    },
    {
      "x": -3,
      "y": 1,
      "z": 1,
      "name": "BO_Parking_Blacktop",
      "rotation": 4
    },
    {
      "x": -3,
      "y": 2,
      "z": 1,
      "name": "BO_Parking_Blacktop",
      "rotation": 4
    },
    {
      "x": -3,
      "y": 3,
      "z": 1,
      "name": "BO_Parking_Blacktop",
      "rotation": 2
    },
    {
      "x": -3,
      "y": 4,
      "z": 1,
      "name": "BO_Parking_Curb",
      "support": 15,
      "rotation": 1
    },
    {
      "x": -3,
      "y": 9,
      "z": 1,
      "name": "BO_Parking_Wall03",
      "rotation": 1
    },
    {
      "x": -3,
      "y": 10,
      "z": 1,
      "name": "BO_Parking_Wall00"
    },
    {
      "x": -3,
      "y": 0,
      "z": 2,
      "name": "BO_Parking_Blacktop",
      "rotation": 4
    },
    {
      "x": -3,
      "y": 1,
      "z": 2,
      "name": "BO_Parking_Blacktop",
      "rotation": 4
    },
    {
      "x": -3,
      "y": 2,
      "z": 2,
      "name": "BO_Parking_Blacktop",
      "rotation": 4
    },
    {
      "x": -3,
      "y": 3,
      "z": 2,
      "name": "BO_Parking_Blacktop",
      "rotation": 4
    },
    {
      "x": -3,
      "y": 9,
      "z": 2,
      "name": "BO_Parking_Wall_Half",
      "rotation": 8
    },
    {
      "x": -3,
      "y": 10,
      "z": 2,
      "name": "BO_Parking_Wall00"
    },
    {
      "x": -3,
      "y": 0,
      "z": 3,
      "name": "BO_Parking_Blacktop",
      "rotation": 4
    },
    {
      "x": -3,
      "y": 1,
      "z": 3,
      "name": "BO_Parking_Blacktop",
      "rotation": 4
    },
    {
      "x": -3,
      "y": 2,
      "z": 3,
      "name": "BO_Parking_Blacktop",
      "rotation": 4
    },
    {
      "x": -3,
      "y": 3,
      "z": 3,
      "name": "BO_Parking_Blacktop",
      "rotation": 4
    },
    {
      "x": -3,
      "y": 9,
      "z": 3,
      "name": "BO_Parking_Wall_Half",
      "rotation": 8
    },
    {
      "x": -3,
      "y": 10,
      "z": 3,
      "name": "BO_Parking_Wall00"
    },
    {
      "x": -3,
      "y": 0,
      "z": 4,
      "name": "Rock_Stone_Brick"
    },
    {
      "x": -3,
      "y": 1,
      "z": 4,
      "name": "Rock_Stone_Brick"
    },
    {
      "x": -3,
      "y": 2,
      "z": 4,
      "name": "Rock_Stone_Brick"
    },
    {
      "x": -3,
      "y": 3,
      "z": 4,
      "name": "BO_Parking_Blacktop"
    },
    {
      "x": -3,
      "y": 9,
      "z": 4,
      "name": "BO_Parking_Wall_Half",
      "rotation": 8
    },
    {
      "x": -3,
      "y": 10,
      "z": 4,
      "name": "BO_Parking_Wall00"
    },
    {
      "x": -3,
      "y": 0,
      "z": 5,
      "name": "Rock_Stone_Brick"
    },
    {
      "x": -3,
      "y": 1,
      "z": 5,
      "name": "Rock_Stone_Brick"
    },
    {
      "x": -3,
      "y": 2,
      "z": 5,
      "name": "Rock_Stone_Brick"
    },
    {
      "x": -3,
      "y": 3,
      "z": 5,
      "name": "BO_Parking_Blacktop"
    },
    {
      "x": -3,
      "y": 9,
      "z": 5,
      "name": "BO_Parking_Wall_Half",
      "rotation": 8
    },
    {
      "x": -3,
      "y": 10,
      "z": 5,
      "name": "BO_Parking_Wall00"
    },
    {
      "x": -3,
      "y": 0,
      "z": 6,
      "name": "Rock_Stone_Brick"
    },
    {
      "x": -3,
      "y": 1,
      "z": 6,
      "name": "Rock_Stone_Brick"
    },
    {
      "x": -3,
      "y": 2,
      "z": 6,
      "name": "Rock_Stone_Brick"
    },
    {
      "x": -3,
      "y": 3,
      "z": 6,
      "name": "BO_Parking_Blacktop"
    },
    {
      "x": -3,
      "y": 9,
      "z": 6,
      "name": "BO_Parking_Wall_Half",
      "rotation": 8
    },
    {
      "x": -3,
      "y": 10,
      "z": 6,
      "name": "BO_Parking_Wall00"
    },
    {
      "x": -3,
      "y": 0,
      "z": 7,
      "name": "BO_Parking_Blacktop",
      "rotation": 4
    },
    {
      "x": -3,
      "y": 1,
      "z": 7,
      "name": "BO_Parking_Blacktop",
      "rotation": 4
    },
    {
      "x": -3,
      "y": 2,
      "z": 7,
      "name": "BO_Parking_Blacktop",
      "rotation": 4
    },
    {
      "x": -3,
      "y": 3,
      "z": 7,
      "name": "BO_Parking_Blacktop",
      "rotation": 4
    },
    {
      "x": -3,
      "y": 9,
      "z": 7,
      "name": "BO_Parking_Wall_Half",
      "rotation": 8
    },
    {
      "x": -3,
      "y": 10,
      "z": 7,
      "name": "BO_Parking_Wall00"
    },
    {
      "x": -3,
      "y": 0,
      "z": 8,
      "name": "BO_Parking_Blacktop",
      "rotation": 4
    },
    {
      "x": -3,
      "y": 1,
      "z": 8,
      "name": "BO_Parking_Blacktop",
      "rotation": 4
    },
    {
      "x": -3,
      "y": 2,
      "z": 8,
      "name": "BO_Parking_Blacktop",
      "rotation": 4
    },
    {
      "x": -3,
      "y": 3,
      "z": 8,
      "name": "BO_Parking_Blacktop",
      "rotation": 4
    },
    {
      "x": -3,
      "y": 9,
      "z": 8,
      "name": "BO_Parking_Wall_Half",
      "rotation": 8
    },
    {
      "x": -3,
      "y": 10,
      "z": 8,
      "name": "BO_Parking_Wall00"
    },
    {
      "x": -3,
      "y": 0,
      "z": 9,
      "name": "BO_Parking_Blacktop",
      "rotation": 4
    },
    {
      "x": -3,
      "y": 1,
      "z": 9,
      "name": "BO_Parking_Blacktop",
      "rotation": 4
    },
    {
      "x": -3,
      "y": 2,
      "z": 9,
      "name": "BO_Parking_Blacktop",
      "rotation": 4
    },
    {
      "x": -3,
      "y": 3,
      "z": 9,
      "name": "BO_Parking_Blacktop"
    },
    {
      "x": -3,
      "y": 9,
      "z": 9,
      "name": "BO_Parking_Wall_Half",
      "rotation": 8
    },
    {
      "x": -3,
      "y": 10,
      "z": 9,
      "name": "BO_Parking_Wall00"
    },
    {
      "x": -3,
      "y": 0,
      "z": 10,
      "name": "BO_Parking_Blacktop",
      "rotation": 4
    },
    {
      "x": -3,
      "y": 1,
      "z": 10,
      "name": "BO_Parking_Blacktop",
      "rotation": 4
    },
    {
      "x": -3,
      "y": 2,
      "z": 10,
      "name": "BO_Parking_Blacktop",
      "rotation": 4
    },
    {
      "x": -3,
      "y": 3,
      "z": 10,
      "name": "BO_Parking_Blacktop",
      "rotation": 3
    },
    {
      "x": -3,
      "y": 9,
      "z": 10,
      "name": "BO_Parking_Wall03"
    },
    {
      "x": -3,
      "y": 10,
      "z": 10,
      "name": "BO_Parking_Wall00"
    },
    {
      "x": -2,
      "y": 0,
      "z": -9,
      "name": "BO_Parking_Blacktop",
      "rotation": 4
    },
    {
      "x": -2,
      "y": 1,
      "z": -9,
      "name": "BO_Parking_Blacktop",
      "rotation": 4
    },
    {
      "x": -2,
      "y": 2,
      "z": -9,
      "name": "BO_Parking_Blacktop",
      "rotation": 4
    },
    {
      "x": -2,
      "y": 3,
      "z": -9,
      "name": "BO_Parking_Blacktop",
      "rotation": 4
    },
    {
      "x": -2,
      "y": 9,
      "z": -9,
      "name": "BO_Parking_Wall03"
    },
    {
      "x": -2,
      "y": 10,
      "z": -9,
      "name": "BO_Parking_Wall00"
    },
    {
      "x": -2,
      "y": 0,
      "z": -8,
      "name": "BO_Parking_Blacktop",
      "rotation": 4
    },
    {
      "x": -2,
      "y": 1,
      "z": -8,
      "name": "BO_Parking_Blacktop",
      "rotation": 4
    },
    {
      "x": -2,
      "y": 2,
      "z": -8,
      "name": "BO_Parking_Blacktop",
      "rotation": 4
    },
    {
      "x": -2,
      "y": 3,
      "z": -8,
      "name": "BO_Parking_Blacktop",
      "rotation": 4
    },
    {
      "x": -2,
      "y": 9,
      "z": -8,
      "name": "*BO_Garage_Overhead_Lights_State_Definitions_Inactive",
      "components": {
        "Components": {
          "BlackoutCycleState": {
            "OnState": "Inactive",
            "OffState": "Active",
            "OnSound": "Garage_Alarm_Disable"
          },
          "PlacedByInteraction": {
            "WhoPlacedUuid": {
