{
  "version": 8,
  "blockIdVersion": 11,
  "anchorX": 0,
  "anchorY": 0,
  "anchorZ": 0,
  "blocks": [
    {
      "x": -9,
      "y": 0,
      "z": -9,
      "name": "BO_Parking_Blacktop",
      "rotation": 4
    },
    {
      "x": -9,
      "y": 1,
      "z": -9,
      "name": "BO_Parking_Wall00",
      "rotation": 3
    },
    {
      "x": -9,
      "y": 2,
      "z": -9,
      "name": "BO_Parking_Wall02",
      "rotation": 3
    },
    {
      "x": -9,
      "y": 3,
      "z": -9,
      "name": "BO_Parking_Wall00",
      "rotation": 3
    },
    {
      "x": -9,
      "y": 4,
      "z": -9,
      "name": "BO_Parking_Wall00",
      "rotation": 3
    },
    {
      "x": -9,
      "y": 5,
      "z": -9,
      "name": "BO_Parking_Wall00",
      "rotation": 3
    },
    {
      "x": -9,
      "y": 6,
      "z": -9,
      "name": "BO_Floor00"
    },
    {
      "x": -9,
      "y": 7,
      "z": -9,
      "name": "BO_Wallpaper00",
      "rotation": 2
    },
    {
      "x": -9,
      "y": 8,
      "z": -9,
      "name": "BO_Wallpaper00",
      "rotation": 2
    },
    {
      "x": -9,
      "y": 9,
      "z": -9,
      "name": "BO_Wallpaper00",
      "rotation": 2
    },
    {
      "x": -9,
      "y": 10,
      "z": -9,
      "name": "BO_Wallpaper00",
      "rotation": 2
    },
    {
      "x": -9,
      "y": 11,
      "z": -9,
      "name": "BO_Wallpaper00",
      "rotation": 2
    },
    {
      "x": -9,
      "y": 12,
      "z": -9,
      "name": "BO_Wallpaper00",
      "rotation": 2
    },
    {
      "x": -9,
      "y": 13,
      "z": -9,
      "name": "BO_Ceiling00"
    },
    {
      "x": -9,
      "y": 0,
      "z": -8,
      "name": "BO_Parking_Blacktop",
      "rotation": 4
    },
    {
      "x": -9,
      "y": 1,
      "z": -8,
      "name": "BO_Parking_Wall00"
    },
    {
      "x": -9,
      "y": 2,
      "z": -8,
      "name": "BO_Parking_Wall02"
    },
    {
      "x": -9,
      "y": 3,
      "z": -8,
      "name": "BO_Parking_Wall00"
    },
    {
      "x": -9,
      "y": 4,
      "z": -8,
      "name": "BO_Parking_Wall00"
    },
    {
      "x": -9,
      "y": 5,
      "z": -8,
      "name": "BO_Parking_Wall00"
    },
    {
      "x": -9,
      "y": 6,
      "z": -8,
      "name": "BO_Floor00"
    },
    {
      "x": -9,
      "y": 13,
      "z": -8,
      "name": "BO_Ceiling00"
    },
    {
      "x": -9,
      "y": 14,
      "z": -8,
      "name": "Build_Black_Cube"
    },
    {
      "x": -9,
      "y": 0,
      "z": -7,
      "name": "BO_Parking_Blacktop",
      "rotation": 4
    },
    {
      "x": -9,
      "y": 1,
      "z": -7,
      "name": "BO_Parking_Wall00"
    },
    {
      "x": -9,
      "y": 2,
      "z": -7,
      "name": "BO_Parking_Wall02"
    },
    {
      "x": -9,
      "y": 3,
      "z": -7,
      "name": "BO_Parking_Wall00"
    },
    {
      "x": -9,
      "y": 4,
      "z": -7,
      "name": "BO_Parking_Wall00"
    },
    {
      "x": -9,
      "y": 5,
      "z": -7,
      "name": "BO_Parking_Wall00"
    },
    {
      "x": -9,
      "y": 6,
      "z": -7,
      "name": "BO_Floor00"
    },
    {
      "x": -9,
      "y": 13,
      "z": -7,
      "name": "BO_Ceiling00"
    },
    {
      "x": -9,
      "y": 0,
      "z": -6,
      "name": "BO_Parking_Blacktop",
      "rotation": 4
    },
    {
      "x": -9,
      "y": 1,
      "z": -6,
      "name": "BO_Parking_Wall00"
    },
    {
      "x": -9,
      "y": 2,
      "z": -6,
      "name": "BO_Parking_Wall02"
    },
    {
      "x": -9,
      "y": 3,
      "z": -6,
      "name": "BO_Parking_Wall00"
    },
    {
      "x": -9,
      "y": 4,
      "z": -6,
      "name": "BO_Parking_Wall00"
    },
    {
      "x": -9,
      "y": 5,
      "z": -6,
      "name": "BO_Parking_Wall00"
    },
    {
      "x": -9,
      "y": 6,
      "z": -6,
      "name": "BO_Floor00"
    },
    {
      "x": -9,
      "y": 13,
      "z": -6,
      "name": "BO_Ceiling00"
    },
    {
      "x": -9,
      "y": 0,
      "z": -5,
      "name": "BO_Parking_Blacktop",
      "rotation": 4
    },
    {
      "x": -9,
      "y": 1,
      "z": -5,
      "name": "BO_Parking_Wall00"
    },
    {
      "x": -9,
      "y": 2,
      "z": -5,
      "name": "BO_Parking_Wall00"
    },
    {
      "x": -9,
      "y": 3,
      "z": -5,
      "name": "BO_Parking_Wall00"
    },
    {
      "x": -9,
      "y": 4,
      "z": -5,
      "name": "BO_Parking_Wall00"
    },
    {
      "x": -9,
      "y": 5,
      "z": -5,
      "name": "BO_Parking_Wall00"
    },
    {
      "x": -9,
      "y": 6,
      "z": -5,
      "name": "BO_Floor00"
    },
    {
      "x": -9,
      "y": 13,
      "z": -5,
      "name": "BO_Ceiling00"
    },
    {
      "x": -9,
      "y": 0,
      "z": -4,
      "name": "BO_Parking_Blacktop",
      "rotation": 4
    },
    {
      "x": -9,
      "y": 1,
      "z": -4,
      "name": "BO_Parking_Wall00"
    },
    {
      "x": -9,
      "y": 2,
      "z": -4,
      "name": "BO_Parking_Wall00"
    },
    {
      "x": -9,
      "y": 3,
      "z": -4,
      "name": "BO_Parking_Wall00"
    },
    {
      "x": -9,
      "y": 4,
      "z": -4,
      "name": "BO_Parking_Wall00"
    },
    {
      "x": -9,
      "y": 5,
      "z": -4,
      "name": "BO_Parking_Wall00"
    },
    {
      "x": -9,
      "y": 6,
      "z": -4,
      "name": "BO_Floor00"
    },
    {
      "x": -9,
      "y": 13,
      "z": -4,
      "name": "BO_Ceiling00"
    },
    {
      "x": -9,
      "y": 0,
      "z": -3,
      "name": "BO_Parking_Blacktop",
      "rotation": 4
    },
    {
      "x": -9,
      "y": 1,
      "z": -3,
      "name": "BO_Parking_Wall00"
    },
    {
      "x": -9,
      "y": 2,
      "z": -3,
      "name": "BO_Parking_Wall02"
    },
    {
      "x": -9,
      "y": 3,
      "z": -3,
      "name": "BO_Parking_Wall00"
    },
    {
      "x": -9,
      "y": 4,
      "z": -3,
      "name": "BO_Parking_Wall00"
    },
    {
      "x": -9,
      "y": 5,
      "z": -3,
      "name": "BO_Parking_Wall00"
    },
    {
      "x": -9,
      "y": 6,
      "z": -3,
      "name": "BO_Floor00"
    },
    {
      "x": -9,
      "y": 13,
      "z": -3,
      "name": "BO_Ceiling00"
    },
    {
      "x": -9,
      "y": 0,
      "z": -2,
      "name": "BO_Parking_Blacktop",
      "rotation": 4
    },
    {
      "x": -9,
      "y": 1,
      "z": -2,
      "name": "BO_Parking_Wall00"
    },
    {
      "x": -9,
      "y": 2,
      "z": -2,
      "name": "BO_Parking_Wall02"
    },
    {
      "x": -9,
      "y": 3,
      "z": -2,
      "name": "BO_Parking_Wall00"
    },
    {
      "x": -9,
      "y": 4,
      "z": -2,
      "name": "BO_Parking_Wall00"
    },
    {
      "x": -9,
      "y": 5,
      "z": -2,
      "name": "BO_Parking_Wall00"
    },
    {
      "x": -9,
      "y": 6,
      "z": -2,
      "name": "BO_Floor00"
    },
    {
      "x": -9,
      "y": 13,
      "z": -2,
      "name": "BO_Ceiling00"
    },
    {
      "x": -9,
      "y": 0,
      "z": -1,
      "name": "BO_Parking_Blacktop",
      "rotation": 4
    },
    {
      "x": -9,
      "y": 1,
      "z": -1,
      "name": "BO_Parking_Wall00"
    },
    {
      "x": -9,
      "y": 2,
      "z": -1,
      "name": "BO_Parking_Wall02"
    },
    {
      "x": -9,
      "y": 3,
      "z": -1,
      "name": "BO_Parking_Wall00"
    },
    {
      "x": -9,
      "y": 4,
      "z": -1,
      "name": "BO_Parking_Wall00"
    },
    {
      "x": -9,
      "y": 5,
      "z": -1,
      "name": "BO_Parking_Wall00"
    },
    {
      "x": -9,
      "y": 6,
      "z": -1,
      "name": "BO_Floor00"
    },
    {
      "x": -9,
      "y": 13,
      "z": -1,
      "name": "BO_Ceiling00"
    },
    {
      "x": -9,
      "y": 14,
      "z": -1,
      "name": "Build_Black_Cube"
    },
    {
      "x": -9,
      "y": 0,
      "z": 0,
      "name": "BO_Parking_Blacktop",
      "rotation": 4
    },
    {
      "x": -9,
      "y": 1,
      "z": 0,
      "name": "BO_Parking_Wall00",
      "rotation": 3
    },
    {
      "x": -9,
      "y": 2,
      "z": 0,
      "name": "BO_Parking_Wall02",
      "rotation": 3
    },
    {
      "x": -9,
      "y": 3,
      "z": 0,
      "name": "BO_Parking_Wall00",
      "rotation": 3
    },
    {
      "x": -9,
      "y": 4,
      "z": 0,
      "name": "BO_Parking_Wall00",
      "rotation": 3
    },
    {
      "x": -9,
      "y": 5,
      "z": 0,
      "name": "BO_Parking_Wall00",
      "rotation": 3
    },
    {
      "x": -9,
      "y": 6,
      "z": 0,
      "name": "BO_Floor00"
    },
    {
      "x": -9,
      "y": 7,
      "z": 0,
      "name": "BO_Wallpaper00"
    },
    {
      "x": -9,
      "y": 8,
      "z": 0,
      "name": "BO_Wallpaper00"
    },
    {
      "x": -9,
      "y": 9,
      "z": 0,
      "name": "BO_Wallpaper00"
    },
    {
      "x": -9,
      "y": 10,
      "z": 0,
      "name": "BO_Wallpaper00"
    },
    {
      "x": -9,
      "y": 11,
      "z": 0,
      "name": "BO_Wallpaper00"
    },
    {
      "x": -9,
      "y": 12,
      "z": 0,
      "name": "BO_Wallpaper00"
    },
    {
      "x": -9,
      "y": 13,
      "z": 0,
      "name": "BO_Ceiling00"
    },
    {
      "x": -9,
      "y": 0,
      "z": 1,
      "name": "BO_Parking_Blacktop",
      "rotation": 4
    },
    {
      "x": -9,
      "y": 1,
      "z": 1,
      "name": "BO_Parking_Wall00",
      "rotation": 3
    },
    {
      "x": -9,
      "y": 2,
      "z": 1,
      "name": "BO_Parking_Wall02",
      "rotation": 3
    },
    {
      "x": -9,
      "y": 3,
      "z": 1,
      "name": "BO_Parking_Wall00",
      "rotation": 3
    },
    {
      "x": -9,
      "y": 4,
      "z": 1,
      "name": "BO_Parking_Wall00",
      "rotation": 3
    },
    {
      "x": -9,
      "y": 5,
      "z": 1,
      "name": "BO_Parking_Wall00",
      "rotation": 3
    },
    {
      "x": -9,
      "y": 6,
      "z": 1,
      "name": "BO_Floor00"
    },
    {
      "x": -9,
      "y": 7,
      "z": 1,
      "name": "BO_Wallpaper00",
      "rotation": 2
    },
    {
      "x": -9,
      "y": 8,
      "z": 1,
      "name": "BO_Wallpaper00",
      "rotation": 2
    },
    {
      "x": -9,
      "y": 9,
      "z": 1,
      "name": "BO_Wallpaper00",
      "rotation": 2
    },
    {
      "x": -9,
      "y": 10,
      "z": 1,
      "name": "BO_Wallpaper00",
      "rotation": 2
    },
    {
      "x": -9,
      "y": 11,
      "z": 1,
      "name": "BO_Wallpaper00",
      "rotation": 2
    },
    {
      "x": -9,
      "y": 12,
      "z": 1,
      "name": "BO_Wallpaper00",
      "rotation": 2
    },
    {
      "x": -9,
      "y": 13,
      "z": 1,
      "name": "BO_Ceiling00"
    },
    {
      "x": -9,
      "y": 0,
      "z": 2,
      "name": "BO_Parking_Blacktop",
      "rotation": 4
    },
    {
      "x": -9,
      "y": 1,
      "z": 2,
      "name": "BO_Parking_Wall00"
    },
    {
      "x": -9,
      "y": 2,
      "z": 2,
      "name": "BO_Parking_Wall02"
    },
    {
      "x": -9,
      "y": 3,
      "z": 2,
      "name": "BO_Parking_Wall00"
    },
    {
      "x": -9,
      "y": 4,
      "z": 2,
      "name": "BO_Parking_Wall00"
    },
    {
      "x": -9,
      "y": 5,
      "z": 2,
      "name": "BO_Parking_Wall00"
    },
    {
      "x": -9,
      "y": 6,
      "z": 2,
      "name": "BO_Floor00"
    },
    {
      "x": -9,
      "y": 13,
      "z": 2,
      "name": "BO_Ceiling00"
    },
    {
      "x": -9,
      "y": 14,
      "z": 2,
      "name": "Build_Black_Cube"
    },
    {
      "x": -9,
      "y": 0,
      "z": 3,
      "name": "BO_Parking_Blacktop",
      "rotation": 4
    },
    {
      "x": -9,
      "y": 1,
      "z": 3,
      "name": "BO_Parking_Wall00"
    },
    {
      "x": -9,
      "y": 2,
      "z": 3,
      "name": "BO_Parking_Wall02"
    },
    {
      "x": -9,
      "y": 3,
      "z": 3,
      "name": "BO_Parking_Wall00"
    },
    {
      "x": -9,
      "y": 4,
      "z": 3,
      "name": "BO_Parking_Wall00"
    },
    {
      "x": -9,
      "y": 5,
      "z": 3,
      "name": "BO_Parking_Wall00"
    },
    {
      "x": -9,
      "y": 6,
      "z": 3,
      "name": "BO_Floor00"
    },
    {
      "x": -9,
      "y": 13,
      "z": 3,
      "name": "BO_Ceiling00"
    },
    {
      "x": -9,
      "y": 0,
      "z": 4,
      "name": "BO_Parking_Blacktop",
      "rotation": 4
    },
    {
      "x": -9,
      "y": 1,
      "z": 4,
      "name": "BO_Parking_Wall00"
    },
    {
      "x": -9,
      "y": 2,
      "z": 4,
      "name": "BO_Parking_Wall02"
    },
    {
      "x": -9,
      "y": 3,
      "z": 4,
      "name": "BO_Parking_Wall00"
    },
    {
      "x": -9,
      "y": 4,
      "z": 4,
      "name": "BO_Parking_Wall00"
    },
    {
      "x": -9,
      "y": 5,
      "z": 4,
      "name": "BO_Parking_Wall00"
    },
    {
      "x": -9,
      "y": 6,
      "z": 4,
      "name": "BO_Floor00"
    },
    {
      "x": -9,
      "y": 13,
      "z": 4,
      "name": "BO_Ceiling00"
    },
    {
      "x": -9,
      "y": 0,
      "z": 5,
      "name": "BO_Parking_Blacktop",
      "rotation": 4
    },
    {
      "x": -9,
      "y": 1,
      "z": 5,
      "name": "BO_Parking_Wall00"
    },
    {
      "x": -9,
      "y": 2,
      "z": 5,
      "name": "BO_Parking_Wall00"
    },
    {
      "x": -9,
      "y": 3,
      "z": 5,
      "name": "BO_Parking_Wall00"
    },
    {
      "x": -9,
      "y": 4,
      "z": 5,
      "name": "BO_Parking_Wall00"
    },
    {
      "x": -9,
      "y": 5,
      "z": 5,
      "name": "BO_Parking_Wall00"
    },
    {
      "x": -9,
      "y": 6,
      "z": 5,
      "name": "BO_Floor00"
    },
    {
      "x": -9,
      "y": 13,
      "z": 5,
      "name": "BO_Ceiling00"
    },
    {
      "x": -9,
      "y": 0,
      "z": 6,
      "name": "BO_Parking_Blacktop",
      "rotation": 4
    },
    {
      "x": -9,
      "y": 1,
      "z": 6,
      "name": "BO_Parking_Wall00"
    },
    {
      "x": -9,
      "y": 2,
      "z": 6,
      "name": "BO_Parking_Wall00"
    },
    {
      "x": -9,
      "y": 3,
      "z": 6,
      "name": "BO_Parking_Wall00"
    },
    {
      "x": -9,
      "y": 4,
      "z": 6,
      "name": "BO_Parking_Wall00"
    },
    {
      "x": -9,
      "y": 5,
      "z": 6,
      "name": "BO_Parking_Wall00"
    },
    {
      "x": -9,
      "y": 6,
      "z": 6,
      "name": "BO_Floor00"
    },
    {
      "x": -9,
      "y": 13,
      "z": 6,
      "name": "BO_Ceiling00"
    },
    {
      "x": -9,
      "y": 0,
      "z": 7,
      "name": "BO_Parking_Blacktop",
      "rotation": 4
    },
    {
      "x": -9,
      "y": 1,
      "z": 7,
      "name": "BO_Parking_Wall00"
    },
    {
      "x": -9,
      "y": 2,
      "z": 7,
      "name": "BO_Parking_Wall02"
    },
    {
      "x": -9,
      "y": 3,
      "z": 7,
      "name": "BO_Parking_Wall00"
    },
    {
      "x": -9,
      "y": 4,
      "z": 7,
      "name": "BO_Parking_Wall00"
    },
    {
      "x": -9,
      "y": 5,
      "z": 7,
      "name": "BO_Parking_Wall00"
    },
    {
      "x": -9,
      "y": 6,
      "z": 7,
      "name": "BO_Floor00"
    },
    {
      "x": -9,
      "y": 13,
      "z": 7,
      "name": "BO_Ceiling00"
    },
    {
      "x": -9,
      "y": 0,
      "z": 8,
      "name": "BO_Parking_Blacktop",
      "rotation": 4
    },
    {
      "x": -9,
      "y": 1,
      "z": 8,
      "name": "BO_Parking_Wall00"
    },
    {
      "x": -9,
      "y": 2,
      "z": 8,
      "name": "BO_Parking_Wall02"
    },
    {
      "x": -9,
      "y": 3,
      "z": 8,
      "name": "BO_Parking_Wall00"
    },
    {
      "x": -9,
      "y": 4,
      "z": 8,
      "name": "BO_Parking_Wall00"
    },
    {
      "x": -9,
      "y": 5,
      "z": 8,
      "name": "BO_Parking_Wall00"
    },
    {
      "x": -9,
      "y": 6,
      "z": 8,
      "name": "BO_Floor00"
    },
    {
      "x": -9,
      "y": 13,
      "z": 8,
      "name": "BO_Ceiling00"
    },
    {
      "x": -9,
      "y": 0,
      "z": 9,
      "name": "BO_Parking_Blacktop",
      "rotation": 4
    },
    {
      "x": -9,
      "y": 1,
      "z": 9,
      "name": "BO_Parking_Wall00"
    },
    {
      "x": -9,
      "y": 2,
      "z": 9,
      "name": "BO_Parking_Wall02"
    },
    {
      "x": -9,
      "y": 3,
      "z": 9,
      "name": "BO_Parking_Wall00"
    },
    {
      "x": -9,
      "y": 4,
      "z": 9,
      "name": "BO_Parking_Wall00"
    },
    {
      "x": -9,
      "y": 5,
      "z": 9,
      "name": "BO_Parking_Wall00"
    },
    {
      "x": -9,
      "y": 6,
      "z": 9,
      "name": "BO_Floor00"
    },
    {
      "x": -9,
      "y": 13,
      "z": 9,
      "name": "BO_Ceiling00"
    },
    {
      "x": -9,
      "y": 14,
      "z": 9,
      "name": "Build_Black_Cube"
    },
    {
      "x": -9,
      "y": 0,
      "z": 10,
      "name": "BO_Parking_Blacktop",
      "rotation": 4
    },
    {
      "x": -9,
      "y": 1,
      "z": 10,
      "name": "BO_Parking_Wall00",
      "rotation": 3
    },
    {
      "x": -9,
      "y": 2,
      "z": 10,
      "name": "BO_Parking_Wall02",
      "rotation": 3
    },
    {
      "x": -9,
      "y": 3,
      "z": 10,
      "name": "BO_Parking_Wall00",
      "rotation": 3
    },
    {
      "x": -9,
      "y": 4,
      "z": 10,
      "name": "BO_Parking_Wall00",
      "rotation": 3
    },
    {
      "x": -9,
      "y": 5,
      "z": 10,
      "name": "BO_Parking_Wall00",
      "rotation": 3
    },
    {
      "x": -9,
      "y": 6,
      "z": 10,
      "name": "BO_Floor00"
    },
    {
      "x": -9,
      "y": 7,
      "z": 10,
      "name": "BO_Wallpaper00"
    },
    {
      "x": -9,
      "y": 8,
      "z": 10,
      "name": "BO_Wallpaper00"
    },
    {
      "x": -9,
      "y": 9,
      "z": 10,
      "name": "BO_Wallpaper00"
    },
    {
      "x": -9,
      "y": 10,
      "z": 10,
      "name": "BO_Wallpaper00"
    },
    {
      "x": -9,
      "y": 11,
      "z": 10,
      "name": "BO_Wallpaper00"
    },
    {
      "x": -9,
      "y": 12,
      "z": 10,
      "name": "BO_Wallpaper00"
    },
    {
      "x": -9,
      "y": 13,
      "z": 10,
      "name": "BO_Ceiling00"
    },
    {
      "x": -8,
      "y": 0,
      "z": -9,
      "name": "BO_Parking_Blacktop",
      "rotation": 4
    },
    {
      "x": -8,
      "y": 1,
      "z": -9,
      "name": "BO_Parking_Wall00",
      "rotation": 3
    },
    {
      "x": -8,
      "y": 2,
      "z": -9,
      "name": "BO_Parking_Wall02",
      "rotation": 3
    },
    {
      "x": -8,
      "y": 3,
      "z": -9,
      "name": "BO_Parking_Wall00",
      "rotation": 3
    },
    {
      "x": -8,
      "y": 4,
      "z": -9,
      "name": "BO_Parking_Wall00",
      "rotation": 3
    },
    {
      "x": -8,
      "y": 5,
      "z": -9,
      "name": "BO_Parking_Wall00",
      "rotation": 3
    },
    {
      "x": -8,
      "y": 6,
      "z": -9,
      "name": "BO_Floor00"
    },
    {
      "x": -8,
      "y": 13,
      "z": -9,
      "name": "BO_Ceiling00"
    },
    {
      "x": -8,
      "y": 14,
      "z": -9,
      "name": "Build_Black_Cube"
    },
    {
      "x": -8,
      "y": 0,
      "z": -8,
      "name": "BO_Parking_Blacktop",
      "rotation": 4
    },
    {
      "x": -8,
      "y": 1,
      "z": -8,
      "name": "BO_Pool_Surface00",
      "rotation": 4
    },
    {
      "x": -8,
      "y": 2,
      "z": -8,
      "name": "BO_Pool_Surface00",
      "rotation": 4
    },
    {
      "x": -8,
      "y": 3,
      "z": -8,
      "name": "BO_Pool_Surface00",
      "rotation": 4
    },
    {
      "x": -8,
      "y": 4,
      "z": -8,
      "name": "BO_Pool_Surface00",
      "rotation": 4
    },
    {
      "x": -8,
      "y": 5,
      "z": -8,
      "name": "BO_Pool_Surface00",
      "rotation": 4
    },
    {
      "x": -8,
      "y": 6,
      "z": -8,
      "name": "BO_Floor00"
    },
    {
      "x": -8,
      "y": 13,
      "z": -8,
      "name": "BO_Ceiling00"
    },
    {
      "x": -8,
      "y": 14,
      "z": -8,
      "name": "Build_Black_Cube"
    },
    {
      "x": -8,
      "y": 0,
      "z": -7,
      "name": "BO_Parking_Blacktop",
      "rotation": 4
    },
    {
      "x": -8,
      "y": 1,
      "z": -7,
      "name": "BO_Pool_Surface00",
      "rotation": 4
    },
    {
      "x": -8,
      "y": 2,
      "z": -7,
      "name": "BO_Pool_Surface00",
      "rotation": 4
    },
    {
      "x": -8,
      "y": 3,
      "z": -7,
      "name": "BO_Pool_Surface00",
      "rotation": 4
    },
    {
      "x": -8,
      "y": 4,
      "z": -7,
      "name": "BO_Pool_Surface00",
      "rotation": 4
    },
    {
      "x": -8,
      "y": 5,
      "z": -7,
      "name": "BO_Pool_Surface00",
      "rotation": 4
    },
    {
      "x": -8,
      "y": 6,
      "z": -7,
      "name": "BO_Floor00"
    },
    {
      "x": -8,
      "y": 13,
      "z": -7,
      "name": "BO_Ceiling00"
    },
    {
      "x": -8,
      "y": 0,
      "z": -6,
      "name": "BO_Parking_Blacktop",
      "rotation": 4
    },
    {
      "x": -8,
      "y": 1,
      "z": -6,
      "name": "BO_Pool_Surface00",
      "rotation": 4
    },
    {
      "x": -8,
      "y": 2,
      "z": -6,
      "name": "BO_Pool_Surface00",
      "rotation": 4
    },
    {
      "x": -8,
      "y": 3,
      "z": -6,
      "name": "BO_Pool_Surface00",
      "rotation": 4
    },
    {
      "x": -8,
      "y": 4,
      "z": -6,
      "name": "BO_Pool_Surface00",
      "rotation": 4
    },
    {
      "x": -8,
      "y": 5,
      "z": -6,
      "name": "BO_Pool_Surface00",
      "rotation": 4
    },
    {
      "x": -8,
      "y": 6,
      "z": -6,
      "name": "BO_Floor00"
    },
    {
      "x": -8,
      "y": 13,
      "z": -6,
      "name": "BO_Ceiling00"
    },
    {
      "x": -8,
      "y": 0,
      "z": -5,
      "name": "BO_Parking_Blacktop",
      "rotation": 4
    },
    {
      "x": -8,
      "y": 1,
      "z": -5,
      "name": "BO_Pool_Surface00",
      "rotation": 4
    },
    {
      "x": -8,
      "y": 2,
      "z": -5,
      "name": "BO_Pool_Surface00",
      "rotation": 4
    },
    {
      "x": -8,
      "y": 3,
      "z": -5,
      "name": "BO_Pool_Surface00",
      "rotation": 4
    },
    {
      "x": -8,
      "y": 4,
      "z": -5,
      "name": "BO_Pool_Surface00",
      "rotation": 4
    },
    {
      "x": -8,
      "y": 5,
      "z": -5,
      "name": "BO_Pool_Surface00",
      "rotation": 4
    },
    {
      "x": -8,
      "y": 6,
      "z": -5,
      "name": "BO_Floor00"
    },
    {
      "x": -8,
      "y": 13,
      "z": -5,
      "name": "BO_Ceiling00"
    },
    {
      "x": -8,
      "y": 0,
      "z": -4,
      "name": "BO_Parking_Blacktop",
      "rotation": 4
    },
    {
      "x": -8,
      "y": 1,
      "z": -4,
      "name": "BO_Pool_Surface00",
      "rotation": 4
    },
    {
      "x": -8,
      "y": 2,
      "z": -4,
      "name": "BO_Pool_Surface00",
      "rotation": 4
    },
    {
      "x": -8,
      "y": 3,
      "z": -4,
      "name": "BO_Pool_Surface00",
      "rotation": 4
    },
    {
      "x": -8,
      "y": 4,
      "z": -4,
      "name": "BO_Pool_Surface00",
      "rotation": 4
    },
    {
      "x": -8,
      "y": 5,
      "z": -4,
      "name": "BO_Pool_Surface00",
      "rotation": 4
    },
    {
      "x": -8,
      "y": 6,
      "z": -4,
      "name": "BO_Floor00"
    },
    {
      "x": -8,
      "y": 13,
      "z": -4,
      "name": "BO_Ceiling00"
    },
    {
      "x": -8,
      "y": 0,
      "z": -3,
      "name": "BO_Parking_Blacktop",
      "rotation": 4
    },
    {
      "x": -8,
      "y": 1,
      "z": -3,
      "name": "BO_Pool_Surface00",
      "rotation": 4
    },
    {
      "x": -8,
      "y": 2,
      "z": -3,
      "name": "BO_Pool_Surface00",
      "rotation": 4
    },
    {
      "x": -8,
      "y": 3,
      "z": -3,
      "name": "BO_Pool_Surface00",
      "rotation": 4
    },
    {
      "x": -8,
      "y": 4,
      "z": -3,
      "name": "BO_Pool_Surface00",
      "rotation": 4
    },
    {
      "x": -8,
      "y": 5,
      "z": -3,
      "name": "BO_Pool_Surface00",
      "rotation": 4
    },
    {
      "x": -8,
      "y": 6,
      "z": -3,
      "name": "BO_Floor00"
    },
    {
      "x": -8,
      "y": 13,
      "z": -3,
      "name": "BO_Ceiling00"
    },
    {
      "x": -8,
      "y": 0,
      "z": -2,
      "name": "BO_Parking_Blacktop",
      "rotation": 4
    },
    {
      "x": -8,
      "y": 1,
      "z": -2,
      "name": "BO_Pool_Surface00",
      "rotation": 4
    },
    {
      "x": -8,
      "y": 2,
      "z": -2,
      "name": "BO_Pool_Surface00",
      "rotation": 4
    },
    {
      "x": -8,
      "y": 3,
      "z": -2,
      "name": "BO_Pool_Surface00",
      "rotation": 4
    },
    {
      "x": -8,
      "y": 4,
      "z": -2,
      "name": "BO_Pool_Surface00",
      "rotation": 4
    },
    {
      "x": -8,
      "y": 5,
      "z": -2,
      "name": "BO_Pool_Surface00",
      "rotation": 4
    },
    {
      "x": -8,
      "y": 6,
      "z": -2,
      "name": "BO_Floor00"
    },
    {
      "x": -8,
      "y": 13,
      "z": -2,
      "name": "BO_Ceiling00"
    },
    {
      "x": -8,
      "y": 0,
      "z": -1,
      "name": "BO_Parking_Blacktop",
      "rotation": 4
    },
    {
      "x": -8,
      "y": 1,
      "z": -1,
      "name": "BO_Pool_Surface00",
      "rotation": 4
    },
    {
      "x": -8,
      "y": 2,
      "z": -1,
      "name": "BO_Pool_Surface00",
      "rotation": 4
    },
    {
      "x": -8,
      "y": 3,
      "z": -1,
      "name": "BO_Pool_Surface00",
      "rotation": 4
    },
    {
      "x": -8,
      "y": 4,
      "z": -1,
      "name": "BO_Pool_Surface00",
      "rotation": 4
    },
    {
      "x": -8,
      "y": 5,
      "z": -1,
      "name": "BO_Pool_Surface00",
      "rotation": 4
    },
    {
      "x": -8,
      "y": 6,
      "z": -1,
      "name": "BO_Floor00"
    },
    {
      "x": -8,
      "y": 13,
      "z": -1,
      "name": "BO_Ceiling00"
    },
    {
      "x": -8,
      "y": 14,
      "z": -1,
      "name": "Build_Black_Cube"
    },
    {
      "x": -8,
      "y": 0,
      "z": 0,
      "name": "BO_Parking_Blacktop",
      "rotation": 4
    },
    {
      "x": -8,
      "y": 1,
      "z": 0,
      "name": "BO_Parking_Wall00",
      "rotation": 3
    },
    {
      "x": -8,
      "y": 2,
      "z": 0,
      "name": "BO_Parking_Wall02",
      "rotation": 3
    },
    {
      "x": -8,
      "y": 3,
      "z": 0,
      "name": "BO_Parking_Wall00",
      "rotation": 3
    },
    {
      "x": -8,
      "y": 4,
      "z": 0,
      "name": "BO_Parking_Wall00",
      "rotation": 3
    },
    {
      "x": -8,
      "y": 5,
      "z": 0,
      "name": "BO_Parking_Wall00",
      "rotation": 3
    },
    {
      "x": -8,
      "y": 6,
      "z": 0,
      "name": "BO_Floor00"
    },
    {
      "x": -8,
      "y": 13,
      "z": 0,
      "name": "BO_Ceiling00"
    },
    {
      "x": -8,
      "y": 14,
      "z": 0,
      "name": "Build_Black_Cube"
    },
    {
      "x": -8,
      "y": 0,
      "z": 1,
      "name": "BO_Parking_Blacktop",
      "rotation": 4
    },
    {
      "x": -8,
      "y": 1,
      "z": 1,
      "name": "BO_Parking_Wall00",
      "rotation": 3
    },
    {
      "x": -8,
      "y": 2,
      "z": 1,
      "name": "BO_Parking_Wall02",
      "rotation": 3
    },
    {
      "x": -8,
      "y": 3,
      "z": 1,
      "name": "BO_Parking_Wall00",
      "rotation": 3
    },
    {
      "x": -8,
      "y": 4,
      "z": 1,
      "name": "BO_Parking_Wall00",
      "rotation": 3
    },
    {
      "x": -8,
      "y": 5,
      "z": 1,
      "name": "BO_Parking_Wall00",
      "rotation": 3
    },
    {
      "x": -8,
      "y": 6,
      "z": 1,
      "name": "BO_Floor00"
    },
    {
      "x": -8,
      "y": 13,
      "z": 1,
      "name": "BO_Ceiling00"
    },
    {
      "x": -8,
      "y": 14,
      "z": 1,
      "name": "Build_Black_Cube"
    },
    {
      "x": -8,
      "y": 0,
      "z": 2,
      "name": "BO_Parking_Blacktop",
      "rotation": 4
    },
    {
      "x": -8,
      "y": 1,
      "z": 2,
      "name": "BO_Pool_Surface00",
      "rotation": 4
    },
    {
      "x": -8,
      "y": 2,
      "z": 2,
      "name": "BO_Pool_Surface00",
      "rotation": 4
    },
    {
      "x": -8,
      "y": 3,
      "z": 2,
      "name": "BO_Pool_Surface00",
      "rotation": 4
    },
    {
      "x": -8,
      "y": 4,
      "z": 2,
      "name": "BO_Pool_Surface00",
      "rotation": 4
    },
    {
      "x": -8,
      "y": 5,
      "z": 2,
      "name": "BO_Pool_Surface00",
      "rotation": 4
    },
    {
      "x": -8,
      "y": 6,
      "z": 2,
      "name": "BO_Floor00"
    },
    {
      "x": -8,
      "y": 13,
      "z": 2,
      "name": "BO_Ceiling00"
    },
    {
      "x": -8,
      "y": 14,
      "z": 2,
      "name": "Build_Black_Cube"
    },
    {
      "x": -8,
      "y": 0,
      "z": 3,
      "name": "BO_Parking_Blacktop",
      "rotation": 4
    },
    {
      "x": -8,
      "y": 1,
      "z": 3,
      "name": "BO_Pool_Surface00",
      "rotation": 4
    },
    {
      "x": -8,
      "y": 2,
      "z": 3,
      "name": "BO_Pool_Surface00",
      "rotation": 4
    },
    {
      "x": -8,
      "y": 3,
      "z": 3,
      "name": "BO_Pool_Surface00",
      "rotation": 4
    },
    {
      "x": -8,
      "y": 4,
      "z": 3,
      "name": "BO_Pool_Surface00",
      "rotation": 4
    },
    {
      "x": -8,
      "y": 5,
      "z": 3,
      "name": "BO_Pool_Surface00",
      "rotation": 4
    },
    {
      "x": -8,
      "y": 6,
      "z": 3,
      "name": "BO_Floor00"
    },
    {
      "x": -8,
      "y": 13,
      "z": 3,
      "name": "BO_Ceiling00"
    },
    {
      "x": -8,
      "y": 0,
      "z": 4,
      "name": "BO_Parking_Blacktop",
      "rotation": 4
    },
    {
      "x": -8,
      "y": 1,
      "z": 4,
      "name": "BO_Pool_Surface00",
      "rotation": 4
    },
    {
      "x": -8,
      "y": 2,
      "z": 4,
      "name": "BO_Pool_Surface00",
      "rotation": 4
    },
    {
      "x": -8,
      "y": 3,
      "z": 4,
      "name": "BO_Pool_Surface00",
      "rotation": 4
    },
    {
      "x": -8,
      "y": 4,
      "z": 4,
      "name": "BO_Pool_Surface00",
      "rotation": 4
    },
    {
      "x": -8,
      "y": 5,
      "z": 4,
      "name": "BO_Pool_Surface00",
      "rotation": 4
    },
    {
      "x": -8,
      "y": 6,
      "z": 4,
      "name": "BO_Floor00"
    },
    {
      "x": -8,
      "y": 13,
      "z": 4,
      "name": "BO_Ceiling00"
    },
    {
      "x": -8,
      "y": 0,
      "z": 5,
      "name": "BO_Parking_Blacktop",
      "rotation": 4
    },
    {
      "x": -8,
      "y": 1,
      "z": 5,
      "name": "BO_Pool_Surface00",
      "rotation": 4
    },
    {
      "x": -8,
      "y": 2,
      "z": 5,
      "name": "BO_Pool_Surface00",
      "rotation": 4
    },
    {
      "x": -8,
      "y": 3,
      "z": 5,
      "name": "BO_Pool_Surface00",
      "rotation": 4
    },
    {
      "x": -8,
      "y": 4,
      "z": 5,
      "name": "BO_Pool_Surface00",
      "rotation": 4
    },
    {
      "x": -8,
      "y": 5,
      "z": 5,
      "name": "BO_Pool_Surface00",
      "rotation": 4
    },
    {
      "x": -8,
      "y": 6,
      "z": 5,
      "name": "BO_Floor00"
    },
    {
      "x": -8,
      "y": 13,
      "z": 5,
      "name": "BO_Ceiling00"
    },
    {
      "x": -8,
      "y": 0,
      "z": 6,
      "name": "BO_Parking_Blacktop",
      "rotation": 4
    },
    {
      "x": -8,
      "y": 1,
      "z": 6,
      "name": "BO_Pool_Surface00",
      "rotation": 4
    },
    {
      "x": -8,
      "y": 2,
      "z": 6,
      "name": "BO_Pool_Surface00",
      "rotation": 4
    },
    {
      "x": -8,
      "y": 3,
      "z": 6,
      "name": "BO_Pool_Surface00",
      "rotation": 4
    },
    {
      "x": -8,
      "y": 4,
      "z": 6,
      "name": "BO_Pool_Surface00",
      "rotation": 4
    },
    {
      "x": -8,
      "y": 5,
      "z": 6,
      "name": "BO_Pool_Surface00",
      "rotation": 4
    },
    {
      "x": -8,
      "y": 6,
      "z": 6,
      "name": "BO_Floor00"
    },
    {
      "x": -8,
      "y": 13,
      "z": 6,
      "name": "BO_Ceiling00"
    },
    {
      "x": -8,
      "y": 0,
      "z": 7,
      "name": "BO_Parking_Blacktop",
      "rotation": 4
    },
    {
      "x": -8,
      "y": 1,
      "z": 7,
      "name": "BO_Pool_Surface00",
      "rotation": 4
    },
    {
      "x": -8,
      "y": 2,
      "z": 7,
      "name": "BO_Pool_Surface00",
      "rotation": 4
    },
    {
      "x": -8,
      "y": 3,
      "z": 7,
      "name": "BO_Pool_Surface00",
      "rotation": 4
    },
    {
      "x": -8,
      "y": 4,
      "z": 7,
      "name": "BO_Pool_Surface00",
      "rotation": 4
    },
    {
      "x": -8,
      "y": 5,
      "z": 7,
      "name": "BO_Pool_Surface00",
      "rotation": 4
    },
    {
      "x": -8,
      "y": 6,
      "z": 7,
      "name": "BO_Floor00"
    },
    {
      "x": -8,
      "y": 13,
      "z": 7,
      "name": "BO_Ceiling00"
    },
    {
      "x": -8,
      "y": 0,
      "z": 8,
      "name": "BO_Parking_Blacktop",
      "rotation": 4
    },
    {
      "x": -8,
      "y": 1,
      "z": 8,
      "name": "BO_Pool_Surface00",
      "rotation": 4
    },
    {
      "x": -8,
      "y": 2,
      "z": 8,
      "name": "BO_Pool_Surface00",
      "rotation": 4
    },
    {
      "x": -8,
      "y": 3,
      "z": 8,
      "name": "BO_Pool_Surface00",
      "rotation": 4
    },
    {
      "x": -8,
      "y": 4,
      "z": 8,
      "name": "BO_Pool_Surface00",
      "rotation": 4
    },
    {
      "x": -8,
      "y": 5,
      "z": 8,
      "name": "BO_Pool_Surface00",
      "rotation": 4
    },
    {
      "x": -8,
      "y": 6,
      "z": 8,
      "name": "BO_Floor00"
    },
    {
      "x": -8,
      "y": 13,
      "z": 8,
      "name": "BO_Ceiling00"
    },
    {
      "x": -8,
      "y": 0,
      "z": 9,
      "name": "BO_Parking_Blacktop",
      "rotation": 4
    },
    {
      "x": -8,
      "y": 1,
      "z": 9,
      "name": "BO_Pool_Surface00",
      "rotation": 4
    },
    {
      "x": -8,
      "y": 2,
      "z": 9,
      "name": "BO_Pool_Surface00",
      "rotation": 4
    },
    {
      "x": -8,
      "y": 3,
      "z": 9,
      "name": "BO_Pool_Surface00",
      "rotation": 4
    },
    {
      "x": -8,
      "y": 4,
      "z": 9,
      "name": "BO_Pool_Surface00",
      "rotation": 4
    },
    {
      "x": -8,
      "y": 5,
      "z": 9,
      "name": "BO_Pool_Surface00",
      "rotation": 4
    },
    {
      "x": -8,
      "y": 6,
      "z": 9,
      "name": "BO_Floor00"
    },
    {
      "x": -8,
      "y": 13,
      "z": 9,
      "name": "BO_Ceiling00"
    },
    {
      "x": -8,
      "y": 14,
      "z": 9,
      "name": "Build_Black_Cube"
    },
    {
      "x": -8,
      "y": 0,
      "z": 10,
      "name": "BO_Parking_Blacktop",
      "rotation": 4
    },
    {
      "x": -8,
      "y": 1,
      "z": 10,
      "name": "BO_Parking_Wall00",
      "rotation": 3
    },
    {
      "x": -8,
      "y": 2,
      "z": 10,
      "name": "BO_Parking_Wall02",
      "rotation": 3
    },
    {
      "x": -8,
      "y": 3,
      "z": 10,
      "name": "BO_Parking_Wall00",
      "rotation": 3
    },
    {
      "x": -8,
      "y": 4,
      "z": 10,
      "name": "BO_Parking_Wall00",
      "rotation": 3
    },
    {
      "x": -8,
      "y": 5,
      "z": 10,
      "name": "BO_Parking_Wall00",
      "rotation": 3
    },
    {
      "x": -8,
      "y": 6,
      "z": 10,
      "name": "BO_Floor00"
    },
    {
      "x": -8,
      "y": 13,
      "z": 10,
      "name": "BO_Ceiling00"
    },
    {
      "x": -8,
      "y": 14,
      "z": 10,
      "name": "Build_Black_Cube"
    },
    {
      "x": -7,
      "y": 0,
      "z": -9,
      "name": "BO_Parking_Blacktop",
      "rotation": 4
    },
    {
      "x": -7,
      "y": 1,
      "z": -9,
      "name": "BO_Parking_Wall00",
      "rotation": 3
    },
    {
      "x": -7,
      "y": 2,
      "z": -9,
      "name": "BO_Parking_Wall02",
      "rotation": 3
    },
    {
      "x": -7,
      "y": 3,
      "z": -9,
      "name": "BO_Parking_Wall00",
      "rotation": 3
    },
    {
      "x": -7,
      "y": 4,
      "z": -9,
      "name": "BO_Parking_Wall00",
      "rotation": 3
    },
    {
      "x": -7,
      "y": 5,
      "z": -9,
      "name": "BO_Parking_Wall00",
      "rotation": 3
    },
    {
      "x": -7,
      "y": 6,
      "z": -9,
      "name": "BO_Floor00"
    },
    {
      "x": -7,
      "y": 13,
      "z": -9,
      "name": "BO_Ceiling00"
    },
    {
      "x": -7,
      "y": 0,
      "z": -8,
      "name": "BO_Parking_Blacktop",
      "rotation": 4
    },
    {
      "x": -7,
      "y": 1,
      "z": -8,
      "name": "BO_Pool_Surface00",
      "rotation": 4
    },
    {
      "x": -7,
      "y": 2,
      "z": -8,
      "name": "BO_Pool_Surface00",
      "rotation": 4
    },
    {
      "x": -7,
      "y": 3,
      "z": -8,
      "name": "BO_Pool_Surface00",
      "rotation": 4
    },
    {
      "x": -7,
      "y": 4,
      "z": -8,
      "name": "BO_Pool_Surface00",
      "rotation": 4
    },
    {
      "x": -7,
      "y": 5,
      "z": -8,
      "name": "BO_Pool_Surface00",
      "rotation": 4
    },
    {
      "x": -7,
      "y": 6,
      "z": -8,
      "name": "BO_Floor00"
    },
    {
      "x": -7,
      "y": 13,
      "z": -8,
      "name": "BO_Ceiling00"
    },
    {
      "x": -7,
      "y": 0,
      "z": -7,
      "name": "BO_Parking_Blacktop",
      "rotation": 4
    },
    {
      "x": -7,
      "y": 1,
      "z": -7,
      "name": "BO_Pool_Surface00",
      "rotation": 4
    },
    {
      "x": -7,
      "y": 2,
      "z": -7,
      "name": "BO_Pool_Surface00",
      "rotation": 4
    },
    {
      "x": -7,
      "y": 3,
      "z": -7,
      "name": "BO_Pool_Surface00",
      "rotation": 4
    },
    {
      "x": -7,
      "y": 4,
      "z": -7,
      "name": "BO_Pool_Surface00",
      "rotation": 4
    },
    {
      "x": -7,
      "y": 5,
      "z": -7,
      "name": "BO_Pool_Surface00",
      "rotation": 4
    },
    {
      "x": -7,
      "y": 6,
      "z": -7,
      "name": "BO_Floor00"
    },
    {
      "x": -7,
      "y": 13,
      "z": -7,
      "name": "BO_Ceiling00"
    },
    {
      "x": -7,
      "y": 0,
      "z": -6,
      "name": "BO_Parking_Blacktop",
      "rotation": 4
    },
    {
      "x": -7,
      "y": 1,
      "z": -6,
      "name": "BO_Pool_Surface00",
      "rotation": 4
    },
    {
      "x": -7,
      "y": 2,
      "z": -6,
      "name": "BO_Pool_Surface00",
      "rotation": 4
    },
    {
      "x": -7,
      "y": 3,
      "z": -6,
      "name": "BO_Pool_Surface00",
      "rotation": 4
    },
    {
      "x": -7,
      "y": 4,
      "z": -6,
      "name": "BO_Pool_Surface00",
      "rotation": 4
    },
    {
      "x": -7,
      "y": 5,
      "z": -6,
      "name": "BO_Pool_Surface00",
      "rotation": 4
    },
    {
      "x": -7,
      "y": 6,
      "z": -6,
      "name": "BO_Floor00"
    },
    {
      "x": -7,
      "y": 13,
      "z": -6,
      "name": "BO_Ceiling00"
    },
    {
      "x": -7,
      "y": 0,
      "z": -5,
      "name": "BO_Parking_Blacktop",
      "rotation": 4
    },
    {
      "x": -7,
      "y": 1,
      "z": -5,
      "name": "BO_Pool_Surface00",
      "rotation": 4
    },
    {
      "x": -7,
      "y": 2,
      "z": -5,
      "name": "BO_Pool_Surface00",
      "rotation": 4
    },
    {
      "x": -7,
      "y": 3,
      "z": -5,
      "name": "BO_Pool_Surface00",
      "rotation": 4
    },
    {
      "x": -7,
      "y": 4,
      "z": -5,
      "name": "BO_Pool_Surface00",
      "rotation": 4
    },
    {
      "x": -7,
      "y": 5,
      "z": -5,
      "name": "BO_Pool_Surface00",
      "rotation": 4
    },
    {
      "x": -7,
      "y": 6,
      "z": -5,
      "name": "BO_Floor00"
    },
    {
      "x": -7,
      "y": 13,
      "z": -5,
      "name": "BO_Ceiling00"
    },
    {
      "x": -7,
      "y": 0,
      "z": -4,
      "name": "BO_Parking_Blacktop",
      "rotation": 4
    },
    {
      "x": -7,
      "y": 1,
      "z": -4,
      "name": "BO_Pool_Surface00",
      "rotation": 4
    },
    {
      "x": -7,
      "y": 2,
      "z": -4,
      "name": "BO_Pool_Surface00",
      "rotation": 4
    },
    {
      "x": -7,
      "y": 3,
      "z": -4,
      "name": "BO_Pool_Surface00",
      "rotation": 4
    },
    {
      "x": -7,
      "y": 4,
      "z": -4,
      "name": "BO_Pool_Surface00",
      "rotation": 4
    },
    {
      "x": -7,
      "y": 5,
      "z": -4,
      "name": "BO_Pool_Surface00",
      "rotation": 4
    },
    {
      "x": -7,
      "y": 6,
      "z": -4,
      "name": "BO_Floor00"
    },
    {
      "x": -7,
      "y": 13,
      "z": -4,
      "name": "BO_Ceiling00"
    },
    {
      "x": -7,
      "y": 0,
      "z": -3,
      "name": "BO_Parking_Blacktop",
      "rotation": 4
    },
    {
      "x": -7,
      "y": 1,
      "z": -3,
      "name": "BO_Pool_Surface00",
      "rotation": 4
    },
    {
      "x": -7,
      "y": 2,
      "z": -3,
      "name": "BO_Pool_Surface00",
      "rotation": 4
    },
    {
      "x": -7,
      "y": 3,
      "z": -3,
      "name": "BO_Pool_Surface00",
      "rotation": 4
    },
    {
      "x": -7,
      "y": 4,
      "z": -3,
      "name": "BO_Pool_Surface00",
      "rotation": 4
    },
    {
      "x": -7,
      "y": 5,
      "z": -3,
      "name": "BO_Pool_Surface00",
      "rotation": 4
    },
    {
      "x": -7,
      "y": 6,
      "z": -3,
      "name": "BO_Floor00"
    },
    {
      "x": -7,
      "y": 13,
      "z": -3,
      "name": "BO_Ceiling00"
    },
    {
      "x": -7,
      "y": 0,
      "z": -2,
      "name": "BO_Parking_Blacktop",
      "rotation": 4
    },
    {
      "x": -7,
      "y": 1,
      "z": -2,
      "name": "BO_Pool_Surface00",
      "rotation": 4
    },
    {
      "x": -7,
      "y": 2,
      "z": -2,
      "name": "BO_Pool_Surface00",
      "rotation": 4
    },
    {
      "x": -7,
      "y": 3,
      "z": -2,
      "name": "BO_Pool_Surface00",
      "rotation": 4
    },
    {
      "x": -7,
      "y": 4,
      "z": -2,
      "name": "BO_Pool_Surface00",
      "rotation": 4
    },
    {
      "x": -7,
      "y": 5,
      "z": -2,
      "name": "BO_Pool_Surface00",
      "rotation": 4
    },
    {
      "x": -7,
      "y": 6,
      "z": -2,
      "name": "BO_Floor00"
    },
    {
      "x": -7,
      "y": 13,
      "z": -2,
      "name": "BO_Ceiling00"
    },
    {
      "x": -7,
      "y": 0,
      "z": -1,
      "name": "BO_Parking_Blacktop",
      "rotation": 4
    },
    {
      "x": -7,
      "y": 1,
      "z": -1,
      "name": "BO_Pool_Surface00",
      "rotation": 4
    },
    {
      "x": -7,
      "y": 2,
      "z": -1,
      "name": "BO_Pool_Surface00",
      "rotation": 4
    },
    {
      "x": -7,
      "y": 3,
      "z": -1,
      "name": "BO_Pool_Surface00",
      "rotation": 4
    },
    {
      "x": -7,
      "y": 4,
      "z": -1,
      "name": "BO_Pool_Surface00",
      "rotation": 4
    },
    {
      "x": -7,
      "y": 5,
      "z": -1,
      "name": "BO_Pool_Surface00",
      "rotation": 4
    },
    {
      "x": -7,
      "y": 6,
      "z": -1,
      "name": "BO_Floor00"
    },
    {
      "x": -7,
      "y": 13,
      "z": -1,
      "name": "BO_Ceiling00"
    },
    {
      "x": -7,
      "y": 0,
      "z": 0,
      "name": "BO_Parking_Blacktop",
      "rotation": 4
    },
    {
      "x": -7,
      "y": 1,
      "z": 0,
      "name": "BO_Parking_Wall00",
      "rotation": 3
    },
    {
      "x": -7,
      "y": 2,
      "z": 0,
      "name": "BO_Parking_Wall02",
      "rotation": 3
    },
    {
      "x": -7,
      "y": 3,
      "z": 0,
      "name": "BO_Parking_Wall00",
      "rotation": 3
    },
    {
      "x": -7,
      "y": 4,
      "z": 0,
      "name": "BO_Parking_Wall00",
      "rotation": 3
    },
    {
      "x": -7,
      "y": 5,
      "z": 0,
      "name": "BO_Parking_Wall00",
      "rotation": 3
    },
    {
      "x": -7,
      "y": 6,
      "z": 0,
      "name": "BO_Floor00"
    },
    {
      "x": -7,
      "y": 13,
      "z": 0,
      "name": "BO_Ceiling00"
    },
    {
      "x": -7,
      "y": 0,
      "z": 1,
      "name": "BO_Parking_Blacktop",
      "rotation": 4
    },
    {
      "x": -7,
      "y": 1,
      "z": 1,
      "name": "BO_Parking_Wall00",
      "rotation": 3
    },
    {
      "x": -7,
      "y": 2,
      "z": 1,
      "name": "BO_Parking_Wall02",
      "rotation": 3
    },
    {
      "x": -7,
      "y": 3,
      "z": 1,
      "name": "BO_Parking_Wall00",
      "rotation": 3
    },
    {
      "x": -7,
      "y": 4,
      "z": 1,
      "name": "BO_Parking_Wall00",
      "rotation": 3
    },
    {
      "x": -7,
      "y": 5,
      "z": 1,
      "name": "BO_Parking_Wall00",
      "rotation": 3
    },
    {
      "x": -7,
      "y": 6,
      "z": 1,
      "name": "BO_Floor00"
    },
    {
      "x": -7,
      "y": 13,
      "z": 1,
      "name": "BO_Ceiling00"
    },
    {
      "x": -7,
      "y": 0,
      "z": 2,
      "name": "BO_Parking_Blacktop",
      "rotation": 4
    },
    {
      "x": -7,
      "y": 1,
      "z": 2,
      "name": "BO_Pool_Surface00",
      "rotation": 4
    },
    {
      "x": -7,
      "y": 2,
      "z": 2,
      "name": "BO_Pool_Surface00",
      "rotation": 4
    },
    {
      "x": -7,
      "y": 3,
      "z": 2,
      "name": "BO_Pool_Surface00",
      "rotation": 4
    },
    {
      "x": -7,
      "y": 4,
      "z": 2,
      "name": "BO_Pool_Surface00",
      "rotation": 4
    },
    {
      "x": -7,
      "y": 5,
      "z": 2,
      "name": "BO_Pool_Surface00",
      "rotation": 4
    },
    {
      "x": -7,
      "y": 6,
      "z": 2,
      "name": "BO_Floor00"
    },
    {
      "x": -7,
      "y": 13,
      "z": 2,
      "name": "BO_Ceiling00"
    },
    {
      "x": -7,
      "y": 0,
      "z": 3,
      "name": "BO_Parking_Blacktop",
      "rotation": 4
    },
    {
      "x": -7,
      "y": 1,
      "z": 3,
      "name": "BO_Pool_Surface00",
      "rotation": 4
    },
    {
      "x": -7,
      "y": 2,
      "z": 3,
      "name": "BO_Pool_Surface00",
      "rotation": 4
    },
    {
      "x": -7,
      "y": 3,
      "z": 3,
      "name": "BO_Pool_Surface00",
      "rotation": 4
    },
    {
      "x": -7,
      "y": 4,
      "z": 3,
      "name": "BO_Pool_Surface00",
      "rotation": 4
    },
    {
      "x": -7,
      "y": 5,
      "z": 3,
      "name": "BO_Pool_Surface00",
      "rotation": 4
    },
    {
      "x": -7,
      "y": 6,
      "z": 3,
      "name": "BO_Floor00"
    },
    {
      "x": -7,
      "y": 13,
      "z": 3,
      "name": "BO_Ceiling00"
    },
    {
      "x": -7,
      "y": 0,
      "z": 4,
      "name": "BO_Parking_Blacktop",
      "rotation": 4
    },
    {
      "x": -7,
      "y": 1,
      "z": 4,
      "name": "BO_Pool_Surface00",
      "rotation": 4
    },
    {
      "x": -7,
      "y": 2,
      "z": 4,
      "name": "BO_Pool_Surface00",
      "rotation": 4
    },
    {
      "x": -7,
      "y": 3,
      "z": 4,
      "name": "BO_Pool_Surface00",
      "rotation": 4
    },
    {
      "x": -7,
      "y": 4,
      "z": 4,
      "name": "BO_Pool_Surface00",
      "rotation": 4
    },
    {
      "x": -7,
      "y": 5,
      "z": 4,
      "name": "BO_Pool_Surface00",
      "rotation": 4
    },
    {
      "x": -7,
      "y": 6,
      "z": 4,
      "name": "BO_Floor00"
    },
    {
      "x": -7,
      "y": 13,
      "z": 4,
      "name": "BO_Ceiling00"
    },
    {
      "x": -7,
      "y": 0,
      "z": 5,
      "name": "BO_Parking_Blacktop",
      "rotation": 4
    },
    {
      "x": -7,
      "y": 1,
      "z": 5,
      "name": "BO_Pool_Surface00",
      "rotation": 4
    },
    {
      "x": -7,
      "y": 2,
      "z": 5,
      "name": "BO_Pool_Surface00",
      "rotation": 4
    },
    {
      "x": -7,
      "y": 3,
      "z": 5,
      "name": "BO_Pool_Surface00",
      "rotation": 4
    },
    {
      "x": -7,
      "y": 4,
      "z": 5,
      "name": "BO_Pool_Surface00",
      "rotation": 4
    },
    {
      "x": -7,
      "y": 5,
      "z": 5,
      "name": "BO_Pool_Surface00",
      "rotation": 4
    },
    {
      "x": -7,
      "y": 6,
      "z": 5,
      "name": "BO_Floor00"
    },
    {
      "x": -7,
      "y": 13,
      "z": 5,
      "name": "BO_Ceiling00"
    },
    {
      "x": -7,
      "y": 0,
      "z": 6,
      "name": "BO_Parking_Blacktop",
      "rotation": 4
    },
    {
      "x": -7,
      "y": 1,
      "z": 6,
      "name": "BO_Pool_Surface00",
      "rotation": 4
    },
    {
      "x": -7,
      "y": 2,
      "z": 6,
      "name": "BO_Pool_Surface00",
      "rotation": 4
    },
    {
      "x": -7,
      "y": 3,
      "z": 6,
      "name": "BO_Pool_Surface00",
      "rotation": 4
    },
    {
      "x": -7,
      "y": 4,
      "z": 6,
      "name": "BO_Pool_Surface00",
      "rotation": 4
    },
    {
      "x": -7,
      "y": 5,
      "z": 6,
      "name": "BO_Pool_Surface00",
      "rotation": 4
    },
    {
      "x": -7,
      "y": 6,
      "z": 6,
      "name": "BO_Floor00"
    },
    {
      "x": -7,
      "y": 13,
      "z": 6,
      "name": "BO_Ceiling00"
    },
    {
      "x": -7,
      "y": 0,
      "z": 7,
      "name": "BO_Parking_Blacktop",
      "rotation": 4
    },
    {
      "x": -7,
      "y": 1,
      "z": 7,
      "name": "BO_Pool_Surface00",
      "rotation": 4
    },
    {
      "x": -7,
      "y": 2,
      "z": 7,
      "name": "BO_Pool_Surface00",
      "rotation": 4
    },
    {
      "x": -7,
      "y": 3,
      "z": 7,
      "name": "BO_Pool_Surface00",
      "rotation": 4
    },
    {
      "x": -7,
      "y": 4,
      "z": 7,
      "name": "BO_Pool_Surface00",
      "rotation": 4
    },
    {
      "x": -7,
      "y": 5,
      "z": 7,
      "name": "BO_Pool_Surface00",
      "rotation": 4
    },
    {
      "x": -7,
      "y": 6,
      "z": 7,
      "name": "BO_Floor00"
    },
    {
      "x": -7,
      "y": 13,
      "z": 7,
      "name": "BO_Ceiling00"
    },
    {
      "x": -7,
      "y": 0,
      "z": 8,
      "name": "BO_Parking_Blacktop",
      "rotation": 4
    },
    {
      "x": -7,
      "y": 1,
      "z": 8,
      "name": "BO_Pool_Surface00",
      "rotation": 4
    },
    {
      "x": -7,
      "y": 2,
      "z": 8,
      "name": "BO_Pool_Surface00",
      "rotation": 4
    },
    {
      "x": -7,
      "y": 3,
      "z": 8,
      "name": "BO_Pool_Surface00",
      "rotation": 4
    },
    {
      "x": -7,
      "y": 4,
      "z": 8,
      "name": "BO_Pool_Surface00",
      "rotation": 4
    },
    {
      "x": -7,
      "y": 5,
      "z": 8,
      "name": "BO_Pool_Surface00",
      "rotation": 4
    },
    {
      "x": -7,
      "y": 6,
      "z": 8,
      "name": "BO_Floor00"
    },
    {
      "x": -7,
      "y": 13,
      "z": 8,
      "name": "BO_Ceiling00"
    },
    {
      "x": -7,
      "y": 0,
      "z": 9,
      "name": "BO_Parking_Blacktop",
      "rotation": 4
    },
    {
      "x": -7,
      "y": 1,
      "z": 9,
      "name": "BO_Pool_Surface00",
      "rotation": 4
    },
    {
      "x": -7,
      "y": 2,
      "z": 9,
      "name": "BO_Pool_Surface00",
      "rotation": 4
    },
    {
      "x": -7,
      "y": 3,
      "z": 9,
      "name": "BO_Pool_Surface00",
      "rotation": 4
    },
    {
      "x": -7,
      "y": 4,
      "z": 9,
      "name": "BO_Pool_Surface00",
      "rotation": 4
    },
    {
      "x": -7,
      "y": 5,
      "z": 9,
      "name": "BO_Pool_Surface00",
      "rotation": 4
    },
    {
      "x": -7,
      "y": 6,
      "z": 9,
      "name": "BO_Floor00"
    },
    {
      "x": -7,
      "y": 13,
      "z": 9,
      "name": "BO_Ceiling00"
    },
    {
      "x": -7,
      "y": 0,
      "z": 10,
      "name": "BO_Parking_Blacktop",
      "rotation": 4
    },
    {
      "x": -7,
      "y": 1,
      "z": 10,
      "name": "BO_Parking_Wall00",
      "rotation": 3
    },
    {
      "x": -7,
      "y": 2,
      "z": 10,
      "name": "BO_Parking_Wall02",
      "rotation": 3
    },
    {
      "x": -7,
      "y": 3,
      "z": 10,
      "name": "BO_Parking_Wall00",
      "rotation": 3
    },
    {
      "x": -7,
      "y": 4,
      "z": 10,
      "name": "BO_Parking_Wall00",
      "rotation": 3
    },
    {
      "x": -7,
      "y": 5,
      "z": 10,
      "name": "BO_Parking_Wall00",
      "rotation": 3
    },
    {
      "x": -7,
      "y": 6,
      "z": 10,
      "name": "BO_Floor00"
    },
    {
      "x": -7,
      "y": 13,
      "z": 10,
      "name": "BO_Ceiling00"
    },
    {
      "x": -6,
      "y": 0,
      "z": -9,
      "name": "BO_Parking_Blacktop",
      "rotation": 4
    },
    {
      "x": -6,
      "y": 1,
      "z": -9,
      "name": "BO_Parking_Wall00",
      "rotation": 3
    },
    {
      "x": -6,
      "y": 2,
      "z": -9,
      "name": "BO_Parking_Wall02",
      "rotation": 3
    },
    {
      "x": -6,
      "y": 3,
      "z": -9,
      "name": "BO_Parking_Wall00",
      "rotation": 3
    },
    {
      "x": -6,
      "y": 4,
      "z": -9,
      "name": "BO_Parking_Wall00",
      "rotation": 3
    },
    {
      "x": -6,
      "y": 5,
      "z": -9,
      "name": "BO_Parking_Wall00",
      "rotation": 3
    },
    {
      "x": -6,
      "y": 6,
      "z": -9,
      "name": "BO_Floor00"
    },
    {
      "x": -6,
      "y": 13,
      "z": -9,
      "name": "BO_Ceiling00"
    },
    {
      "x": -6,
      "y": 0,
      "z": -8,
      "name": "BO_Parking_Blacktop",
      "rotation": 4
    },
    {
      "x": -6,
      "y": 1,
      "z": -8,
      "name": "BO_Pool_Surface00",
      "rotation": 4
    },
    {
      "x": -6,
      "y": 2,
      "z": -8,
      "name": "BO_Pool_Surface00",
      "rotation": 4
    },
    {
      "x": -6,
      "y": 3,
      "z": -8,
      "name": "BO_Pool_Surface00",
      "rotation": 4
    },
    {
      "x": -6,
      "y": 4,
      "z": -8,
      "name": "BO_Pool_Surface00",
      "rotation": 4
    },
    {
      "x": -6,
      "y": 5,
      "z": -8,
      "name": "BO_Pool_Surface00",
      "rotation": 4
    },
    {
      "x": -6,
      "y": 6,
      "z": -8,
      "name": "BO_Floor00"
    },
    {
      "x": -6,
      "y": 13,
      "z": -8,
      "name": "BO_Ceiling00"
    },
    {
      "x": -6,
      "y": 0,
      "z": -7,
      "name": "BO_Parking_Blacktop",
      "rotation": 4
    },
    {
      "x": -6,
      "y": 1,
      "z": -7,
      "name": "BO_Pool_Surface00",
      "rotation": 4
    },
    {
      "x": -6,
      "y": 2,
      "z": -7,
      "name": "BO_Pool_Surface00",
      "rotation": 4
    },
    {
      "x": -6,
      "y": 3,
      "z": -7,
      "name": "BO_Pool_Surface00",
      "rotation": 4
    },
    {
      "x": -6,
      "y": 4,
      "z": -7,
      "name": "BO_Pool_Surface00",
      "rotation": 4
    },
    {
      "x": -6,
      "y": 5,
      "z": -7,
      "name": "BO_Pool_Surface00",
      "rotation": 4
    },
    {
      "x": -6,
      "y": 6,
      "z": -7,
      "name": "BO_Floor00"
    },
    {
      "x": -6,
      "y": 13,
      "z": -7,
      "name": "BO_Ceiling00"
    },
    {
      "x": -6,
      "y": 0,
      "z": -6,
      "name": "BO_Parking_Blacktop",
      "rotation": 4
    },
    {
      "x": -6,
      "y": 1,
      "z": -6,
      "name": "BO_Pool_Surface00",
      "rotation": 4
    },
    {
      "x": -6,
      "y": 2,
      "z": -6,
      "name": "BO_Pool_Surface00",
      "rotation": 4
    },
    {
      "x": -6,
      "y": 3,
      "z": -6,
      "name": "BO_Pool_Surface00",
      "rotation": 4
    },
    {
      "x": -6,
      "y": 4,
      "z": -6,
      "name": "BO_Pool_Surface00",
      "rotation": 4
    },
    {
      "x": -6,
      "y": 5,
      "z": -6,
      "name": "BO_Pool_Surface00",
      "rotation": 4
    },
    {
      "x": -6,
      "y": 6,
      "z": -6,
      "name": "BO_Floor00"
    },
    {
      "x": -6,
      "y": 13,
      "z": -6,
      "name": "BO_Ceiling00"
    },
    {
      "x": -6,
      "y": 0,
      "z": -5,
      "name": "BO_Parking_Blacktop",
      "rotation": 4
    },
    {
      "x": -6,
      "y": 1,
      "z": -5,
      "name": "BO_Pool_Surface00",
      "rotation": 4
    },
    {
      "x": -6,
      "y": 2,
      "z": -5,
      "name": "BO_Pool_Surface00",
      "rotation": 4
    },
    {
      "x": -6,
      "y": 3,
      "z": -5,
      "name": "BO_Pool_Surface00",
      "rotation": 4
    },
    {
      "x": -6,
      "y": 4,
      "z": -5,
      "name": "BO_Pool_Surface00",
      "rotation": 4
    },
    {
      "x": -6,
      "y": 5,
      "z": -5,
      "name": "BO_Pool_Surface00",
      "rotation": 4
    },
    {
      "x": -6,
      "y": 6,
      "z": -5,
      "name": "BO_Floor00"
    },
    {
      "x": -6,
      "y": 13,
      "z": -5,
      "name": "BO_Ceiling00"
    },
    {
      "x": -6,
      "y": 0,
      "z": -4,
      "name": "BO_Parking_Blacktop",
      "rotation": 4
    },
    {
      "x": -6,
      "y": 1,
      "z": -4,
      "name": "BO_Pool_Surface00",
      "rotation": 4
    },
    {
      "x": -6,
      "y": 2,
      "z": -4,
      "name": "BO_Pool_Surface00",
      "rotation": 4
    },
    {
      "x": -6,
      "y": 3,
      "z": -4,
      "name": "BO_Pool_Surface00",
      "rotation": 4
    },
    {
      "x": -6,
      "y": 4,
      "z": -4,
      "name": "BO_Pool_Surface00",
      "rotation": 4
    },
    {
      "x": -6,
      "y": 5,
      "z": -4,
      "name": "BO_Pool_Surface00",
      "rotation": 4
    },
    {
      "x": -6,
      "y": 6,
      "z": -4,
      "name": "BO_Floor00"
    },
    {
      "x": -6,
      "y": 13,
      "z": -4,
      "name": "BO_Ceiling00"
    },
    {
      "x": -6,
      "y": 0,
      "z": -3,
      "name": "BO_Parking_Blacktop",
      "rotation": 4
    },
    {
      "x": -6,
      "y": 1,
      "z": -3,
      "name": "BO_Pool_Surface00",
      "rotation": 4
    },
    {
      "x": -6,
      "y": 2,
      "z": -3,
      "name": "BO_Pool_Surface00",
      "rotation": 4
    },
    {
      "x": -6,
      "y": 3,
      "z": -3,
      "name": "BO_Pool_Surface00",
      "rotation": 4
    },
    {
      "x": -6,
      "y": 4,
      "z": -3,
      "name": "BO_Pool_Surface00",
      "rotation": 4
    },
    {
      "x": -6,
      "y": 5,
      "z": -3,
      "name": "BO_Pool_Surface00",
      "rotation": 4
    },
    {
      "x": -6,
      "y": 6,
      "z": -3,
      "name": "BO_Floor00"
    },
    {
      "x": -6,
      "y": 13,
      "z": -3,
      "name": "BO_Ceiling00"
    },
    {
      "x": -6,
      "y": 0,
      "z": -2,
      "name": "BO_Parking_Blacktop",
      "rotation": 4
    },
    {
      "x": -6,
      "y": 1,
      "z": -2,
      "name": "BO_Pool_Surface00",
      "rotation": 4
    },
    {
      "x": -6,
      "y": 2,
      "z": -2,
      "name": "BO_Pool_Surface00",
      "rotation": 4
    },
    {
      "x": -6,
      "y": 3,
      "z": -2,
      "name": "BO_Pool_Surface00",
      "rotation": 4
    },
    {
      "x": -6,
      "y": 4,
      "z": -2,
      "name": "BO_Pool_Surface00",
      "rotation": 4
    },
    {
      "x": -6,
      "y": 5,
      "z": -2,
      "name": "BO_Pool_Surface00",
      "rotation": 4
    },
    {
      "x": -6,
      "y": 6,
      "z": -2,
      "name": "BO_Floor00"
    },
    {
      "x": -6,
      "y": 13,
      "z": -2,
      "name": "BO_Ceiling00"
    },
    {
      "x": -6,
      "y": 0,
      "z": -1,
      "name": "BO_Parking_Blacktop"
    },
    {
      "x": -6,
      "y": 1,
      "z": -1,
      "name": "BO_Pool_Surface00",
      "rotation": 4
    },
    {
      "x": -6,
      "y": 2,
      "z": -1,
      "name": "BO_Pool_Surface00",
      "rotation": 4
    },
    {
      "x": -6,
      "y": 3,
      "z": -1,
      "name": "BO_Pool_Surface00",
      "rotation": 4
    },
    {
      "x": -6,
      "y": 4,
      "z": -1,
      "name": "BO_Pool_Surface00",
      "rotation": 4
    },
    {
      "x": -6,
      "y": 5,
      "z": -1,
      "name": "BO_Pool_Surface00",
      "rotation": 4
    },
    {
      "x": -6,
      "y": 6,
      "z": -1,
      "name": "BO_Floor00"
    },
    {
      "x": -6,
      "y": 13,
      "z": -1,
      "name": "BO_Ceiling00"
    },
    {
      "x": -6,
      "y": 0,
      "z": 0,
      "name": "BO_Parking_Blacktop",
      "rotation": 4
    },
    {
      "x": -6,
      "y": 1,
      "z": 0,
      "name": "BO_Parking_Wall00",
      "rotation": 3
    },
    {
      "x": -6,
      "y": 2,
      "z": 0,
      "name": "BO_Parking_Wall02",
      "rotation": 3
    },
    {
      "x": -6,
      "y": 3,
      "z": 0,
      "name": "BO_Parking_Wall00",
      "rotation": 3
    },
    {
      "x": -6,
      "y": 4,
      "z": 0,
      "name": "BO_Parking_Wall00",
      "rotation": 3
    },
    {
      "x": -6,
      "y": 5,
      "z": 0,
      "name": "BO_Parking_Wall00",
      "rotation": 3
    },
    {
      "x": -6,
      "y": 6,
      "z": 0,
      "name": "BO_Floor00"
    },
    {
      "x": -6,
      "y": 13,
      "z": 0,
      "name": "BO_Ceiling00"
    },
    {
      "x": -6,
      "y": 0,
      "z": 1,
      "name": "BO_Parking_Blacktop",
      "rotation": 4
    },
    {
      "x": -6,
      "y": 1,
      "z": 1,
      "name": "BO_Parking_Wall00",
      "rotation": 3
    },
    {
      "x": -6,
      "y": 2,
      "z": 1,
      "name": "BO_Parking_Wall02",
      "rotation": 3
    },
    {
      "x": -6,
      "y": 3,
      "z": 1,
      "name": "BO_Parking_Wall00",
      "rotation": 3
    },
    {
      "x": -6,
      "y": 4,
      "z": 1,
      "name": "BO_Parking_Wall00",
      "rotation": 3
    },
    {
      "x": -6,
      "y": 5,
      "z": 1,
      "name": "BO_Parking_Wall00",
      "rotation": 3
    },
    {
      "x": -6,
      "y": 6,
      "z": 1,
      "name": "BO_Floor00"
    },
    {
      "x": -6,
      "y": 13,
      "z": 1,
      "name": "BO_Ceiling00"
    },
    {
      "x": -6,
      "y": 0,
      "z": 2,
      "name": "BO_Parking_Blacktop",
      "rotation": 4
    },
    {
      "x": -6,
      "y": 1,
      "z": 2,
      "name": "BO_Pool_Surface00",
      "rotation": 4
    },
    {
      "x": -6,
      "y": 2,
      "z": 2,
      "name": "BO_Pool_Surface00",
      "rotation": 4
    },
    {
      "x": -6,
      "y": 3,
      "z": 2,
      "name": "BO_Pool_Surface00",
      "rotation": 4
    },
    {
      "x": -6,
      "y": 4,
      "z": 2,
      "name": "BO_Pool_Surface00",
      "rotation": 4
    },
    {
      "x": -6,
      "y": 5,
      "z": 2,
      "name": "BO_Pool_Surface00",
      "rotation": 4
    },
    {
      "x": -6,
      "y": 6,
      "z": 2,
      "name": "BO_Floor00"
    },
    {
      "x": -6,
      "y": 13,
      "z": 2,
      "name": "BO_Ceiling00"
    },
    {
      "x": -6,
      "y": 0,
      "z": 3,
      "name": "BO_Parking_Blacktop",
      "rotation": 4
    },
    {
      "x": -6,
      "y": 1,
      "z": 3,
      "name": "BO_Pool_Surface00",
      "rotation": 4
    },
    {
      "x": -6,
      "y": 2,
      "z": 3,
      "name": "BO_Pool_Surface00",
      "rotation": 4
    },
    {
      "x": -6,
      "y": 3,
      "z": 3,
      "name": "BO_Pool_Surface00",
      "rotation": 4
    },
    {
      "x": -6,
      "y": 4,
      "z": 3,
      "name": "BO_Pool_Surface00",
      "rotation": 4
    },
    {
      "x": -6,
      "y": 5,
      "z": 3,
      "name": "BO_Pool_Surface00",
      "rotation": 4
    },
    {
      "x": -6,
      "y": 6,
      "z": 3,
      "name": "BO_Floor00"
    },
    {
      "x": -6,
      "y": 13,
      "z": 3,
      "name": "BO_Ceiling00"
    },
    {
      "x": -6,
      "y": 0,
      "z": 4,
      "name": "BO_Parking_Blacktop",
      "rotation": 4
    },
    {
      "x": -6,
      "y": 1,
      "z": 4,
      "name": "BO_Pool_Surface00",
      "rotation": 4
    },
    {
      "x": -6,
      "y": 2,
      "z": 4,
      "name": "BO_Pool_Surface00",
      "rotation": 4
    },
    {
      "x": -6,
      "y": 3,
      "z": 4,
      "name": "BO_Pool_Surface00",
      "rotation": 4
    },
    {
      "x": -6,
      "y": 4,
      "z": 4,
      "name": "BO_Pool_Surface00",
      "rotation": 4
    },
    {
      "x": -6,
      "y": 5,
      "z": 4,
      "name": "BO_Pool_Surface00",
      "rotation": 4
    },
    {
      "x": -6,
      "y": 6,
      "z": 4,
      "name": "BO_Floor00"
    },
    {
      "x": -6,
      "y": 13,
      "z": 4,
      "name": "BO_Ceiling00"
    },
    {
      "x": -6,
      "y": 0,
      "z": 5,
      "name": "BO_Parking_Blacktop",
      "rotation": 4
    },
    {
      "x": -6,
      "y": 1,
      "z": 5,
      "name": "BO_Pool_Surface00",
      "rotation": 4
    },
    {
      "x": -6,
      "y": 2,
      "z": 5,
      "name": "BO_Pool_Surface00",
      "rotation": 4
    },
    {
      "x": -6,
      "y": 3,
      "z": 5,
      "name": "BO_Pool_Surface00",
      "rotation": 4
    },
    {
      "x": -6,
      "y": 4,
      "z": 5,
      "name": "BO_Pool_Surface00",
      "rotation": 4
    },
    {
      "x": -6,
      "y": 5,
      "z": 5,
      "name": "BO_Pool_Surface00",
      "rotation": 4
    },
    {
      "x": -6,
      "y": 6,
      "z": 5,
      "name": "BO_Floor00"
    },
    {
      "x": -6,
      "y": 13,
      "z": 5,
      "name": "BO_Ceiling00"
    },
    {
      "x": -6,
      "y": 0,
      "z": 6,
      "name": "BO_Parking_Blacktop",
      "rotation": 4
    },
    {
      "x": -6,
      "y": 1,
      "z": 6,
      "name": "BO_Pool_Surface00",
      "rotation": 4
    },
    {
      "x": -6,
      "y": 2,
      "z": 6,
      "name": "BO_Pool_Surface00",
      "rotation": 4
    },
    {
      "x": -6,
      "y": 3,
      "z": 6,
      "name": "BO_Pool_Surface00",
      "rotation": 4
    },
    {
      "x": -6,
      "y": 4,
      "z": 6,
      "name": "BO_Pool_Surface00",
      "rotation": 4
    },
    {
      "x": -6,
      "y": 5,
      "z": 6,
      "name": "BO_Pool_Surface00",
      "rotation": 4
    },
    {
      "x": -6,
      "y": 6,
      "z": 6,
      "name": "BO_Floor00"
    },
    {
      "x": -6,
      "y": 13,
      "z": 6,
      "name": "BO_Ceiling00"
    },
    {
      "x": -6,
      "y": 0,
      "z": 7,
      "name": "BO_Parking_Blacktop",
      "rotation": 4
    },
    {
      "x": -6,
      "y": 1,
      "z": 7,
      "name": "BO_Pool_Surface00",
      "rotation": 4
    },
    {
      "x": -6,
      "y": 2,
      "z": 7,
      "name": "BO_Pool_Surface00",
      "rotation": 4
    },
    {
      "x": -6,
      "y": 3,
      "z": 7,
      "name": "BO_Pool_Surface00",
      "rotation": 4
    },
    {
      "x": -6,
      "y": 4,
      "z": 7,
      "name": "BO_Pool_Surface00",
      "rotation": 4
    },
    {
      "x": -6,
      "y": 5,
      "z": 7,
      "name": "BO_Pool_Surface00",
      "rotation": 4
    },
    {
      "x": -6,
      "y": 6,
      "z": 7,
      "name": "BO_Floor00"
    },
    {
      "x": -6,
      "y": 13,
      "z": 7,
      "name": "BO_Ceiling00"
    },
    {
      "x": -6,
      "y": 0,
      "z": 8,
      "name": "BO_Parking_Blacktop",
      "rotation": 4
    },
    {
      "x": -6,
      "y": 1,
      "z": 8,
      "name": "BO_Pool_Surface00",
      "rotation": 4
    },
    {
      "x": -6,
      "y": 2,
      "z": 8,
      "name": "BO_Pool_Surface00",
      "rotation": 4
    },
    {
      "x": -6,
      "y": 3,
      "z": 8,
      "name": "BO_Pool_Surface00",
      "rotation": 4
    },
    {
      "x": -6,
      "y": 4,
      "z": 8,
      "name": "BO_Pool_Surface00",
      "rotation": 4
    },
    {
      "x": -6,
      "y": 5,
      "z": 8,
      "name": "BO_Pool_Surface00",
      "rotation": 4
    },
    {
      "x": -6,
      "y": 6,
      "z": 8,
      "name": "BO_Floor00"
    },
    {
      "x": -6,
      "y": 13,
      "z": 8,
      "name": "BO_Ceiling00"
    },
    {
      "x": -6,
      "y": 0,
      "z": 9,
      "name": "BO_Parking_Blacktop"
    },
    {
      "x": -6,
      "y": 1,
      "z": 9,
      "name": "BO_Pool_Surface00",
      "rotation": 4
    },
    {
      "x": -6,
      "y": 2,
      "z": 9,
      "name": "BO_Pool_Surface00",
      "rotation": 4
    },
    {
      "x": -6,
      "y": 3,
      "z": 9,
      "name": "BO_Pool_Surface00",
      "rotation": 4
    },
    {
      "x": -6,
      "y": 4,
      "z": 9,
      "name": "BO_Pool_Surface00",
      "rotation": 4
    },
    {
      "x": -6,
      "y": 5,
      "z": 9,
      "name": "BO_Pool_Surface00",
      "rotation": 4
    },
    {
      "x": -6,
      "y": 6,
      "z": 9,
      "name": "BO_Floor00"
    },
    {
      "x": -6,
      "y": 13,
      "z": 9,
      "name": "BO_Ceiling00"
    },
    {
      "x": -6,
      "y": 0,
      "z": 10,
      "name": "BO_Parking_Blacktop",
      "rotation": 4
    },
    {
      "x": -6,
      "y": 1,
      "z": 10,
      "name": "BO_Parking_Wall00",
      "rotation": 3
    },
    {
      "x": -6,
      "y": 2,
      "z": 10,
      "name": "BO_Parking_Wall02",
      "rotation": 3
    },
    {
      "x": -6,
      "y": 3,
      "z": 10,
      "name": "BO_Parking_Wall00",
      "rotation": 3
    },
    {
      "x": -6,
      "y": 4,
      "z": 10,
      "name": "BO_Parking_Wall00",
      "rotation": 3
    },
    {
      "x": -6,
      "y": 5,
      "z": 10,
      "name": "BO_Parking_Wall00",
      "rotation": 3
    },
    {
      "x": -6,
      "y": 6,
      "z": 10,
      "name": "BO_Floor00"
    },
    {
      "x": -6,
      "y": 13,
      "z": 10,
      "name": "BO_Ceiling00"
    },
    {
      "x": -5,
      "y": 0,
      "z": -9,
      "name": "Build_White_Cube"
    },
    {
      "x": -5,
      "y": 1,
      "z": -9,
      "name": "BO_Parking_Wall00",
      "rotation": 3
    },
    {
      "x": -5,
      "y": 2,
      "z": -9,
      "name": "BO_Parking_Wall00",
      "rotation": 3
    },
    {
      "x": -5,
      "y": 3,
      "z": -9,
      "name": "BO_Parking_Wall00",
      "rotation": 3
    },
    {
      "x": -5,
      "y": 4,
      "z": -9,
      "name": "BO_Parking_Wall00",
      "rotation": 3
    },
    {
      "x": -5,
      "y": 5,
      "z": -9,
      "name": "BO_Parking_Wall00",
      "rotation": 3
    },
    {
      "x": -5,
      "y": 6,
      "z": -9,
      "name": "BO_Floor00"
    },
    {
      "x": -5,
      "y": 13,
      "z": -9,
      "name": "BO_Ceiling00"
    },
    {
      "x": -5,
      "y": 0,
      "z": -8,
      "name": "BO_Parking_Blacktop",
      "rotation": 4
    },
    {
      "x": -5,
      "y": 1,
      "z": -8,
      "name": "BO_Pool_Surface00",
      "rotation": 4
    },
    {
      "x": -5,
      "y": 2,
      "z": -8,
      "name": "BO_Pool_Surface00",
      "rotation": 4
    },
    {
      "x": -5,
      "y": 3,
      "z": -8,
      "name": "BO_Pool_Surface00",
      "rotation": 4
    },
    {
      "x": -5,
      "y": 4,
      "z": -8,
      "name": "BO_Pool_Surface00",
      "rotation": 4
    },
    {
      "x": -5,
      "y": 5,
      "z": -8,
      "name": "BO_Pool_Surface00",
      "rotation": 4
    },
    {
      "x": -5,
      "y": 6,
      "z": -8,
      "name": "BO_Floor00"
    },
    {
      "x": -5,
      "y": 13,
      "z": -8,
      "name": "BO_Ceiling00"
    },
    {
      "x": -5,
      "y": 0,
      "z": -7,
      "name": "BO_Parking_Blacktop",
      "rotation": 4
    },
    {
      "x": -5,
      "y": 1,
      "z": -7,
      "name": "BO_Pool_Surface00",
      "rotation": 4
    },
    {
      "x": -5,
      "y": 2,
      "z": -7,
      "name": "BO_Pool_Surface00",
      "rotation": 4
    },
    {
      "x": -5,
      "y": 3,
      "z": -7,
      "name": "BO_Pool_Surface00",
      "rotation": 4
    },
    {
      "x": -5,
      "y": 4,
      "z": -7,
      "name": "BO_Pool_Surface00",
      "rotation": 4
    },
    {
      "x": -5,
      "y": 5,
      "z": -7,
      "name": "BO_Pool_Surface00",
      "rotation": 4
    },
    {
      "x": -5,
      "y": 6,
      "z": -7,
      "name": "BO_Floor00"
    },
    {
      "x": -5,
      "y": 13,
      "z": -7,
      "name": "BO_Ceiling00"
    },
    {
      "x": -5,
      "y": 0,
      "z": -6,
      "name": "BO_Parking_Blacktop"
    },
    {
      "x": -5,
      "y": 1,
      "z": -6,
      "name": "Build_Lightsource_White",
      "rotation": 5
    },
    {
      "x": -5,
      "y": 2,
      "z": -6,
      "name": "Build_Lightsource_White",
      "rotation": 5
    },
    {
      "x": -5,
      "y": 3,
      "z": -6,
      "name": "Build_Lightsource_White",
      "rotation": 5
    },
    {
      "x": -5,
      "y": 4,
      "z": -6,
      "name": "Build_Lightsource_White",
      "rotation": 5
    },
    {
      "x": -5,
      "y": 5,
      "z": -6,
      "name": "Build_Lightsource_White",
      "rotation": 5
    },
    {
      "x": -5,
      "y": 6,
      "z": -6,
      "name": "BO_Floor00"
    },
    {
      "x": -5,
      "y": 13,
      "z": -6,
      "name": "BO_Ceiling00"
    },
    {
      "x": -5,
      "y": 0,
      "z": -5,
      "name": "BO_Parking_Blacktop",
      "rotation": 4
    },
    {
      "x": -5,
      "y": 1,
      "z": -5,
      "name": "BO_Parking_Wall00"
    },
    {
      "x": -5,
      "y": 2,
      "z": -5,
      "name": "BO_Parking_Wall02"
    },
    {
      "x": -5,
      "y": 3,
      "z": -5,
      "name": "BO_Parking_Wall00"
    },
    {
      "x": -5,
      "y": 4,
      "z": -5,
      "name": "BO_Parking_Wall00"
    },
    {
      "x": -5,
      "y": 5,
      "z": -5,
      "name": "BO_Parking_Wall00"
    },
    {
      "x": -5,
      "y": 6,
      "z": -5,
      "name": "BO_Floor00"
    },
    {
      "x": -5,
      "y": 13,
      "z": -5,
      "name": "BO_Ceiling_Light00"
    },
    {
      "x": -5,
      "y": 14,
      "z": -5,
      "name": "Build_Lightsource_White"
    },
    {
      "x": -5,
      "y": 0,
      "z": -4,
      "name": "BO_Parking_Blacktop",
      "rotation": 4
    },
    {
      "x": -5,
      "y": 1,
      "z": -4,
      "name": "BO_Parking_Wall00"
    },
    {
      "x": -5,
      "y": 2,
      "z": -4,
      "name": "BO_Parking_Wall02"
    },
    {
      "x": -5,
      "y": 3,
      "z": -4,
      "name": "BO_Parking_Wall00"
    },
    {
      "x": -5,
      "y": 4,
      "z": -4,
      "name": "BO_Parking_Wall00"
    },
    {
      "x": -5,
      "y": 5,
      "z": -4,
      "name": "BO_Parking_Wall00"
    },
    {
      "x": -5,
      "y": 6,
      "z": -4,
      "name": "BO_Floor00"
    },
    {
      "x": -5,
      "y": 13,
      "z": -4,
      "name": "BO_Ceiling_Light00"
    },
    {
      "x": -5,
      "y": 14,
      "z": -4,
      "name": "Build_Lightsource_White"
    },
    {
      "x": -5,
      "y": 0,
      "z": -3,
      "name": "BO_Parking_Blacktop",
      "rotation": 4
    },
    {
      "x": -5,
      "y": 1,
      "z": -3,
      "name": "BO_Pool_Surface00",
      "rotation": 4
    },
    {
      "x": -5,
      "y": 2,
      "z": -3,
      "name": "BO_Pool_Surface00",
      "rotation": 4
    },
    {
      "x": -5,
      "y": 3,
      "z": -3,
      "name": "BO_Pool_Surface00",
      "rotation": 4
    },
    {
      "x": -5,
      "y": 4,
      "z": -3,
      "name": "BO_Pool_Surface00",
      "rotation": 4
    },
    {
      "x": -5,
      "y": 5,
      "z": -3,
      "name": "BO_Pool_Surface00",
      "rotation": 4
    },
    {
      "x": -5,
      "y": 6,
      "z": -3,
      "name": "BO_Floor00"
    },
    {
      "x": -5,
      "y": 13,
      "z": -3,
      "name": "BO_Ceiling00"
    },
    {
      "x": -5,
      "y": 0,
      "z": -2,
      "name": "BO_Parking_Blacktop",
      "rotation": 4
    },
    {
      "x": -5,
      "y": 1,
      "z": -2,
      "name": "BO_Pool_Surface00",
      "rotation": 4
    },
    {
      "x": -5,
      "y": 2,
      "z": -2,
      "name": "BO_Pool_Surface00",
      "rotation": 4
    },
    {
      "x": -5,
      "y": 3,
      "z": -2,
      "name": "BO_Pool_Surface00",
      "rotation": 4
    },
    {
      "x": -5,
      "y": 4,
      "z": -2,
      "name": "BO_Pool_Surface00",
      "rotation": 4
    },
    {
      "x": -5,
      "y": 5,
      "z": -2,
      "name": "BO_Pool_Surface00",
      "rotation": 4
    },
    {
      "x": -5,
      "y": 6,
      "z": -2,
      "name": "BO_Floor00"
    },
    {
      "x": -5,
      "y": 13,
      "z": -2,
      "name": "BO_Ceiling00"
    },
    {
      "x": -5,
      "y": 0,
      "z": -1,
      "name": "BO_Parking_Blacktop"
    },
    {
      "x": -5,
      "y": 1,
      "z": -1,
      "name": "BO_Pool_Surface00",
      "rotation": 4
    },
    {
      "x": -5,
      "y": 2,
      "z": -1,
      "name": "BO_Pool_Surface00",
      "rotation": 4
    },
    {
      "x": -5,
      "y": 3,
      "z": -1,
      "name": "BO_Pool_Surface00",
      "rotation": 4
    },
    {
      "x": -5,
      "y": 4,
      "z": -1,
      "name": "BO_Pool_Surface00",
      "rotation": 4
    },
    {
      "x": -5,
      "y": 5,
      "z": -1,
      "name": "BO_Pool_Surface00",
      "rotation": 4
    },
    {
      "x": -5,
      "y": 6,
      "z": -1,
      "name": "BO_Floor00"
    },
    {
      "x": -5,
      "y": 13,
      "z": -1,
      "name": "BO_Ceiling00"
    },
    {
      "x": -5,
      "y": 0,
      "z": 0,
      "name": "Build_White_Cube"
    },
    {
      "x": -5,
      "y": 1,
      "z": 0,
      "name": "BO_Parking_Wall00",
      "rotation": 3
    },
    {
      "x": -5,
      "y": 2,
      "z": 0,
      "name": "BO_Parking_Wall00",
      "rotation": 3
    },
    {
      "x": -5,
      "y": 3,
      "z": 0,
      "name": "BO_Parking_Wall00",
      "rotation": 3
    },
    {
      "x": -5,
      "y": 4,
      "z": 0,
      "name": "BO_Parking_Wall00",
      "rotation": 3
    },
    {
      "x": -5,
      "y": 5,
      "z": 0,
      "name": "BO_Parking_Wall00",
      "rotation": 3
    },
    {
      "x": -5,
      "y": 6,
      "z": 0,
      "name": "BO_Floor00"
    },
    {
      "x": -5,
      "y": 13,
      "z": 0,
      "name": "BO_Ceiling00"
    },
    {
      "x": -5,
      "y": 0,
      "z": 1,
      "name": "Build_White_Cube"
    },
    {
      "x": -5,
      "y": 1,
      "z": 1,
      "name": "BO_Parking_Wall00",
      "rotation": 3
    },
    {
      "x": -5,
      "y": 2,
      "z": 1,
      "name": "BO_Parking_Wall00",
      "rotation": 3
    },
    {
      "x": -5,
      "y": 3,
      "z": 1,
      "name": "BO_Parking_Wall00",
      "rotation": 3
    },
    {
      "x": -5,
      "y": 4,
      "z": 1,
      "name": "BO_Parking_Wall00",
      "rotation": 3
    },
    {
      "x": -5,
      "y": 5,
      "z": 1,
      "name": "BO_Parking_Wall00",
      "rotation": 3
    },
    {
      "x": -5,
      "y": 6,
      "z": 1,
      "name": "BO_Floor00"
    },
    {
      "x": -5,
      "y": 13,
      "z": 1,
      "name": "BO_Ceiling00"
    },
    {
      "x": -5,
      "y": 0,
      "z": 2,
      "name": "BO_Parking_Blacktop",
      "rotation": 4
    },
    {
      "x": -5,
      "y": 1,
      "z": 2,
      "name": "BO_Pool_Surface00",
      "rotation": 4
    },
    {
      "x": -5,
      "y": 2,
      "z": 2,
      "name": "BO_Pool_Surface00",
      "rotation": 4
    },
    {
      "x": -5,
      "y": 3,
      "z": 2,
      "name": "BO_Pool_Surface00",
      "rotation": 4
    },
    {
      "x": -5,
      "y": 4,
      "z": 2,
      "name": "BO_Pool_Surface00",
      "rotation": 4
    },
    {
      "x": -5,
      "y": 5,
      "z": 2,
      "name": "BO_Pool_Surface00",
      "rotation": 4
    },
    {
      "x": -5,
      "y": 6,
      "z": 2,
      "name": "BO_Floor00"
    },
    {
      "x": -5,
      "y": 13,
      "z": 2,
      "name": "BO_Ceiling00"
    },
    {
      "x": -5,
      "y": 0,
      "z": 3,
      "name": "BO_Parking_Blacktop",
      "rotation": 4
    },
    {
      "x": -5,
      "y": 1,
      "z": 3,
      "name": "BO_Pool_Surface00",
      "rotation": 4
    },
    {
      "x": -5,
      "y": 2,
      "z": 3,
      "name": "BO_Pool_Surface00",
      "rotation": 4
    },
    {
      "x": -5,
      "y": 3,
      "z": 3,
      "name": "BO_Pool_Surface00",
      "rotation": 4
    },
    {
      "x": -5,
      "y": 4,
      "z": 3,
      "name": "BO_Pool_Surface00",
      "rotation": 4
    },
    {
      "x": -5,
      "y": 5,
      "z": 3,
      "name": "BO_Pool_Surface00",
      "rotation": 4
    },
    {
      "x": -5,
      "y": 6,
      "z": 3,
      "name": "BO_Floor00"
    },
    {
      "x": -5,
      "y": 13,
      "z": 3,
      "name": "BO_Ceiling00"
    },
    {
      "x": -5,
      "y": 0,
      "z": 4,
      "name": "BO_Parking_Blacktop"
    },
    {
      "x": -5,
      "y": 1,
      "z": 4,
      "name": "Build_Lightsource_White",
      "rotation": 5
    },
    {
      "x": -5,
      "y": 2,
      "z": 4,
      "name": "Build_Lightsource_White",
      "rotation": 5
    },
    {
      "x": -5,
      "y": 3,
      "z": 4,
      "name": "Build_Lightsource_White",
      "rotation": 5
    },
    {
      "x": -5,
      "y": 4,
      "z": 4,
      "name": "Build_Lightsource_White",
      "rotation": 5
    },
    {
      "x": -5,
      "y": 5,
      "z": 4,
      "name": "Build_Lightsource_White",
      "rotation": 5
    },
    {
      "x": -5,
      "y": 6,
      "z": 4,
      "name": "BO_Floor00"
    },
    {
      "x": -5,
      "y": 13,
      "z": 4,
      "name": "BO_Ceiling00"
    },
    {
      "x": -5,
      "y": 0,
      "z": 5,
      "name": "BO_Parking_Blacktop",
      "rotation": 4
    },
    {
      "x": -5,
      "y": 1,
      "z": 5,
      "name": "BO_Parking_Wall00"
    },
    {
      "x": -5,
      "y": 2,
      "z": 5,
      "name": "BO_Parking_Wall02"
    },
    {
      "x": -5,
      "y": 3,
      "z": 5,
      "name": "BO_Parking_Wall00"
    },
    {
      "x": -5,
      "y": 4,
      "z": 5,
      "name": "BO_Parking_Wall00"
    },
    {
      "x": -5,
      "y": 5,
      "z": 5,
      "name": "BO_Parking_Wall00"
    },
    {
      "x": -5,
      "y": 6,
      "z": 5,
      "name": "BO_Floor00"
    },
    {
      "x": -5,
      "y": 13,
      "z": 5,
      "name": "BO_Ceiling_Light00"
    },
    {
      "x": -5,
      "y": 14,
      "z": 5,
      "name": "Build_Lightsource_White"
    },
    {
      "x": -5,
      "y": 0,
      "z": 6,
      "name": "BO_Parking_Blacktop",
      "rotation": 4
    },
    {
      "x": -5,
      "y": 1,
      "z": 6,
      "name": "BO_Parking_Wall00"
    },
    {
      "x": -5,
      "y": 2,
      "z": 6,
      "name": "BO_Parking_Wall02"
    },
    {
      "x": -5,
      "y": 3,
      "z": 6,
      "name": "BO_Parking_Wall00"
    },
    {
      "x": -5,
      "y": 4,
      "z": 6,
      "name": "BO_Parking_Wall00"
    },
    {
      "x": -5,
      "y": 5,
      "z": 6,
      "name": "BO_Parking_Wall00"
    },
    {
      "x": -5,
      "y": 6,
      "z": 6,
      "name": "BO_Floor00"
    },
    {
      "x": -5,
      "y": 13,
      "z": 6,
      "name": "BO_Ceiling_Light00"
    },
    {
      "x": -5,
      "y": 14,
      "z": 6,
      "name": "Build_Lightsource_White"
    },
    {
      "x": -5,
      "y": 0,
      "z": 7,
      "name": "BO_Parking_Blacktop",
      "rotation": 4
    },
    {
      "x": -5,
      "y": 1,
      "z": 7,
      "name": "BO_Pool_Surface00",
      "rotation": 4
    },
    {
      "x": -5,
      "y": 2,
      "z": 7,
      "name": "BO_Pool_Surface00",
      "rotation": 4
    },
    {
      "x": -5,
      "y": 3,
      "z": 7,
      "name": "BO_Pool_Surface00",
      "rotation": 4
    },
    {
      "x": -5,
      "y": 4,
      "z": 7,
      "name": "BO_Pool_Surface00",
      "rotation": 4
    },
    {
      "x": -5,
      "y": 5,
      "z": 7,
      "name": "BO_Pool_Surface00",
      "rotation": 4
    },
    {
      "x": -5,
      "y": 6,
      "z": 7,
      "name": "BO_Floor00"
    },
    {
      "x": -5,
      "y": 13,
      "z": 7,
      "name": "BO_Ceiling00"
    },
    {
      "x": -5,
      "y": 0,
      "z": 8,
      "name": "BO_Parking_Blacktop",
      "rotation": 4
    },
    {
      "x": -5,
      "y": 1,
      "z": 8,
      "name": "BO_Pool_Surface00",
      "rotation": 4
    },
    {
      "x": -5,
      "y": 2,
      "z": 8,
      "name": "BO_Pool_Surface00",
      "rotation": 4
    },
    {
      "x": -5,
      "y": 3,
      "z": 8,
      "name": "BO_Pool_Surface00",
      "rotation": 4
    },
    {
      "x": -5,
      "y": 4,
      "z": 8,
      "name": "BO_Pool_Surface00",
      "rotation": 4
    },
    {
      "x": -5,
      "y": 5,
      "z": 8,
      "name": "BO_Pool_Surface00",
      "rotation": 4
    },
    {
      "x": -5,
      "y": 6,
      "z": 8,
      "name": "BO_Floor00"
    },
    {
      "x": -5,
      "y": 13,
      "z": 8,
      "name": "BO_Ceiling00"
    },
    {
      "x": -5,
      "y": 0,
      "z": 9,
      "name": "BO_Parking_Blacktop"
    },
    {
      "x": -5,
      "y": 1,
      "z": 9,
      "name": "BO_Pool_Surface00",
      "rotation": 4
    },
    {
      "x": -5,
      "y": 2,
      "z": 9,
      "name": "BO_Pool_Surface00",
      "rotation": 4
    },
    {
      "x": -5,
      "y": 3,
      "z": 9,
      "name": "BO_Pool_Surface00",
      "rotation": 4
    },
    {
      "x": -5,
      "y": 4,
      "z": 9,
      "name": "BO_Pool_Surface00",
      "rotation": 4
    },
    {
      "x": -5,
      "y": 5,
      "z": 9,
      "name": "BO_Pool_Surface00",
      "rotation": 4
    },
    {
      "x": -5,
      "y": 6,
      "z": 9,
      "name": "BO_Floor00"
    },
    {
      "x": -5,
      "y": 13,
      "z": 9,
      "name": "BO_Ceiling00"
    },
    {
      "x": -5,
      "y": 0,
      "z": 10,
      "name": "Build_White_Cube"
    },
    {
      "x": -5,
      "y": 1,
      "z": 10,
      "name": "BO_Parking_Wall00",
      "rotation": 3
    },
    {
      "x": -5,
      "y": 2,
      "z": 10,
      "name": "BO_Parking_Wall00",
      "rotation": 3
    },
    {
      "x": -5,
      "y": 3,
      "z": 10,
      "name": "BO_Parking_Wall00",
      "rotation": 3
    },
    {
      "x": -5,
      "y": 4,
      "z": 10,
      "name": "BO_Parking_Wall00",
      "rotation": 3
    },
    {
      "x": -5,
      "y": 5,
      "z": 10,
      "name": "BO_Parking_Wall00",
      "rotation": 3
    },
    {
      "x": -5,
      "y": 6,
      "z": 10,
      "name": "BO_Floor00"
    },
    {
      "x": -5,
      "y": 13,
      "z": 10,
      "name": "BO_Ceiling00"
    },
    {
      "x": -4,
      "y": 0,
      "z": -9,
      "name": "Build_White_Cube"
    },
    {
      "x": -4,
      "y": 1,
      "z": -9,
      "name": "BO_Parking_Wall00",
      "rotation": 3
    },
    {
      "x": -4,
      "y": 2,
      "z": -9,
      "name": "BO_Parking_Wall00",
      "rotation": 3
    },
    {
      "x": -4,
      "y": 3,
      "z": -9,
      "name": "BO_Parking_Wall00",
      "rotation": 3
    },
    {
      "x": -4,
      "y": 4,
      "z": -9,
      "name": "BO_Parking_Wall00",
      "rotation": 3
    },
    {
      "x": -4,
      "y": 5,
      "z": -9,
      "name": "BO_Parking_Wall00",
      "rotation": 3
    },
    {
      "x": -4,
      "y": 6,
      "z": -9,
      "name": "BO_Floor00"
    },
    {
      "x": -4,
      "y": 13,
      "z": -9,
      "name": "BO_Ceiling00"
    },
    {
      "x": -4,
      "y": 0,
      "z": -8,
      "name": "BO_Parking_Blacktop",
      "rotation": 4
    },
    {
      "x": -4,
      "y": 1,
      "z": -8,
      "name": "BO_Pool_Surface00",
      "rotation": 4
    },
    {
      "x": -4,
      "y": 2,
      "z": -8,
      "name": "BO_Pool_Surface00",
      "rotation": 4
    },
    {
      "x": -4,
      "y": 3,
      "z": -8,
      "name": "BO_Pool_Surface00",
      "rotation": 4
    },
    {
      "x": -4,
      "y": 4,
      "z": -8,
      "name": "BO_Pool_Surface00",
      "rotation": 4
    },
    {
      "x": -4,
      "y": 5,
      "z": -8,
      "name": "BO_Pool_Surface00",
      "rotation": 4
    },
    {
      "x": -4,
      "y": 6,
      "z": -8,
      "name": "BO_Floor00"
    },
    {
      "x": -4,
      "y": 13,
      "z": -8,
      "name": "BO_Ceiling00"
    },
    {
      "x": -4,
      "y": 0,
      "z": -7,
      "name": "BO_Parking_Blacktop",
      "rotation": 4
    },
    {
      "x": -4,
      "y": 1,
      "z": -7,
      "name": "BO_Pool_Surface00",
      "rotation": 4
    },
    {
      "x": -4,
      "y": 2,
      "z": -7,
      "name": "BO_Pool_Surface00",
      "rotation": 4
    },
    {
      "x": -4,
      "y": 3,
      "z": -7,
      "name": "BO_Pool_Surface00",
      "rotation": 4
    },
    {
      "x": -4,
      "y": 4,
      "z": -7,
      "name": "BO_Pool_Surface00",
      "rotation": 4
    },
    {
      "x": -4,
      "y": 5,
      "z": -7,
      "name": "BO_Pool_Surface00",
      "rotation": 4
    },
    {
      "x": -4,
      "y": 6,
      "z": -7,
      "name": "BO_Floor00"
    },
    {
      "x": -4,
      "y": 13,
      "z": -7,
      "name": "BO_Ceiling00"
    },
    {
      "x": -4,
      "y": 0,
      "z": -6,
      "name": "BO_Parking_Blacktop"
    },
    {
      "x": -4,
      "y": 1,
      "z": -6,
      "name": "Build_Lightsource_White",
      "rotation": 4
    },
    {
      "x": -4,
      "y": 2,
      "z": -6,
      "name": "Build_Lightsource_White",
      "rotation": 4
    },
    {
      "x": -4,
      "y": 3,
      "z": -6,
      "name": "Build_Lightsource_White",
      "rotation": 4
    },
    {
      "x": -4,
      "y": 4,
      "z": -6,
      "name": "Build_Lightsource_White",
      "rotation": 4
    },
    {
      "x": -4,
      "y": 5,
      "z": -6,
      "name": "Build_Lightsource_White",
      "rotation": 4
    },
    {
      "x": -4,
      "y": 6,
      "z": -6,
      "name": "BO_Floor00"
    },
    {
      "x": -4,
      "y": 13,
      "z": -6,
      "name": "BO_Ceiling00"
    },
    {
      "x": -4,
      "y": 0,
      "z": -5,
      "name": "BO_Parking_Blacktop",
      "rotation": 4
    },
    {
      "x": -4,
      "y": 1,
      "z": -5,
      "name": "BO_Parking_Wall00"
    },
    {
      "x": -4,
      "y": 2,
      "z": -5,
      "name": "BO_Parking_Wall02"
    },
    {
      "x": -4,
      "y": 3,
      "z": -5,
      "name": "BO_Parking_Wall00"
    },
    {
      "x": -4,
      "y": 4,
      "z": -5,
      "name": "BO_Parking_Wall00"
    },
    {
      "x": -4,
      "y": 5,
      "z": -5,
      "name": "BO_Parking_Wall00"
    },
    {
      "x": -4,
      "y": 6,
      "z": -5,
      "name": "BO_Floor00"
    },
    {
      "x": -4,
      "y": 13,
      "z": -5,
      "name": "BO_Ceiling_Light00"
    },
    {
      "x": -4,
      "y": 14,
      "z": -5,
      "name": "Build_Lightsource_White"
    },
    {
      "x": -4,
      "y": 0,
      "z": -4,
      "name": "BO_Parking_Blacktop",
      "rotation": 4
    },
    {
      "x": -4,
      "y": 1,
      "z": -4,
      "name": "BO_Parking_Wall00"
    },
    {
      "x": -4,
      "y": 2,
      "z": -4,
      "name": "BO_Parking_Wall02"
    },
    {
      "x": -4,
      "y": 3,
      "z": -4,
      "name": "BO_Parking_Wall00"
    },
    {
      "x": -4,
      "y": 4,
      "z": -4,
      "name": "BO_Parking_Wall00"
    },
    {
      "x": -4,
      "y": 5,
      "z": -4,
      "name": "BO_Parking_Wall00"
    },
    {
      "x": -4,
      "y": 6,
      "z": -4,
      "name": "BO_Floor00"
    },
    {
      "x": -4,
      "y": 13,
      "z": -4,
      "name": "BO_Ceiling_Light00"
    },
    {
      "x": -4,
      "y": 14,
      "z": -4,
      "name": "Build_Lightsource_White"
    },
    {
      "x": -4,
      "y": 0,
      "z": -3,
      "name": "BO_Parking_Blacktop",
      "rotation": 4
    },
    {
      "x": -4,
      "y": 1,
      "z": -3,
      "name": "BO_Pool_Surface00",
      "rotation": 4
    },
    {
      "x": -4,
      "y": 2,
      "z": -3,
      "name": "BO_Pool_Surface00",
      "rotation": 4
    },
    {
      "x": -4,
      "y": 3,
      "z": -3,
      "name": "BO_Pool_Surface00",
      "rotation": 4
    },
    {
      "x": -4,
      "y": 4,
      "z": -3,
      "name": "BO_Pool_Surface00",
      "rotation": 4
    },
    {
      "x": -4,
      "y": 5,
      "z": -3,
      "name": "BO_Pool_Surface00",
      "rotation": 4
    },
    {
      "x": -4,
      "y": 6,
      "z": -3,
      "name": "BO_Floor00"
    },
    {
      "x": -4,
      "y": 13,
      "z": -3,
      "name": "BO_Ceiling00"
    },
    {
      "x": -4,
      "y": 0,
      "z": -2,
      "name": "BO_Parking_Blacktop",
      "rotation": 4
    },
    {
      "x": -4,
      "y": 1,
      "z": -2,
      "name": "BO_Pool_Surface00",
      "rotation": 4
    },
    {
      "x": -4,
      "y": 2,
      "z": -2,
      "name": "BO_Pool_Surface00",
      "rotation": 4
    },
    {
      "x": -4,
      "y": 3,
      "z": -2,
      "name": "BO_Pool_Surface00",
      "rotation": 4
    },
    {
      "x": -4,
      "y": 4,
      "z": -2,
      "name": "BO_Pool_Surface00",
      "rotation": 4
    },
    {
      "x": -4,
      "y": 5,
      "z": -2,
      "name": "BO_Pool_Surface00",
      "rotation": 4
    },
    {
      "x": -4,
      "y": 6,
      "z": -2,
      "name": "BO_Floor00"
    },
    {
      "x": -4,
      "y": 13,
      "z": -2,
      "name": "BO_Ceiling00"
    },
    {
      "x": -4,
      "y": 0,
      "z": -1,
      "name": "BO_Parking_Blacktop"
    },
    {
      "x": -4,
      "y": 1,
      "z": -1,
      "name": "BO_Pool_Surface00",
      "rotation": 4
    },
    {
      "x": -4,
      "y": 2,
      "z": -1,
      "name": "BO_Pool_Surface00",
      "rotation": 4
    },
    {
      "x": -4,
      "y": 3,
      "z": -1,
      "name": "BO_Pool_Surface00",
      "rotation": 4
    },
    {
      "x": -4,
      "y": 4,
      "z": -1,
      "name": "BO_Pool_Surface00",
      "rotation": 4
    },
    {
      "x": -4,
      "y": 5,
      "z": -1,
      "name": "BO_Pool_Surface00",
      "rotation": 4
    },
    {
      "x": -4,
      "y": 6,
      "z": -1,
      "name": "BO_Floor00"
    },
    {
      "x": -4,
      "y": 13,
      "z": -1,
      "name": "BO_Ceiling00"
    },
    {
      "x": -4,
      "y": 0,
      "z": 0,
      "name": "Build_White_Cube"
    },
    {
      "x": -4,
      "y": 1,
      "z": 0,
      "name": "BO_Parking_Wall00",
      "rotation": 3
    },
    {
      "x": -4,
      "y": 2,
      "z": 0,
      "name": "BO_Parking_Wall00",
      "rotation": 3
    },
    {
      "x": -4,
      "y": 3,
      "z": 0,
      "name": "BO_Parking_Wall00",
      "rotation": 3
    },
    {
      "x": -4,
      "y": 4,
      "z": 0,
      "name": "BO_Parking_Wall00",
      "rotation": 3
    },
    {
      "x": -4,
      "y": 5,
      "z": 0,
      "name": "BO_Parking_Wall00",
      "rotation": 3
    },
    {
      "x": -4,
      "y": 6,
      "z": 0,
      "name": "BO_Floor00"
    },
    {
      "x": -4,
      "y": 13,
      "z": 0,
      "name": "BO_Ceiling00"
    },
    {
      "x": -4,
      "y": 0,
      "z": 1,
      "name": "Build_White_Cube"
    },
    {
      "x": -4,
      "y": 1,
      "z": 1,
      "name": "BO_Parking_Wall00",
      "rotation": 3
    },
    {
      "x": -4,
      "y": 2,
      "z": 1,
      "name": "BO_Parking_Wall00",
      "rotation": 3
    },
    {
      "x": -4,
      "y": 3,
      "z": 1,
      "name": "BO_Parking_Wall00",
      "rotation": 3
    },
    {
      "x": -4,
      "y": 4,
      "z": 1,
      "name": "BO_Parking_Wall00",
      "rotation": 3
    },
    {
      "x": -4,
      "y": 5,
      "z": 1,
      "name": "BO_Parking_Wall00",
      "rotation": 3
    },
    {
      "x": -4,
      "y": 6,
      "z": 1,
      "name": "BO_Floor00"
    },
    {
      "x": -4,
      "y": 13,
      "z": 1,
      "name": "BO_Ceiling00"
    },
    {
      "x": -4,
      "y": 0,
      "z": 2,
      "name": "BO_Parking_Blacktop",
      "rotation": 4
    },
    {
      "x": -4,
      "y": 1,
      "z": 2,
      "name": "BO_Pool_Surface00",
      "rotation": 4
    },
    {
      "x": -4,
      "y": 2,
      "z": 2,
      "name": "BO_Pool_Surface00",
      "rotation": 4
    },
    {
      "x": -4,
      "y": 3,
      "z": 2,
      "name": "BO_Pool_Surface00",
      "rotation": 4
    },
    {
      "x": -4,
      "y": 4,
      "z": 2,
      "name": "BO_Pool_Surface00",
      "rotation": 4
    },
    {
      "x": -4,
      "y": 5,
      "z": 2,
      "name": "BO_Pool_Surface00",
      "rotation": 4
    },
    {
      "x": -4,
      "y": 6,
      "z": 2,
      "name": "BO_Floor00"
    },
    {
      "x": -4,
      "y": 13,
      "z": 2,
      "name": "BO_Ceiling00"
    },
    {
      "x": -4,
      "y": 0,
      "z": 3,
      "name": "BO_Parking_Blacktop",
      "rotation": 4
    },
    {
      "x": -4,
      "y": 1,
      "z": 3,
      "name": "BO_Pool_Surface00",
      "rotation": 4
    },
    {
      "x": -4,
      "y": 2,
      "z": 3,
      "name": "BO_Pool_Surface00",
      "rotation": 4
    },
    {
      "x": -4,
      "y": 3,
      "z": 3,
      "name": "BO_Pool_Surface00",
      "rotation": 4
    },
    {
      "x": -4,
      "y": 4,
      "z": 3,
      "name": "BO_Pool_Surface00",
      "rotation": 4
    },
    {
      "x": -4,
      "y": 5,
      "z": 3,
      "name": "BO_Pool_Surface00",
      "rotation": 4
    },
    {
      "x": -4,
      "y": 6,
      "z": 3,
      "name": "BO_Floor00"
    },
    {
      "x": -4,
      "y": 13,
      "z": 3,
      "name": "BO_Ceiling00"
    },
    {
      "x": -4,
      "y": 0,
      "z": 4,
      "name": "BO_Parking_Blacktop"
    },
    {
      "x": -4,
      "y": 1,
      "z": 4,
      "name": "Build_Lightsource_White",
      "rotation": 4
    },
    {
      "x": -4,
      "y": 2,
      "z": 4,
      "name": "Build_Lightsource_White",
      "rotation": 4
    },
    {
      "x": -4,
      "y": 3,
      "z": 4,
      "name": "Build_Lightsource_White",
      "rotation": 4
    },
    {
      "x": -4,
      "y": 4,
      "z": 4,
      "name": "Build_Lightsource_White",
      "rotation": 4
    },
    {
      "x": -4,
      "y": 5,
      "z": 4,
      "name": "Build_Lightsource_White",
      "rotation": 4
    },
    {
      "x": -4,
      "y": 6,
      "z": 4,
      "name": "BO_Floor00"
    },
    {
      "x": -4,
      "y": 13,
      "z": 4,
      "name": "BO_Ceiling00"
    },
    {
      "x": -4,
      "y": 0,
      "z": 5,
      "name": "BO_Parking_Blacktop",
      "rotation": 4
    },
    {
      "x": -4,
      "y": 1,
      "z": 5,
      "name": "BO_Parking_Wall00"
    },
    {
      "x": -4,
      "y": 2,
      "z": 5,
      "name": "BO_Parking_Wall02"
    },
    {
      "x": -4,
      "y": 3,
      "z": 5,
      "name": "BO_Parking_Wall00"
    },
    {
      "x": -4,
      "y": 4,
      "z": 5,
      "name": "BO_Parking_Wall00"
    },
    {
      "x": -4,
      "y": 5,
      "z": 5,
      "name": "BO_Parking_Wall00"
    },
    {
      "x": -4,
      "y": 6,
      "z": 5,
      "name": "BO_Floor00"
    },
    {
      "x": -4,
      "y": 13,
      "z": 5,
      "name": "BO_Ceiling_Light00"
    },
    {
      "x": -4,
      "y": 14,
      "z": 5,
      "name": "Build_Lightsource_White"
    },
    {
      "x": -4,
      "y": 0,
      "z": 6,
      "name": "BO_Parking_Blacktop",
      "rotation": 4
    },
    {
      "x": -4,
      "y": 1,
      "z": 6,
      "name": "BO_Parking_Wall00"
    },
    {
      "x": -4,
      "y": 2,
      "z": 6,
      "name": "BO_Parking_Wall02"
    },
    {
      "x": -4,
      "y": 3,
      "z": 6,
      "name": "BO_Parking_Wall00"
    },
    {
      "x": -4,
      "y": 4,
      "z": 6,
      "name": "BO_Parking_Wall00"
    },
    {
      "x": -4,
      "y": 5,
      "z": 6,
      "name": "BO_Parking_Wall00"
    },
    {
      "x": -4,
      "y": 6,
      "z": 6,
      "name": "BO_Floor00"
    },
    {
      "x": -4,
      "y": 13,
      "z": 6,
      "name": "BO_Ceiling_Light00"
    },
    {
      "x": -4,
      "y": 14,
      "z": 6,
      "name": "Build_Lightsource_White"
    },
    {
      "x": -4,
      "y": 0,
      "z": 7,
      "name": "BO_Parking_Blacktop",
      "rotation": 4
    },
    {
      "x": -4,
      "y": 1,
      "z": 7,
      "name": "BO_Pool_Surface00",
      "rotation": 4
    },
    {
      "x": -4,
      "y": 2,
      "z": 7,
      "name": "BO_Pool_Surface00",
      "rotation": 4
    },
    {
      "x": -4,
      "y": 3,
      "z": 7,
      "name": "BO_Pool_Surface00",
      "rotation": 4
    },
    {
      "x": -4,
      "y": 4,
      "z": 7,
      "name": "BO_Pool_Surface00",
      "rotation": 4
    },
    {
      "x": -4,
      "y": 5,
      "z": 7,
      "name": "BO_Pool_Surface00",
      "rotation": 4
    },
    {
      "x": -4,
      "y": 6,
      "z": 7,
      "name": "BO_Floor00"
    },
    {
      "x": -4,
      "y": 13,
      "z": 7,
