{
  "version": 8,
  "blockIdVersion": 11,
  "anchorX": 0,
  "anchorY": 0,
  "anchorZ": 0,
  "blocks": [
    {
      "x": -13,
      "y": -7,
      "z": 15,
      "name": "Rock_Stone"
    },
    {
      "x": -13,
      "y": -6,
      "z": 15,
      "name": "Rock_Stone"
    },
    {
      "x": -13,
      "y": -5,
      "z": 15,
      "name": "Rock_Stone"
    },
    {
      "x": -13,
      "y": -4,
      "z": 15,
      "name": "Rock_Stone"
    },
    {
      "x": -13,
      "y": -3,
      "z": 15,
      "name": "Rock_Stone"
    },
    {
      "x": -13,
      "y": -2,
      "z": 15,
      "name": "Rock_Stone"
    },
    {
      "x": -13,
      "y": -1,
      "z": 15,
      "name": "Rock_Stone"
    },
    {
      "x": -13,
      "y": 0,
      "z": 15,
      "name": "Rock_Stone"
    },
    {
      "x": -13,
      "y": 1,
      "z": 15,
      "name": "Rock_Stone"
    },
    {
      "x": -13,
      "y": -7,
      "z": 16,
      "name": "Rock_Stone"
    },
    {
      "x": -13,
      "y": -6,
      "z": 16,
      "name": "Rock_Stone"
    },
    {
      "x": -13,
      "y": -5,
      "z": 16,
      "name": "Rock_Stone"
    },
    {
      "x": -13,
      "y": -4,
      "z": 16,
      "name": "Rock_Stone"
    },
    {
      "x": -13,
      "y": -3,
      "z": 16,
      "name": "Rock_Stone"
    },
    {
      "x": -13,
      "y": -2,
      "z": 16,
      "name": "Rock_Stone"
    },
    {
      "x": -13,
      "y": -1,
      "z": 16,
      "name": "Rock_Stone"
    },
    {
      "x": -13,
      "y": 0,
      "z": 16,
      "name": "Rock_Stone"
    },
    {
      "x": -13,
      "y": 1,
      "z": 16,
      "name": "Rock_Stone"
    },
    {
      "x": -13,
      "y": 2,
      "z": 16,
      "name": "Rock_Stone"
    },
    {
      "x": -13,
      "y": 3,
      "z": 16,
      "name": "Rock_Stone"
    },
    {
      "x": -13,
      "y": 4,
      "z": 16,
      "name": "Rock_Stone"
    },
    {
      "x": -13,
      "y": 5,
      "z": 16,
      "name": "Rock_Stone"
    },
    {
      "x": -13,
      "y": -7,
      "z": 17,
      "name": "Rock_Stone"
    },
    {
      "x": -13,
      "y": -6,
      "z": 17,
      "name": "Rock_Stone"
    },
    {
      "x": -13,
      "y": -5,
      "z": 17,
      "name": "Rock_Stone"
    },
    {
      "x": -13,
      "y": -4,
      "z": 17,
      "name": "Rock_Stone"
    },
    {
      "x": -13,
      "y": -3,
      "z": 17,
      "name": "Rock_Stone"
    },
    {
      "x": -13,
      "y": -2,
      "z": 17,
      "name": "Rock_Stone"
    },
    {
      "x": -13,
      "y": -1,
      "z": 17,
      "name": "Rock_Stone"
    },
    {
      "x": -13,
      "y": 0,
      "z": 17,
      "name": "Rock_Stone"
    },
    {
      "x": -13,
      "y": 1,
      "z": 17,
      "name": "Rock_Stone"
    },
    {
      "x": -13,
      "y": 2,
      "z": 17,
      "name": "Rock_Stone"
    },
    {
      "x": -13,
      "y": 3,
      "z": 17,
      "name": "Rock_Stone"
    },
    {
      "x": -13,
      "y": 4,
      "z": 17,
      "name": "Rock_Stone"
    },
    {
      "x": -13,
      "y": 5,
      "z": 17,
      "name": "Rock_Stone"
    },
    {
      "x": -13,
      "y": 6,
      "z": 17,
      "name": "Soil_Dirt"
    },
    {
      "x": -13,
      "y": 7,
      "z": 17,
      "name": "Soil_Grass"
    },
    {
      "x": -13,
      "y": -7,
      "z": 18,
      "name": "Rock_Stone"
    },
    {
      "x": -13,
      "y": -6,
      "z": 18,
      "name": "Rock_Stone"
    },
    {
      "x": -13,
      "y": -5,
      "z": 18,
      "name": "Rock_Stone"
    },
    {
      "x": -13,
      "y": -4,
      "z": 18,
      "name": "Rock_Stone"
    },
    {
      "x": -13,
      "y": -3,
      "z": 18,
      "name": "Rock_Stone"
    },
    {
      "x": -13,
      "y": -2,
      "z": 18,
      "name": "Rock_Stone"
    },
    {
      "x": -13,
      "y": -1,
      "z": 18,
      "name": "Rock_Stone"
    },
    {
      "x": -13,
      "y": 0,
      "z": 18,
      "name": "Rock_Stone"
    },
    {
      "x": -13,
      "y": 1,
      "z": 18,
      "name": "Rock_Stone"
    },
    {
      "x": -13,
      "y": 2,
      "z": 18,
      "name": "Rock_Stone"
    },
    {
      "x": -13,
      "y": 3,
      "z": 18,
      "name": "Rock_Stone"
    },
    {
      "x": -13,
      "y": 4,
      "z": 18,
      "name": "Rock_Stone"
    },
    {
      "x": -13,
      "y": 5,
      "z": 18,
      "name": "Rock_Stone"
    },
    {
      "x": -13,
      "y": 6,
      "z": 18,
      "name": "Soil_Dirt"
    },
    {
      "x": -13,
      "y": 7,
      "z": 18,
      "name": "Soil_Grass"
    },
    {
      "x": -13,
      "y": -7,
      "z": 19,
      "name": "Rock_Stone"
    },
    {
      "x": -13,
      "y": -6,
      "z": 19,
      "name": "Rock_Stone"
    },
    {
      "x": -13,
      "y": -5,
      "z": 19,
      "name": "Rock_Stone"
    },
    {
      "x": -13,
      "y": -4,
      "z": 19,
      "name": "Rock_Stone"
    },
    {
      "x": -13,
      "y": -3,
      "z": 19,
      "name": "Rock_Stone"
    },
    {
      "x": -13,
      "y": -2,
      "z": 19,
      "name": "Rock_Stone"
    },
    {
      "x": -13,
      "y": -1,
      "z": 19,
      "name": "Rock_Stone"
    },
    {
      "x": -13,
      "y": 0,
      "z": 19,
      "name": "Rock_Stone"
    },
    {
      "x": -13,
      "y": 1,
      "z": 19,
      "name": "Rock_Stone"
    },
    {
      "x": -13,
      "y": 2,
      "z": 19,
      "name": "Rock_Stone"
    },
    {
      "x": -13,
      "y": 3,
      "z": 19,
      "name": "Rock_Stone"
    },
    {
      "x": -13,
      "y": 4,
      "z": 19,
      "name": "Rock_Stone"
    },
    {
      "x": -13,
      "y": 5,
      "z": 19,
      "name": "Soil_Dirt"
    },
    {
      "x": -13,
      "y": 6,
      "z": 19,
      "name": "Soil_Grass"
    },
    {
      "x": -13,
      "y": -7,
      "z": 20,
      "name": "Rock_Stone"
    },
    {
      "x": -13,
      "y": -6,
      "z": 20,
      "name": "Rock_Stone"
    },
    {
      "x": -13,
      "y": -5,
      "z": 20,
      "name": "Rock_Stone"
    },
    {
      "x": -13,
      "y": -4,
      "z": 20,
      "name": "Rock_Stone"
    },
    {
      "x": -13,
      "y": -3,
      "z": 20,
      "name": "Rock_Stone"
    },
    {
      "x": -13,
      "y": -2,
      "z": 20,
      "name": "Rock_Stone"
    },
    {
      "x": -13,
      "y": -1,
      "z": 20,
      "name": "Rock_Stone"
    },
    {
      "x": -13,
      "y": 0,
      "z": 20,
      "name": "Rock_Stone"
    },
    {
      "x": -13,
      "y": 1,
      "z": 20,
      "name": "Rock_Stone"
    },
    {
      "x": -13,
      "y": 2,
      "z": 20,
      "name": "Rock_Stone"
    },
    {
      "x": -13,
      "y": 3,
      "z": 20,
      "name": "Rock_Stone"
    },
    {
      "x": -13,
      "y": 4,
      "z": 20,
      "name": "Rock_Stone"
    },
    {
      "x": -13,
      "y": 5,
      "z": 20,
      "name": "Soil_Dirt"
    },
    {
      "x": -13,
      "y": 6,
      "z": 20,
      "name": "Soil_Grass"
    },
    {
      "x": -13,
      "y": -7,
      "z": 21,
      "name": "Rock_Stone"
    },
    {
      "x": -13,
      "y": -6,
      "z": 21,
      "name": "Rock_Stone"
    },
    {
      "x": -13,
      "y": -5,
      "z": 21,
      "name": "Rock_Stone"
    },
    {
      "x": -13,
      "y": -4,
      "z": 21,
      "name": "Rock_Stone"
    },
    {
      "x": -13,
      "y": -3,
      "z": 21,
      "name": "Rock_Stone"
    },
    {
      "x": -13,
      "y": -2,
      "z": 21,
      "name": "Rock_Stone"
    },
    {
      "x": -13,
      "y": -1,
      "z": 21,
      "name": "Rock_Stone"
    },
    {
      "x": -13,
      "y": 0,
      "z": 21,
      "name": "Rock_Stone"
    },
    {
      "x": -13,
      "y": 1,
      "z": 21,
      "name": "Rock_Stone"
    },
    {
      "x": -13,
      "y": 2,
      "z": 21,
      "name": "Rock_Stone"
    },
    {
      "x": -13,
      "y": 3,
      "z": 21,
      "name": "Rock_Stone"
    },
    {
      "x": -13,
      "y": 4,
      "z": 21,
      "name": "Soil_Dirt"
    },
    {
      "x": -13,
      "y": 5,
      "z": 21,
      "name": "Soil_Grass"
    },
    {
      "x": -13,
      "y": -1,
      "z": 22,
      "name": "Rock_Stone"
    },
    {
      "x": -13,
      "y": 0,
      "z": 22,
      "name": "Rock_Stone"
    },
    {
      "x": -13,
      "y": 1,
      "z": 22,
      "name": "Rock_Stone"
    },
    {
      "x": -13,
      "y": 2,
      "z": 22,
      "name": "Rock_Stone"
    },
    {
      "x": -13,
      "y": 3,
      "z": 22,
      "name": "Rock_Stone"
    },
    {
      "x": -13,
      "y": 4,
      "z": 22,
      "name": "Rock_Stone"
    },
    {
      "x": -13,
      "y": 5,
      "z": 22,
      "name": "Soil_Grass"
    },
    {
      "x": -12,
      "y": -7,
      "z": 14,
      "name": "Rock_Stone"
    },
    {
      "x": -12,
      "y": -6,
      "z": 14,
      "name": "Rock_Stone"
    },
    {
      "x": -12,
      "y": -5,
      "z": 14,
      "name": "Rock_Stone"
    },
    {
      "x": -12,
      "y": -4,
      "z": 14,
      "name": "Rock_Stone"
    },
    {
      "x": -12,
      "y": -3,
      "z": 14,
      "name": "Rock_Stone"
    },
    {
      "x": -12,
      "y": -2,
      "z": 14,
      "name": "Rock_Stone"
    },
    {
      "x": -12,
      "y": -1,
      "z": 14,
      "name": "Rock_Stone"
    },
    {
      "x": -12,
      "y": 0,
      "z": 14,
      "name": "Rock_Stone"
    },
    {
      "x": -12,
      "y": 1,
      "z": 14,
      "name": "Rock_Stone"
    },
    {
      "x": -12,
      "y": 2,
      "z": 14,
      "name": "Rock_Stone"
    },
    {
      "x": -12,
      "y": 3,
      "z": 14,
      "name": "Rock_Stone"
    },
    {
      "x": -12,
      "y": 4,
      "z": 14,
      "name": "Rock_Stone"
    },
    {
      "x": -12,
      "y": 5,
      "z": 14,
      "name": "Rock_Stone"
    },
    {
      "x": -12,
      "y": 6,
      "z": 14,
      "name": "Rock_Stone"
    },
    {
      "x": -12,
      "y": 7,
      "z": 14,
      "name": "Rock_Stone"
    },
    {
      "x": -12,
      "y": -7,
      "z": 15,
      "name": "Rock_Stone"
    },
    {
      "x": -12,
      "y": -6,
      "z": 15,
      "name": "Rock_Stone"
    },
    {
      "x": -12,
      "y": -5,
      "z": 15,
      "name": "Rock_Stone"
    },
    {
      "x": -12,
      "y": -4,
      "z": 15,
      "name": "Rock_Stone"
    },
    {
      "x": -12,
      "y": -3,
      "z": 15,
      "name": "Rock_Stone"
    },
    {
      "x": -12,
      "y": -2,
      "z": 15,
      "name": "Rock_Stone"
    },
    {
      "x": -12,
      "y": -1,
      "z": 15,
      "name": "Rock_Stone"
    },
    {
      "x": -12,
      "y": 0,
      "z": 15,
      "name": "Rock_Stone"
    },
    {
      "x": -12,
      "y": 1,
      "z": 15,
      "name": "Rock_Stone"
    },
    {
      "x": -12,
      "y": 2,
      "z": 15,
      "name": "Rock_Stone"
    },
    {
      "x": -12,
      "y": 3,
      "z": 15,
      "name": "Rock_Stone"
    },
    {
      "x": -12,
      "y": 4,
      "z": 15,
      "name": "Rock_Stone"
    },
    {
      "x": -12,
      "y": 5,
      "z": 15,
      "name": "Rock_Stone"
    },
    {
      "x": -12,
      "y": 6,
      "z": 15,
      "name": "Rock_Stone"
    },
    {
      "x": -12,
      "y": 7,
      "z": 15,
      "name": "Rock_Stone"
    },
    {
      "x": -12,
      "y": 8,
      "z": 15,
      "name": "Soil_Grass"
    },
    {
      "x": -12,
      "y": -7,
      "z": 16,
      "name": "Rock_Stone"
    },
    {
      "x": -12,
      "y": -6,
      "z": 16,
      "name": "Rock_Stone"
    },
    {
      "x": -12,
      "y": -5,
      "z": 16,
      "name": "Rock_Stone"
    },
    {
      "x": -12,
      "y": -4,
      "z": 16,
      "name": "Rock_Stone"
    },
    {
      "x": -12,
      "y": -3,
      "z": 16,
      "name": "Rock_Stone"
    },
    {
      "x": -12,
      "y": -2,
      "z": 16,
      "name": "Rock_Stone"
    },
    {
      "x": -12,
      "y": -1,
      "z": 16,
      "name": "Rock_Stone"
    },
    {
      "x": -12,
      "y": 0,
      "z": 16,
      "name": "Rock_Stone"
    },
    {
      "x": -12,
      "y": 1,
      "z": 16,
      "name": "Rock_Stone"
    },
    {
      "x": -12,
      "y": 2,
      "z": 16,
      "name": "Rock_Stone"
    },
    {
      "x": -12,
      "y": 3,
      "z": 16,
      "name": "Rock_Stone"
    },
    {
      "x": -12,
      "y": 4,
      "z": 16,
      "name": "Rock_Stone"
    },
    {
      "x": -12,
      "y": 5,
      "z": 16,
      "name": "Rock_Stone"
    },
    {
      "x": -12,
      "y": 6,
      "z": 16,
      "name": "Rock_Stone"
    },
    {
      "x": -12,
      "y": 7,
      "z": 16,
      "name": "Soil_Dirt"
    },
    {
      "x": -12,
      "y": 8,
      "z": 16,
      "name": "Soil_Grass"
    },
    {
      "x": -12,
      "y": -7,
      "z": 17,
      "name": "Rock_Stone"
    },
    {
      "x": -12,
      "y": -6,
      "z": 17,
      "name": "Rock_Stone"
    },
    {
      "x": -12,
      "y": -5,
      "z": 17,
      "name": "Rock_Stone"
    },
    {
      "x": -12,
      "y": -4,
      "z": 17,
      "name": "Rock_Stone"
    },
    {
      "x": -12,
      "y": -3,
      "z": 17,
      "name": "Rock_Stone"
    },
    {
      "x": -12,
      "y": -2,
      "z": 17,
      "name": "Rock_Stone"
    },
    {
      "x": -12,
      "y": -1,
      "z": 17,
      "name": "Rock_Stone"
    },
    {
      "x": -12,
      "y": 0,
      "z": 17,
      "name": "Rock_Stone"
    },
    {
      "x": -12,
      "y": 1,
      "z": 17,
      "name": "Rock_Stone"
    },
    {
      "x": -12,
      "y": 2,
      "z": 17,
      "name": "Rock_Stone"
    },
    {
      "x": -12,
      "y": 3,
      "z": 17,
      "name": "Rock_Stone"
    },
    {
      "x": -12,
      "y": 4,
      "z": 17,
      "name": "Rock_Stone"
    },
    {
      "x": -12,
      "y": 5,
      "z": 17,
      "name": "Rock_Stone"
    },
    {
      "x": -12,
      "y": 6,
      "z": 17,
      "name": "Soil_Dirt"
    },
    {
      "x": -12,
      "y": 7,
      "z": 17,
      "name": "Soil_Grass"
    },
    {
      "x": -12,
      "y": -7,
      "z": 18,
      "name": "Rock_Stone"
    },
    {
      "x": -12,
      "y": -6,
      "z": 18,
      "name": "Rock_Stone"
    },
    {
      "x": -12,
      "y": -5,
      "z": 18,
      "name": "Rock_Stone"
    },
    {
      "x": -12,
      "y": -4,
      "z": 18,
      "name": "Rock_Stone"
    },
    {
      "x": -12,
      "y": -3,
      "z": 18,
      "name": "Rock_Stone"
    },
    {
      "x": -12,
      "y": -2,
      "z": 18,
      "name": "Rock_Stone"
    },
    {
      "x": -12,
      "y": -1,
      "z": 18,
      "name": "Rock_Stone"
    },
    {
      "x": -12,
      "y": 0,
      "z": 18,
      "name": "Rock_Stone"
    },
    {
      "x": -12,
      "y": 1,
      "z": 18,
      "name": "Rock_Stone"
    },
    {
      "x": -12,
      "y": 2,
      "z": 18,
      "name": "Rock_Stone"
    },
    {
      "x": -12,
      "y": 3,
      "z": 18,
      "name": "Rock_Stone"
    },
    {
      "x": -12,
      "y": 4,
      "z": 18,
      "name": "Rock_Stone"
    },
    {
      "x": -12,
      "y": 5,
      "z": 18,
      "name": "Rock_Stone"
    },
    {
      "x": -12,
      "y": 6,
      "z": 18,
      "name": "Soil_Dirt"
    },
    {
      "x": -12,
      "y": 7,
      "z": 18,
      "name": "Soil_Grass"
    },
    {
      "x": -12,
      "y": -7,
      "z": 19,
      "name": "Rock_Stone"
    },
    {
      "x": -12,
      "y": -6,
      "z": 19,
      "name": "Rock_Stone"
    },
    {
      "x": -12,
      "y": -5,
      "z": 19,
      "name": "Rock_Stone"
    },
    {
      "x": -12,
      "y": -4,
      "z": 19,
      "name": "Rock_Stone"
    },
    {
      "x": -12,
      "y": -3,
      "z": 19,
      "name": "Rock_Stone"
    },
    {
      "x": -12,
      "y": -2,
      "z": 19,
      "name": "Rock_Stone"
    },
    {
      "x": -12,
      "y": -1,
      "z": 19,
      "name": "Rock_Stone"
    },
    {
      "x": -12,
      "y": 0,
      "z": 19,
      "name": "Rock_Stone"
    },
    {
      "x": -12,
      "y": 1,
      "z": 19,
      "name": "Rock_Stone"
    },
    {
      "x": -12,
      "y": 2,
      "z": 19,
      "name": "Rock_Stone"
    },
    {
      "x": -12,
      "y": 3,
      "z": 19,
      "name": "Rock_Stone"
    },
    {
      "x": -12,
      "y": 4,
      "z": 19,
      "name": "Rock_Stone"
    },
    {
      "x": -12,
      "y": 5,
      "z": 19,
      "name": "Soil_Dirt"
    },
    {
      "x": -12,
      "y": 6,
      "z": 19,
      "name": "Soil_Dirt"
    },
    {
      "x": -12,
      "y": 7,
      "z": 19,
      "name": "Soil_Grass"
    },
    {
      "x": -12,
      "y": -7,
      "z": 20,
      "name": "Rock_Stone"
    },
    {
      "x": -12,
      "y": -6,
      "z": 20,
      "name": "Rock_Stone"
    },
    {
      "x": -12,
      "y": -5,
      "z": 20,
      "name": "Rock_Stone"
    },
    {
      "x": -12,
      "y": -4,
      "z": 20,
      "name": "Rock_Stone"
    },
    {
      "x": -12,
      "y": -3,
      "z": 20,
      "name": "Rock_Stone"
    },
    {
      "x": -12,
      "y": -2,
      "z": 20,
      "name": "Rock_Stone"
    },
    {
      "x": -12,
      "y": -1,
      "z": 20,
      "name": "Rock_Stone"
    },
    {
      "x": -12,
      "y": 0,
      "z": 20,
      "name": "Rock_Stone"
    },
    {
      "x": -12,
      "y": 1,
      "z": 20,
      "name": "Rock_Stone"
    },
    {
      "x": -12,
      "y": 2,
      "z": 20,
      "name": "Rock_Stone"
    },
    {
      "x": -12,
      "y": 3,
      "z": 20,
      "name": "Rock_Stone"
    },
    {
      "x": -12,
      "y": 4,
      "z": 20,
      "name": "Rock_Stone"
    },
    {
      "x": -12,
      "y": 5,
      "z": 20,
      "name": "Soil_Dirt"
    },
    {
      "x": -12,
      "y": 6,
      "z": 20,
      "name": "Soil_Grass"
    },
    {
      "x": -12,
      "y": -7,
      "z": 21,
      "name": "Rock_Stone"
    },
    {
      "x": -12,
      "y": -6,
      "z": 21,
      "name": "Rock_Stone"
    },
    {
      "x": -12,
      "y": -5,
      "z": 21,
      "name": "Rock_Stone"
    },
    {
      "x": -12,
      "y": -4,
      "z": 21,
      "name": "Rock_Stone"
    },
    {
      "x": -12,
      "y": -3,
      "z": 21,
      "name": "Rock_Stone"
    },
    {
      "x": -12,
      "y": -2,
      "z": 21,
      "name": "Rock_Stone"
    },
    {
      "x": -12,
      "y": -1,
      "z": 21,
      "name": "Rock_Stone"
    },
    {
      "x": -12,
      "y": 0,
      "z": 21,
      "name": "Rock_Stone"
    },
    {
      "x": -12,
      "y": 1,
      "z": 21,
      "name": "Rock_Stone"
    },
    {
      "x": -12,
      "y": 2,
      "z": 21,
      "name": "Rock_Stone"
    },
    {
      "x": -12,
      "y": 3,
      "z": 21,
      "name": "Rock_Stone"
    },
    {
      "x": -12,
      "y": 4,
      "z": 21,
      "name": "Soil_Dirt"
    },
    {
      "x": -12,
      "y": 5,
      "z": 21,
      "name": "Soil_Dirt"
    },
    {
      "x": -12,
      "y": 6,
      "z": 21,
      "name": "Soil_Grass"
    },
    {
      "x": -12,
      "y": -7,
      "z": 22,
      "name": "Rock_Stone"
    },
    {
      "x": -12,
      "y": -6,
      "z": 22,
      "name": "Rock_Stone"
    },
    {
      "x": -12,
      "y": -5,
      "z": 22,
      "name": "Rock_Stone"
    },
    {
      "x": -12,
      "y": -4,
      "z": 22,
      "name": "Rock_Stone"
    },
    {
      "x": -12,
      "y": -3,
      "z": 22,
      "name": "Rock_Stone"
    },
    {
      "x": -12,
      "y": -2,
      "z": 22,
      "name": "Rock_Stone"
    },
    {
      "x": -12,
      "y": -1,
      "z": 22,
      "name": "Rock_Stone"
    },
    {
      "x": -12,
      "y": 0,
      "z": 22,
      "name": "Rock_Stone"
    },
    {
      "x": -12,
      "y": 1,
      "z": 22,
      "name": "Rock_Stone"
    },
    {
      "x": -12,
      "y": 2,
      "z": 22,
      "name": "Rock_Stone"
    },
    {
      "x": -12,
      "y": 3,
      "z": 22,
      "name": "Rock_Stone"
    },
    {
      "x": -12,
      "y": 4,
      "z": 22,
      "name": "Soil_Dirt"
    },
    {
      "x": -12,
      "y": 5,
      "z": 22,
      "name": "Soil_Grass"
    },
    {
      "x": -12,
      "y": -7,
      "z": 23,
      "name": "Rock_Stone"
    },
    {
      "x": -12,
      "y": -6,
      "z": 23,
      "name": "Rock_Stone"
    },
    {
      "x": -12,
      "y": -5,
      "z": 23,
      "name": "Rock_Stone"
    },
    {
      "x": -12,
      "y": -4,
      "z": 23,
      "name": "Rock_Stone"
    },
    {
      "x": -12,
      "y": -3,
      "z": 23,
      "name": "Rock_Stone"
    },
    {
      "x": -12,
      "y": -2,
      "z": 23,
      "name": "Rock_Stone"
    },
    {
      "x": -12,
      "y": -1,
      "z": 23,
      "name": "Rock_Stone"
    },
    {
      "x": -12,
      "y": 0,
      "z": 23,
      "name": "Rock_Stone"
    },
    {
      "x": -12,
      "y": 1,
      "z": 23,
      "name": "Rock_Stone"
    },
    {
      "x": -12,
      "y": 2,
      "z": 23,
      "name": "Rock_Stone"
    },
    {
      "x": -12,
      "y": 3,
      "z": 23,
      "name": "Rock_Stone"
    },
    {
      "x": -12,
      "y": 4,
      "z": 23,
      "name": "Soil_Dirt"
    },
    {
      "x": -12,
      "y": 5,
      "z": 23,
      "name": "Soil_Grass"
    },
    {
      "x": -12,
      "y": 2,
      "z": 24,
      "name": "Rock_Stone"
    },
    {
      "x": -12,
      "y": 3,
      "z": 24,
      "name": "Rock_Stone"
    },
    {
      "x": -12,
      "y": 4,
      "z": 24,
      "name": "Soil_Grass"
    },
    {
      "x": -11,
      "y": -7,
      "z": 12,
      "name": "Rock_Stone"
    },
    {
      "x": -11,
      "y": -6,
      "z": 12,
      "name": "Rock_Stone"
    },
    {
      "x": -11,
      "y": -5,
      "z": 12,
      "name": "Rock_Stone"
    },
    {
      "x": -11,
      "y": -4,
      "z": 12,
      "name": "Rock_Stone"
    },
    {
      "x": -11,
      "y": -3,
      "z": 12,
      "name": "Rock_Stone"
    },
    {
      "x": -11,
      "y": -2,
      "z": 12,
      "name": "Rock_Stone"
    },
    {
      "x": -11,
      "y": -1,
      "z": 12,
      "name": "Rock_Stone"
    },
    {
      "x": -11,
      "y": 0,
      "z": 12,
      "name": "Rock_Stone"
    },
    {
      "x": -11,
      "y": 1,
      "z": 12,
      "name": "Rock_Stone"
    },
    {
      "x": -11,
      "y": 2,
      "z": 12,
      "name": "Rock_Stone"
    },
    {
      "x": -11,
      "y": 3,
      "z": 12,
      "name": "Rock_Stone"
    },
    {
      "x": -11,
      "y": -7,
      "z": 13,
      "name": "Rock_Stone"
    },
    {
      "x": -11,
      "y": -6,
      "z": 13,
      "name": "Rock_Stone"
    },
    {
      "x": -11,
      "y": -5,
      "z": 13,
      "name": "Rock_Stone"
    },
    {
      "x": -11,
      "y": -4,
      "z": 13,
      "name": "Rock_Stone"
    },
    {
      "x": -11,
      "y": -3,
      "z": 13,
      "name": "Rock_Stone"
    },
    {
      "x": -11,
      "y": -2,
      "z": 13,
      "name": "Rock_Stone"
    },
    {
      "x": -11,
      "y": -1,
      "z": 13,
      "name": "Rock_Stone"
    },
    {
      "x": -11,
      "y": 0,
      "z": 13,
      "name": "Rock_Stone"
    },
    {
      "x": -11,
      "y": 1,
      "z": 13,
      "name": "Rock_Stone"
    },
    {
      "x": -11,
      "y": 2,
      "z": 13,
      "name": "Rock_Stone"
    },
    {
      "x": -11,
      "y": 3,
      "z": 13,
      "name": "Rock_Stone"
    },
    {
      "x": -11,
      "y": 4,
      "z": 13,
      "name": "Rock_Stone"
    },
    {
      "x": -11,
      "y": 5,
      "z": 13,
      "name": "Rock_Stone"
    },
    {
      "x": -11,
      "y": 6,
      "z": 13,
      "name": "Rock_Stone"
    },
    {
      "x": -11,
      "y": 7,
      "z": 13,
      "name": "Rock_Stone"
    },
    {
      "x": -11,
      "y": 8,
      "z": 13,
      "name": "Soil_Dirt"
    },
    {
      "x": -11,
      "y": 9,
      "z": 13,
      "name": "Soil_Grass"
    },
    {
      "x": -11,
      "y": -7,
      "z": 14,
      "name": "Rock_Stone"
    },
    {
      "x": -11,
      "y": -6,
      "z": 14,
      "name": "Rock_Stone"
    },
    {
      "x": -11,
      "y": -5,
      "z": 14,
      "name": "Rock_Stone"
    },
    {
      "x": -11,
      "y": -4,
      "z": 14,
      "name": "Rock_Stone"
    },
    {
      "x": -11,
      "y": -3,
      "z": 14,
      "name": "Rock_Stone"
    },
    {
      "x": -11,
      "y": -2,
      "z": 14,
      "name": "Rock_Stone"
    },
    {
      "x": -11,
      "y": -1,
      "z": 14,
      "name": "Rock_Stone"
    },
    {
      "x": -11,
      "y": 0,
      "z": 14,
      "name": "Rock_Stone"
    },
    {
      "x": -11,
      "y": 1,
      "z": 14,
      "name": "Rock_Stone"
    },
    {
      "x": -11,
      "y": 2,
      "z": 14,
      "name": "Rock_Stone"
    },
    {
      "x": -11,
      "y": 3,
      "z": 14,
      "name": "Rock_Stone"
    },
    {
      "x": -11,
      "y": 4,
      "z": 14,
      "name": "Rock_Stone"
    },
    {
      "x": -11,
      "y": 5,
      "z": 14,
      "name": "Rock_Stone"
    },
    {
      "x": -11,
      "y": 6,
      "z": 14,
      "name": "Rock_Stone"
    },
    {
      "x": -11,
      "y": 7,
      "z": 14,
      "name": "Rock_Stone"
    },
    {
      "x": -11,
      "y": 8,
      "z": 14,
      "name": "Rock_Stone"
    },
    {
      "x": -11,
      "y": 9,
      "z": 14,
      "name": "Soil_Grass"
    },
    {
      "x": -11,
      "y": -7,
      "z": 15,
      "name": "Rock_Stone"
    },
    {
      "x": -11,
      "y": -6,
      "z": 15,
      "name": "Rock_Stone"
    },
    {
      "x": -11,
      "y": -5,
      "z": 15,
      "name": "Rock_Stone"
    },
    {
      "x": -11,
      "y": -4,
      "z": 15,
      "name": "Rock_Stone"
    },
    {
      "x": -11,
      "y": -3,
      "z": 15,
      "name": "Rock_Stone"
    },
    {
      "x": -11,
      "y": -2,
      "z": 15,
      "name": "Rock_Stone"
    },
    {
      "x": -11,
      "y": -1,
      "z": 15,
      "name": "Rock_Stone"
    },
    {
      "x": -11,
      "y": 0,
      "z": 15,
      "name": "Rock_Stone"
    },
    {
      "x": -11,
      "y": 1,
      "z": 15,
      "name": "Rock_Stone"
    },
    {
      "x": -11,
      "y": 2,
      "z": 15,
      "name": "Rock_Stone"
    },
    {
      "x": -11,
      "y": 3,
      "z": 15,
      "name": "Rock_Stone"
    },
    {
      "x": -11,
      "y": 4,
      "z": 15,
      "name": "Rock_Stone"
    },
    {
      "x": -11,
      "y": 5,
      "z": 15,
      "name": "Rock_Stone"
    },
    {
      "x": -11,
      "y": 6,
      "z": 15,
      "name": "Rock_Stone"
    },
    {
      "x": -11,
      "y": 7,
      "z": 15,
      "name": "Rock_Stone"
    },
    {
      "x": -11,
      "y": 8,
      "z": 15,
      "name": "Rock_Stone"
    },
    {
      "x": -11,
      "y": 9,
      "z": 15,
      "name": "Soil_Grass"
    },
    {
      "x": -11,
      "y": -7,
      "z": 16,
      "name": "Rock_Stone"
    },
    {
      "x": -11,
      "y": -6,
      "z": 16,
      "name": "Rock_Stone"
    },
    {
      "x": -11,
      "y": -5,
      "z": 16,
      "name": "Rock_Stone"
    },
    {
      "x": -11,
      "y": -4,
      "z": 16,
      "name": "Rock_Stone"
    },
    {
      "x": -11,
      "y": -3,
      "z": 16,
      "name": "Rock_Stone"
    },
    {
      "x": -11,
      "y": -2,
      "z": 16,
      "name": "Rock_Stone"
    },
    {
      "x": -11,
      "y": -1,
      "z": 16,
      "name": "Rock_Stone"
    },
    {
      "x": -11,
      "y": 0,
      "z": 16,
      "name": "Rock_Stone"
    },
    {
      "x": -11,
      "y": 1,
      "z": 16,
      "name": "Rock_Stone"
    },
    {
      "x": -11,
      "y": 2,
      "z": 16,
      "name": "Rock_Stone"
    },
    {
      "x": -11,
      "y": 3,
      "z": 16,
      "name": "Rock_Stone"
    },
    {
      "x": -11,
      "y": 4,
      "z": 16,
      "name": "Rock_Stone"
    },
    {
      "x": -11,
      "y": 5,
      "z": 16,
      "name": "Rock_Stone"
    },
    {
      "x": -11,
      "y": 6,
      "z": 16,
      "name": "Rock_Stone"
    },
    {
      "x": -11,
      "y": 7,
      "z": 16,
      "name": "Rock_Stone"
    },
    {
      "x": -11,
      "y": 8,
      "z": 16,
      "name": "Soil_Grass"
    },
    {
      "x": -11,
      "y": -7,
      "z": 17,
      "name": "Rock_Stone"
    },
    {
      "x": -11,
      "y": -6,
      "z": 17,
      "name": "Rock_Stone"
    },
    {
      "x": -11,
      "y": -5,
      "z": 17,
      "name": "Rock_Stone"
    },
    {
      "x": -11,
      "y": -4,
      "z": 17,
      "name": "Rock_Stone"
    },
    {
      "x": -11,
      "y": -3,
      "z": 17,
      "name": "Rock_Stone"
    },
    {
      "x": -11,
      "y": -2,
      "z": 17,
      "name": "Rock_Stone"
    },
    {
      "x": -11,
      "y": -1,
      "z": 17,
      "name": "Rock_Stone"
    },
    {
      "x": -11,
      "y": 0,
      "z": 17,
      "name": "Rock_Stone"
    },
    {
      "x": -11,
      "y": 1,
      "z": 17,
      "name": "Rock_Stone"
    },
    {
      "x": -11,
      "y": 2,
      "z": 17,
      "name": "Rock_Stone"
    },
    {
      "x": -11,
      "y": 3,
      "z": 17,
      "name": "Rock_Stone"
    },
    {
      "x": -11,
      "y": 4,
      "z": 17,
      "name": "Rock_Stone"
    },
    {
      "x": -11,
      "y": 5,
      "z": 17,
      "name": "Rock_Stone"
    },
    {
      "x": -11,
      "y": 6,
      "z": 17,
      "name": "Rock_Stone"
    },
    {
      "x": -11,
      "y": 7,
      "z": 17,
      "name": "Soil_Dirt"
    },
    {
      "x": -11,
      "y": 8,
      "z": 17,
      "name": "Soil_Grass"
    },
    {
      "x": -11,
      "y": -7,
      "z": 18,
      "name": "Rock_Stone"
    },
    {
      "x": -11,
      "y": -6,
      "z": 18,
      "name": "Rock_Stone"
    },
    {
      "x": -11,
      "y": -5,
      "z": 18,
      "name": "Rock_Stone"
    },
    {
      "x": -11,
      "y": -4,
      "z": 18,
      "name": "Rock_Stone"
    },
    {
      "x": -11,
      "y": -3,
      "z": 18,
      "name": "Rock_Stone"
    },
    {
      "x": -11,
      "y": -2,
      "z": 18,
      "name": "Rock_Stone"
    },
    {
      "x": -11,
      "y": -1,
      "z": 18,
      "name": "Rock_Stone"
    },
    {
      "x": -11,
      "y": 0,
      "z": 18,
      "name": "Rock_Stone"
    },
    {
      "x": -11,
      "y": 1,
      "z": 18,
      "name": "Rock_Stone"
    },
    {
      "x": -11,
      "y": 2,
      "z": 18,
      "name": "Rock_Stone"
    },
    {
      "x": -11,
      "y": 3,
      "z": 18,
      "name": "Rock_Stone"
    },
    {
      "x": -11,
      "y": 4,
      "z": 18,
      "name": "Rock_Stone"
    },
    {
      "x": -11,
      "y": 5,
      "z": 18,
      "name": "Rock_Stone"
    },
    {
      "x": -11,
      "y": 6,
      "z": 18,
      "name": "Rock_Stone"
    },
    {
      "x": -11,
      "y": 7,
      "z": 18,
      "name": "Soil_Dirt"
    },
    {
      "x": -11,
      "y": 8,
      "z": 18,
      "name": "Soil_Grass"
    },
    {
      "x": -11,
      "y": -7,
      "z": 19,
      "name": "Rock_Stone"
    },
    {
      "x": -11,
      "y": -6,
      "z": 19,
      "name": "Rock_Stone"
    },
    {
      "x": -11,
      "y": -5,
      "z": 19,
      "name": "Rock_Stone"
    },
    {
      "x": -11,
      "y": -4,
      "z": 19,
      "name": "Rock_Stone"
    },
    {
      "x": -11,
      "y": -3,
      "z": 19,
      "name": "Rock_Stone"
    },
    {
      "x": -11,
      "y": -2,
      "z": 19,
      "name": "Rock_Stone"
    },
    {
      "x": -11,
      "y": -1,
      "z": 19,
      "name": "Rock_Stone"
    },
    {
      "x": -11,
      "y": 0,
      "z": 19,
      "name": "Rock_Stone"
    },
    {
      "x": -11,
      "y": 1,
      "z": 19,
      "name": "Rock_Stone"
    },
    {
      "x": -11,
      "y": 2,
      "z": 19,
      "name": "Rock_Stone"
    },
    {
      "x": -11,
      "y": 3,
      "z": 19,
      "name": "Rock_Stone"
    },
    {
      "x": -11,
      "y": 4,
      "z": 19,
      "name": "Rock_Stone"
    },
    {
      "x": -11,
      "y": 5,
      "z": 19,
      "name": "Rock_Stone"
    },
    {
      "x": -11,
      "y": 6,
      "z": 19,
      "name": "Rock_Stone"
    },
    {
      "x": -11,
      "y": 7,
      "z": 19,
      "name": "Soil_Grass"
    },
    {
      "x": -11,
      "y": -7,
      "z": 20,
      "name": "Rock_Stone"
    },
    {
      "x": -11,
      "y": -6,
      "z": 20,
      "name": "Rock_Stone"
    },
    {
      "x": -11,
      "y": -5,
      "z": 20,
      "name": "Rock_Stone"
    },
    {
      "x": -11,
      "y": -4,
      "z": 20,
      "name": "Rock_Stone"
    },
    {
      "x": -11,
      "y": -3,
      "z": 20,
      "name": "Rock_Stone"
    },
    {
      "x": -11,
      "y": -2,
      "z": 20,
      "name": "Rock_Stone"
    },
    {
      "x": -11,
      "y": -1,
      "z": 20,
      "name": "Rock_Stone"
    },
    {
      "x": -11,
      "y": 0,
      "z": 20,
      "name": "Rock_Stone"
    },
    {
      "x": -11,
      "y": 1,
      "z": 20,
      "name": "Rock_Stone"
    },
    {
      "x": -11,
      "y": 2,
      "z": 20,
      "name": "Rock_Stone"
    },
    {
      "x": -11,
      "y": 3,
      "z": 20,
      "name": "Rock_Stone"
    },
    {
      "x": -11,
      "y": 4,
      "z": 20,
      "name": "Rock_Stone"
    },
    {
      "x": -11,
      "y": 5,
      "z": 20,
      "name": "Soil_Dirt"
    },
    {
      "x": -11,
      "y": 6,
      "z": 20,
      "name": "Soil_Dirt"
    },
    {
      "x": -11,
      "y": 7,
      "z": 20,
      "name": "Soil_Grass"
    },
    {
      "x": -11,
      "y": -7,
      "z": 21,
      "name": "Rock_Stone"
    },
    {
      "x": -11,
      "y": -6,
      "z": 21,
      "name": "Rock_Stone"
    },
    {
      "x": -11,
      "y": -5,
      "z": 21,
      "name": "Rock_Stone"
    },
    {
      "x": -11,
      "y": -4,
      "z": 21,
      "name": "Rock_Stone"
    },
    {
      "x": -11,
      "y": -3,
      "z": 21,
      "name": "Rock_Stone"
    },
    {
      "x": -11,
      "y": -2,
      "z": 21,
      "name": "Rock_Stone"
    },
    {
      "x": -11,
      "y": -1,
      "z": 21,
      "name": "Rock_Stone"
    },
    {
      "x": -11,
      "y": 0,
      "z": 21,
      "name": "Rock_Stone"
    },
    {
      "x": -11,
      "y": 1,
      "z": 21,
      "name": "Rock_Stone"
    },
    {
      "x": -11,
      "y": 2,
      "z": 21,
      "name": "Rock_Stone"
    },
    {
      "x": -11,
      "y": 3,
      "z": 21,
      "name": "Rock_Stone"
    },
    {
      "x": -11,
      "y": 4,
      "z": 21,
      "name": "Soil_Dirt"
    },
    {
      "x": -11,
      "y": 5,
      "z": 21,
      "name": "Soil_Dirt"
    },
    {
      "x": -11,
      "y": 6,
      "z": 21,
      "name": "Soil_Grass"
    },
    {
      "x": -11,
      "y": -7,
      "z": 22,
      "name": "Rock_Stone"
    },
    {
      "x": -11,
      "y": -6,
      "z": 22,
      "name": "Rock_Stone"
    },
    {
      "x": -11,
      "y": -5,
      "z": 22,
      "name": "Rock_Stone"
    },
    {
      "x": -11,
      "y": -4,
      "z": 22,
      "name": "Rock_Stone"
    },
    {
      "x": -11,
      "y": -3,
      "z": 22,
      "name": "Rock_Stone"
    },
    {
      "x": -11,
      "y": -2,
      "z": 22,
      "name": "Rock_Stone"
    },
    {
      "x": -11,
      "y": -1,
      "z": 22,
      "name": "Rock_Stone"
    },
    {
      "x": -11,
      "y": 0,
      "z": 22,
      "name": "Rock_Stone"
    },
    {
      "x": -11,
      "y": 1,
      "z": 22,
      "name": "Rock_Stone"
    },
    {
      "x": -11,
      "y": 2,
      "z": 22,
      "name": "Rock_Stone"
    },
    {
      "x": -11,
      "y": 3,
      "z": 22,
      "name": "Rock_Stone"
    },
    {
      "x": -11,
      "y": 4,
      "z": 22,
      "name": "Rock_Stone"
    },
    {
      "x": -11,
      "y": 5,
      "z": 22,
      "name": "Soil_Grass"
    },
    {
      "x": -11,
      "y": -7,
      "z": 23,
      "name": "Rock_Stone"
    },
    {
      "x": -11,
      "y": -6,
      "z": 23,
      "name": "Rock_Stone"
    },
    {
      "x": -11,
      "y": -5,
      "z": 23,
      "name": "Rock_Stone"
    },
    {
      "x": -11,
      "y": -4,
      "z": 23,
      "name": "Rock_Stone"
    },
    {
      "x": -11,
      "y": -3,
      "z": 23,
      "name": "Rock_Stone"
    },
    {
      "x": -11,
      "y": -2,
      "z": 23,
      "name": "Rock_Stone"
    },
    {
      "x": -11,
      "y": -1,
      "z": 23,
      "name": "Rock_Stone"
    },
    {
      "x": -11,
      "y": 0,
      "z": 23,
      "name": "Rock_Stone"
    },
    {
      "x": -11,
      "y": 1,
      "z": 23,
      "name": "Rock_Stone"
    },
    {
      "x": -11,
      "y": 2,
      "z": 23,
      "name": "Rock_Stone"
    },
    {
      "x": -11,
      "y": 3,
      "z": 23,
      "name": "Soil_Dirt"
    },
    {
      "x": -11,
      "y": 4,
      "z": 23,
      "name": "Soil_Dirt"
    },
    {
      "x": -11,
      "y": 5,
      "z": 23,
      "name": "Soil_Grass"
    },
    {
      "x": -11,
      "y": -7,
      "z": 24,
      "name": "Rock_Stone"
    },
    {
      "x": -11,
      "y": -6,
      "z": 24,
      "name": "Rock_Stone"
    },
    {
      "x": -11,
      "y": -5,
      "z": 24,
      "name": "Rock_Stone"
    },
    {
      "x": -11,
      "y": -4,
      "z": 24,
      "name": "Rock_Stone"
    },
    {
      "x": -11,
      "y": -3,
      "z": 24,
      "name": "Rock_Stone"
    },
    {
      "x": -11,
      "y": -2,
      "z": 24,
      "name": "Rock_Stone"
    },
    {
      "x": -11,
      "y": -1,
      "z": 24,
      "name": "Rock_Stone"
    },
    {
      "x": -11,
      "y": 0,
      "z": 24,
      "name": "Rock_Stone"
    },
    {
      "x": -11,
      "y": 1,
      "z": 24,
      "name": "Rock_Stone"
    },
    {
      "x": -11,
      "y": 2,
      "z": 24,
      "name": "Rock_Stone"
    },
    {
      "x": -11,
      "y": 3,
      "z": 24,
      "name": "Soil_Dirt"
    },
    {
      "x": -11,
      "y": 4,
      "z": 24,
      "name": "Soil_Grass"
    },
    {
      "x": -11,
      "y": 0,
      "z": 25,
      "name": "Rock_Stone"
    },
    {
      "x": -11,
      "y": 1,
      "z": 25,
      "name": "Rock_Stone"
    },
    {
      "x": -11,
      "y": 2,
      "z": 25,
      "name": "Rock_Stone"
    },
    {
      "x": -11,
      "y": 3,
      "z": 25,
      "name": "Rock_Stone"
    },
    {
      "x": -11,
      "y": 4,
      "z": 25,
      "name": "Soil_Grass"
    },
    {
      "x": -10,
      "y": -7,
      "z": 11,
      "name": "Rock_Stone"
    },
    {
      "x": -10,
      "y": -6,
      "z": 11,
      "name": "Rock_Stone"
    },
    {
      "x": -10,
      "y": -5,
      "z": 11,
      "name": "Rock_Stone"
    },
    {
      "x": -10,
      "y": -4,
      "z": 11,
      "name": "Rock_Stone"
    },
    {
      "x": -10,
      "y": -3,
      "z": 11,
      "name": "Rock_Stone"
    },
    {
      "x": -10,
      "y": -2,
      "z": 11,
      "name": "Rock_Stone"
    },
    {
      "x": -10,
      "y": -1,
      "z": 11,
      "name": "Rock_Stone"
    },
    {
      "x": -10,
      "y": 0,
      "z": 11,
      "name": "Rock_Stone"
    },
    {
      "x": -10,
      "y": 1,
      "z": 11,
      "name": "Rock_Stone"
    },
    {
      "x": -10,
      "y": 2,
      "z": 11,
      "name": "Rock_Stone"
    },
    {
      "x": -10,
      "y": 3,
      "z": 11,
      "name": "Rock_Stone"
    },
    {
      "x": -10,
      "y": 4,
      "z": 11,
      "name": "Rock_Stone"
    },
    {
      "x": -10,
      "y": -7,
      "z": 12,
      "name": "Rock_Stone"
    },
    {
      "x": -10,
      "y": -6,
      "z": 12,
      "name": "Rock_Stone"
    },
    {
      "x": -10,
      "y": -5,
      "z": 12,
      "name": "Rock_Stone"
    },
    {
      "x": -10,
      "y": -4,
      "z": 12,
      "name": "Rock_Stone"
    },
    {
      "x": -10,
      "y": -3,
      "z": 12,
      "name": "Rock_Stone"
    },
    {
      "x": -10,
      "y": -2,
      "z": 12,
      "name": "Rock_Stone"
    },
    {
      "x": -10,
      "y": -1,
      "z": 12,
      "name": "Rock_Stone"
    },
    {
      "x": -10,
      "y": 0,
      "z": 12,
      "name": "Rock_Stone"
    },
    {
      "x": -10,
      "y": 1,
      "z": 12,
      "name": "Rock_Stone"
    },
    {
      "x": -10,
      "y": 2,
      "z": 12,
      "name": "Rock_Stone"
    },
    {
      "x": -10,
      "y": 3,
      "z": 12,
      "name": "Rock_Stone"
    },
    {
      "x": -10,
      "y": 4,
      "z": 12,
      "name": "Rock_Stone"
    },
    {
      "x": -10,
      "y": 5,
      "z": 12,
      "name": "Rock_Stone"
    },
    {
      "x": -10,
      "y": 6,
      "z": 12,
      "name": "Rock_Stone"
    },
    {
      "x": -10,
      "y": 7,
      "z": 12,
      "name": "Rock_Stone"
    },
    {
      "x": -10,
      "y": 8,
      "z": 12,
      "name": "Rock_Stone"
    },
    {
      "x": -10,
      "y": -7,
      "z": 13,
      "name": "Rock_Stone"
    },
    {
      "x": -10,
      "y": -6,
      "z": 13,
      "name": "Rock_Stone"
    },
    {
      "x": -10,
      "y": -5,
      "z": 13,
      "name": "Rock_Stone"
    },
    {
      "x": -10,
      "y": -4,
      "z": 13,
      "name": "Rock_Stone"
    },
    {
      "x": -10,
      "y": -3,
      "z": 13,
      "name": "Rock_Stone"
    },
    {
      "x": -10,
      "y": -2,
      "z": 13,
      "name": "Rock_Stone"
    },
    {
      "x": -10,
      "y": -1,
      "z": 13,
      "name": "Rock_Stone"
    },
    {
      "x": -10,
      "y": 0,
      "z": 13,
      "name": "Rock_Stone"
    },
    {
      "x": -10,
      "y": 1,
      "z": 13,
      "name": "Rock_Stone"
    },
    {
      "x": -10,
      "y": 2,
      "z": 13,
      "name": "Rock_Stone"
    },
    {
      "x": -10,
      "y": 3,
      "z": 13,
      "name": "Rock_Stone"
    },
    {
      "x": -10,
      "y": 4,
      "z": 13,
      "name": "Rock_Stone"
    },
    {
      "x": -10,
      "y": 5,
      "z": 13,
      "name": "Rock_Stone"
    },
    {
      "x": -10,
      "y": 6,
      "z": 13,
      "name": "Rock_Stone"
    },
    {
      "x": -10,
      "y": 7,
      "z": 13,
      "name": "Rock_Stone"
    },
    {
      "x": -10,
      "y": 8,
      "z": 13,
      "name": "Rock_Stone"
    },
    {
      "x": -10,
      "y": 9,
      "z": 13,
      "name": "Soil_Dirt"
    },
    {
      "x": -10,
      "y": 10,
      "z": 13,
      "name": "Soil_Grass"
    },
    {
      "x": -10,
      "y": -7,
      "z": 14,
      "name": "Rock_Stone"
    },
    {
      "x": -10,
      "y": -6,
      "z": 14,
      "name": "Rock_Stone"
    },
    {
      "x": -10,
      "y": -5,
      "z": 14,
      "name": "Rock_Stone"
    },
    {
      "x": -10,
      "y": -4,
      "z": 14,
      "name": "Rock_Stone"
    },
    {
      "x": -10,
      "y": -3,
      "z": 14,
      "name": "Rock_Stone"
    },
    {
      "x": -10,
      "y": -2,
      "z": 14,
      "name": "Rock_Stone"
    },
    {
      "x": -10,
      "y": -1,
      "z": 14,
      "name": "Rock_Stone"
    },
    {
      "x": -10,
      "y": 0,
      "z": 14,
      "name": "Rock_Stone"
    },
    {
      "x": -10,
      "y": 1,
      "z": 14,
      "name": "Rock_Stone"
    },
    {
      "x": -10,
      "y": 2,
      "z": 14,
      "name": "Rock_Stone"
    },
    {
      "x": -10,
      "y": 3,
      "z": 14,
      "name": "Rock_Stone"
    },
    {
      "x": -10,
      "y": 4,
      "z": 14,
      "name": "Rock_Stone"
    },
    {
      "x": -10,
      "y": 5,
      "z": 14,
      "name": "Rock_Stone"
    },
    {
      "x": -10,
      "y": 6,
      "z": 14,
      "name": "Rock_Stone"
    },
    {
      "x": -10,
      "y": 7,
      "z": 14,
      "name": "Rock_Stone"
    },
    {
      "x": -10,
      "y": 8,
      "z": 14,
      "name": "Rock_Stone"
    },
    {
      "x": -10,
      "y": 9,
      "z": 14,
      "name": "Soil_Dirt"
    },
    {
      "x": -10,
      "y": 10,
      "z": 14,
      "name": "Soil_Grass"
    },
    {
      "x": -10,
      "y": -7,
      "z": 15,
      "name": "Rock_Stone"
    },
    {
      "x": -10,
      "y": -6,
      "z": 15,
      "name": "Rock_Stone"
    },
    {
      "x": -10,
      "y": -5,
      "z": 15,
      "name": "Rock_Stone"
    },
    {
      "x": -10,
      "y": -4,
      "z": 15,
      "name": "Rock_Stone"
    },
    {
      "x": -10,
      "y": -3,
      "z": 15,
      "name": "Rock_Stone"
    },
    {
      "x": -10,
      "y": -2,
      "z": 15,
      "name": "Rock_Stone"
    },
    {
      "x": -10,
      "y": -1,
      "z": 15,
      "name": "Rock_Stone"
    },
    {
      "x": -10,
      "y": 0,
      "z": 15,
      "name": "Rock_Stone"
    },
    {
      "x": -10,
      "y": 1,
      "z": 15,
      "name": "Rock_Stone"
    },
    {
      "x": -10,
      "y": 2,
      "z": 15,
      "name": "Rock_Stone"
    },
    {
      "x": -10,
      "y": 3,
      "z": 15,
      "name": "Rock_Stone"
    },
    {
      "x": -10,
      "y": 4,
      "z": 15,
      "name": "Rock_Stone"
    },
    {
      "x": -10,
      "y": 5,
      "z": 15,
      "name": "Rock_Stone"
    },
    {
      "x": -10,
      "y": 6,
      "z": 15,
      "name": "Rock_Stone"
    },
    {
      "x": -10,
      "y": 7,
      "z": 15,
      "name": "Rock_Stone"
    },
    {
      "x": -10,
      "y": 8,
      "z": 15,
      "name": "Rock_Stone"
    },
    {
      "x": -10,
      "y": 9,
      "z": 15,
      "name": "Soil_Grass"
    },
    {
      "x": -10,
      "y": -7,
      "z": 16,
      "name": "Rock_Stone"
    },
    {
      "x": -10,
      "y": -6,
      "z": 16,
      "name": "Rock_Stone"
    },
    {
      "x": -10,
      "y": -5,
      "z": 16,
      "name": "Rock_Stone"
    },
    {
      "x": -10,
      "y": -4,
      "z": 16,
      "name": "Rock_Stone"
    },
    {
      "x": -10,
      "y": -3,
      "z": 16,
      "name": "Rock_Stone"
    },
    {
      "x": -10,
      "y": -2,
      "z": 16,
      "name": "Rock_Stone"
    },
    {
      "x": -10,
      "y": -1,
      "z": 16,
      "name": "Rock_Stone"
    },
    {
      "x": -10,
      "y": 0,
      "z": 16,
      "name": "Rock_Stone"
    },
    {
      "x": -10,
      "y": 1,
      "z": 16,
      "name": "Rock_Stone"
    },
    {
      "x": -10,
      "y": 2,
      "z": 16,
      "name": "Rock_Stone"
    },
    {
      "x": -10,
      "y": 3,
      "z": 16,
      "name": "Rock_Stone"
    },
    {
      "x": -10,
      "y": 4,
      "z": 16,
      "name": "Rock_Stone"
    },
    {
      "x": -10,
      "y": 5,
      "z": 16,
      "name": "Rock_Stone"
    },
    {
      "x": -10,
      "y": 6,
      "z": 16,
      "name": "Rock_Stone"
    },
    {
      "x": -10,
      "y": 7,
      "z": 16,
      "name": "Rock_Stone"
    },
    {
      "x": -10,
      "y": 8,
      "z": 16,
      "name": "Rock_Stone"
    },
    {
      "x": -10,
      "y": 9,
      "z": 16,
      "name": "Soil_Grass"
    },
    {
      "x": -10,
      "y": -7,
      "z": 17,
      "name": "Rock_Stone"
    },
    {
      "x": -10,
      "y": -6,
      "z": 17,
      "name": "Rock_Stone"
    },
    {
      "x": -10,
      "y": -5,
      "z": 17,
      "name": "Rock_Stone"
    },
    {
      "x": -10,
      "y": -4,
      "z": 17,
      "name": "Rock_Stone"
    },
    {
      "x": -10,
      "y": -3,
      "z": 17,
      "name": "Rock_Stone"
    },
    {
      "x": -10,
      "y": -2,
      "z": 17,
      "name": "Rock_Stone"
    },
    {
      "x": -10,
      "y": -1,
      "z": 17,
      "name": "Rock_Stone"
    },
    {
      "x": -10,
      "y": 0,
      "z": 17,
      "name": "Rock_Stone"
    },
    {
      "x": -10,
      "y": 1,
      "z": 17,
      "name": "Rock_Stone"
    },
    {
      "x": -10,
      "y": 2,
      "z": 17,
      "name": "Rock_Stone"
    },
    {
      "x": -10,
      "y": 3,
      "z": 17,
      "name": "Rock_Stone"
    },
    {
      "x": -10,
      "y": 4,
      "z": 17,
      "name": "Rock_Stone"
    },
    {
      "x": -10,
      "y": 5,
      "z": 17,
      "name": "Rock_Stone"
    },
    {
      "x": -10,
      "y": 6,
      "z": 17,
      "name": "Rock_Stone"
    },
    {
      "x": -10,
      "y": 7,
      "z": 17,
      "name": "Rock_Stone"
    },
    {
      "x": -10,
      "y": 8,
      "z": 17,
      "name": "Rock_Stone"
    },
    {
      "x": -10,
      "y": 9,
      "z": 17,
      "name": "Soil_Grass"
    },
    {
      "x": -10,
      "y": -7,
      "z": 18,
      "name": "Rock_Stone"
    },
    {
      "x": -10,
      "y": -6,
      "z": 18,
      "name": "Rock_Stone"
    },
    {
      "x": -10,
      "y": -5,
      "z": 18,
      "name": "Rock_Stone"
    },
    {
      "x": -10,
      "y": -4,
      "z": 18,
      "name": "Rock_Stone"
    },
    {
      "x": -10,
      "y": -3,
      "z": 18,
      "name": "Rock_Stone"
    },
    {
      "x": -10,
      "y": -2,
      "z": 18,
      "name": "Rock_Stone"
    },
    {
      "x": -10,
      "y": -1,
      "z": 18,
      "name": "Rock_Stone"
    },
    {
      "x": -10,
      "y": 0,
      "z": 18,
      "name": "Rock_Stone"
    },
    {
      "x": -10,
      "y": 1,
      "z": 18,
      "name": "Rock_Stone"
    },
    {
      "x": -10,
      "y": 2,
      "z": 18,
      "name": "Rock_Stone"
    },
    {
      "x": -10,
      "y": 3,
      "z": 18,
      "name": "Rock_Stone"
    },
    {
      "x": -10,
      "y": 4,
      "z": 18,
      "name": "Rock_Stone"
    },
    {
      "x": -10,
      "y": 5,
      "z": 18,
      "name": "Rock_Stone"
    },
    {
      "x": -10,
      "y": 6,
      "z": 18,
      "name": "Rock_Stone"
    },
    {
      "x": -10,
      "y": 7,
      "z": 18,
      "name": "Rock_Stone"
    },
    {
      "x": -10,
      "y": 8,
      "z": 18,
      "name": "Soil_Dirt"
    },
    {
      "x": -10,
      "y": 9,
      "z": 18,
      "name": "Soil_Grass"
    },
    {
      "x": -10,
      "y": -7,
      "z": 19,
      "name": "Rock_Stone"
    },
    {
      "x": -10,
      "y": -6,
      "z": 19,
      "name": "Rock_Stone"
    },
    {
      "x": -10,
      "y": -5,
      "z": 19,
      "name": "Rock_Stone"
    },
    {
      "x": -10,
      "y": -4,
      "z": 19,
      "name": "Rock_Stone"
    },
    {
      "x": -10,
      "y": -3,
      "z": 19,
      "name": "Rock_Stone"
    },
    {
      "x": -10,
      "y": -2,
      "z": 19,
      "name": "Rock_Stone"
    },
    {
      "x": -10,
      "y": -1,
      "z": 19,
      "name": "Rock_Stone"
    },
    {
      "x": -10,
      "y": 0,
      "z": 19,
      "name": "Rock_Stone"
    },
    {
      "x": -10,
      "y": 1,
      "z": 19,
      "name": "Rock_Stone"
    },
    {
      "x": -10,
      "y": 2,
      "z": 19,
      "name": "Rock_Stone"
    },
    {
      "x": -10,
      "y": 3,
      "z": 19,
      "name": "Rock_Stone"
    },
    {
      "x": -10,
      "y": 4,
      "z": 19,
      "name": "Rock_Stone"
    },
    {
      "x": -10,
      "y": 5,
      "z": 19,
      "name": "Rock_Stone"
    },
    {
      "x": -10,
      "y": 6,
      "z": 19,
      "name": "Rock_Stone"
    },
    {
      "x": -10,
      "y": 7,
      "z": 19,
      "name": "Rock_Stone"
    },
    {
      "x": -10,
      "y": 8,
      "z": 19,
      "name": "Soil_Dirt"
    },
    {
      "x": -10,
      "y": 9,
      "z": 19,
      "name": "Soil_Grass"
    },
    {
      "x": -10,
      "y": -7,
      "z": 20,
      "name": "Rock_Stone"
    },
    {
      "x": -10,
      "y": -6,
      "z": 20,
      "name": "Rock_Stone"
    },
    {
      "x": -10,
      "y": -5,
      "z": 20,
      "name": "Rock_Stone"
    },
    {
      "x": -10,
      "y": -4,
      "z": 20,
      "name": "Rock_Stone"
    },
    {
      "x": -10,
      "y": -3,
      "z": 20,
      "name": "Rock_Stone"
    },
    {
      "x": -10,
      "y": -2,
      "z": 20,
      "name": "Rock_Stone"
    },
    {
      "x": -10,
      "y": -1,
      "z": 20,
      "name": "Rock_Stone"
    },
    {
      "x": -10,
      "y": 0,
      "z": 20,
      "name": "Rock_Stone"
    },
    {
      "x": -10,
      "y": 1,
      "z": 20,
      "name": "Rock_Stone"
    },
    {
      "x": -10,
      "y": 2,
      "z": 20,
      "name": "Rock_Stone"
    },
    {
      "x": -10,
      "y": 3,
      "z": 20,
      "name": "Rock_Stone"
    },
    {
      "x": -10,
      "y": 4,
      "z": 20,
      "name": "Rock_Stone"
    },
    {
      "x": -10,
      "y": 5,
      "z": 20,
      "name": "Rock_Stone"
    },
    {
      "x": -10,
      "y": 6,
      "z": 20,
      "name": "Rock_Stone"
    },
    {
      "x": -10,
      "y": 7,
      "z": 20,
      "name": "Rock_Stone"
    },
    {
      "x": -10,
      "y": 8,
      "z": 20,
      "name": "Rock_Stone"
    },
    {
      "x": -10,
      "y": 9,
      "z": 20,
      "name": "Rock_Stone"
    },
    {
      "x": -10,
      "y": -7,
      "z": 21,
      "name": "Rock_Stone"
    },
    {
      "x": -10,
      "y": -6,
      "z": 21,
      "name": "Rock_Stone"
    },
    {
      "x": -10,
      "y": -5,
      "z": 21,
      "name": "Rock_Stone"
    },
    {
      "x": -10,
      "y": -4,
      "z": 21,
      "name": "Rock_Stone"
    },
    {
      "x": -10,
      "y": -3,
      "z": 21,
      "name": "Rock_Stone"
    },
    {
      "x": -10,
      "y": -2,
      "z": 21,
      "name": "Rock_Stone"
    },
    {
      "x": -10,
      "y": -1,
      "z": 21,
      "name": "Rock_Stone"
    },
    {
      "x": -10,
      "y": 0,
      "z": 21,
      "name": "Rock_Stone"
    },
    {
      "x": -10,
      "y": 1,
      "z": 21,
      "name": "Rock_Stone"
    },
    {
      "x": -10,
      "y": 2,
      "z": 21,
      "name": "Rock_Stone"
    },
    {
      "x": -10,
      "y": 3,
      "z": 21,
      "name": "Rock_Stone"
    },
    {
      "x": -10,
      "y": 4,
      "z": 21,
      "name": "Rock_Stone"
    },
    {
      "x": -10,
      "y": 5,
      "z": 21,
      "name": "Rock_Stone"
    },
    {
      "x": -10,
      "y": 6,
      "z": 21,
      "name": "Rock_Stone"
    },
    {
      "x": -10,
      "y": 7,
      "z": 21,
      "name": "Rock_Stone"
    },
    {
      "x": -10,
      "y": 8,
      "z": 21,
      "name": "Rock_Stone"
    },
    {
      "x": -10,
      "y": 9,
      "z": 21,
      "name": "Rock_Stone"
    },
    {
      "x": -10,
      "y": 10,
      "z": 21,
      "name": "Rock_Stone"
    },
    {
      "x": -10,
      "y": -7,
      "z": 22,
      "name": "Rock_Stone"
    },
    {
      "x": -10,
      "y": -6,
      "z": 22,
      "name": "Rock_Stone"
    },
    {
      "x": -10,
      "y": -5,
      "z": 22,
      "name": "Rock_Stone"
    },
    {
      "x": -10,
      "y": -4,
      "z": 22,
      "name": "Rock_Stone"
    },
    {
      "x": -10,
      "y": -3,
      "z": 22,
      "name": "Rock_Stone"
    },
    {
      "x": -10,
      "y": -2,
      "z": 22,
      "name": "Rock_Stone"
    },
    {
      "x": -10,
      "y": -1,
      "z": 22,
      "name": "Rock_Stone"
    },
    {
      "x": -10,
      "y": 0,
      "z": 22,
      "name": "Rock_Stone"
    },
    {
      "x": -10,
      "y": 1,
      "z": 22,
      "name": "Rock_Stone"
    },
    {
      "x": -10,
      "y": 2,
      "z": 22,
      "name": "Rock_Stone"
    },
    {
      "x": -10,
      "y": 3,
      "z": 22,
      "name": "Rock_Stone"
    },
    {
      "x": -10,
      "y": 4,
      "z": 22,
      "name": "Rock_Stone"
    },
    {
      "x": -10,
      "y": 5,
      "z": 22,
      "name": "Rock_Stone"
    },
    {
      "x": -10,
      "y": 6,
      "z": 22,
      "name": "Rock_Stone"
    },
    {
      "x": -10,
      "y": 7,
      "z": 22,
      "name": "Rock_Stone"
    },
    {
      "x": -10,
      "y": 8,
      "z": 22,
      "name": "Rock_Stone"
    },
    {
      "x": -10,
      "y": 9,
      "z": 22,
      "name": "Rock_Stone"
    },
    {
      "x": -10,
      "y": 10,
      "z": 22,
      "name": "Rock_Stone"
    },
    {
      "x": -10,
      "y": -7,
      "z": 23,
      "name": "Rock_Stone"
    },
    {
      "x": -10,
      "y": -6,
      "z": 23,
      "name": "Rock_Stone"
    },
    {
      "x": -10,
      "y": -5,
      "z": 23,
      "name": "Rock_Stone"
    },
    {
      "x": -10,
      "y": -4,
      "z": 23,
      "name": "Rock_Stone"
    },
    {
      "x": -10,
      "y": -3,
      "z": 23,
      "name": "Rock_Stone"
    },
    {
      "x": -10,
      "y": -2,
      "z": 23,
      "name": "Rock_Stone"
    },
    {
      "x": -10,
      "y": -1,
      "z": 23,
      "name": "Rock_Stone"
    },
    {
      "x": -10,
      "y": 0,
      "z": 23,
      "name": "Rock_Stone"
    },
    {
      "x": -10,
      "y": 1,
      "z": 23,
      "name": "Rock_Stone"
    },
    {
      "x": -10,
      "y": 2,
      "z": 23,
      "name": "Rock_Stone"
    },
    {
      "x": -10,
      "y": 3,
      "z": 23,
      "name": "Rock_Stone"
    },
    {
      "x": -10,
      "y": 4,
      "z": 23,
      "name": "Rock_Stone"
    },
    {
      "x": -10,
      "y": 5,
      "z": 23,
      "name": "Rock_Stone"
    },
    {
      "x": -10,
      "y": 6,
      "z": 23,
      "name": "Rock_Stone"
    },
    {
      "x": -10,
      "y": 7,
      "z": 23,
      "name": "Rock_Stone"
    },
    {
      "x": -10,
      "y": 8,
      "z": 23,
      "name": "Rock_Stone"
    },
    {
      "x": -10,
      "y": 9,
      "z": 23,
      "name": "Rock_Stone"
    },
    {
      "x": -10,
      "y": -7,
      "z": 24,
      "name": "Rock_Stone"
    },
    {
      "x": -10,
      "y": -6,
      "z": 24,
      "name": "Rock_Stone"
    },
    {
      "x": -10,
      "y": -5,
      "z": 24,
      "name": "Rock_Stone"
    },
    {
      "x": -10,
      "y": -4,
      "z": 24,
      "name": "Rock_Stone"
    },
    {
      "x": -10,
      "y": -3,
      "z": 24,
      "name": "Rock_Stone"
    },
    {
      "x": -10,
      "y": -2,
      "z": 24,
      "name": "Rock_Stone"
    },
    {
      "x": -10,
      "y": -1,
      "z": 24,
      "name": "Rock_Stone"
    },
    {
      "x": -10,
      "y": 0,
      "z": 24,
      "name": "Rock_Stone"
    },
    {
      "x": -10,
      "y": 1,
      "z": 24,
      "name": "Rock_Stone"
    },
    {
      "x": -10,
      "y": 2,
      "z": 24,
      "name": "Rock_Stone"
    },
    {
      "x": -10,
      "y": 3,
      "z": 24,
      "name": "Soil_Dirt"
    },
    {
      "x": -10,
      "y": 4,
      "z": 24,
      "name": "Soil_Grass"
    },
    {
      "x": -10,
      "y": -7,
      "z": 25,
      "name": "Rock_Stone"
    },
    {
      "x": -10,
      "y": -6,
      "z": 25,
      "name": "Rock_Stone"
    },
    {
      "x": -10,
      "y": -5,
      "z": 25,
      "name": "Rock_Stone"
    },
    {
      "x": -10,
      "y": -4,
      "z": 25,
      "name": "Rock_Stone"
    },
    {
      "x": -10,
      "y": -3,
      "z": 25,
      "name": "Rock_Stone"
    },
    {
      "x": -10,
      "y": -2,
      "z": 25,
      "name": "Rock_Stone"
    },
    {
      "x": -10,
      "y": -1,
      "z": 25,
      "name": "Rock_Stone"
    },
    {
      "x": -10,
      "y": 0,
      "z": 25,
      "name": "Rock_Stone"
    },
    {
      "x": -10,
      "y": 1,
      "z": 25,
      "name": "Rock_Stone"
    },
    {
      "x": -10,
      "y": 2,
      "z": 25,
      "name": "Rock_Stone"
    },
    {
      "x": -10,
      "y": 3,
      "z": 25,
      "name": "Rock_Stone"
    },
    {
      "x": -10,
      "y": 4,
      "z": 25,
      "name": "Soil_Grass"
    },
    {
      "x": -9,
      "y": -7,
      "z": 11,
      "name": "Rock_Stone"
    },
    {
      "x": -9,
      "y": -6,
      "z": 11,
      "name": "Rock_Stone"
    },
    {
      "x": -9,
      "y": -5,
      "z": 11,
      "name": "Rock_Stone"
    },
    {
      "x": -9,
      "y": -4,
      "z": 11,
      "name": "Rock_Stone"
    },
    {
      "x": -9,
      "y": -3,
      "z": 11,
      "name": "Rock_Stone"
    },
    {
      "x": -9,
      "y": -2,
      "z": 11,
      "name": "Rock_Stone"
    },
    {
      "x": -9,
      "y": -1,
      "z": 11,
      "name": "Rock_Stone"
    },
    {
      "x": -9,
      "y": 0,
      "z": 11,
      "name": "Rock_Stone"
    },
    {
      "x": -9,
      "y": 1,
      "z": 11,
      "name": "Rock_Stone"
    },
    {
      "x": -9,
      "y": 2,
      "z": 11,
      "name": "Rock_Stone"
    },
    {
      "x": -9,
      "y": 3,
      "z": 11,
      "name": "Rock_Stone"
    },
    {
      "x": -9,
      "y": 4,
      "z": 11,
      "name": "Rock_Stone"
    },
    {
      "x": -9,
      "y": 5,
      "z": 11,
      "name": "Rock_Stone"
    },
    {
      "x": -9,
      "y": 6,
      "z": 11,
      "name": "Rock_Stone"
    },
    {
      "x": -9,
      "y": -7,
      "z": 12,
      "name": "Rock_Stone"
    },
    {
      "x": -9,
      "y": -6,
      "z": 12,
      "name": "Rock_Stone"
    },
    {
      "x": -9,
      "y": -5,
      "z": 12,
      "name": "Rock_Stone"
    },
    {
      "x": -9,
      "y": -4,
      "z": 12,
      "name": "Rock_Stone"
    },
    {
      "x": -9,
      "y": -3,
      "z": 12,
      "name": "Rock_Stone"
    },
    {
      "x": -9,
      "y": -2,
      "z": 12,
      "name": "Rock_Stone"
    },
    {
      "x": -9,
      "y": -1,
      "z": 12,
      "name": "Rock_Stone"
    },
    {
      "x": -9,
      "y": 0,
      "z": 12,
      "name": "Rock_Stone"
    },
    {
      "x": -9,
      "y": 1,
      "z": 12,
      "name": "Rock_Stone"
    },
    {
      "x": -9,
      "y": 2,
      "z": 12,
      "name": "Rock_Stone"
    },
    {
      "x": -9,
      "y": 3,
      "z": 12,
      "name": "Rock_Stone"
    },
    {
      "x": -9,
      "y": 4,
      "z": 12,
      "name": "Rock_Stone"
    },
    {
      "x": -9,
      "y": 5,
      "z": 12,
      "name": "Rock_Stone"
    },
    {
      "x": -9,
      "y": 6,
      "z": 12,
      "name": "Rock_Stone"
    },
    {
      "x": -9,
      "y": 7,
      "z": 12,
      "name": "Rock_Stone"
    },
    {
      "x": -9,
      "y": 8,
      "z": 12,
      "name": "Rock_Stone"
    },
    {
      "x": -9,
      "y": 9,
      "z": 12,
      "name": "Soil_Dirt"
    },
    {
      "x": -9,
      "y": 10,
      "z": 12,
      "name": "Soil_Grass"
    },
    {
      "x": -9,
      "y": -7,
      "z": 13,
      "name": "Rock_Stone"
    },
    {
      "x": -9,
      "y": -6,
      "z": 13,
      "name": "Rock_Stone"
    },
    {
      "x": -9,
      "y": -5,
      "z": 13,
      "name": "Rock_Stone"
    },
    {
      "x": -9,
      "y": -4,
      "z": 13,
      "name": "Rock_Stone"
    },
    {
      "x": -9,
      "y": -3,
      "z": 13,
      "name": "Rock_Stone"
    },
    {
      "x": -9,
      "y": -2,
      "z": 13,
      "name": "Rock_Stone"
    },
    {
      "x": -9,
      "y": -1,
      "z": 13,
      "name": "Rock_Stone"
    },
    {
      "x": -9,
      "y": 0,
      "z": 13,
      "name": "Rock_Stone"
    },
    {
      "x": -9,
      "y": 1,
      "z": 13,
      "name": "Rock_Stone"
    },
    {
      "x": -9,
      "y": 2,
      "z": 13,
      "name": "Rock_Stone"
    },
    {
      "x": -9,
      "y": 3,
      "z": 13,
      "name": "Rock_Stone"
    },
    {
      "x": -9,
      "y": 4,
      "z": 13,
      "name": "Rock_Stone"
    },
    {
      "x": -9,
      "y": 5,
      "z": 13,
      "name": "Rock_Stone"
    },
    {
      "x": -9,
      "y": 6,
      "z": 13,
      "name": "Rock_Stone"
    },
    {
      "x": -9,
      "y": 7,
      "z": 13,
      "name": "Rock_Stone"
    },
    {
      "x": -9,
      "y": 8,
      "z": 13,
      "name": "Rock_Stone"
    },
    {
      "x": -9,
      "y": 9,
      "z": 13,
      "name": "Soil_Dirt"
    },
    {
      "x": -9,
      "y": 10,
      "z": 13,
      "name": "Soil_Grass"
    },
    {
      "x": -9,
      "y": -7,
      "z": 14,
      "name": "Rock_Stone"
    },
    {
      "x": -9,
      "y": -6,
      "z": 14,
      "name": "Rock_Stone"
    },
    {
      "x": -9,
      "y": -5,
      "z": 14,
      "name": "Rock_Stone"
    },
    {
      "x": -9,
      "y": -4,
      "z": 14,
      "name": "Rock_Stone"
    },
    {
      "x": -9,
      "y": -3,
      "z": 14,
      "name": "Rock_Stone"
    },
    {
      "x": -9,
      "y": -2,
      "z": 14,
      "name": "Rock_Stone"
    },
    {
      "x": -9,
      "y": -1,
      "z": 14,
      "name": "Rock_Stone"
    },
    {
      "x": -9,
      "y": 0,
      "z": 14,
      "name": "Rock_Stone"
    },
    {
      "x": -9,
      "y": 1,
      "z": 14,
      "name": "Rock_Stone"
    },
    {
      "x": -9,
      "y": 2,
      "z": 14,
      "name": "Rock_Stone"
    },
    {
      "x": -9,
      "y": 3,
      "z": 14,
      "name": "Rock_Stone"
    },
    {
      "x": -9,
      "y": 4,
      "z": 14,
      "name": "Rock_Stone"
    },
    {
      "x": -9,
      "y": 5,
      "z": 14,
      "name": "Rock_Stone"
    },
    {
      "x": -9,
      "y": 6,
      "z": 14,
      "name": "Rock_Stone"
    },
    {
      "x": -9,
      "y": 7,
      "z": 14,
      "name": "Rock_Stone"
    },
    {
      "x": -9,
      "y": 8,
      "z": 14,
      "name": "Rock_Stone"
    },
    {
      "x": -9,
      "y": 9,
      "z": 14,
      "name": "Soil_Dirt"
    },
    {
      "x": -9,
      "y": 10,
      "z": 14,
      "name": "Soil_Grass"
    },
    {
      "x": -9,
      "y": 11,
      "z": 14,
      "name": "Plant_Grass_Sharp_Short"
    },
    {
      "x": -9,
      "y": -7,
      "z": 15,
      "name": "Rock_Stone"
    },
    {
      "x": -9,
      "y": -6,
      "z": 15,
      "name": "Rock_Stone"
    },
    {
      "x": -9,
      "y": -5,
      "z": 15,
      "name": "Rock_Stone"
    },
    {
      "x": -9,
      "y": -4,
      "z": 15,
      "name": "Rock_Stone"
    },
    {
      "x": -9,
      "y": -3,
      "z": 15,
      "name": "Rock_Stone"
    },
    {
      "x": -9,
      "y": -2,
      "z": 15,
      "name": "Rock_Stone"
    },
    {
      "x": -9,
      "y": -1,
      "z": 15,
      "name": "Rock_Stone"
    },
    {
      "x": -9,
      "y": 0,
      "z": 15,
      "name": "Rock_Stone"
    },
    {
      "x": -9,
      "y": 1,
      "z": 15,
      "name": "Rock_Quartzite_Brick"
    },
    {
      "x": -9,
      "y": 2,
      "z": 15,
      "name": "Rock_Quartzite"
    },
    {
      "x": -9,
      "y": 3,
      "z": 15,
      "name": "Rock_Quartzite"
    },
    {
      "x": -9,
      "y": 4,
      "z": 15,
      "name": "Rock_Stone"
    },
    {
      "x": -9,
      "y": 5,
      "z": 15,
      "name": "Rock_Stone"
    },
    {
      "x": -9,
      "y": 6,
      "z": 15,
      "name": "Rock_Stone"
    },
    {
      "x": -9,
      "y": 7,
      "z": 15,
      "name": "Rock_Stone"
    },
    {
      "x": -9,
      "y": 8,
      "z": 15,
      "name": "Rock_Stone"
    },
    {
      "x": -9,
      "y": 9,
      "z": 15,
      "name": "Soil_Dirt"
    },
    {
      "x": -9,
      "y": 10,
      "z": 15,
      "name": "Soil_Grass"
    },
    {
      "x": -9,
      "y": -7,
      "z": 16,
      "name": "Rock_Stone"
    },
    {
      "x": -9,
      "y": -6,
      "z": 16,
      "name": "Rock_Stone"
    },
    {
      "x": -9,
      "y": -5,
      "z": 16,
      "name": "Rock_Stone"
    },
    {
      "x": -9,
      "y": -4,
      "z": 16,
      "name": "Rock_Stone"
    },
    {
      "x": -9,
      "y": -3,
      "z": 16,
      "name": "Rock_Stone"
    },
    {
      "x": -9,
      "y": -2,
      "z": 16,
      "name": "Rock_Stone"
    },
    {
      "x": -9,
      "y": -1,
      "z": 16,
      "name": "Rock_Stone"
    },
    {
      "x": -9,
      "y": 0,
      "z": 16,
      "name": "Rock_Stone"
    },
    {
      "x": -9,
      "y": 1,
      "z": 16,
      "name": "Rock_Quartzite"
    },
    {
      "x": -9,
      "y": 2,
      "z": 16,
      "name": "Rock_Quartzite"
    },
    {
      "x": -9,
      "y": 3,
      "z": 16,
      "name": "Rock_Quartzite"
    },
    {
      "x": -9,
      "y": 4,
      "z": 16,
      "name": "Rock_Quartzite_Brick"
    },
    {
      "x": -9,
      "y": 5,
      "z": 16,
      "name": "Rock_Stone"
    },
    {
      "x": -9,
      "y": 6,
      "z": 16,
      "name": "Rock_Stone"
    },
    {
      "x": -9,
      "y": 7,
      "z": 16,
      "name": "Rock_Stone"
    },
    {
      "x": -9,
      "y": 8,
      "z": 16,
      "name": "Rock_Stone"
    },
    {
      "x": -9,
      "y": 9,
      "z": 16,
      "name": "Soil_Dirt"
    },
    {
      "x": -9,
      "y": 10,
      "z": 16,
      "name": "Soil_Grass"
    },
    {
      "x": -9,
      "y": -7,
      "z": 17,
      "name": "Rock_Stone"
    },
    {
      "x": -9,
      "y": -6,
      "z": 17,
      "name": "Rock_Stone"
    },
    {
      "x": -9,
      "y": -5,
      "z": 17,
      "name": "Rock_Stone"
    },
    {
      "x": -9,
      "y": -4,
      "z": 17,
      "name": "Rock_Stone"
    },
    {
      "x": -9,
      "y": -3,
      "z": 17,
      "name": "Rock_Stone"
    },
    {
      "x": -9,
      "y": -2,
      "z": 17,
      "name": "Rock_Stone"
    },
    {
      "x": -9,
      "y": -1,
      "z": 17,
      "name": "Rock_Stone"
    },
    {
      "x": -9,
      "y": 0,
      "z": 17,
      "name": "Rock_Stone"
    },
    {
      "x": -9,
      "y": 1,
      "z": 17,
      "name": "Rock_Quartzite"
    },
    {
      "x": -9,
      "y": 2,
      "z": 17,
      "name": "Rock_Quartzite"
    },
    {
      "x": -9,
      "y": 3,
      "z": 17,
      "name": "Rock_Quartzite"
    },
    {
      "x": -9,
      "y": 4,
      "z": 17,
      "name": "Rock_Quartzite_Cobble"
    },
    {
      "x": -9,
      "y": 5,
      "z": 17,
      "name": "Rock_Stone"
    },
    {
      "x": -9,
      "y": 6,
      "z": 17,
      "name": "Rock_Stone"
    },
    {
      "x": -9,
      "y": 7,
      "z": 17,
      "name": "Rock_Stone"
    },
    {
      "x": -9,
      "y": 8,
      "z": 17,
      "name": "Rock_Stone"
    },
    {
      "x": -9,
      "y": 9,
      "z": 17,
      "name": "Soil_Grass"
    },
    {
      "x": -9,
      "y": -7,
      "z": 18,
      "name": "Rock_Stone"
    },
    {
      "x": -9,
      "y": -6,
      "z": 18,
      "name": "Rock_Stone"
    },
    {
      "x": -9,
      "y": -5,
      "z": 18,
      "name": "Rock_Stone"
    },
    {
      "x": -9,
      "y": -4,
      "z": 18,
      "name": "Rock_Stone"
    },
    {
      "x": -9,
      "y": -3,
      "z": 18,
      "name": "Rock_Stone"
    },
    {
      "x": -9,
      "y": -2,
      "z": 18,
      "name": "Rock_Stone"
    },
    {
      "x": -9,
      "y": -1,
      "z": 18,
      "name": "Rock_Stone"
    },
    {
      "x": -9,
      "y": 0,
      "z": 18,
      "name": "Rock_Stone"
    },
    {
      "x": -9,
      "y": 1,
      "z": 18,
      "name": "Rock_Quartzite"
    },
    {
      "x": -9,
      "y": 2,
      "z": 18,
      "name": "Rock_Quartzite"
    },
    {
      "x": -9,
      "y": 3,
      "z": 18,
      "name": "Rock_Quartzite"
    },
    {
      "x": -9,
      "y": 4,
      "z": 18,
      "name": "Rock_Quartzite_Cobble"
    },
    {
      "x": -9,
      "y": 5,
      "z": 18,
      "name": "Rock_Quartzite_Cobble"
    },
    {
      "x": -9,
      "y": 6,
      "z": 18,
      "name": "Rock_Stone"
    },
    {
      "x": -9,
      "y": 7,
      "z": 18,
      "name": "Rock_Stone"
    },
    {
      "x": -9,
      "y": 8,
      "z": 18,
      "name": "Rock_Stone"
    },
    {
      "x": -9,
      "y": 9,
      "z": 18,
      "name": "Soil_Grass"
    },
    {
      "x": -9,
      "y": -7,
      "z": 19,
      "name": "Rock_Stone"
    },
    {
      "x": -9,
      "y": -6,
      "z": 19,
      "name": "Rock_Stone"
    },
    {
      "x": -9,
      "y": -5,
      "z": 19,
      "name": "Rock_Stone"
    },
    {
      "x": -9,
      "y": -4,
      "z": 19,
      "name": "Rock_Stone"
    },
    {
      "x": -9,
      "y": -3,
      "z": 19,
      "name": "Rock_Stone"
    },
    {
      "x": -9,
      "y": -2,
      "z": 19,
      "name": "Rock_Stone"
    },
    {
      "x": -9,
      "y": -1,
      "z": 19,
      "name": "Rock_Stone"
    },
    {
      "x": -9,
      "y": 0,
      "z": 19,
      "name": "Rock_Stone"
    },
    {
      "x": -9,
      "y": 1,
      "z": 19,
      "name": "Rock_Quartzite"
    },
    {
      "x": -9,
      "y": 2,
      "z": 19,
      "name": "Rock_Quartzite"
    },
    {
      "x": -9,
      "y": 3,
      "z": 19,
      "name": "Rock_Quartzite"
    },
    {
      "x": -9,
      "y": 4,
      "z": 19,
      "name": "Rock_Quartzite_Cobble"
    },
    {
      "x": -9,
      "y": 5,
      "z": 19,
      "name": "Rock_Quartzite_Cobble"
    },
    {
      "x": -9,
      "y": 6,
      "z": 19,
      "name": "Rock_Stone"
    },
    {
      "x": -9,
      "y": 7,
      "z": 19,
      "name": "Rock_Stone"
    },
    {
      "x": -9,
      "y": 8,
      "z": 19,
      "name": "Rock_Stone"
    },
    {
      "x": -9,
      "y": 9,
      "z": 19,
      "name": "Rock_Stone"
    },
    {
      "x": -9,
      "y": 10,
      "z": 19,
      "name": "Rock_Stone"
    },
    {
      "x": -9,
      "y": -7,
      "z": 20,
      "name": "Rock_Stone"
    },
    {
      "x": -9,
      "y": -6,
      "z": 20,
      "name": "Rock_Stone"
    },
    {
      "x": -9,
      "y": -5,
      "z": 20,
      "name": "Rock_Stone"
    },
    {
      "x": -9,
      "y": -4,
      "z": 20,
      "name": "Rock_Stone"
    },
    {
      "x": -9,
      "y": -3,
      "z": 20,
      "name": "Rock_Stone"
    },
    {
      "x": -9,
      "y": -2,
      "z": 20,
      "name": "Rock_Stone"
    },
    {
      "x": -9,
      "y": -1,
      "z": 20,
      "name": "Rock_Stone"
    },
    {
      "x": -9,
      "y": 0,
      "z": 20,
      "name": "Rock_Stone"
    },
    {
      "x": -9,
      "y": 1,
      "z": 20,
      "name": "Rock_Quartzite"
    },
    {
      "x": -9,
      "y": 2,
      "z": 20,
      "name": "Rock_Quartzite"
    },
    {
      "x": -9,
      "y": 3,
      "z": 20,
      "name": "Rock_Quartzite"
    },
    {
      "x": -9,
      "y": 4,
      "z": 20,
      "name": "Rock_Quartzite_Cobble"
    },
    {
      "x": -9,
      "y": 5,
      "z": 20,
      "name": "Rock_Quartzite_Cobble"
    },
    {
      "x": -9,
      "y": 6,
      "z": 20,
      "name": "Rock_Quartzite_Brick"
    },
    {
      "x": -9,
      "y": 7,
      "z": 20,
      "name": "Rock_Quartzite_Brick"
    },
    {
      "x": -9,
      "y": 8,
      "z": 20,
      "name": "Rock_Quartzite_Brick"
    },
    {
      "x": -9,
      "y": 9,
      "z": 20,
      "name": "Rock_Stone"
    },
    {
      "x": -9,
      "y": 10,
      "z": 20,
      "name": "Rock_Stone"
    },
    {
      "x": -9,
      "y": 11,
      "z": 20,
      "name": "Rock_Stone"
    },
    {
      "x": -9,
      "y": 12,
      "z": 20,
      "name": "Soil_Grass"
    },
    {
      "x": -9,
      "y": -7,
      "z": 21,
      "name": "Rock_Stone"
    },
    {
      "x": -9,
      "y": -6,
      "z": 21,
      "name": "Rock_Stone"
    },
    {
      "x": -9,
      "y": -5,
      "z": 21,
      "name": "Rock_Stone"
    },
    {
      "x": -9,
      "y": -4,
      "z": 21,
      "name": "Rock_Stone"
    },
    {
      "x": -9,
      "y": -3,
      "z": 21,
      "name": "Rock_Stone"
    },
    {
      "x": -9,
      "y": -2,
      "z": 21,
      "name": "Rock_Stone"
    },
    {
      "x": -9,
      "y": -1,
      "z": 21,
      "name": "Rock_Stone"
    },
    {
      "x": -9,
      "y": 0,
      "z": 21,
      "name": "Rock_Stone"
    },
    {
      "x": -9,
      "y": 1,
      "z": 21,
      "name": "Rock_Stone"
    },
    {
      "x": -9,
      "y": 2,
      "z": 21,
      "name": "Rock_Quartzite"
    },
    {
      "x": -9,
      "y": 3,
      "z": 21,
      "name": "Rock_Quartzite"
    },
    {
      "x": -9,
      "y": 4,
      "z": 21,
      "name": "Rock_Quartzite_Cobble"
    },
    {
      "x": -9,
      "y": 5,
      "z": 21,
      "name": "Rock_Quartzite_Cobble"
    },
    {
      "x": -9,
      "y": 6,
      "z": 21,
      "name": "Rock_Quartzite_Brick"
    },
    {
      "x": -9,
      "y": 7,
      "z": 21,
      "name": "Rock_Quartzite_Brick"
    },
    {
      "x": -9,
      "y": 8,
      "z": 21,
      "name": "Rock_Quartzite_Brick"
    },
    {
      "x": -9,
      "y": 9,
      "z": 21,
      "name": "Rock_Quartzite_Brick"
    },
    {
      "x": -9,
      "y": 10,
      "z": 21,
      "name": "Rock_Stone"
    },
    {
      "x": -9,
      "y": 11,
      "z": 21,
      "name": "Rock_Stone"
    },
    {
      "x": -9,
      "y": 12,
      "z": 21,
      "name": "Soil_Dirt"
    },
    {
      "x": -9,
      "y": 13,
      "z": 21,
      "name": "Soil_Grass"
    },
    {
      "x": -9,
      "y": -7,
      "z": 22,
      "name": "Rock_Stone"
    },
    {
      "x": -9,
      "y": -6,
      "z": 22,
      "name": "Rock_Stone"
    },
    {
      "x": -9,
      "y": -5,
      "z": 22,
      "name": "Rock_Stone"
    },
    {
      "x": -9,
      "y": -4,
      "z": 22,
      "name": "Rock_Stone"
    },
    {
      "x": -9,
      "y": -3,
      "z": 22,
      "name": "Rock_Stone"
    },
    {
      "x": -9,
      "y": -2,
      "z": 22,
      "name": "Rock_Stone"
    },
    {
      "x": -9,
      "y": -1,
      "z": 22,
      "name": "Rock_Stone"
    },
    {
      "x": -9,
      "y": 0,
      "z": 22,
      "name": "Rock_Stone"
    },
    {
      "x": -9,
      "y": 1,
      "z": 22,
      "name": "Rock_Quartzite"
    },
    {
      "x": -9,
      "y": 2,
      "z": 22,
      "name": "Rock_Quartzite"
    },
    {
      "x": -9,
      "y": 3,
      "z": 22,
      "name": "Rock_Quartzite"
    },
    {
      "x": -9,
      "y": 4,
      "z": 22,
      "name": "Rock_Quartzite_Cobble"
    },
    {
      "x": -9,
      "y": 5,
      "z": 22,
      "name": "Rock_Quartzite_Cobble"
    },
    {
      "x": -9,
      "y": 6,
      "z": 22,
      "name": "Rock_Quartzite_Brick"
    },
    {
      "x": -9,
      "y": 7,
      "z": 22,
      "name": "Rock_Quartzite_Brick"
    },
    {
      "x": -9,
      "y": 8,
      "z": 22,
      "name": "Rock_Quartzite_Brick"
    },
    {
      "x": -9,
      "y": 9,
      "z": 22,
      "name": "Rock_Quartzite_Brick"
    },
    {
      "x": -9,
      "y": 10,
      "z": 22,
      "name": "Rock_Stone"
    },
    {
      "x": -9,
      "y": 11,
      "z": 22,
      "name": "Rock_Stone"
    },
    {
      "x": -9,
      "y": 12,
      "z": 22,
      "name": "Rock_Stone"
    },
    {
      "x": -9,
      "y": 13,
      "z": 22,
      "name": "Soil_Grass"
    },
    {
      "x": -9,
      "y": -7,
      "z": 23,
      "name": "Rock_Stone"
    },
    {
      "x": -9,
      "y": -6,
      "z": 23,
      "name": "Rock_Stone"
    },
    {
      "x": -9,
      "y": -5,
      "z": 23,
      "name": "Rock_Stone"
    },
    {
      "x": -9,
      "y": -4,
      "z": 23,
      "name": "Rock_Stone"
    },
    {
      "x": -9,
      "y": -3,
      "z": 23,
      "name": "Rock_Stone"
    },
    {
      "x": -9,
      "y": -2,
      "z": 23,
      "name": "Rock_Stone"
    },
    {
      "x": -9,
      "y": -1,
      "z": 23,
      "name": "Rock_Stone"
    },
    {
      "x": -9,
      "y": 0,
      "z": 23,
      "name": "Rock_Stone"
    },
    {
      "x": -9,
      "y": 1,
      "z": 23,
      "name": "Rock_Quartzite"
    },
    {
      "x": -9,
      "y": 2,
      "z": 23,
      "name": "Rock_Quartzite"
    },
    {
      "x": -9,
      "y": 3,
      "z": 23,
      "name": "Rock_Quartzite"
    },
    {
      "x": -9,
      "y": 4,
      "z": 23,
      "name": "Rock_Quartzite_Cobble"
    },
    {
      "x": -9,
      "y": 5,
      "z": 23,
      "name": "Rock_Quartzite_Brick"
    },
    {
      "x": -9,
      "y": 6,
      "z": 23,
      "name": "Rock_Quartzite_Brick"
    },
    {
      "x": -9,
      "y": 7,
      "z": 23,
      "name": "Rock_Quartzite_Brick"
    },
    {
      "x": -9,
      "y": 8,
      "z": 23,
      "name": "Rock_Quartzite_Brick"
    },
    {
      "x": -9,
      "y": 9,
      "z": 23,
      "name": "Rock_Quartzite_Brick"
    },
    {
      "x": -9,
      "y": 10,
      "z": 23,
      "name": "Rock_Stone"
    },
    {
      "x": -9,
      "y": 11,
      "z": 23,
      "name": "Rock_Stone"
    },
    {
      "x": -9,
      "y": 12,
      "z": 23,
      "name": "Rock_Stone"
    },
    {
      "x": -9,
      "y": 13,
      "z": 23,
      "name": "Soil_Grass"
    },
    {
      "x": -9,
      "y": -7,
      "z": 24,
      "name": "Rock_Stone"
    },
    {
      "x": -9,
      "y": -6,
      "z": 24,
      "name": "Rock_Stone"
    },
    {
      "x": -9,
      "y": -5,
      "z": 24,
      "name": "Rock_Stone"
    },
    {
      "x": -9,
      "y": -4,
      "z": 24,
      "name": "Rock_Stone"
    },
    {
      "x": -9,
      "y": -3,
      "z": 24,
      "name": "Rock_Stone"
    },
    {
      "x": -9,
      "y": -2,
      "z": 24,
      "name": "Rock_Stone"
    },
    {
      "x": -9,
      "y": -1,
      "z": 24,
      "name": "Rock_Stone"
    },
    {
      "x": -9,
      "y": 0,
      "z": 24,
      "name": "Rock_Stone"
    },
    {
      "x": -9,
      "y": 1,
      "z": 24,
      "name": "Rock_Stone"
    },
    {
      "x": -9,
      "y": 2,
      "z": 24,
      "name": "Rock_Stone"
    },
    {
      "x": -9,
      "y": 3,
      "z": 24,
      "name": "Rock_Stone"
    },
    {
      "x": -9,
      "y": 4,
      "z": 24,
      "name": "Rock_Stone"
    },
    {
      "x": -9,
      "y": 5,
      "z": 24,
      "name": "Rock_Stone"
    },
    {
      "x": -9,
      "y": 6,
      "z": 24,
      "name": "Rock_Stone"
    },
    {
      "x": -9,
      "y": 7,
      "z": 24,
      "name": "Rock_Stone"
    },
    {
      "x": -9,
      "y": 8,
      "z": 24,
      "name": "Rock_Stone"
    },
    {
      "x": -9,
      "y": 9,
      "z": 24,
      "name": "Rock_Stone"
    },
    {
      "x": -9,
      "y": 10,
      "z": 24,
      "name": "Rock_Stone"
    },
    {
      "x": -9,
      "y": -7,
      "z": 25,
      "name": "Rock_Stone"
    },
    {
      "x": -9,
      "y": -6,
      "z": 25,
      "name": "Rock_Stone"
    },
    {
      "x": -9,
      "y": -5,
      "z": 25,
      "name": "Rock_Stone"
    },
    {
      "x": -9,
      "y": -4,
      "z": 25,
      "name": "Rock_Stone"
    },
    {
      "x": -9,
      "y": -3,
      "z": 25,
      "name": "Rock_Stone"
    },
    {
      "x": -9,
      "y": -2,
      "z": 25,
      "name": "Rock_Stone"
    },
    {
      "x": -9,
      "y": -1,
      "z": 25,
      "name": "Rock_Stone"
    },
    {
      "x": -9,
      "y": 0,
      "z": 25,
      "name": "Rock_Stone"
    },
    {
      "x": -9,
      "y": 1,
      "z": 25,
      "name": "Rock_Stone"
    },
    {
      "x": -9,
      "y": 2,
      "z": 25,
      "name": "Rock_Stone"
    },
    {
      "x": -9,
      "y": 3,
      "z": 25,
      "name": "Soil_Dirt"
    },
    {
      "x": -9,
      "y": 4,
      "z": 25,
      "name": "Soil_Grass"
    },
    {
      "x": -8,
      "y": -7,
      "z": 10,
      "name": "Rock_Stone"
    },
    {
      "x": -8,
      "y": -6,
      "z": 10,
      "name": "Rock_Stone"
    },
    {
      "x": -8,
      "y": -5,
      "z": 10,
      "name": "Rock_Stone"
    },
    {
      "x": -8,
      "y": -4,
      "z": 10,
      "name": "Rock_Stone"
    },
    {
      "x": -8,
      "y": -3,
      "z": 10,
      "name": "Rock_Stone"
    },
    {
      "x": -8,
      "y": -2,
      "z": 10,
      "name": "Rock_Stone"
    },
    {
      "x": -8,
      "y": -1,
      "z": 10,
      "name": "Rock_Stone"
    },
    {
      "x": -8,
      "y": 0,
      "z": 10,
      "name": "Rock_Stone"
    },
    {
      "x": -8,
      "y": 1,
      "z": 10,
      "name": "Rock_Stone"
    },
    {
      "x": -8,
      "y": 2,
      "z": 10,
      "name": "Rock_Stone"
    },
    {
      "x": -8,
      "y": 3,
      "z": 10,
      "name": "Rock_Stone"
    },
    {
      "x": -8,
      "y": 9,
      "z": 10,
      "name": "Rock_Stone"
    },
    {
      "x": -8,
      "y": 10,
      "z": 10,
      "name": "Soil_Grass"
    },
    {
      "x": -8,
      "y": -7,
      "z": 11,
      "name": "Rock_Stone"
    },
    {
      "x": -8,
      "y": -6,
      "z": 11,
      "name": "Rock_Stone"
    },
    {
      "x": -8,
      "y": -5,
      "z": 11,
      "name": "Rock_Stone"
    },
    {
      "x": -8,
      "y": -4,
      "z": 11,
      "name": "Rock_Stone"
    },
    {
      "x": -8,
      "y": -3,
      "z": 11,
      "name": "Rock_Stone"
    },
    {
      "x": -8,
      "y": -2,
      "z": 11,
      "name": "Rock_Stone"
    },
    {
      "x": -8,
      "y": -1,
      "z": 11,
      "name": "Rock_Stone"
    },
    {
      "x": -8,
      "y": 0,
      "z": 11,
      "name": "Rock_Stone"
    },
    {
      "x": -8,
      "y": 1,
      "z": 11,
      "name": "Rock_Stone"
    },
    {
      "x": -8,
      "y": 2,
      "z": 11,
      "name": "Rock_Stone"
    },
    {
      "x": -8,
      "y": 3,
      "z": 11,
      "name": "Rock_Stone"
    },
    {
      "x": -8,
      "y": 4,
      "z": 11,
      "name": "Rock_Stone"
    },
    {
      "x": -8,
      "y": 5,
      "z": 11,
      "name": "Rock_Stone"
    },
    {
      "x": -8,
      "y": 6,
      "z": 11,
      "name": "Rock_Stone"
    },
    {
      "x": -8,
      "y": 7,
      "z": 11,
      "name": "Rock_Stone"
    },
    {
      "x": -8,
      "y": 8,
      "z": 11,
      "name": "Rock_Stone"
    },
    {
      "x": -8,
      "y": 9,
      "z": 11,
      "name": "Rock_Stone"
    },
    {
      "x": -8,
      "y": 10,
      "z": 11,
      "name": "Soil_Grass"
    },
    {
      "x": -8,
      "y": -7,
      "z": 12,
      "name": "Rock_Stone"
    },
    {
      "x": -8,
      "y": -6,
      "z": 12,
      "name": "Rock_Stone"
    },
    {
      "x": -8,
      "y": -5,
      "z": 12,
      "name": "Rock_Stone"
    },
    {
      "x": -8,
      "y": -4,
      "z": 12,
      "name": "Rock_Stone"
    },
    {
      "x": -8,
      "y": -3,
      "z": 12,
      "name": "Rock_Stone"
    },
    {
      "x": -8,
      "y": -2,
      "z": 12,
      "name": "Rock_Stone"
    },
    {
      "x": -8,
      "y": -1,
      "z": 12,
      "name": "Rock_Stone"
    },
    {
      "x": -8,
      "y": 0,
      "z": 12,
      "name": "Rock_Stone"
    },
    {
      "x": -8,
      "y": 1,
      "z": 12,
      "name": "Rock_Stone"
    },
    {
      "x": -8,
      "y": 2,
      "z": 12,
      "name": "Rock_Stone"
    },
    {
      "x": -8,
      "y": 3,
      "z": 12,
      "name": "Rock_Stone"
    },
    {
      "x": -8,
      "y": 4,
      "z": 12,
      "name": "Rock_Stone"
    },
    {
      "x": -8,
      "y": 5,
      "z": 12,
      "name": "Rock_Stone"
    },
    {
      "x": -8,
      "y": 6,
      "z": 12,
      "name": "Rock_Stone"
    },
    {
      "x": -8,
      "y": 7,
      "z": 12,
      "name": "Rock_Stone"
    },
    {
      "x": -8,
      "y": 8,
      "z": 12,
      "name": "Rock_Stone"
    },
    {
      "x": -8,
      "y": 9,
      "z": 12,
      "name": "Soil_Dirt"
    },
    {
      "x": -8,
      "y": 10,
      "z": 12,
      "name": "Soil_Grass"
    },
    {
      "x": -8,
      "y": -7,
      "z": 13,
      "name": "Rock_Stone"
    },
    {
      "x": -8,
      "y": -6,
      "z": 13,
      "name": "Rock_Stone"
    },
    {
      "x": -8,
      "y": -5,
      "z": 13,
      "name": "Rock_Stone"
    },
    {
      "x": -8,
      "y": -4,
      "z": 13,
      "name": "Rock_Stone"
    },
    {
      "x": -8,
      "y": -3,
      "z": 13,
      "name": "Rock_Stone"
    },
    {
      "x": -8,
      "y": -2,
      "z": 13,
      "name": "Rock_Stone"
    },
    {
      "x": -8,
      "y": -1,
      "z": 13,
      "name": "Rock_Stone"
    },
    {
      "x": -8,
      "y": 0,
      "z": 13,
      "name": "Rock_Stone"
    },
    {
      "x": -8,
      "y": 1,
      "z": 13,
      "name": "Rock_Stone"
    },
    {
      "x": -8,
      "y": 2,
      "z": 13,
      "name": "Rock_Stone"
    },
    {
      "x": -8,
      "y": 3,
      "z": 13,
      "name": "Rock_Stone"
    },
    {
      "x": -8,
      "y": 4,
      "z": 13,
      "name": "Rock_Stone"
    },
    {
      "x": -8,
      "y": 5,
      "z": 13,
      "name": "Rock_Stone"
    },
    {
      "x": -8,
      "y": 6,
      "z": 13,
      "name": "Rock_Stone"
    },
    {
      "x": -8,
      "y": 7,
      "z": 13,
      "name": "Rock_Stone"
    },
    {
      "x": -8,
      "y": 8,
      "z": 13,
      "name": "Rock_Stone"
    },
    {
      "x": -8,
      "y": 9,
      "z": 13,
      "name": "Soil_Dirt"
    },
    {
      "x": -8,
      "y": 10,
      "z": 13,
      "name": "Soil_Grass"
    },
    {
      "x": -8,
      "y": -7,
      "z": 14,
      "name": "Rock_Stone"
    },
    {
      "x": -8,
      "y": -6,
      "z": 14,
      "name": "Rock_Stone"
    },
    {
      "x": -8,
      "y": -5,
      "z": 14,
      "name": "Rock_Stone"
    },
    {
      "x": -8,
      "y": -4,
      "z": 14,
      "name": "Rock_Stone"
    },
    {
      "x": -8,
      "y": -3,
      "z": 14,
      "name": "Rock_Stone"
    },
    {
      "x": -8,
      "y": -2,
      "z": 14,
      "name": "Rock_Stone"
    },
    {
      "x": -8,
      "y": -1,
      "z": 14,
      "name": "Rock_Stone"
    },
    {
      "x": -8,
      "y": 0,
      "z": 14,
      "name": "Rock_Stone"
    },
    {
      "x": -8,
      "y": 1,
      "z": 14,
      "name": "Rock_Stone"
    },
    {
      "x": -8,
      "y": 2,
      "z": 14,
      "name": "Rock_Stone"
    },
    {
      "x": -8,
      "y": 3,
      "z": 14,
      "name": "Rock_Stone"
    },
    {
      "x": -8,
      "y": 4,
      "z": 14,
      "name": "Rock_Stone"
    },
    {
      "x": -8,
      "y": 5,
      "z": 14,
      "name": "Rock_Stone"
    },
    {
      "x": -8,
      "y": 6,
      "z": 14,
      "name": "Rock_Stone"
    },
    {
      "x": -8,
      "y": 7,
      "z": 14,
      "name": "Rock_Stone"
    },
    {
      "x": -8,
      "y": 8,
      "z": 14,
      "name": "Rock_Stone"
    },
    {
      "x": -8,
      "y": 9,
      "z": 14,
      "name": "Soil_Dirt"
    },
    {
      "x": -8,
      "y": 10,
      "z": 14,
      "name": "Soil_Grass"
    },
    {
      "x": -8,
      "y": -7,
      "z": 15,
      "name": "Rock_Stone"
    },
    {
      "x": -8,
      "y": -6,
      "z": 15,
      "name": "Rock_Stone"
    },
    {
      "x": -8,
      "y": -5,
      "z": 15,
      "name": "Rock_Stone"
    },
    {
      "x": -8,
      "y": -4,
      "z": 15,
      "name": "Rock_Stone"
    },
    {
      "x": -8,
      "y": -3,
      "z": 15,
      "name": "Rock_Stone"
    },
    {
      "x": -8,
      "y": -2,
      "z": 15,
      "name": "Rock_Stone"
    },
    {
      "x": -8,
      "y": -1,
      "z": 15,
      "name": "Rock_Stone"
    },
    {
      "x": -8,
      "y": 0,
      "z": 15,
      "name": "Rock_Stone"
    },
    {
      "x": -8,
      "y": 1,
      "z": 15,
      "name": "Rock_Quartzite"
    },
    {
      "x": -8,
      "y": 2,
      "z": 15,
      "name": "Rock_Quartzite"
    },
    {
      "x": -8,
      "y": 3,
      "z": 15,
      "name": "Rock_Quartzite_Brick"
    },
    {
      "x": -8,
      "y": 5,
      "z": 15,
      "name": "Rock_Stone"
    },
    {
      "x": -8,
      "y": 6,
      "z": 15,
      "name": "Rock_Stone"
    },
    {
      "x": -8,
      "y": 7,
      "z": 15,
      "name": "Rock_Stone"
    },
    {
      "x": -8,
      "y": 8,
      "z": 15,
      "name": "Rock_Stone"
    },
    {
      "x": -8,
      "y": 9,
      "z": 15,
      "name": "Soil_Dirt"
    },
    {
      "x": -8,
      "y": 10,
      "z": 15,
      "name": "Soil_Grass"
    },
    {
      "x": -8,
      "y": -7,
      "z": 16,
      "name": "Rock_Stone"
    },
    {
      "x": -8,
      "y": -6,
      "z": 16,
      "name": "Rock_Stone"
    },
    {
      "x": -8,
      "y": -5,
      "z": 16,
      "name": "Rock_Stone"
    },
    {
      "x": -8,
      "y": -4,
      "z": 16,
      "name": "Rock_Stone"
    },
    {
      "x": -8,
      "y": -3,
      "z": 16,
      "name": "Rock_Stone"
    },
    {
      "x": -8,
      "y": -2,
      "z": 16,
      "name": "Rock_Stone"
    },
    {
      "x": -8,
      "y": -1,
      "z": 16,
      "name": "Rock_Stone"
    },
    {
      "x": -8,
      "y": 0,
      "z": 16,
      "name": "Rock_Stone"
    },
    {
      "x": -8,
      "y": 1,
      "z": 16,
      "name": "Soil_Dirt"
    },
    {
      "x": -8,
      "y": 2,
      "z": 16,
      "name": "Soil_Grass"
    },
    {
      "x": -8,
      "y": 3,
      "z": 16,
      "name": "Plant_Moss_Rug_Green"
    },
    {
      "x": -8,
      "y": 5,
      "z": 16,
      "name": "Rock_Stone"
    },
    {
      "x": -8,
      "y": 6,
      "z": 16,
      "name": "Rock_Stone"
    },
    {
      "x": -8,
      "y": 7,
      "z": 16,
      "name": "Rock_Stone"
    },
    {
      "x": -8,
      "y": 8,
      "z": 16,
      "name": "Rock_Stone"
    },
    {
      "x": -8,
      "y": 9,
      "z": 16,
      "name": "Rock_Stone"
    },
    {
      "x": -8,
      "y": 10,
      "z": 16,
      "name": "Rock_Stone"
    },
    {
      "x": -8,
      "y": 11,
      "z": 16,
      "name": "Soil_Grass"
    },
    {
      "x": -8,
      "y": -7,
      "z": 17,
      "name": "Rock_Stone"
    },
    {
      "x": -8,
      "y": -6,
      "z": 17,
      "name": "Rock_Stone"
    },
    {
      "x": -8,
      "y": -5,
      "z": 17,
      "name": "Rock_Stone"
    },
    {
      "x": -8,
      "y": -4,
      "z": 17,
      "name": "Rock_Stone"
    },
    {
      "x": -8,
      "y": -3,
      "z": 17,
      "name": "Rock_Stone"
    },
    {
      "x": -8,
      "y": -2,
      "z": 17,
      "name": "Rock_Stone"
    },
    {
      "x": -8,
      "y": -1,
      "z": 17,
      "name": "Rock_Stone"
    },
    {
      "x": -8,
      "y": 0,
      "z": 17,
      "name": "Rock_Stone"
    },
    {
      "x": -8,
      "y": 1,
      "z": 17,
      "name": "Soil_Dirt"
    },
    {
      "x": -8,
      "y": 2,
      "z": 17,
      "name": "Soil_Grass"
    },
    {
      "x": -8,
      "y": 3,
      "z": 17,
      "name": "Plant_Grass_Sharp"
    },
    {
      "x": -8,
      "y": 7,
      "z": 17,
      "name": "Rock_Stone"
    },
    {
      "x": -8,
      "y": 8,
      "z": 17,
      "name": "Rock_Stone"
    },
    {
      "x": -8,
      "y": 9,
      "z": 17,
      "name": "Rock_Stone"
    },
    {
      "x": -8,
      "y": 10,
      "z": 17,
      "name": "Rock_Stone"
    },
    {
      "x": -8,
      "y": 11,
      "z": 17,
      "name": "Soil_Grass"
    },
    {
      "x": -8,
      "y": -7,
      "z": 18,
      "name": "Rock_Stone"
    },
    {
      "x": -8,
      "y": -6,
      "z": 18,
      "name": "Rock_Stone"
    },
    {
      "x": -8,
      "y": -5,
      "z": 18,
      "name": "Rock_Stone"
    },
    {
      "x": -8,
      "y": -4,
      "z": 18,
      "name": "Rock_Stone"
    },
    {
      "x": -8,
      "y": -3,
      "z": 18,
      "name": "Rock_Stone"
    },
    {
      "x": -8,
      "y": -2,
      "z": 18,
      "name": "Rock_Stone"
    },
    {
      "x": -8,
      "y": -1,
      "z": 18,
      "name": "Rock_Stone"
    },
    {
      "x": -8,
      "y": 0,
      "z": 18,
      "name": "Rock_Stone"
    },
    {
      "x": -8,
      "y": 1,
      "z": 18,
      "name": "Soil_Dirt"
    },
    {
      "x": -8,
      "y": 2,
      "z": 18,
      "name": "Soil_Grass"
    },
    {
      "x": -8,
      "y": 3,
      "z": 18,
      "name": "Plant_Grass_Sharp_Tall"
    },
    {
      "x": -8,
      "y": 4,
      "z": 18,
      "name": "Plant_Grass_Sharp_Tall",
      "filler": 1024
    },
    {
      "x": -8,
      "y": 7,
      "z": 18,
      "name": "Rock_Stone"
    },
    {
      "x": -8,
      "y": 8,
      "z": 18,
      "name": "Rock_Stone"
    },
    {
      "x": -8,
      "y": 9,
      "z": 18,
      "name": "Rock_Stone"
    },
    {
      "x": -8,
      "y": 10,
      "z": 18,
      "name": "Rock_Stone"
    },
    {
      "x": -8,
      "y": 11,
      "z": 18,
      "name": "Rock_Stone"
    },
    {
      "x": -8,
      "y": 12,
      "z": 18,
      "name": "Soil_Grass"
    },
    {
      "x": -8,
      "y": -7,
      "z": 19,
      "name": "Rock_Stone"
    },
    {
      "x": -8,
      "y": -6,
      "z": 19,
      "name": "Rock_Stone"
    },
    {
      "x": -8,
      "y": -5,
      "z": 19,
      "name": "Rock_Stone"
    },
    {
      "x": -8,
      "y": -4,
      "z": 19,
      "name": "Rock_Stone"
    },
    {
      "x": -8,
      "y": -3,
      "z": 19,
      "name": "Rock_Stone"
    },
    {
      "x": -8,
      "y": -2,
      "z": 19,
      "name": "Rock_Stone"
    },
    {
      "x": -8,
      "y": -1,
      "z": 19,
      "name": "Rock_Stone"
    },
    {
      "x": -8,
      "y": 0,
      "z": 19,
      "name": "Rock_Stone"
    },
    {
      "x": -8,
      "y": 1,
      "z": 19,
      "name": "Soil_Dirt"
    },
    {
      "x": -8,
      "y": 2,
      "z": 19,
      "name": "Soil_Grass"
    },
    {
      "x": -8,
      "y": 3,
      "z": 19,
      "name": "Plant_Grass_Sharp_Short"
    },
    {
      "x": -8,
      "y": 8,
      "z": 19,
      "name": "Rock_Stone"
    },
    {
      "x": -8,
      "y": 9,
      "z": 19,
      "name": "Rock_Stone"
    },
    {
      "x": -8,
      "y": 10,
      "z": 19,
      "name": "Rock_Stone"
    },
    {
      "x": -8,
      "y": 11,
      "z": 19,
      "name": "Rock_Stone"
    },
    {
      "x": -8,
      "y": 12,
      "z": 19,
      "name": "Soil_Dirt"
    },
    {
      "x": -8,
      "y": 13,
      "z": 19,
      "name": "Soil_Grass"
    },
    {
      "x": -8,
      "y": -7,
      "z": 20,
      "name": "Rock_Stone"
    },
    {
      "x": -8,
      "y": -6,
      "z": 20,
      "name": "Rock_Stone"
    },
    {
      "x": -8,
      "y": -5,
      "z": 20,
      "name": "Rock_Stone"
    },
    {
      "x": -8,
      "y": -4,
      "z": 20,
      "name": "Rock_Stone"
    },
    {
      "x": -8,
      "y": -3,
      "z": 20,
      "name": "Rock_Stone"
    },
    {
      "x": -8,
      "y": -2,
      "z": 20,
      "name": "Rock_Stone"
    },
    {
      "x": -8,
      "y": -1,
      "z": 20,
      "name": "Rock_Stone"
    },
    {
      "x": -8,
      "y": 0,
      "z": 20,
      "name": "Rock_Stone"
    },
    {
      "x": -8,
      "y": 1,
      "z": 20,
      "name": "Soil_Grass"
    },
    {
      "x": -8,
      "y": 2,
      "z": 20,
      "name": "Plant_Grass_Sharp"
    },
    {
      "x": -8,
      "y": 10,
      "z": 20,
      "name": "Rock_Stone"
    },
    {
      "x": -8,
      "y": 11,
      "z": 20,
      "name": "Rock_Stone"
    },
    {
      "x": -8,
      "y": 12,
      "z": 20,
      "name": "Soil_Dirt"
    },
    {
      "x": -8,
      "y": 13,
      "z": 20,
      "name": "Soil_Grass"
    },
    {
      "x": -8,
      "y": -7,
      "z": 21,
      "name": "Rock_Stone"
    },
    {
      "x": -8,
      "y": -6,
      "z": 21,
      "name": "Rock_Stone"
    },
    {
      "x": -8,
      "y": -5,
      "z": 21,
      "name": "Rock_Stone"
    },
    {
      "x": -8,
      "y": -4,
      "z": 21,
      "name": "Rock_Stone"
    },
    {
      "x": -8,
      "y": -3,
      "z": 21,
      "name": "Rock_Stone"
    },
    {
      "x": -8,
      "y": -2,
      "z": 21,
      "name": "Rock_Stone"
    },
    {
      "x": -8,
      "y": -1,
      "z": 21,
      "name": "Rock_Stone"
    },
    {
      "x": -8,
      "y": 0,
      "z": 21,
      "name": "Rock_Stone"
    },
    {
      "x": -8,
      "y": 1,
      "z": 21,
      "name": "Soil_Dirt"
    },
    {
      "x": -8,
      "y": 6,
      "z": 21,
      "name": "Rock_Stone_Stalactite_Small",
      "rotation": 8
    },
    {
      "x": -8,
      "y": 7,
      "z": 21,
      "name": "Rock_Stone"
    },
    {
      "x": -8,
      "y": 8,
      "z": 21,
      "name": "Rock_Stone"
    },
    {
      "x": -8,
      "y": 9,
      "z": 21,
      "name": "Rock_Stone"
    },
    {
      "x": -8,
      "y": 10,
      "z": 21,
      "name": "Rock_Quartzite_Brick"
    },
    {
      "x": -8,
      "y": 11,
      "z": 21,
      "name": "Rock_Stone"
    },
    {
      "x": -8,
      "y": 12,
      "z": 21,
      "name": "Rock_Stone"
    },
    {
      "x": -8,
      "y": 13,
      "z": 21,
      "name": "Soil_Grass"
    },
    {
      "x": -8,
      "y": -7,
      "z": 22,
      "name": "Rock_Stone"
    },
    {
      "x": -8,
      "y": -6,
      "z": 22,
      "name": "Rock_Stone"
    },
    {
      "x": -8,
      "y": -5,
      "z": 22,
      "name": "Rock_Stone"
    },
    {
      "x": -8,
      "y": -4,
      "z": 22,
      "name": "Rock_Stone"
    },
    {
      "x": -8,
      "y": -3,
      "z": 22,
      "name": "Rock_Stone"
    },
    {
      "x": -8,
      "y": -2,
      "z": 22,
      "name": "Rock_Stone"
    },
    {
      "x": -8,
      "y": -1,
      "z": 22,
      "name": "Rock_Stone"
    },
