{
  "version": 8,
  "blockIdVersion": 11,
  "anchorX": 0,
  "anchorY": 0,
  "anchorZ": 0,
  "blocks": [
    {
      "x": -4,
      "y": 0,
      "z": -4,
      "name": "BO_Parking_Blacktop",
      "rotation": 4
    },
    {
      "x": -4,
      "y": 1,
      "z": -4,
      "name": "BO_Parking_Blacktop",
      "rotation": 4
    },
    {
      "x": -4,
      "y": 2,
      "z": -4,
      "name": "BO_Parking_Blacktop",
      "rotation": 4
    },
    {
      "x": -4,
      "y": 3,
      "z": -4,
      "name": "BO_Parking_Blacktop",
      "rotation": 4
    },
    {
      "x": -4,
      "y": 4,
      "z": -4,
      "name": "BO_Parking_Wall00",
      "support": 15
    },
    {
      "x": -4,
      "y": 5,
      "z": -4,
      "name": "BO_Parking_Wall02"
    },
    {
      "x": -4,
      "y": 6,
      "z": -4,
      "name": "BO_Parking_Wall00",
      "support": 15
    },
    {
      "x": -4,
      "y": 7,
      "z": -4,
      "name": "BO_Parking_Wall00",
      "support": 15
    },
    {
      "x": -4,
      "y": 8,
      "z": -4,
      "name": "BO_Parking_Wall00",
      "support": 15
    },
    {
      "x": -4,
      "y": 9,
      "z": -4,
      "name": "Prototype_Rock_Concrete_Brick"
    },
    {
      "x": -4,
      "y": 10,
      "z": -4,
      "name": "Prototype_Rock_Concrete_Brick"
    },
    {
      "x": -4,
      "y": 11,
      "z": -4,
      "name": "Soil_Clay_Smooth_Black",
      "rotation": 4
    },
    {
      "x": -4,
      "y": 12,
      "z": -4,
      "name": "Soil_Clay_Smooth_Black",
      "rotation": 4
    },
    {
      "x": -4,
      "y": 13,
      "z": -4,
      "name": "Soil_Clay_Smooth_Black",
      "rotation": 4
    },
    {
      "x": -4,
      "y": 14,
      "z": -4,
      "name": "Soil_Clay_Smooth_Black",
      "rotation": 4
    },
    {
      "x": -4,
      "y": 15,
      "z": -4,
      "name": "Soil_Clay_Smooth_Black",
      "rotation": 4
    },
    {
      "x": -4,
      "y": 16,
      "z": -4,
      "name": "Soil_Clay_Smooth_Black",
      "rotation": 4
    },
    {
      "x": -4,
      "y": 17,
      "z": -4,
      "name": "Soil_Clay_Smooth_Black",
      "rotation": 4
    },
    {
      "x": -4,
      "y": 18,
      "z": -4,
      "name": "Prototype_Rock_Concrete_Brick",
      "rotation": 3
    },
    {
      "x": -4,
      "y": 19,
      "z": -4,
      "name": "Soil_Clay_Smooth_Yellow",
      "rotation": 3
    },
    {
      "x": -4,
      "y": 20,
      "z": -4,
      "name": "Prototype_Rock_Concrete_Brick",
      "rotation": 3
    },
    {
      "x": -4,
      "y": 21,
      "z": -4,
      "name": "Prototype_Rock_Concrete_Brick",
      "rotation": 3
    },
    {
      "x": -4,
      "y": 22,
      "z": -4,
      "name": "BO_Floor00"
    },
    {
      "x": -4,
      "y": 23,
      "z": -4,
      "name": "BO_Wallpaper00",
      "rotation": 1
    },
    {
      "x": -4,
      "y": 24,
      "z": -4,
      "name": "BO_Wallpaper00",
      "rotation": 1
    },
    {
      "x": -4,
      "y": 25,
      "z": -4,
      "name": "BO_Wallpaper00",
      "rotation": 1
    },
    {
      "x": -4,
      "y": 26,
      "z": -4,
      "name": "BO_Wallpaper00",
      "rotation": 1
    },
    {
      "x": -4,
      "y": 27,
      "z": -4,
      "name": "BO_Wallpaper00",
      "rotation": 1
    },
    {
      "x": -4,
      "y": 28,
      "z": -4,
      "name": "BO_Wallpaper00",
      "rotation": 2
    },
    {
      "x": -4,
      "y": 29,
      "z": -4,
      "name": "BO_Pool_Surface00",
      "rotation": 4
    },
    {
      "x": -4,
      "y": 30,
      "z": -4,
      "name": "BO_Pool_Surface00",
      "rotation": 4
    },
    {
      "x": -4,
      "y": 31,
      "z": -4,
      "name": "BO_Pool_Surface00",
      "rotation": 4
    },
    {
      "x": -4,
      "y": 32,
      "z": -4,
      "name": "BO_Pool_Surface00",
      "rotation": 4
    },
    {
      "x": -4,
      "y": 33,
      "z": -4,
      "name": "BO_Pool_Surface00",
      "rotation": 4
    },
    {
      "x": -4,
      "y": 34,
      "z": -4,
      "name": "BO_Pool_Surface00",
      "rotation": 4
    },
    {
      "x": -4,
      "y": 35,
      "z": -4,
      "name": "BO_Pool_Surface00",
      "rotation": 4
    },
    {
      "x": -4,
      "y": 36,
      "z": -4,
      "name": "BO_Pool_Surface00",
      "rotation": 4
    },
    {
      "x": -4,
      "y": 37,
      "z": -4,
      "name": "BO_Pool_Surface00",
      "rotation": 4
    },
    {
      "x": -4,
      "y": 38,
      "z": -4,
      "name": "BO_Pool_Surface00",
      "rotation": 4
    },
    {
      "x": -4,
      "y": 39,
      "z": -4,
      "name": "BO_Pool_Surface00",
      "rotation": 4
    },
    {
      "x": -4,
      "y": 40,
      "z": -4,
      "name": "BO_Pool_Surface00",
      "rotation": 4
    },
    {
      "x": -4,
      "y": 41,
      "z": -4,
      "name": "BO_Pool_Surface00",
      "rotation": 4
    },
    {
      "x": -4,
      "y": 42,
      "z": -4,
      "name": "*BO_Lightsource_Cycle_State_Definitions_Day",
      "components": {
        "Components": {
          "BlackoutCycleState": {
            "OnState": "Day",
            "OffState": "Night"
          }
        }
      },
      "rotation": 2
    },
    {
      "x": -4,
      "y": 46,
      "z": -4,
      "name": "BO_Pool_Surface00",
      "rotation": 2
    },
    {
      "x": -4,
      "y": 47,
      "z": -4,
      "name": "Empty"
    },
    {
      "x": -4,
      "y": 0,
      "z": -3,
      "name": "BO_Parking_Blacktop",
      "rotation": 4
    },
    {
      "x": -4,
      "y": 1,
      "z": -3,
      "name": "BO_Parking_Blacktop",
      "rotation": 4
    },
    {
      "x": -4,
      "y": 2,
      "z": -3,
      "name": "BO_Parking_Blacktop",
      "rotation": 4
    },
    {
      "x": -4,
      "y": 3,
      "z": -3,
      "name": "BO_Parking_Blacktop",
      "rotation": 4
    },
    {
      "x": -4,
      "y": 9,
      "z": -3,
      "name": "Prototype_Rock_Concrete_Brick_Half"
    },
    {
      "x": -4,
      "y": 10,
      "z": -3,
      "name": "Prototype_Rock_Concrete_Brick"
    },
    {
      "x": -4,
      "y": 11,
      "z": -3,
      "name": "Soil_Clay_Smooth_Black",
      "rotation": 4
    },
    {
      "x": -4,
      "y": 12,
      "z": -3,
      "name": "Soil_Clay_Smooth_Black",
      "rotation": 4
    },
    {
      "x": -4,
      "y": 13,
      "z": -3,
      "name": "Soil_Clay_Smooth_Black",
      "rotation": 4
    },
    {
      "x": -4,
      "y": 14,
      "z": -3,
      "name": "Soil_Clay_Smooth_Black",
      "rotation": 4
    },
    {
      "x": -4,
      "y": 15,
      "z": -3,
      "name": "Soil_Clay_Smooth_Black",
      "rotation": 4
    },
    {
      "x": -4,
      "y": 16,
      "z": -3,
      "name": "Soil_Clay_Smooth_Black",
      "rotation": 4
    },
    {
      "x": -4,
      "y": 17,
      "z": -3,
      "name": "Soil_Clay_Smooth_Black",
      "rotation": 4
    },
    {
      "x": -4,
      "y": 18,
      "z": -3,
      "name": "Prototype_Rock_Concrete_Brick"
    },
    {
      "x": -4,
      "y": 19,
      "z": -3,
      "name": "Soil_Clay_Smooth_Yellow"
    },
    {
      "x": -4,
      "y": 20,
      "z": -3,
      "name": "Prototype_Rock_Concrete_Brick"
    },
    {
      "x": -4,
      "y": 21,
      "z": -3,
      "name": "Prototype_Rock_Concrete_Brick",
      "support": 15
    },
    {
      "x": -4,
      "y": 22,
      "z": -3,
      "name": "BO_Floor00"
    },
    {
      "x": -4,
      "y": 23,
      "z": -3,
      "name": "BO_Wallpaper00",
      "rotation": 1
    },
    {
      "x": -4,
      "y": 24,
      "z": -3,
      "name": "BO_Wallpaper00",
      "rotation": 1
    },
    {
      "x": -4,
      "y": 25,
      "z": -3,
      "name": "BO_Wallpaper00",
      "rotation": 1
    },
    {
      "x": -4,
      "y": 26,
      "z": -3,
      "name": "BO_Wallpaper00",
      "rotation": 1
    },
    {
      "x": -4,
      "y": 27,
      "z": -3,
      "name": "BO_Wallpaper00",
      "rotation": 1
    },
    {
      "x": -4,
      "y": 28,
      "z": -3,
      "name": "BO_Ceiling00",
      "rotation": 10
    },
    {
      "x": -4,
      "y": 29,
      "z": -3,
      "name": "BO_Pool_Surface00",
      "rotation": 4
    },
    {
      "x": -4,
      "y": 30,
      "z": -3,
      "name": "BO_Pool_Surface00",
      "rotation": 4
    },
    {
      "x": -4,
      "y": 31,
      "z": -3,
      "name": "BO_Pool_Surface00",
      "rotation": 4
    },
    {
      "x": -4,
      "y": 32,
      "z": -3,
      "name": "BO_Pool_Surface00",
      "rotation": 4
    },
    {
      "x": -4,
      "y": 33,
      "z": -3,
      "name": "BO_Pool_Surface00",
      "rotation": 4
    },
    {
      "x": -4,
      "y": 34,
      "z": -3,
      "name": "BO_Pool_Surface00",
      "rotation": 4
    },
    {
      "x": -4,
      "y": 35,
      "z": -3,
      "name": "BO_Pool_Surface00",
      "rotation": 4
    },
    {
      "x": -4,
      "y": 36,
      "z": -3,
      "name": "BO_Pool_Surface00",
      "rotation": 4
    },
    {
      "x": -4,
      "y": 37,
      "z": -3,
      "name": "BO_Pool_Surface00"
    },
    {
      "x": -4,
      "y": 38,
      "z": -3,
      "name": "BO_Pool_Surface00",
      "rotation": 4
    },
    {
      "x": -4,
      "y": 39,
      "z": -3,
      "name": "BO_Pool_Surface00",
      "rotation": 4
    },
    {
      "x": -4,
      "y": 40,
      "z": -3,
      "name": "BO_Pool_Surface00",
      "rotation": 4
    },
    {
      "x": -4,
      "y": 41,
      "z": -3,
      "name": "BO_Pool_Surface00",
      "rotation": 4
    },
    {
      "x": -4,
      "y": 42,
      "z": -3,
      "name": "*BO_Lightsource_Cycle_State_Definitions_Day",
      "components": {
        "Components": {
          "BlackoutCycleState": {
            "OnState": "Day",
            "OffState": "Night"
          }
        }
      },
      "rotation": 2
    },
    {
      "x": -4,
      "y": 46,
      "z": -3,
      "name": "BO_Pool_Surface00",
      "rotation": 2
    },
    {
      "x": -4,
      "y": 47,
      "z": -3,
      "name": "Empty"
    },
    {
      "x": -4,
      "y": 0,
      "z": -2,
      "name": "BO_Parking_Blacktop",
      "rotation": 4
    },
    {
      "x": -4,
      "y": 1,
      "z": -2,
      "name": "BO_Parking_Blacktop",
      "rotation": 4
    },
    {
      "x": -4,
      "y": 2,
      "z": -2,
      "name": "BO_Parking_Blacktop",
      "rotation": 4
    },
    {
      "x": -4,
      "y": 3,
      "z": -2,
      "name": "BO_Parking_Blacktop",
      "rotation": 4
    },
    {
      "x": -4,
      "y": 9,
      "z": -2,
      "name": "Prototype_Rock_Concrete_Brick_Half"
    },
    {
      "x": -4,
      "y": 10,
      "z": -2,
      "name": "Prototype_Rock_Concrete_Brick"
    },
    {
      "x": -4,
      "y": 11,
      "z": -2,
      "name": "Soil_Clay_Smooth_Black",
      "rotation": 4
    },
    {
      "x": -4,
      "y": 12,
      "z": -2,
      "name": "Soil_Clay_Smooth_Black",
      "rotation": 4
    },
    {
      "x": -4,
      "y": 13,
      "z": -2,
      "name": "Soil_Clay_Smooth_Black",
      "rotation": 4
    },
    {
      "x": -4,
      "y": 14,
      "z": -2,
      "name": "Soil_Clay_Smooth_Black",
      "rotation": 4
    },
    {
      "x": -4,
      "y": 15,
      "z": -2,
      "name": "Soil_Clay_Smooth_Black",
      "rotation": 4
    },
    {
      "x": -4,
      "y": 16,
      "z": -2,
      "name": "Soil_Clay_Smooth_Black",
      "rotation": 4
    },
    {
      "x": -4,
      "y": 17,
      "z": -2,
      "name": "Soil_Clay_Smooth_Black",
      "rotation": 4
    },
    {
      "x": -4,
      "y": 18,
      "z": -2,
      "name": "Prototype_Rock_Concrete_Brick"
    },
    {
      "x": -4,
      "y": 19,
      "z": -2,
      "name": "Soil_Clay_Smooth_Yellow"
    },
    {
      "x": -4,
      "y": 20,
      "z": -2,
      "name": "Prototype_Rock_Concrete_Brick"
    },
    {
      "x": -4,
      "y": 21,
      "z": -2,
      "name": "Prototype_Rock_Concrete_Brick"
    },
    {
      "x": -4,
      "y": 22,
      "z": -2,
      "name": "BO_Floor00"
    },
    {
      "x": -4,
      "y": 23,
      "z": -2,
      "name": "BO_Wallpaper00",
      "rotation": 1
    },
    {
      "x": -4,
      "y": 24,
      "z": -2,
      "name": "BO_Wallpaper00",
      "rotation": 1
    },
    {
      "x": -4,
      "y": 25,
      "z": -2,
      "name": "BO_Wallpaper00",
      "rotation": 1
    },
    {
      "x": -4,
      "y": 26,
      "z": -2,
      "name": "BO_Wallpaper00",
      "rotation": 1
    },
    {
      "x": -4,
      "y": 27,
      "z": -2,
      "name": "BO_Wallpaper00",
      "rotation": 1
    },
    {
      "x": -4,
      "y": 28,
      "z": -2,
      "name": "BO_Ceiling00",
      "rotation": 10
    },
    {
      "x": -4,
      "y": 29,
      "z": -2,
      "name": "BO_Pool_Surface00"
    },
    {
      "x": -4,
      "y": 30,
      "z": -2,
      "name": "BO_Pool_Surface00"
    },
    {
      "x": -4,
      "y": 31,
      "z": -2,
      "name": "BO_Pool_Surface00"
    },
    {
      "x": -4,
      "y": 32,
      "z": -2,
      "name": "BO_Pool_Surface00"
    },
    {
      "x": -4,
      "y": 33,
      "z": -2,
      "name": "BO_Pool_Surface00",
      "rotation": 4
    },
    {
      "x": -4,
      "y": 41,
      "z": -2,
      "name": "BO_Pool_Surface00",
      "rotation": 4
    },
    {
      "x": -4,
      "y": 42,
      "z": -2,
      "name": "*BO_Lightsource_Cycle_State_Definitions_Day",
      "components": {
        "Components": {
          "BlackoutCycleState": {
            "OnState": "Day",
            "OffState": "Night"
          }
        }
      },
      "rotation": 2
    },
    {
      "x": -4,
      "y": 46,
      "z": -2,
      "name": "BO_Pool_Surface00",
      "rotation": 2
    },
    {
      "x": -4,
      "y": 47,
      "z": -2,
      "name": "Empty"
    },
    {
      "x": -4,
      "y": 0,
      "z": -1,
      "name": "BO_Parking_Blacktop",
      "rotation": 4
    },
    {
      "x": -4,
      "y": 1,
      "z": -1,
      "name": "BO_Parking_Blacktop",
      "rotation": 4
    },
    {
      "x": -4,
      "y": 2,
      "z": -1,
      "name": "BO_Parking_Blacktop",
      "rotation": 4
    },
    {
      "x": -4,
      "y": 3,
      "z": -1,
      "name": "BO_Parking_Blacktop",
      "rotation": 4
    },
    {
      "x": -4,
      "y": 9,
      "z": -1,
      "name": "Prototype_Rock_Concrete_Brick_Half"
    },
    {
      "x": -4,
      "y": 10,
      "z": -1,
      "name": "Prototype_Rock_Concrete_Brick"
    },
    {
      "x": -4,
      "y": 11,
      "z": -1,
      "name": "Soil_Clay_Smooth_Black",
      "rotation": 4
    },
    {
      "x": -4,
      "y": 12,
      "z": -1,
      "name": "Soil_Clay_Smooth_Black",
      "rotation": 4
    },
    {
      "x": -4,
      "y": 13,
      "z": -1,
      "name": "Soil_Clay_Smooth_Black",
      "rotation": 4
    },
    {
      "x": -4,
      "y": 14,
      "z": -1,
      "name": "Soil_Clay_Smooth_Black",
      "rotation": 4
    },
    {
      "x": -4,
      "y": 15,
      "z": -1,
      "name": "Soil_Clay_Smooth_Black",
      "rotation": 4
    },
    {
      "x": -4,
      "y": 16,
      "z": -1,
      "name": "Soil_Clay_Smooth_Black",
      "rotation": 4
    },
    {
      "x": -4,
      "y": 17,
      "z": -1,
      "name": "Soil_Clay_Smooth_Black",
      "rotation": 4
    },
    {
      "x": -4,
      "y": 18,
      "z": -1,
      "name": "Prototype_Rock_Concrete_Brick"
    },
    {
      "x": -4,
      "y": 19,
      "z": -1,
      "name": "Soil_Clay_Smooth_Yellow"
    },
    {
      "x": -4,
      "y": 20,
      "z": -1,
      "name": "Prototype_Rock_Concrete_Brick"
    },
    {
      "x": -4,
      "y": 21,
      "z": -1,
      "name": "Prototype_Rock_Concrete_Brick"
    },
    {
      "x": -4,
      "y": 22,
      "z": -1,
      "name": "BO_Floor00"
    },
    {
      "x": -4,
      "y": 23,
      "z": -1,
      "name": "BO_Wallpaper00"
    },
    {
      "x": -4,
      "y": 24,
      "z": -1,
      "name": "BO_Wallpaper00"
    },
    {
      "x": -4,
      "y": 25,
      "z": -1,
      "name": "BO_Wallpaper00"
    },
    {
      "x": -4,
      "y": 26,
      "z": -1,
      "name": "BO_Wallpaper00"
    },
    {
      "x": -4,
      "y": 27,
      "z": -1,
      "name": "BO_Wallpaper00"
    },
    {
      "x": -4,
      "y": 28,
      "z": -1,
      "name": "BO_Ceiling00",
      "rotation": 10
    },
    {
      "x": -4,
      "y": 29,
      "z": -1,
      "name": "BO_Pool_Surface00"
    },
    {
      "x": -4,
      "y": 30,
      "z": -1,
      "name": "BO_Pool_Surface00"
    },
    {
      "x": -4,
      "y": 31,
      "z": -1,
      "name": "BO_Pool_Surface00"
    },
    {
      "x": -4,
      "y": 32,
      "z": -1,
      "name": "BO_Pool_Surface00"
    },
    {
      "x": -4,
      "y": 33,
      "z": -1,
      "name": "BO_Pool_Surface00",
      "rotation": 4
    },
    {
      "x": -4,
      "y": 41,
      "z": -1,
      "name": "BO_Pool_Surface00",
      "rotation": 4
    },
    {
      "x": -4,
      "y": 42,
      "z": -1,
      "name": "*BO_Lightsource_Cycle_State_Definitions_Day",
      "components": {
        "Components": {
          "BlackoutCycleState": {
            "OnState": "Day",
            "OffState": "Night"
          }
        }
      },
      "rotation": 2
    },
    {
      "x": -4,
      "y": 46,
      "z": -1,
      "name": "BO_Pool_Surface00",
      "rotation": 2
    },
    {
      "x": -4,
      "y": 47,
      "z": -1,
      "name": "Empty"
    },
    {
      "x": -4,
      "y": 0,
      "z": 0,
      "name": "BO_Parking_Blacktop",
      "rotation": 4
    },
    {
      "x": -4,
      "y": 1,
      "z": 0,
      "name": "BO_Parking_Blacktop",
      "rotation": 4
    },
    {
      "x": -4,
      "y": 2,
      "z": 0,
      "name": "BO_Parking_Blacktop",
      "rotation": 4
    },
    {
      "x": -4,
      "y": 3,
      "z": 0,
      "name": "BO_Parking_Blacktop",
      "rotation": 4
    },
    {
      "x": -4,
      "y": 9,
      "z": 0,
      "name": "Prototype_Rock_Concrete_Brick_Half"
    },
    {
      "x": -4,
      "y": 10,
      "z": 0,
      "name": "Prototype_Rock_Concrete_Brick"
    },
    {
      "x": -4,
      "y": 11,
      "z": 0,
      "name": "Soil_Clay_Smooth_Black",
      "rotation": 4
    },
    {
      "x": -4,
      "y": 12,
      "z": 0,
      "name": "Soil_Clay_Smooth_Black",
      "rotation": 4
    },
    {
      "x": -4,
      "y": 13,
      "z": 0,
      "name": "Soil_Clay_Smooth_Black",
      "rotation": 4
    },
    {
      "x": -4,
      "y": 14,
      "z": 0,
      "name": "Soil_Clay_Smooth_Black",
      "rotation": 4
    },
    {
      "x": -4,
      "y": 15,
      "z": 0,
      "name": "Soil_Clay_Smooth_Black",
      "rotation": 4
    },
    {
      "x": -4,
      "y": 16,
      "z": 0,
      "name": "Soil_Clay_Smooth_Black",
      "rotation": 4
    },
    {
      "x": -4,
      "y": 17,
      "z": 0,
      "name": "Soil_Clay_Smooth_Black",
      "rotation": 4
    },
    {
      "x": -4,
      "y": 18,
      "z": 0,
      "name": "Prototype_Rock_Concrete_Brick"
    },
    {
      "x": -4,
      "y": 19,
      "z": 0,
      "name": "Prototype_Rock_Concrete_Brick"
    },
    {
      "x": -4,
      "y": 20,
      "z": 0,
      "name": "Prototype_Rock_Concrete_Brick"
    },
    {
      "x": -4,
      "y": 21,
      "z": 0,
      "name": "Prototype_Rock_Concrete_Brick"
    },
    {
      "x": -4,
      "y": 22,
      "z": 0,
      "name": "BO_Floor00"
    },
    {
      "x": -4,
      "y": 23,
      "z": 0,
      "name": "BO_Wallpaper00"
    },
    {
      "x": -4,
      "y": 24,
      "z": 0,
      "name": "BO_Wallpaper00"
    },
    {
      "x": -4,
      "y": 25,
      "z": 0,
      "name": "BO_Wallpaper00"
    },
    {
      "x": -4,
      "y": 26,
      "z": 0,
      "name": "BO_Wallpaper00"
    },
    {
      "x": -4,
      "y": 27,
      "z": 0,
      "name": "BO_Wallpaper00"
    },
    {
      "x": -4,
      "y": 28,
      "z": 0,
      "name": "BO_Ceiling00",
      "rotation": 10
    },
    {
      "x": -4,
      "y": 29,
      "z": 0,
      "name": "BO_Pool_Surface00"
    },
    {
      "x": -4,
      "y": 30,
      "z": 0,
      "name": "BO_Pool_Surface00"
    },
    {
      "x": -4,
      "y": 31,
      "z": 0,
      "name": "BO_Pool_Surface00"
    },
    {
      "x": -4,
      "y": 32,
      "z": 0,
      "name": "BO_Pool_Surface00"
    },
    {
      "x": -4,
      "y": 33,
      "z": 0,
      "name": "BO_Pool_Surface00",
      "rotation": 4
    },
    {
      "x": -4,
      "y": 41,
      "z": 0,
      "name": "BO_Pool_Surface00",
      "rotation": 4
    },
    {
      "x": -4,
      "y": 42,
      "z": 0,
      "name": "*BO_Lightsource_Cycle_State_Definitions_Day",
      "components": {
        "Components": {
          "BlackoutCycleState": {
            "OnState": "Day",
            "OffState": "Night"
          }
        }
      },
      "rotation": 2
    },
    {
      "x": -4,
      "y": 46,
      "z": 0,
      "name": "BO_Pool_Surface00",
      "rotation": 2
    },
    {
      "x": -4,
      "y": 47,
      "z": 0,
      "name": "Empty"
    },
    {
      "x": -4,
      "y": 0,
      "z": 1,
      "name": "BO_Parking_Blacktop",
      "rotation": 4
    },
    {
      "x": -4,
      "y": 1,
      "z": 1,
      "name": "BO_Parking_Blacktop",
      "rotation": 4
    },
    {
      "x": -4,
      "y": 2,
      "z": 1,
      "name": "BO_Parking_Blacktop",
      "rotation": 4
    },
    {
      "x": -4,
      "y": 3,
      "z": 1,
      "name": "BO_Parking_Blacktop",
      "rotation": 4
    },
    {
      "x": -4,
      "y": 9,
      "z": 1,
      "name": "Prototype_Rock_Concrete_Brick_Half"
    },
    {
      "x": -4,
      "y": 10,
      "z": 1,
      "name": "Prototype_Rock_Concrete_Brick"
    },
    {
      "x": -4,
      "y": 11,
      "z": 1,
      "name": "Soil_Clay_Smooth_Black",
      "rotation": 4
    },
    {
      "x": -4,
      "y": 12,
      "z": 1,
      "name": "Soil_Clay_Smooth_Black",
      "rotation": 4
    },
    {
      "x": -4,
      "y": 13,
      "z": 1,
      "name": "Soil_Clay_Smooth_Black",
      "rotation": 4
    },
    {
      "x": -4,
      "y": 14,
      "z": 1,
      "name": "Soil_Clay_Smooth_Black",
      "rotation": 4
    },
    {
      "x": -4,
      "y": 15,
      "z": 1,
      "name": "Soil_Clay_Smooth_Black",
      "rotation": 4
    },
    {
      "x": -4,
      "y": 16,
      "z": 1,
      "name": "Soil_Clay_Smooth_Black",
      "rotation": 4
    },
    {
      "x": -4,
      "y": 17,
      "z": 1,
      "name": "Soil_Clay_Smooth_Black",
      "rotation": 4
    },
    {
      "x": -4,
      "y": 18,
      "z": 1,
      "name": "Prototype_Rock_Concrete_Brick"
    },
    {
      "x": -4,
      "y": 19,
      "z": 1,
      "name": "Prototype_Rock_Concrete_Brick"
    },
    {
      "x": -4,
      "y": 20,
      "z": 1,
      "name": "Prototype_Rock_Concrete_Brick"
    },
    {
      "x": -4,
      "y": 21,
      "z": 1,
      "name": "Prototype_Rock_Concrete_Brick"
    },
    {
      "x": -4,
      "y": 22,
      "z": 1,
      "name": "BO_Floor00"
    },
    {
      "x": -4,
      "y": 23,
      "z": 1,
      "name": "BO_Wallpaper00"
    },
    {
      "x": -4,
      "y": 24,
      "z": 1,
      "name": "BO_Wallpaper00"
    },
    {
      "x": -4,
      "y": 25,
      "z": 1,
      "name": "BO_Wallpaper00"
    },
    {
      "x": -4,
      "y": 26,
      "z": 1,
      "name": "BO_Wallpaper00"
    },
    {
      "x": -4,
      "y": 27,
      "z": 1,
      "name": "BO_Wallpaper00"
    },
    {
      "x": -4,
      "y": 28,
      "z": 1,
      "name": "BO_Ceiling00",
      "rotation": 10
    },
    {
      "x": -4,
      "y": 29,
      "z": 1,
      "name": "BO_Pool_Surface00"
    },
    {
      "x": -4,
      "y": 30,
      "z": 1,
      "name": "BO_Pool_Surface00"
    },
    {
      "x": -4,
      "y": 31,
      "z": 1,
      "name": "BO_Pool_Surface00"
    },
    {
      "x": -4,
      "y": 32,
      "z": 1,
      "name": "BO_Pool_Surface00"
    },
    {
      "x": -4,
      "y": 33,
      "z": 1,
      "name": "BO_Pool_Surface00",
      "rotation": 4
    },
    {
      "x": -4,
      "y": 41,
      "z": 1,
      "name": "BO_Pool_Surface00",
      "rotation": 4
    },
    {
      "x": -4,
      "y": 42,
      "z": 1,
      "name": "*BO_Lightsource_Cycle_State_Definitions_Day",
      "components": {
        "Components": {
          "BlackoutCycleState": {
            "OnState": "Day",
            "OffState": "Night"
          }
        }
      },
      "rotation": 2
    },
    {
      "x": -4,
      "y": 46,
      "z": 1,
      "name": "BO_Pool_Surface00",
      "rotation": 2
    },
    {
      "x": -4,
      "y": 47,
      "z": 1,
      "name": "Empty"
    },
    {
      "x": -4,
      "y": 0,
      "z": 2,
      "name": "BO_Parking_Blacktop",
      "rotation": 4
    },
    {
      "x": -4,
      "y": 1,
      "z": 2,
      "name": "BO_Parking_Blacktop",
      "rotation": 4
    },
    {
      "x": -4,
      "y": 2,
      "z": 2,
      "name": "BO_Parking_Blacktop",
      "rotation": 4
    },
    {
      "x": -4,
      "y": 3,
      "z": 2,
      "name": "BO_Parking_Blacktop",
      "rotation": 4
    },
    {
      "x": -4,
      "y": 9,
      "z": 2,
      "name": "Prototype_Rock_Concrete_Brick_Half"
    },
    {
      "x": -4,
      "y": 10,
      "z": 2,
      "name": "Prototype_Rock_Concrete_Brick"
    },
    {
      "x": -4,
      "y": 11,
      "z": 2,
      "name": "Soil_Clay_Smooth_Black",
      "rotation": 4
    },
    {
      "x": -4,
      "y": 12,
      "z": 2,
      "name": "Soil_Clay_Smooth_Black",
      "rotation": 4
    },
    {
      "x": -4,
      "y": 13,
      "z": 2,
      "name": "Soil_Clay_Smooth_Black",
      "rotation": 4
    },
    {
      "x": -4,
      "y": 14,
      "z": 2,
      "name": "Soil_Clay_Smooth_Black",
      "rotation": 4
    },
    {
      "x": -4,
      "y": 15,
      "z": 2,
      "name": "Soil_Clay_Smooth_Black",
      "rotation": 4
    },
    {
      "x": -4,
      "y": 16,
      "z": 2,
      "name": "Soil_Clay_Smooth_Black",
      "rotation": 4
    },
    {
      "x": -4,
      "y": 17,
      "z": 2,
      "name": "Soil_Clay_Smooth_Black",
      "rotation": 4
    },
    {
      "x": -4,
      "y": 18,
      "z": 2,
      "name": "Prototype_Rock_Concrete_Brick"
    },
    {
      "x": -4,
      "y": 19,
      "z": 2,
      "name": "Soil_Clay_Smooth_Yellow"
    },
    {
      "x": -4,
      "y": 20,
      "z": 2,
      "name": "Prototype_Rock_Concrete_Brick"
    },
    {
      "x": -4,
      "y": 21,
      "z": 2,
      "name": "Prototype_Rock_Concrete_Brick"
    },
    {
      "x": -4,
      "y": 22,
      "z": 2,
      "name": "Prototype_Rock_Concrete_Brick"
    },
    {
      "x": -4,
      "y": 23,
      "z": 2,
      "name": "BO_Wallpaper00"
    },
    {
      "x": -4,
      "y": 24,
      "z": 2,
      "name": "BO_Wallpaper00"
    },
    {
      "x": -4,
      "y": 25,
      "z": 2,
      "name": "BO_Wallpaper00"
    },
    {
      "x": -4,
      "y": 26,
      "z": 2,
      "name": "BO_Wallpaper00"
    },
    {
      "x": -4,
      "y": 27,
      "z": 2,
      "name": "BO_Wallpaper00"
    },
    {
      "x": -4,
      "y": 28,
      "z": 2,
      "name": "BO_Ceiling00",
      "rotation": 10
    },
    {
      "x": -4,
      "y": 29,
      "z": 2,
      "name": "BO_Pool_Surface00"
    },
    {
      "x": -4,
      "y": 30,
      "z": 2,
      "name": "BO_Pool_Surface00"
    },
    {
      "x": -4,
      "y": 31,
      "z": 2,
      "name": "BO_Pool_Surface00"
    },
    {
      "x": -4,
      "y": 32,
      "z": 2,
      "name": "BO_Pool_Surface00"
    },
    {
      "x": -4,
      "y": 33,
      "z": 2,
      "name": "BO_Pool_Surface00",
      "rotation": 4
    },
    {
      "x": -4,
      "y": 41,
      "z": 2,
      "name": "BO_Pool_Surface00",
      "rotation": 4
    },
    {
      "x": -4,
      "y": 42,
      "z": 2,
      "name": "*BO_Lightsource_Cycle_State_Definitions_Day",
      "components": {
        "Components": {
          "BlackoutCycleState": {
            "OnState": "Day",
            "OffState": "Night"
          }
        }
      },
      "rotation": 2
    },
    {
      "x": -4,
      "y": 46,
      "z": 2,
      "name": "BO_Pool_Surface00",
      "rotation": 2
    },
    {
      "x": -4,
      "y": 47,
      "z": 2,
      "name": "Empty"
    },
    {
      "x": -4,
      "y": 0,
      "z": 3,
      "name": "BO_Parking_Blacktop",
      "rotation": 4
    },
    {
      "x": -4,
      "y": 1,
      "z": 3,
      "name": "BO_Parking_Blacktop",
      "rotation": 4
    },
    {
      "x": -4,
      "y": 2,
      "z": 3,
      "name": "BO_Parking_Blacktop",
      "rotation": 4
    },
    {
      "x": -4,
      "y": 3,
      "z": 3,
      "name": "BO_Parking_Blacktop",
      "rotation": 4
    },
    {
      "x": -4,
      "y": 9,
      "z": 3,
      "name": "Prototype_Rock_Concrete_Brick_Half",
      "support": 15
    },
    {
      "x": -4,
      "y": 10,
      "z": 3,
      "name": "Prototype_Rock_Concrete_Brick",
      "support": 15
    },
    {
      "x": -4,
      "y": 11,
      "z": 3,
      "name": "Soil_Clay_Smooth_Black",
      "rotation": 4
    },
    {
      "x": -4,
      "y": 12,
      "z": 3,
      "name": "Soil_Clay_Smooth_Black",
      "rotation": 4
    },
    {
      "x": -4,
      "y": 13,
      "z": 3,
      "name": "Soil_Clay_Smooth_Black",
      "rotation": 4
    },
    {
      "x": -4,
      "y": 14,
      "z": 3,
      "name": "Soil_Clay_Smooth_Black",
      "rotation": 4
    },
    {
      "x": -4,
      "y": 15,
      "z": 3,
      "name": "Soil_Clay_Smooth_Black",
      "rotation": 4
    },
    {
      "x": -4,
      "y": 16,
      "z": 3,
      "name": "Soil_Clay_Smooth_Black",
      "rotation": 4
    },
    {
      "x": -4,
      "y": 17,
      "z": 3,
      "name": "Soil_Clay_Smooth_Black",
      "rotation": 4
    },
    {
      "x": -4,
      "y": 18,
      "z": 3,
      "name": "Prototype_Rock_Concrete_Brick"
    },
    {
      "x": -4,
      "y": 19,
      "z": 3,
      "name": "Soil_Clay_Smooth_Yellow"
    },
    {
      "x": -4,
      "y": 20,
      "z": 3,
      "name": "Prototype_Rock_Concrete_Brick"
    },
    {
      "x": -4,
      "y": 21,
      "z": 3,
      "name": "Prototype_Rock_Concrete_Brick"
    },
    {
      "x": -4,
      "y": 22,
      "z": 3,
      "name": "BO_Wallpaper00"
    },
    {
      "x": -4,
      "y": 23,
      "z": 3,
      "name": "BO_Wallpaper00"
    },
    {
      "x": -4,
      "y": 24,
      "z": 3,
      "name": "BO_Wallpaper00"
    },
    {
      "x": -4,
      "y": 25,
      "z": 3,
      "name": "BO_Wallpaper00"
    },
    {
      "x": -4,
      "y": 26,
      "z": 3,
      "name": "BO_Wallpaper00"
    },
    {
      "x": -4,
      "y": 27,
      "z": 3,
      "name": "BO_Wallpaper00"
    },
    {
      "x": -4,
      "y": 28,
      "z": 3,
      "name": "BO_Ceiling00",
      "rotation": 10
    },
    {
      "x": -4,
      "y": 29,
      "z": 3,
      "name": "BO_Pool_Surface00"
    },
    {
      "x": -4,
      "y": 30,
      "z": 3,
      "name": "BO_Pool_Surface00"
    },
    {
      "x": -4,
      "y": 31,
      "z": 3,
      "name": "BO_Pool_Surface00"
    },
    {
      "x": -4,
      "y": 32,
      "z": 3,
      "name": "BO_Pool_Surface00"
    },
    {
      "x": -4,
      "y": 33,
      "z": 3,
      "name": "BO_Pool_Surface00",
      "rotation": 4
    },
    {
      "x": -4,
      "y": 41,
      "z": 3,
      "name": "BO_Pool_Surface00",
      "rotation": 4
    },
    {
      "x": -4,
      "y": 42,
      "z": 3,
      "name": "*BO_Lightsource_Cycle_State_Definitions_Day",
      "components": {
        "Components": {
          "BlackoutCycleState": {
            "OnState": "Day",
            "OffState": "Night"
          }
        }
      },
      "rotation": 2
    },
    {
      "x": -4,
      "y": 46,
      "z": 3,
      "name": "BO_Pool_Surface00",
      "rotation": 2
    },
    {
      "x": -4,
      "y": 47,
      "z": 3,
      "name": "Empty"
    },
    {
      "x": -4,
      "y": 0,
      "z": 4,
      "name": "BO_Parking_Blacktop",
      "rotation": 4
    },
    {
      "x": -4,
      "y": 1,
      "z": 4,
      "name": "BO_Parking_Blacktop",
      "rotation": 4
    },
    {
      "x": -4,
      "y": 2,
      "z": 4,
      "name": "BO_Parking_Blacktop",
      "rotation": 4
    },
    {
      "x": -4,
      "y": 3,
      "z": 4,
      "name": "BO_Parking_Blacktop",
      "rotation": 4
    },
    {
      "x": -4,
      "y": 9,
      "z": 4,
      "name": "Prototype_Rock_Concrete_Brick_Half",
      "support": 15
    },
    {
      "x": -4,
      "y": 10,
      "z": 4,
      "name": "Prototype_Rock_Concrete_Brick",
      "support": 15
    },
    {
      "x": -4,
      "y": 11,
      "z": 4,
      "name": "Soil_Clay_Smooth_Black",
      "rotation": 4
    },
    {
      "x": -4,
      "y": 12,
      "z": 4,
      "name": "Soil_Clay_Smooth_Black",
      "rotation": 4
    },
    {
      "x": -4,
      "y": 13,
      "z": 4,
      "name": "Soil_Clay_Smooth_Black",
      "rotation": 4
    },
    {
      "x": -4,
      "y": 14,
      "z": 4,
      "name": "Soil_Clay_Smooth_Black",
      "rotation": 4
    },
    {
      "x": -4,
      "y": 15,
      "z": 4,
      "name": "Soil_Clay_Smooth_Black",
      "rotation": 4
    },
    {
      "x": -4,
      "y": 16,
      "z": 4,
      "name": "Soil_Clay_Smooth_Black",
      "rotation": 4
    },
    {
      "x": -4,
      "y": 17,
      "z": 4,
      "name": "Soil_Clay_Smooth_Black",
      "rotation": 4
    },
    {
      "x": -4,
      "y": 18,
      "z": 4,
      "name": "Prototype_Rock_Concrete_Brick"
    },
    {
      "x": -4,
      "y": 19,
      "z": 4,
      "name": "Soil_Clay_Smooth_Yellow"
    },
    {
      "x": -4,
      "y": 20,
      "z": 4,
      "name": "Prototype_Rock_Concrete_Brick"
    },
    {
      "x": -4,
      "y": 21,
      "z": 4,
      "name": "Prototype_Rock_Concrete_Brick"
    },
    {
      "x": -4,
      "y": 22,
      "z": 4,
      "name": "BO_Wallpaper00"
    },
    {
      "x": -4,
      "y": 23,
      "z": 4,
      "name": "BO_Wallpaper00"
    },
    {
      "x": -4,
      "y": 24,
      "z": 4,
      "name": "BO_Wallpaper00"
    },
    {
      "x": -4,
      "y": 25,
      "z": 4,
      "name": "BO_Wallpaper00"
    },
    {
      "x": -4,
      "y": 26,
      "z": 4,
      "name": "BO_Wallpaper00"
    },
    {
      "x": -4,
      "y": 27,
      "z": 4,
      "name": "BO_Wallpaper00"
    },
    {
      "x": -4,
      "y": 28,
      "z": 4,
      "name": "BO_Ceiling00",
      "rotation": 10
    },
    {
      "x": -4,
      "y": 29,
      "z": 4,
      "name": "BO_Pool_Surface00"
    },
    {
      "x": -4,
      "y": 30,
      "z": 4,
      "name": "BO_Pool_Surface00"
    },
    {
      "x": -4,
      "y": 31,
      "z": 4,
      "name": "BO_Pool_Surface00"
    },
    {
      "x": -4,
      "y": 32,
      "z": 4,
      "name": "BO_Pool_Surface00"
    },
    {
      "x": -4,
      "y": 33,
      "z": 4,
      "name": "BO_Pool_Surface00",
      "rotation": 4
    },
    {
      "x": -4,
      "y": 34,
      "z": 4,
      "name": "BO_Pool_Surface00",
      "rotation": 4
    },
    {
      "x": -4,
      "y": 35,
      "z": 4,
      "name": "BO_Pool_Surface00",
      "rotation": 4
    },
    {
      "x": -4,
      "y": 36,
      "z": 4,
      "name": "BO_Pool_Surface00",
      "rotation": 4
    },
    {
      "x": -4,
      "y": 37,
      "z": 4,
      "name": "BO_Pool_Surface00",
      "rotation": 4
    },
    {
      "x": -4,
      "y": 38,
      "z": 4,
      "name": "BO_Pool_Surface00",
      "rotation": 4
    },
    {
      "x": -4,
      "y": 39,
      "z": 4,
      "name": "BO_Pool_Surface00",
      "rotation": 4
    },
    {
      "x": -4,
      "y": 40,
      "z": 4,
      "name": "BO_Pool_Surface00",
      "rotation": 4
    },
    {
      "x": -4,
      "y": 41,
      "z": 4,
      "name": "BO_Pool_Surface00",
      "rotation": 4
    },
    {
      "x": -4,
      "y": 42,
      "z": 4,
      "name": "*BO_Lightsource_Cycle_State_Definitions_Day",
      "components": {
        "Components": {
          "BlackoutCycleState": {
            "OnState": "Day",
            "OffState": "Night"
          }
        }
      },
      "rotation": 2
    },
    {
      "x": -4,
      "y": 46,
      "z": 4,
      "name": "BO_Pool_Surface00",
      "rotation": 2
    },
    {
      "x": -4,
      "y": 47,
      "z": 4,
      "name": "Empty"
    },
    {
      "x": -4,
      "y": 0,
      "z": 5,
      "name": "BO_Parking_Blacktop",
      "rotation": 4
    },
    {
      "x": -4,
      "y": 1,
      "z": 5,
      "name": "BO_Parking_Blacktop",
      "rotation": 4
    },
    {
      "x": -4,
      "y": 2,
      "z": 5,
      "name": "BO_Parking_Blacktop",
      "rotation": 4
    },
    {
      "x": -4,
      "y": 3,
      "z": 5,
      "name": "BO_Parking_Blacktop",
      "support": 15,
      "rotation": 3
    },
    {
      "x": -4,
      "y": 4,
      "z": 5,
      "name": "BO_Parking_Wall00",
      "support": 15
    },
    {
      "x": -4,
      "y": 5,
      "z": 5,
      "name": "BO_Parking_Wall02"
    },
    {
      "x": -4,
      "y": 6,
      "z": 5,
      "name": "BO_Parking_Wall00",
      "support": 15
    },
    {
      "x": -4,
      "y": 7,
      "z": 5,
      "name": "BO_Parking_Wall00",
      "support": 15
    },
    {
      "x": -4,
      "y": 8,
      "z": 5,
      "name": "BO_Parking_Wall00",
      "support": 15
    },
    {
      "x": -4,
      "y": 9,
      "z": 5,
      "name": "BO_Parking_Wall00",
      "support": 15
    },
    {
      "x": -4,
      "y": 10,
      "z": 5,
      "name": "Prototype_Rock_Concrete_Brick"
    },
    {
      "x": -4,
      "y": 11,
      "z": 5,
      "name": "Soil_Clay_Smooth_Black",
      "rotation": 4
    },
    {
      "x": -4,
      "y": 12,
      "z": 5,
      "name": "Soil_Clay_Smooth_Black",
      "rotation": 4
    },
    {
      "x": -4,
      "y": 13,
      "z": 5,
      "name": "Soil_Clay_Smooth_Black",
      "rotation": 4
    },
    {
      "x": -4,
      "y": 14,
      "z": 5,
      "name": "Soil_Clay_Smooth_Black",
      "rotation": 4
    },
    {
      "x": -4,
      "y": 15,
      "z": 5,
      "name": "Soil_Clay_Smooth_Black",
      "rotation": 4
    },
    {
      "x": -4,
      "y": 16,
      "z": 5,
      "name": "Soil_Clay_Smooth_Black",
      "rotation": 4
    },
    {
      "x": -4,
      "y": 17,
      "z": 5,
      "name": "Soil_Clay_Smooth_Black",
      "rotation": 4
    },
    {
      "x": -4,
      "y": 18,
      "z": 5,
      "name": "Prototype_Rock_Concrete_Brick",
      "rotation": 3
    },
    {
      "x": -4,
      "y": 19,
      "z": 5,
      "name": "Soil_Clay_Smooth_Yellow",
      "rotation": 3
    },
    {
      "x": -4,
      "y": 20,
      "z": 5,
      "name": "Prototype_Rock_Concrete_Brick",
      "rotation": 3
    },
    {
      "x": -4,
      "y": 21,
      "z": 5,
      "name": "Prototype_Rock_Concrete_Brick",
      "rotation": 3
    },
    {
      "x": -4,
      "y": 22,
      "z": 5,
      "name": "BO_Floor00"
    },
    {
      "x": -4,
      "y": 23,
      "z": 5,
      "name": "BO_Wallpaper00"
    },
    {
      "x": -4,
      "y": 24,
      "z": 5,
      "name": "BO_Wallpaper00"
    },
    {
      "x": -4,
      "y": 25,
      "z": 5,
      "name": "BO_Wallpaper00"
    },
    {
      "x": -4,
      "y": 26,
      "z": 5,
      "name": "BO_Wallpaper00"
    },
    {
      "x": -4,
      "y": 27,
      "z": 5,
      "name": "BO_Wallpaper00"
    },
    {
      "x": -4,
      "y": 28,
      "z": 5,
      "name": "BO_Ceiling00",
      "rotation": 10
    },
    {
      "x": -4,
      "y": 29,
      "z": 5,
      "name": "BO_Pool_Surface00"
    },
    {
      "x": -4,
      "y": 30,
      "z": 5,
      "name": "BO_Pool_Surface00"
    },
    {
      "x": -4,
      "y": 31,
      "z": 5,
      "name": "BO_Pool_Surface00"
    },
    {
      "x": -4,
      "y": 32,
      "z": 5,
      "name": "BO_Pool_Surface00"
    },
    {
      "x": -4,
      "y": 33,
      "z": 5,
      "name": "BO_Pool_Surface00",
      "rotation": 4
    },
    {
      "x": -4,
      "y": 34,
      "z": 5,
      "name": "BO_Pool_Surface00",
      "rotation": 4
    },
    {
      "x": -4,
      "y": 35,
      "z": 5,
      "name": "BO_Pool_Surface00",
      "rotation": 4
    },
    {
      "x": -4,
      "y": 36,
      "z": 5,
      "name": "BO_Pool_Surface00",
      "rotation": 4
    },
    {
      "x": -4,
      "y": 37,
      "z": 5,
      "name": "BO_Pool_Surface00",
      "rotation": 4
    },
    {
      "x": -4,
      "y": 38,
      "z": 5,
      "name": "BO_Pool_Surface00",
      "rotation": 4
    },
    {
      "x": -4,
      "y": 39,
      "z": 5,
      "name": "BO_Pool_Surface00",
      "rotation": 4
    },
    {
      "x": -4,
      "y": 40,
      "z": 5,
      "name": "BO_Pool_Surface00",
      "rotation": 4
    },
    {
      "x": -4,
      "y": 41,
      "z": 5,
      "name": "BO_Pool_Surface00",
      "rotation": 4
    },
    {
      "x": -4,
      "y": 42,
      "z": 5,
      "name": "*BO_Lightsource_Cycle_State_Definitions_Day",
      "components": {
        "Components": {
          "BlackoutCycleState": {
            "OnState": "Day",
            "OffState": "Night"
          }
        }
      },
      "rotation": 2
    },
    {
      "x": -4,
      "y": 46,
      "z": 5,
      "name": "BO_Pool_Surface00",
      "rotation": 2
    },
    {
      "x": -4,
      "y": 47,
      "z": 5,
      "name": "Empty"
    },
    {
      "x": -3,
      "y": 0,
      "z": -4,
      "name": "BO_Parking_Blacktop",
      "rotation": 4
    },
    {
      "x": -3,
      "y": 1,
      "z": -4,
      "name": "BO_Parking_Blacktop",
      "rotation": 4
    },
    {
      "x": -3,
      "y": 2,
      "z": -4,
      "name": "BO_Parking_Blacktop",
      "rotation": 4
    },
    {
      "x": -3,
      "y": 3,
      "z": -4,
      "name": "BO_Parking_Blacktop",
      "rotation": 4
    },
    {
      "x": -3,
      "y": 9,
      "z": -4,
      "name": "Prototype_Rock_Concrete_Brick_Half"
    },
    {
      "x": -3,
      "y": 10,
      "z": -4,
      "name": "Prototype_Rock_Concrete_Brick"
    },
    {
      "x": -3,
      "y": 11,
      "z": -4,
      "name": "Soil_Clay_Smooth_Black",
      "rotation": 4
    },
    {
      "x": -3,
      "y": 12,
      "z": -4,
      "name": "Soil_Clay_Smooth_Black",
      "rotation": 4
    },
    {
      "x": -3,
      "y": 13,
      "z": -4,
      "name": "Soil_Clay_Smooth_Black",
      "rotation": 4
    },
    {
      "x": -3,
      "y": 14,
      "z": -4,
      "name": "Soil_Clay_Smooth_Black",
      "rotation": 4
    },
    {
      "x": -3,
      "y": 15,
      "z": -4,
      "name": "Soil_Clay_Smooth_Black",
      "rotation": 4
    },
    {
      "x": -3,
      "y": 16,
      "z": -4,
      "name": "Soil_Clay_Smooth_Black",
      "rotation": 4
    },
    {
      "x": -3,
      "y": 17,
      "z": -4,
      "name": "Soil_Clay_Smooth_Black",
      "rotation": 4
    },
    {
      "x": -3,
      "y": 18,
      "z": -4,
      "name": "Prototype_Rock_Concrete_Brick",
      "rotation": 3
    },
    {
      "x": -3,
      "y": 19,
      "z": -4,
      "name": "Soil_Clay_Smooth_Yellow",
      "rotation": 3
    },
    {
      "x": -3,
      "y": 20,
      "z": -4,
      "name": "Prototype_Rock_Concrete_Brick",
      "rotation": 3
    },
    {
      "x": -3,
      "y": 21,
      "z": -4,
      "name": "Prototype_Rock_Concrete_Brick",
      "rotation": 3
    },
    {
      "x": -3,
      "y": 22,
      "z": -4,
      "name": "BO_Floor00"
    },
    {
      "x": -3,
      "y": 23,
      "z": -4,
      "name": "Empty"
    },
    {
      "x": -3,
      "y": 24,
      "z": -4,
      "name": "Empty"
    },
    {
      "x": -3,
      "y": 25,
      "z": -4,
      "name": "Empty"
    },
    {
      "x": -3,
      "y": 26,
      "z": -4,
      "name": "Empty"
    },
    {
      "x": -3,
      "y": 27,
      "z": -4,
      "name": "Empty"
    },
    {
      "x": -3,
      "y": 28,
      "z": -4,
      "name": "BO_Wallpaper00",
      "rotation": 2
    },
    {
      "x": -3,
      "y": 29,
      "z": -4,
      "name": "BO_Pool_Surface00",
      "rotation": 4
    },
    {
      "x": -3,
      "y": 30,
      "z": -4,
      "name": "BO_Pool_Surface00",
      "rotation": 4
    },
    {
      "x": -3,
      "y": 31,
      "z": -4,
      "name": "BO_Pool_Surface00",
      "rotation": 4
    },
    {
      "x": -3,
      "y": 32,
      "z": -4,
      "name": "BO_Pool_Surface00",
      "rotation": 4
    },
    {
      "x": -3,
      "y": 33,
      "z": -4,
      "name": "BO_Pool_Surface00",
      "rotation": 4
    },
    {
      "x": -3,
      "y": 34,
      "z": -4,
      "name": "BO_Pool_Surface00",
      "rotation": 4
    },
    {
      "x": -3,
      "y": 35,
      "z": -4,
      "name": "BO_Pool_Surface00",
      "rotation": 4
    },
    {
      "x": -3,
      "y": 36,
      "z": -4,
      "name": "BO_Pool_Surface00",
      "rotation": 4
    },
    {
      "x": -3,
      "y": 37,
      "z": -4,
      "name": "BO_Pool_Surface00",
      "rotation": 4
    },
    {
      "x": -3,
      "y": 38,
      "z": -4,
      "name": "BO_Pool_Surface00",
      "rotation": 4
    },
    {
      "x": -3,
      "y": 39,
      "z": -4,
      "name": "BO_Pool_Surface00",
      "rotation": 4
    },
    {
      "x": -3,
      "y": 40,
      "z": -4,
      "name": "BO_Pool_Surface00",
      "rotation": 4
    },
    {
      "x": -3,
      "y": 41,
      "z": -4,
      "name": "BO_Pool_Surface00",
      "rotation": 4
    },
    {
      "x": -3,
      "y": 42,
      "z": -4,
      "name": "*BO_Lightsource_Cycle_State_Definitions_Day",
      "components": {
        "Components": {
          "BlackoutCycleState": {
            "OnState": "Day",
            "OffState": "Night"
          }
        }
      },
      "rotation": 2
    },
    {
      "x": -3,
      "y": 46,
      "z": -4,
      "name": "BO_Pool_Surface00",
      "rotation": 2
    },
    {
      "x": -3,
      "y": 47,
      "z": -4,
      "name": "Build_Black_Cube",
      "rotation": 2
    },
    {
      "x": -3,
      "y": 0,
      "z": -3,
      "name": "BO_Parking_Blacktop",
      "rotation": 4
    },
    {
      "x": -3,
      "y": 1,
      "z": -3,
      "name": "BO_Parking_Blacktop",
      "rotation": 4
    },
    {
      "x": -3,
      "y": 2,
      "z": -3,
      "name": "BO_Parking_Blacktop",
      "rotation": 4
    },
    {
      "x": -3,
      "y": 3,
      "z": -3,
      "name": "BO_Parking_Blacktop",
      "rotation": 4
    },
    {
      "x": -3,
      "y": 9,
      "z": -3,
      "name": "Prototype_Rock_Concrete_Brick_Half",
      "rotation": 8
    },
    {
      "x": -3,
      "y": 10,
      "z": -3,
      "name": "Prototype_Rock_Concrete_Brick"
    },
    {
      "x": -3,
      "y": 11,
      "z": -3,
      "name": "BO_Pool_Surface00"
    },
    {
      "x": -3,
      "y": 12,
      "z": -3,
      "name": "BO_Pool_Surface00"
    },
    {
      "x": -3,
      "y": 13,
      "z": -3,
      "name": "BO_Pool_Surface00"
    },
    {
      "x": -3,
      "y": 14,
      "z": -3,
      "name": "BO_Pool_Surface00"
    },
    {
      "x": -3,
      "y": 15,
      "z": -3,
      "name": "BO_Pool_Surface00"
    },
    {
      "x": -3,
      "y": 16,
      "z": -3,
      "name": "BO_Pool_Surface00"
    },
    {
      "x": -3,
      "y": 17,
      "z": -3,
      "name": "BO_Pool_Surface00"
    },
    {
      "x": -3,
      "y": 18,
      "z": -3,
      "name": "BO_Pool_Surface00"
    },
    {
      "x": -3,
      "y": 19,
      "z": -3,
      "name": "BO_Pool_Surface00"
    },
    {
      "x": -3,
      "y": 20,
      "z": -3,
      "name": "BO_Pool_Surface00"
    },
    {
      "x": -3,
      "y": 21,
      "z": -3,
      "name": "BO_Pool_Surface00"
    },
    {
      "x": -3,
      "y": 22,
      "z": -3,
      "name": "BO_Floor00"
    },
    {
      "x": -3,
      "y": 23,
      "z": -3,
      "name": "Empty"
    },
    {
      "x": -3,
      "y": 24,
      "z": -3,
      "name": "Empty"
    },
    {
      "x": -3,
      "y": 25,
      "z": -3,
      "name": "Empty"
    },
    {
      "x": -3,
      "y": 26,
      "z": -3,
      "name": "Empty"
    },
    {
      "x": -3,
      "y": 27,
      "z": -3,
      "name": "Empty"
    },
    {
      "x": -3,
      "y": 28,
      "z": -3,
      "name": "BO_Ceiling00",
      "rotation": 10
    },
    {
      "x": -3,
      "y": 29,
      "z": -3,
      "name": "BO_Pool_Surface00",
      "rotation": 4
    },
    {
      "x": -3,
      "y": 30,
      "z": -3,
      "name": "BO_Pool_Surface00",
      "rotation": 4
    },
    {
      "x": -3,
      "y": 31,
      "z": -3,
      "name": "BO_Pool_Surface00",
      "rotation": 4
    },
    {
      "x": -3,
      "y": 32,
      "z": -3,
      "name": "BO_Pool_Surface00",
      "rotation": 4
    },
    {
      "x": -3,
      "y": 33,
      "z": -3,
      "name": "BO_Pool_Surface00",
      "rotation": 4
    },
    {
      "x": -3,
      "y": 34,
      "z": -3,
      "name": "BO_Pool_Surface00",
      "rotation": 4
    },
    {
      "x": -3,
      "y": 35,
      "z": -3,
      "name": "BO_Pool_Surface00",
      "rotation": 4
    },
    {
      "x": -3,
      "y": 36,
      "z": -3,
      "name": "BO_Pool_Surface00",
      "rotation": 4
    },
    {
      "x": -3,
      "y": 37,
      "z": -3,
      "name": "BO_Pool_Surface00",
      "rotation": 4
    },
    {
      "x": -3,
      "y": 38,
      "z": -3,
      "name": "BO_Pool_Surface00",
      "rotation": 4
    },
    {
      "x": -3,
      "y": 39,
      "z": -3,
      "name": "BO_Pool_Surface00",
      "rotation": 4
    },
    {
      "x": -3,
      "y": 40,
      "z": -3,
      "name": "BO_Pool_Surface00",
      "rotation": 4
    },
    {
      "x": -3,
      "y": 41,
      "z": -3,
      "name": "BO_Pool_Surface00",
      "rotation": 4
    },
    {
      "x": -3,
      "y": 42,
      "z": -3,
      "name": "*BO_Lightsource_Cycle_State_Definitions_Day",
      "components": {
        "Components": {
          "BlackoutCycleState": {
            "OnState": "Day",
            "OffState": "Night"
          }
        }
      },
      "rotation": 2
    },
    {
      "x": -3,
      "y": 46,
      "z": -3,
      "name": "BO_Pool_Surface00",
      "rotation": 2
    },
    {
      "x": -3,
      "y": 47,
      "z": -3,
      "name": "Build_Black_Cube",
      "rotation": 2
    },
    {
      "x": -3,
      "y": 0,
      "z": -2,
      "name": "BO_Parking_Blacktop",
      "rotation": 4
    },
    {
      "x": -3,
      "y": 1,
      "z": -2,
      "name": "BO_Parking_Blacktop",
      "rotation": 4
    },
    {
      "x": -3,
      "y": 2,
      "z": -2,
      "name": "BO_Parking_Blacktop",
      "rotation": 4
    },
    {
      "x": -3,
      "y": 3,
      "z": -2,
      "name": "BO_Parking_Blacktop",
      "rotation": 4
    },
    {
      "x": -3,
      "y": 9,
      "z": -2,
      "name": "Prototype_Rock_Concrete_Brick_Half",
      "rotation": 8
    },
    {
      "x": -3,
      "y": 10,
      "z": -2,
      "name": "Prototype_Rock_Concrete_Brick"
    },
    {
      "x": -3,
      "y": 11,
      "z": -2,
      "name": "BO_Pool_Surface00"
    },
    {
      "x": -3,
      "y": 12,
      "z": -2,
      "name": "BO_Pool_Surface00"
    },
    {
      "x": -3,
      "y": 13,
      "z": -2,
      "name": "BO_Pool_Surface00"
    },
    {
      "x": -3,
      "y": 14,
      "z": -2,
      "name": "BO_Pool_Surface00"
    },
    {
      "x": -3,
      "y": 15,
      "z": -2,
      "name": "BO_Pool_Surface00"
    },
    {
      "x": -3,
      "y": 16,
      "z": -2,
      "name": "BO_Pool_Surface00"
    },
    {
      "x": -3,
      "y": 17,
      "z": -2,
      "name": "BO_Pool_Surface00"
    },
    {
      "x": -3,
      "y": 18,
      "z": -2,
      "name": "BO_Pool_Surface00"
    },
    {
      "x": -3,
      "y": 19,
      "z": -2,
      "name": "BO_Pool_Surface00"
    },
    {
      "x": -3,
      "y": 20,
      "z": -2,
      "name": "BO_Pool_Surface00"
    },
    {
      "x": -3,
      "y": 21,
      "z": -2,
      "name": "BO_Pool_Surface00"
    },
    {
      "x": -3,
      "y": 22,
      "z": -2,
      "name": "BO_Floor00"
    },
    {
      "x": -3,
      "y": 23,
      "z": -2,
      "name": "Empty"
    },
    {
      "x": -3,
      "y": 24,
      "z": -2,
      "name": "Empty"
    },
    {
      "x": -3,
      "y": 25,
      "z": -2,
      "name": "Empty"
    },
    {
      "x": -3,
      "y": 26,
      "z": -2,
      "name": "Empty"
    },
    {
      "x": -3,
      "y": 27,
      "z": -2,
      "name": "Empty"
    },
    {
      "x": -3,
      "y": 28,
      "z": -2,
      "name": "BO_Ceiling00",
      "rotation": 10
    },
    {
      "x": -3,
      "y": 29,
      "z": -2,
      "name": "BO_Pool_Surface00"
    },
    {
      "x": -3,
      "y": 30,
      "z": -2,
      "name": "BO_Pool_Surface00"
    },
    {
      "x": -3,
      "y": 31,
      "z": -2,
      "name": "BO_Pool_Surface00"
    },
    {
      "x": -3,
      "y": 32,
      "z": -2,
      "name": "BO_Pool_Surface00"
    },
    {
      "x": -3,
      "y": 33,
      "z": -2,
      "name": "BO_Pool_Surface00",
      "rotation": 4
    },
    {
      "x": -3,
      "y": 34,
      "z": -2,
      "name": "Empty"
    },
    {
      "x": -3,
      "y": 35,
      "z": -2,
      "name": "Empty"
    },
    {
      "x": -3,
      "y": 36,
      "z": -2,
      "name": "Empty"
    },
    {
      "x": -3,
      "y": 37,
      "z": -2,
      "name": "Empty"
    },
    {
      "x": -3,
      "y": 39,
      "z": -2,
      "name": "Empty"
    },
    {
      "x": -3,
      "y": 40,
      "z": -2,
      "name": "Empty"
    },
    {
      "x": -3,
      "y": 41,
      "z": -2,
      "name": "BO_Pool_Surface00",
      "rotation": 4
    },
    {
      "x": -3,
      "y": 42,
      "z": -2,
      "name": "*BO_Lightsource_Cycle_State_Definitions_Day",
      "components": {
        "Components": {
          "BlackoutCycleState": {
            "OnState": "Day",
            "OffState": "Night"
          }
        }
      },
      "rotation": 2
    },
    {
      "x": -3,
      "y": 46,
      "z": -2,
      "name": "BO_Pool_Surface00",
      "rotation": 2
    },
    {
      "x": -3,
      "y": 47,
      "z": -2,
      "name": "Build_Black_Cube",
      "rotation": 2
    },
    {
      "x": -3,
      "y": 0,
      "z": -1,
      "name": "BO_Parking_Blacktop",
      "rotation": 4
    },
    {
      "x": -3,
      "y": 1,
      "z": -1,
      "name": "BO_Parking_Blacktop",
      "rotation": 4
    },
    {
      "x": -3,
      "y": 2,
      "z": -1,
      "name": "BO_Parking_Blacktop",
      "rotation": 4
    },
    {
      "x": -3,
      "y": 3,
      "z": -1,
      "name": "BO_Parking_Blacktop",
      "rotation": 4
    },
    {
      "x": -3,
      "y": 9,
      "z": -1,
      "name": "Prototype_Rock_Concrete_Brick_Half",
      "rotation": 8
    },
    {
      "x": -3,
      "y": 10,
      "z": -1,
      "name": "Prototype_Rock_Concrete_Brick"
    },
    {
      "x": -3,
      "y": 11,
      "z": -1,
      "name": "BO_Pool_Surface00"
    },
    {
      "x": -3,
      "y": 12,
      "z": -1,
      "name": "BO_Pool_Surface00"
    },
    {
      "x": -3,
      "y": 13,
      "z": -1,
      "name": "BO_Pool_Surface00"
    },
    {
      "x": -3,
      "y": 14,
      "z": -1,
      "name": "BO_Pool_Surface00"
    },
    {
      "x": -3,
      "y": 15,
      "z": -1,
      "name": "BO_Pool_Surface00"
    },
    {
      "x": -3,
      "y": 16,
      "z": -1,
      "name": "BO_Pool_Surface00"
    },
    {
      "x": -3,
      "y": 17,
      "z": -1,
      "name": "BO_Pool_Surface00"
    },
    {
      "x": -3,
      "y": 18,
      "z": -1,
      "name": "BO_Pool_Surface00"
    },
    {
      "x": -3,
      "y": 19,
      "z": -1,
      "name": "BO_Pool_Surface00"
    },
    {
      "x": -3,
      "y": 20,
      "z": -1,
      "name": "BO_Pool_Surface00"
    },
    {
      "x": -3,
      "y": 21,
      "z": -1,
      "name": "BO_Pool_Surface00"
    },
    {
      "x": -3,
      "y": 22,
      "z": -1,
      "name": "BO_Floor00"
    },
    {
      "x": -3,
      "y": 23,
      "z": -1,
      "name": "BO_Wallpaper00",
      "rotation": 2
    },
    {
      "x": -3,
      "y": 24,
      "z": -1,
      "name": "BO_Wallpaper00",
      "rotation": 2
    },
    {
      "x": -3,
      "y": 25,
      "z": -1,
      "name": "BO_Wallpaper00",
      "rotation": 2
    },
    {
      "x": -3,
      "y": 26,
      "z": -1,
      "name": "BO_Wallpaper00",
      "rotation": 2
    },
    {
      "x": -3,
      "y": 27,
      "z": -1,
      "name": "BO_Wallpaper00",
      "rotation": 2
    },
    {
      "x": -3,
      "y": 28,
      "z": -1,
      "name": "BO_Ceiling00",
      "rotation": 10
    },
    {
      "x": -3,
      "y": 29,
      "z": -1,
      "name": "BO_Pool_Surface00"
    },
    {
      "x": -3,
      "y": 30,
      "z": -1,
      "name": "BO_Pool_Surface00"
    },
    {
      "x": -3,
      "y": 31,
      "z": -1,
      "name": "BO_Pool_Surface00"
    },
    {
      "x": -3,
      "y": 32,
      "z": -1,
      "name": "BO_Pool_Surface00"
    },
    {
      "x": -3,
      "y": 33,
      "z": -1,
      "name": "BO_Pool_Surface00",
      "rotation": 4
    },
    {
      "x": -3,
      "y": 34,
      "z": -1,
      "name": "Empty"
    },
    {
      "x": -3,
      "y": 36,
      "z": -1,
      "name": "Empty"
    },
    {
      "x": -3,
      "y": 37,
      "z": -1,
      "name": "Empty"
    },
    {
      "x": -3,
      "y": 38,
      "z": -1,
      "name": "Empty"
    },
    {
      "x": -3,
      "y": 39,
      "z": -1,
      "name": "Empty"
    },
    {
      "x": -3,
      "y": 40,
      "z": -1,
      "name": "Empty"
    },
    {
      "x": -3,
      "y": 41,
      "z": -1,
      "name": "BO_Pool_Surface00",
      "rotation": 4
    },
    {
      "x": -3,
      "y": 42,
      "z": -1,
      "name": "*BO_Lightsource_Cycle_State_Definitions_Day",
      "components": {
        "Components": {
          "BlackoutCycleState": {
            "OnState": "Day",
            "OffState": "Night"
          }
        }
      },
      "rotation": 2
    },
    {
      "x": -3,
      "y": 46,
      "z": -1,
      "name": "BO_Pool_Surface00",
      "rotation": 2
    },
    {
      "x": -3,
      "y": 47,
      "z": -1,
      "name": "Build_Black_Cube",
      "rotation": 2
    },
    {
      "x": -3,
      "y": 0,
      "z": 0,
      "name": "BO_Parking_Blacktop",
      "rotation": 4
    },
    {
      "x": -3,
      "y": 1,
      "z": 0,
      "name": "BO_Parking_Blacktop",
      "rotation": 4
    },
    {
      "x": -3,
      "y": 2,
      "z": 0,
      "name": "BO_Parking_Blacktop",
      "rotation": 4
    },
    {
      "x": -3,
      "y": 3,
      "z": 0,
      "name": "BO_Parking_Blacktop",
      "rotation": 4
    },
    {
      "x": -3,
      "y": 9,
      "z": 0,
      "name": "Prototype_Rock_Concrete_Brick_Half",
      "support": 15,
      "rotation": 8
    },
    {
      "x": -3,
      "y": 10,
      "z": 0,
      "name": "Prototype_Rock_Concrete_Brick"
    },
    {
      "x": -3,
      "y": 11,
      "z": 0,
      "name": "BO_Pool_Surface00"
    },
    {
      "x": -3,
      "y": 12,
      "z": 0,
      "name": "BO_Pool_Surface00"
    },
    {
      "x": -3,
      "y": 13,
      "z": 0,
      "name": "BO_Pool_Surface00"
    },
    {
      "x": -3,
      "y": 14,
      "z": 0,
      "name": "BO_Pool_Surface00"
    },
    {
      "x": -3,
      "y": 15,
      "z": 0,
      "name": "BO_Pool_Surface00"
    },
    {
      "x": -3,
      "y": 16,
      "z": 0,
      "name": "BO_Pool_Surface00"
    },
    {
      "x": -3,
      "y": 17,
      "z": 0,
      "name": "BO_Pool_Surface00"
    },
    {
      "x": -3,
      "y": 18,
      "z": 0,
      "name": "BO_Pool_Surface00"
    },
    {
      "x": -3,
      "y": 19,
      "z": 0,
      "name": "BO_Pool_Surface00"
    },
    {
      "x": -3,
      "y": 20,
      "z": 0,
      "name": "BO_Pool_Surface00"
    },
    {
      "x": -3,
      "y": 22,
      "z": 0,
      "name": "BO_Pool_Surface00"
    },
    {
      "x": -3,
      "y": 23,
      "z": 0,
      "name": "Empty"
    },
    {
      "x": -3,
      "y": 24,
      "z": 0,
      "name": "BO_Floor00"
    },
    {
      "x": -3,
      "y": 25,
      "z": 0,
      "name": "Empty"
    },
    {
      "x": -3,
      "y": 26,
      "z": 0,
      "name": "Empty"
    },
    {
      "x": -3,
      "y": 27,
      "z": 0,
      "name": "Empty"
    },
    {
      "x": -3,
      "y": 28,
      "z": 0,
      "name": "BO_Ceiling00",
      "rotation": 10
    },
    {
      "x": -3,
      "y": 29,
      "z": 0,
      "name": "BO_Pool_Surface00"
    },
    {
      "x": -3,
      "y": 30,
      "z": 0,
      "name": "BO_Pool_Surface00"
    },
    {
      "x": -3,
      "y": 31,
      "z": 0,
      "name": "BO_Pool_Surface00"
    },
    {
      "x": -3,
      "y": 32,
      "z": 0,
      "name": "BO_Pool_Surface00"
    },
    {
      "x": -3,
      "y": 33,
      "z": 0,
      "name": "BO_Pool_Surface00",
      "rotation": 4
    },
    {
      "x": -3,
      "y": 34,
      "z": 0,
      "name": "Empty"
    },
    {
      "x": -3,
      "y": 36,
      "z": 0,
      "name": "Empty"
    },
    {
      "x": -3,
      "y": 37,
      "z": 0,
      "name": "Empty"
    },
    {
      "x": -3,
      "y": 38,
      "z": 0,
      "name": "Empty"
    },
    {
      "x": -3,
      "y": 39,
      "z": 0,
      "name": "Empty"
    },
    {
      "x": -3,
      "y": 40,
      "z": 0,
      "name": "Empty"
    },
    {
      "x": -3,
      "y": 41,
      "z": 0,
      "name": "BO_Pool_Surface00",
      "rotation": 4
    },
    {
      "x": -3,
      "y": 42,
      "z": 0,
      "name": "*BO_Lightsource_Cycle_State_Definitions_Day",
      "components": {
        "Components": {
          "BlackoutCycleState": {
            "OnState": "Day",
            "OffState": "Night"
          }
        }
      },
      "rotation": 2
    },
    {
      "x": -3,
      "y": 46,
      "z": 0,
      "name": "BO_Pool_Surface00",
      "rotation": 2
    },
    {
      "x": -3,
      "y": 47,
      "z": 0,
      "name": "Build_Black_Cube",
      "rotation": 2
    },
    {
      "x": -3,
      "y": 0,
      "z": 1,
      "name": "BO_Parking_Blacktop",
      "rotation": 4
    },
    {
      "x": -3,
      "y": 1,
      "z": 1,
      "name": "BO_Parking_Blacktop",
      "rotation": 4
    },
    {
      "x": -3,
      "y": 2,
      "z": 1,
      "name": "BO_Parking_Blacktop",
      "rotation": 4
    },
    {
      "x": -3,
      "y": 3,
      "z": 1,
      "name": "BO_Parking_Blacktop",
      "rotation": 4
    },
    {
      "x": -3,
      "y": 9,
      "z": 1,
      "name": "Prototype_Rock_Concrete_Brick_Half",
      "support": 15,
      "rotation": 8
    },
    {
      "x": -3,
      "y": 10,
      "z": 1,
      "name": "Prototype_Rock_Concrete_Brick"
    },
    {
      "x": -3,
      "y": 11,
      "z": 1,
      "name": "BO_Pool_Surface00"
    },
    {
      "x": -3,
      "y": 12,
      "z": 1,
      "name": "BO_Pool_Surface00"
    },
    {
      "x": -3,
      "y": 13,
      "z": 1,
      "name": "BO_Pool_Surface00"
    },
    {
      "x": -3,
      "y": 14,
      "z": 1,
      "name": "BO_Pool_Surface00"
    },
    {
      "x": -3,
      "y": 15,
      "z": 1,
      "name": "BO_Pool_Surface00"
    },
    {
      "x": -3,
      "y": 16,
      "z": 1,
      "name": "BO_Pool_Surface00"
    },
    {
      "x": -3,
      "y": 17,
      "z": 1,
      "name": "BO_Pool_Surface00"
    },
    {
      "x": -3,
      "y": 18,
      "z": 1,
      "name": "BO_Pool_Surface00"
    },
    {
      "x": -3,
      "y": 19,
      "z": 1,
      "name": "BO_Pool_Surface00"
    },
    {
      "x": -3,
      "y": 20,
      "z": 1,
      "name": "BO_Pool_Surface00"
    },
    {
      "x": -3,
      "y": 22,
      "z": 1,
      "name": "BO_Pool_Surface00"
    },
    {
      "x": -3,
      "y": 23,
      "z": 1,
      "name": "Empty"
    },
    {
      "x": -3,
      "y": 24,
      "z": 1,
      "name": "BO_Floor00"
    },
    {
      "x": -3,
      "y": 25,
      "z": 1,
      "name": "Empty"
    },
    {
      "x": -3,
      "y": 26,
      "z": 1,
      "name": "Empty"
    },
    {
      "x": -3,
      "y": 27,
      "z": 1,
      "name": "Empty"
    },
    {
      "x": -3,
      "y": 28,
      "z": 1,
      "name": "BO_Ceiling00",
      "rotation": 10
    },
    {
      "x": -3,
      "y": 29,
      "z": 1,
      "name": "BO_Pool_Surface00"
    },
    {
      "x": -3,
      "y": 30,
      "z": 1,
      "name": "BO_Pool_Surface00"
    },
    {
      "x": -3,
      "y": 31,
      "z": 1,
      "name": "BO_Pool_Surface00"
    },
    {
      "x": -3,
      "y": 32,
      "z": 1,
      "name": "BO_Pool_Surface00"
    },
    {
      "x": -3,
      "y": 33,
      "z": 1,
      "name": "BO_Pool_Surface00",
      "rotation": 4
    },
    {
      "x": -3,
      "y": 34,
      "z": 1,
      "name": "Empty"
    },
    {
      "x": -3,
      "y": 35,
      "z": 1,
      "name": "Empty"
    },
    {
      "x": -3,
      "y": 36,
      "z": 1,
      "name": "Empty"
    },
    {
      "x": -3,
      "y": 37,
      "z": 1,
      "name": "Empty"
    },
    {
      "x": -3,
      "y": 38,
      "z": 1,
      "name": "Empty"
    },
    {
      "x": -3,
      "y": 39,
      "z": 1,
      "name": "Empty"
    },
    {
      "x": -3,
      "y": 40,
      "z": 1,
      "name": "Empty"
    },
    {
      "x": -3,
      "y": 41,
      "z": 1,
      "name": "BO_Pool_Surface00",
      "rotation": 4
    },
    {
      "x": -3,
      "y": 42,
      "z": 1,
      "name": "*BO_Lightsource_Cycle_State_Definitions_Day",
      "components": {
        "Components": {
          "BlackoutCycleState": {
            "OnState": "Day",
            "OffState": "Night"
          }
        }
      },
      "rotation": 2
    },
    {
      "x": -3,
      "y": 46,
      "z": 1,
      "name": "BO_Pool_Surface00",
      "rotation": 2
    },
    {
      "x": -3,
      "y": 47,
      "z": 1,
      "name": "Build_Black_Cube",
      "rotation": 2
    },
    {
      "x": -3,
      "y": 0,
      "z": 2,
      "name": "BO_Parking_Blacktop",
      "rotation": 4
    },
    {
      "x": -3,
      "y": 1,
      "z": 2,
      "name": "BO_Parking_Blacktop",
      "rotation": 4
    },
    {
      "x": -3,
      "y": 2,
      "z": 2,
      "name": "BO_Parking_Blacktop",
      "rotation": 4
    },
    {
      "x": -3,
      "y": 3,
      "z": 2,
      "name": "BO_Parking_Blacktop",
      "rotation": 4
    },
    {
      "x": -3,
      "y": 9,
      "z": 2,
      "name": "Prototype_Rock_Concrete_Brick_Half",
      "support": 15,
      "rotation": 8
    },
    {
      "x": -3,
      "y": 10,
      "z": 2,
      "name": "Prototype_Rock_Concrete_Brick",
      "support": 15
    },
    {
      "x": -3,
      "y": 11,
      "z": 2,
      "name": "BO_Pool_Surface00"
    },
    {
      "x": -3,
      "y": 12,
      "z": 2,
      "name": "BO_Pool_Surface00"
    },
    {
      "x": -3,
      "y": 13,
      "z": 2,
      "name": "BO_Pool_Surface00"
    },
    {
      "x": -3,
      "y": 14,
      "z": 2,
      "name": "BO_Pool_Surface00"
    },
    {
      "x": -3,
      "y": 15,
      "z": 2,
      "name": "BO_Pool_Surface00"
    },
    {
      "x": -3,
      "y": 16,
      "z": 2,
      "name": "BO_Pool_Surface00"
    },
    {
      "x": -3,
      "y": 17,
      "z": 2,
      "name": "BO_Pool_Surface00"
    },
    {
      "x": -3,
      "y": 18,
      "z": 2,
      "name": "BO_Pool_Surface00"
    },
    {
      "x": -3,
      "y": 19,
      "z": 2,
      "name": "BO_Pool_Surface00"
    },
    {
      "x": -3,
      "y": 20,
      "z": 2,
      "name": "BO_Pool_Surface00"
    },
    {
      "x": -3,
      "y": 22,
      "z": 2,
      "name": "BO_Pool_Surface00"
    },
    {
      "x": -3,
      "y": 23,
      "z": 2,
      "name": "BO_Pool_Surface00"
    },
    {
      "x": -3,
      "y": 24,
      "z": 2,
      "name": "BO_Floor00"
    },
    {
      "x": -3,
      "y": 25,
      "z": 2,
      "name": "Empty"
    },
    {
      "x": -3,
      "y": 26,
      "z": 2,
      "name": "Empty"
    },
    {
      "x": -3,
      "y": 27,
      "z": 2,
      "name": "Empty"
    },
    {
      "x": -3,
      "y": 28,
      "z": 2,
      "name": "BO_Ceiling00",
      "rotation": 10
    },
    {
      "x": -3,
      "y": 29,
      "z": 2,
      "name": "BO_Pool_Surface00"
    },
    {
      "x": -3,
      "y": 30,
      "z": 2,
      "name": "BO_Pool_Surface00"
    },
    {
      "x": -3,
      "y": 31,
      "z": 2,
      "name": "BO_Pool_Surface00"
    },
    {
      "x": -3,
      "y": 32,
      "z": 2,
      "name": "BO_Pool_Surface00"
    },
    {
      "x": -3,
      "y": 33,
      "z": 2,
      "name": "BO_Pool_Surface00",
      "rotation": 4
    },
    {
      "x": -3,
      "y": 34,
      "z": 2,
      "name": "Empty"
    },
    {
      "x": -3,
      "y": 35,
      "z": 2,
      "name": "Empty"
    },
    {
      "x": -3,
      "y": 36,
      "z": 2,
      "name": "Empty"
    },
    {
      "x": -3,
      "y": 37,
      "z": 2,
      "name": "Empty"
    },
    {
      "x": -3,
      "y": 38,
      "z": 2,
      "name": "Empty"
    },
    {
      "x": -3,
      "y": 39,
      "z": 2,
      "name": "Empty"
    },
    {
      "x": -3,
      "y": 40,
      "z": 2,
      "name": "Empty"
    },
    {
      "x": -3,
      "y": 41,
      "z": 2,
      "name": "BO_Pool_Surface00",
      "rotation": 4
    },
    {
      "x": -3,
      "y": 42,
      "z": 2,
      "name": "*BO_Lightsource_Cycle_State_Definitions_Day",
      "components": {
        "Components": {
          "BlackoutCycleState": {
            "OnState": "Day",
            "OffState": "Night"
          }
        }
      },
      "rotation": 2
    },
    {
      "x": -3,
      "y": 46,
      "z": 2,
      "name": "BO_Pool_Surface00",
      "rotation": 2
    },
    {
      "x": -3,
      "y": 47,
      "z": 2,
      "name": "Build_Black_Cube",
      "rotation": 2
    },
    {
      "x": -3,
      "y": 0,
      "z": 3,
      "name": "BO_Parking_Blacktop",
      "rotation": 4
    },
    {
      "x": -3,
      "y": 1,
      "z": 3,
      "name": "BO_Parking_Blacktop",
      "rotation": 4
    },
    {
      "x": -3,
      "y": 2,
      "z": 3,
      "name": "BO_Parking_Blacktop",
      "rotation": 4
    },
    {
      "x": -3,
      "y": 3,
      "z": 3,
      "name": "BO_Parking_Blacktop",
      "rotation": 4
    },
    {
      "x": -3,
      "y": 9,
      "z": 3,
      "name": "Prototype_Rock_Concrete_Brick_Half",
      "support": 15,
      "rotation": 8
    },
    {
      "x": -3,
      "y": 10,
      "z": 3,
      "name": "Prototype_Rock_Concrete_Brick",
      "support": 15
    },
    {
      "x": -3,
      "y": 11,
      "z": 3,
      "name": "BO_Pool_Surface00"
    },
    {
      "x": -3,
      "y": 12,
      "z": 3,
      "name": "BO_Pool_Surface00"
    },
    {
      "x": -3,
      "y": 13,
      "z": 3,
      "name": "BO_Pool_Surface00"
    },
    {
      "x": -3,
      "y": 14,
      "z": 3,
      "name": "BO_Pool_Surface00"
    },
    {
      "x": -3,
      "y": 15,
      "z": 3,
      "name": "BO_Pool_Surface00"
    },
    {
      "x": -3,
      "y": 16,
      "z": 3,
      "name": "BO_Pool_Surface00"
    },
    {
      "x": -3,
      "y": 17,
      "z": 3,
      "name": "BO_Pool_Surface00"
    },
    {
      "x": -3,
      "y": 18,
      "z": 3,
      "name": "BO_Pool_Surface00"
    },
    {
      "x": -3,
      "y": 19,
      "z": 3,
      "name": "BO_Pool_Surface00"
    },
    {
      "x": -3,
      "y": 20,
      "z": 3,
      "name": "BO_Pool_Surface00"
    },
    {
      "x": -3,
      "y": 22,
      "z": 3,
      "name": "BO_Pool_Surface00"
    },
    {
      "x": -3,
      "y": 23,
      "z": 3,
      "name": "BO_Pool_Surface00"
    },
    {
      "x": -3,
      "y": 24,
      "z": 3,
      "name": "BO_Floor00"
    },
    {
      "x": -3,
      "y": 25,
      "z": 3,
      "name": "Empty"
    },
    {
      "x": -3,
      "y": 26,
      "z": 3,
      "name": "Empty"
    },
    {
      "x": -3,
      "y": 27,
      "z": 3,
      "name": "Empty"
    },
    {
      "x": -3,
      "y": 28,
      "z": 3,
      "name": "BO_Ceiling00",
      "rotation": 10
    },
    {
      "x": -3,
      "y": 29,
      "z": 3,
      "name": "BO_Pool_Surface00"
    },
    {
      "x": -3,
      "y": 30,
      "z": 3,
      "name": "BO_Pool_Surface00"
    },
    {
      "x": -3,
      "y": 31,
      "z": 3,
      "name": "BO_Pool_Surface00"
    },
    {
      "x": -3,
      "y": 32,
      "z": 3,
      "name": "BO_Pool_Surface00"
    },
    {
      "x": -3,
      "y": 33,
      "z": 3,
      "name": "BO_Pool_Surface00",
      "rotation": 4
    },
    {
      "x": -3,
      "y": 34,
      "z": 3,
      "name": "Empty"
    },
    {
      "x": -3,
      "y": 35,
      "z": 3,
      "name": "Empty"
    },
    {
      "x": -3,
      "y": 36,
      "z": 3,
      "name": "Empty"
    },
    {
      "x": -3,
      "y": 37,
      "z": 3,
      "name": "Empty"
    },
    {
      "x": -3,
      "y": 38,
      "z": 3,
      "name": "Empty"
    },
    {
      "x": -3,
      "y": 39,
      "z": 3,
      "name": "Empty"
    },
    {
      "x": -3,
      "y": 40,
      "z": 3,
      "name": "Empty"
    },
    {
      "x": -3,
      "y": 41,
      "z": 3,
      "name": "BO_Pool_Surface00",
      "rotation": 4
    },
    {
      "x": -3,
      "y": 42,
      "z": 3,
      "name": "*BO_Lightsource_Cycle_State_Definitions_Day",
      "components": {
        "Components": {
          "BlackoutCycleState": {
            "OnState": "Day",
            "OffState": "Night"
          }
        }
      },
      "rotation": 2
    },
    {
      "x": -3,
      "y": 46,
      "z": 3,
      "name": "BO_Pool_Surface00",
      "rotation": 2
    },
    {
      "x": -3,
      "y": 47,
      "z": 3,
      "name": "Build_Black_Cube",
      "rotation": 2
    },
    {
      "x": -3,
      "y": 0,
      "z": 4,
      "name": "BO_Parking_Blacktop",
      "rotation": 4
    },
    {
      "x": -3,
      "y": 1,
      "z": 4,
      "name": "BO_Parking_Blacktop",
      "rotation": 4
    },
    {
      "x": -3,
      "y": 2,
      "z": 4,
      "name": "BO_Parking_Blacktop",
      "rotation": 4
    },
    {
      "x": -3,
      "y": 3,
      "z": 4,
      "name": "BO_Parking_Blacktop",
      "rotation": 4
    },
    {
      "x": -3,
      "y": 9,
      "z": 4,
      "name": "Build_Lightsource_White",
      "support": 15,
      "rotation": 5
    },
    {
      "x": -3,
      "y": 10,
      "z": 4,
      "name": "Prototype_Rock_Concrete_Brick",
      "support": 15
    },
    {
      "x": -3,
      "y": 11,
      "z": 4,
      "name": "BO_Pool_Surface00"
    },
    {
      "x": -3,
      "y": 12,
      "z": 4,
      "name": "BO_Pool_Surface00"
    },
    {
      "x": -3,
      "y": 13,
      "z": 4,
      "name": "BO_Pool_Surface00"
    },
    {
      "x": -3,
      "y": 14,
      "z": 4,
      "name": "BO_Pool_Surface00"
    },
    {
      "x": -3,
      "y": 15,
      "z": 4,
      "name": "BO_Pool_Surface00"
    },
    {
      "x": -3,
      "y": 16,
      "z": 4,
      "name": "BO_Pool_Surface00"
    },
    {
      "x": -3,
      "y": 17,
      "z": 4,
      "name": "BO_Pool_Surface00"
    },
    {
      "x": -3,
      "y": 18,
      "z": 4,
      "name": "BO_Pool_Surface00"
    },
    {
      "x": -3,
      "y": 19,
      "z": 4,
      "name": "BO_Pool_Surface00"
    },
    {
      "x": -3,
      "y": 20,
      "z": 4,
      "name": "BO_Pool_Surface00"
    },
    {
      "x": -3,
      "y": 21,
      "z": 4,
      "name": "BO_Pool_Surface00"
    },
    {
      "x": -3,
      "y": 22,
      "z": 4,
      "name": "BO_Pool_Surface00"
    },
    {
      "x": -3,
      "y": 23,
      "z": 4,
      "name": "BO_Pool_Surface00"
    },
    {
      "x": -3,
      "y": 24,
      "z": 4,
      "name": "BO_Floor00"
    },
    {
      "x": -3,
      "y": 25,
      "z": 4,
      "name": "BO_Wallpaper00",
      "rotation": 2
    },
    {
      "x": -3,
      "y": 26,
      "z": 4,
      "name": "BO_Wallpaper00",
      "rotation": 2
    },
    {
      "x": -3,
      "y": 27,
      "z": 4,
      "name": "BO_Wallpaper00",
      "rotation": 2
    },
    {
      "x": -3,
      "y": 28,
      "z": 4,
      "name": "BO_Ceiling00",
      "rotation": 10
    },
    {
      "x": -3,
      "y": 29,
      "z": 4,
      "name": "BO_Pool_Surface00"
    },
    {
      "x": -3,
      "y": 30,
      "z": 4,
      "name": "BO_Pool_Surface00"
    },
    {
      "x": -3,
      "y": 31,
      "z": 4,
      "name": "BO_Pool_Surface00"
    },
    {
      "x": -3,
      "y": 32,
      "z": 4,
      "name": "BO_Pool_Surface00"
    },
    {
      "x": -3,
      "y": 33,
      "z": 4,
      "name": "BO_Pool_Surface00",
      "rotation": 4
    },
    {
      "x": -3,
      "y": 34,
      "z": 4,
      "name": "BO_Pool_Surface00",
      "rotation": 4
    },
    {
      "x": -3,
      "y": 35,
      "z": 4,
      "name": "BO_Pool_Surface00",
      "rotation": 4
    },
    {
      "x": -3,
      "y": 36,
      "z": 4,
      "name": "BO_Pool_Surface00",
      "rotation": 4
    },
    {
      "x": -3,
      "y": 37,
      "z": 4,
      "name": "BO_Pool_Surface00",
      "rotation": 4
    },
    {
      "x": -3,
      "y": 38,
      "z": 4,
      "name": "BO_Pool_Surface00",
      "rotation": 4
    },
    {
      "x": -3,
      "y": 39,
      "z": 4,
      "name": "BO_Pool_Surface00",
      "rotation": 4
    },
    {
      "x": -3,
      "y": 40,
      "z": 4,
      "name": "BO_Pool_Surface00",
      "rotation": 4
    },
    {
      "x": -3,
      "y": 41,
      "z": 4,
      "name": "BO_Pool_Surface00",
      "rotation": 4
    },
    {
      "x": -3,
      "y": 42,
      "z": 4,
      "name": "*BO_Lightsource_Cycle_State_Definitions_Day",
      "components": {
        "Components": {
          "BlackoutCycleState": {
            "OnState": "Day",
            "OffState": "Night"
          }
        }
      },
      "rotation": 2
    },
    {
      "x": -3,
      "y": 46,
      "z": 4,
      "name": "BO_Pool_Surface00",
      "rotation": 2
    },
    {
      "x": -3,
      "y": 47,
      "z": 4,
      "name": "Build_Black_Cube",
      "rotation": 2
    },
    {
      "x": -3,
      "y": 0,
      "z": 5,
      "name": "BO_Parking_Blacktop",
      "rotation": 4
    },
    {
      "x": -3,
      "y": 1,
      "z": 5,
      "name": "BO_Parking_Blacktop",
      "rotation": 4
    },
    {
      "x": -3,
      "y": 2,
      "z": 5,
      "name": "BO_Parking_Blacktop",
      "rotation": 4
    },
    {
      "x": -3,
      "y": 3,
      "z": 5,
      "name": "BO_Parking_Blacktop",
      "rotation": 4
    },
    {
      "x": -3,
      "y": 9,
      "z": 5,
      "name": "Prototype_Rock_Concrete_Brick_Half"
    },
    {
      "x": -3,
      "y": 10,
      "z": 5,
      "name": "Prototype_Rock_Concrete_Brick"
    },
    {
      "x": -3,
      "y": 11,
      "z": 5,
      "name": "Soil_Clay_Smooth_Black",
      "rotation": 4
    },
    {
      "x": -3,
      "y": 12,
      "z": 5,
      "name": "Soil_Clay_Smooth_Black",
      "rotation": 4
    },
    {
      "x": -3,
      "y": 13,
      "z": 5,
      "name": "Soil_Clay_Smooth_Black",
      "rotation": 4
    },
    {
      "x": -3,
      "y": 14,
      "z": 5,
      "name": "Soil_Clay_Smooth_Black",
      "rotation": 4
    },
    {
      "x": -3,
      "y": 15,
      "z": 5,
      "name": "Soil_Clay_Smooth_Black",
      "rotation": 4
    },
    {
      "x": -3,
      "y": 16,
      "z": 5,
      "name": "Soil_Clay_Smooth_Black",
      "rotation": 4
    },
    {
      "x": -3,
      "y": 17,
      "z": 5,
      "name": "Soil_Clay_Smooth_Black",
      "rotation": 4
    },
    {
      "x": -3,
      "y": 18,
      "z": 5,
      "name": "Prototype_Rock_Concrete_Brick",
      "rotation": 3
    },
    {
      "x": -3,
      "y": 19,
      "z": 5,
      "name": "Soil_Clay_Smooth_Yellow",
      "rotation": 3
    },
    {
      "x": -3,
      "y": 20,
      "z": 5,
      "name": "Prototype_Rock_Concrete_Brick",
      "rotation": 3
    },
    {
      "x": -3,
      "y": 21,
      "z": 5,
      "name": "Prototype_Rock_Concrete_Brick",
      "rotation": 3
    },
    {
      "x": -3,
      "y": 22,
      "z": 5,
      "name": "BO_Floor00"
    },
    {
      "x": -3,
      "y": 23,
      "z": 5,
      "name": "BO_Wallpaper00"
    },
    {
      "x": -3,
      "y": 24,
      "z": 5,
      "name": "BO_Wallpaper00"
    },
    {
      "x": -3,
      "y": 25,
      "z": 5,
      "name": "BO_Wallpaper00"
    },
    {
      "x": -3,
      "y": 26,
      "z": 5,
      "name": "BO_Wallpaper00"
    },
    {
      "x": -3,
      "y": 27,
      "z": 5,
      "name": "BO_Wallpaper00"
    },
    {
      "x": -3,
      "y": 28,
      "z": 5,
      "name": "BO_Ceiling00",
      "rotation": 10
    },
    {
      "x": -3,
      "y": 29,
      "z": 5,
      "name": "BO_Pool_Surface00"
    },
    {
      "x": -3,
      "y": 30,
      "z": 5,
      "name": "BO_Pool_Surface00"
    },
    {
      "x": -3,
      "y": 31,
      "z": 5,
      "name": "BO_Pool_Surface00"
    },
    {
      "x": -3,
      "y": 32,
      "z": 5,
      "name": "BO_Pool_Surface00"
    },
    {
      "x": -3,
      "y": 33,
      "z": 5,
      "name": "BO_Pool_Surface00",
      "rotation": 4
    },
    {
      "x": -3,
      "y": 34,
      "z": 5,
      "name": "BO_Pool_Surface00",
      "rotation": 4
    },
    {
      "x": -3,
      "y": 35,
      "z": 5,
      "name": "BO_Pool_Surface00",
      "rotation": 4
    },
    {
      "x": -3,
      "y": 36,
      "z": 5,
      "name": "BO_Pool_Surface00",
      "rotation": 4
    },
    {
      "x": -3,
      "y": 37,
      "z": 5,
      "name": "BO_Pool_Surface00",
      "rotation": 4
    },
    {
      "x": -3,
      "y": 38,
      "z": 5,
      "name": "BO_Pool_Surface00",
      "rotation": 4
    },
    {
      "x": -3,
      "y": 39,
      "z": 5,
      "name": "BO_Pool_Surface00",
      "rotation": 4
    },
    {
      "x": -3,
      "y": 40,
      "z": 5,
      "name": "BO_Pool_Surface00",
      "rotation": 4
    },
    {
      "x": -3,
      "y": 41,
      "z": 5,
      "name": "BO_Pool_Surface00",
      "rotation": 4
    },
    {
      "x": -3,
      "y": 42,
      "z": 5,
      "name": "*BO_Lightsource_Cycle_State_Definitions_Day",
      "components": {
        "Components": {
          "BlackoutCycleState": {
            "OnState": "Day",
            "OffState": "Night"
          }
        }
      },
      "rotation": 2
    },
    {
      "x": -3,
      "y": 46,
      "z": 5,
      "name": "BO_Pool_Surface00",
      "rotation": 2
    },
    {
      "x": -3,
      "y": 47,
      "z": 5,
      "name": "Build_Black_Cube",
      "rotation": 2
    },
    {
      "x": -2,
      "y": 0,
      "z": -4,
      "name": "BO_Parking_Blacktop",
      "rotation": 4
    },
    {
      "x": -2,
      "y": 1,
      "z": -4,
      "name": "BO_Parking_Blacktop",
      "rotation": 4
    },
    {
      "x": -2,
      "y": 2,
      "z": -4,
      "name": "BO_Parking_Blacktop",
      "rotation": 4
    },
    {
      "x": -2,
      "y": 3,
      "z": -4,
      "name": "BO_Parking_Blacktop",
      "rotation": 4
    },
    {
      "x": -2,
      "y": 9,
      "z": -4,
      "name": "Prototype_Rock_Concrete_Brick_Half"
    },
    {
      "x": -2,
      "y": 10,
      "z": -4,
      "name": "Prototype_Rock_Concrete_Brick"
    },
    {
      "x": -2,
      "y": 11,
      "z": -4,
      "name": "Soil_Clay_Smooth_Black",
      "rotation": 4
    },
    {
      "x": -2,
      "y": 12,
      "z": -4,
      "name": "Soil_Clay_Smooth_Black",
      "rotation": 4
    },
    {
      "x": -2,
      "y": 13,
      "z": -4,
      "name": "Soil_Clay_Smooth_Black",
      "rotation": 4
    },
    {
      "x": -2,
      "y": 14,
      "z": -4,
      "name": "Soil_Clay_Smooth_Black",
      "rotation": 4
    },
    {
      "x": -2,
      "y": 15,
      "z": -4,
      "name": "Soil_Clay_Smooth_Black",
      "rotation": 4
    },
    {
      "x": -2,
      "y": 16,
      "z": -4,
      "name": "Soil_Clay_Smooth_Black",
      "rotation": 4
    },
    {
      "x": -2,
      "y": 17,
      "z": -4,
      "name": "Soil_Clay_Smooth_Black",
      "rotation": 4
    },
    {
      "x": -2,
      "y": 18,
      "z": -4,
      "name": "Prototype_Rock_Concrete_Brick",
      "rotation": 3
    },
    {
      "x": -2,
      "y": 19,
      "z": -4,
      "name": "Soil_Clay_Smooth_Yellow",
      "rotation": 3
    },
    {
      "x": -2,
      "y": 20,
      "z": -4,
      "name": "Prototype_Rock_Concrete_Brick",
      "rotation": 3
    },
    {
      "x": -2,
      "y": 21,
      "z": -4,
      "name": "Prototype_Rock_Concrete_Brick",
      "rotation": 3
    },
    {
      "x": -2,
      "y": 22,
      "z": -4,
      "name": "BO_Floor00"
    },
    {
      "x": -2,
      "y": 23,
      "z": -4,
      "name": "Empty"
    },
    {
      "x": -2,
      "y": 24,
      "z": -4,
      "name": "Empty"
    },
    {
      "x": -2,
      "y": 25,
      "z": -4,
      "name": "Empty"
    },
    {
      "x": -2,
      "y": 26,
      "z": -4,
      "name": "Empty"
    },
    {
      "x": -2,
      "y": 27,
      "z": -4,
      "name": "Empty"
    },
    {
      "x": -2,
      "y": 28,
      "z": -4,
      "name": "BO_Wallpaper00",
      "rotation": 2
    },
    {
      "x": -2,
      "y": 29,
      "z": -4,
      "name": "BO_Pool_Surface00",
      "rotation": 4
    },
    {
      "x": -2,
      "y": 30,
      "z": -4,
      "name": "BO_Pool_Surface00",
      "rotation": 4
    },
    {
      "x": -2,
      "y": 31,
      "z": -4,
      "name": "BO_Pool_Surface00",
      "rotation": 4
    },
    {
      "x": -2,
      "y": 32,
      "z": -4,
      "name": "BO_Pool_Surface00",
      "rotation": 4
    },
    {
      "x": -2,
      "y": 33,
      "z": -4,
      "name": "BO_Pool_Surface00",
      "rotation": 4
    },
    {
      "x": -2,
      "y": 41,
      "z": -4,
      "name": "BO_Pool_Surface00",
      "rotation": 4
    },
    {
      "x": -2,
      "y": 42,
      "z": -4,
      "name": "*BO_Lightsource_Cycle_State_Definitions_Day",
      "components": {
        "Components": {
          "BlackoutCycleState": {
            "OnState": "Day",
            "OffState": "Night"
          }
        }
      },
      "rotation": 2
    },
    {
      "x": -2,
      "y": 46,
      "z": -4,
      "name": "BO_Pool_Surface00",
      "rotation": 2
    },
    {
      "x": -2,
      "y": 47,
      "z": -4,
      "name": "Empty"
    },
    {
      "x": -2,
      "y": 0,
      "z": -3,
      "name": "BO_Parking_Blacktop",
      "rotation": 4
    },
    {
      "x": -2,
      "y": 1,
      "z": -3,
      "name": "BO_Parking_Blacktop",
      "rotation": 4
    },
    {
      "x": -2,
      "y": 2,
      "z": -3,
      "name": "BO_Parking_Blacktop",
      "rotation": 4
    },
    {
      "x": -2,
      "y": 3,
      "z": -3,
      "name": "BO_Parking_Blacktop",
      "rotation": 4
    },
    {
      "x": -2,
      "y": 9,
      "z": -3,
      "name": "Prototype_Rock_Concrete_Brick_Half",
      "rotation": 8
    },
    {
      "x": -2,
      "y": 10,
      "z": -3,
      "name": "Prototype_Rock_Concrete_Brick"
    },
    {
      "x": -2,
      "y": 11,
      "z": -3,
      "name": "BO_Pool_Surface00"
    },
    {
      "x": -2,
      "y": 12,
      "z": -3,
      "name": "BO_Pool_Surface00"
    },
    {
      "x": -2,
      "y": 13,
      "z": -3,
      "name": "BO_Pool_Surface00"
    },
    {
      "x": -2,
      "y": 14,
      "z": -3,
      "name": "BO_Pool_Surface00"
    },
    {
      "x": -2,
      "y": 15,
      "z": -3,
      "name": "BO_Pool_Surface00"
    },
    {
      "x": -2,
      "y": 16,
      "z": -3,
      "name": "BO_Pool_Surface00"
    },
    {
      "x": -2,
      "y": 17,
      "z": -3,
      "name": "BO_Pool_Surface00"
    },
    {
      "x": -2,
      "y": 18,
      "z": -3,
      "name": "BO_Pool_Surface00"
    },
    {
      "x": -2,
      "y": 19,
      "z": -3,
      "name": "BO_Pool_Surface00"
    },
    {
      "x": -2,
      "y": 20,
      "z": -3,
      "name": "BO_Pool_Surface00"
    },
    {
      "x": -2,
      "y": 21,
      "z": -3,
      "name": "BO_Pool_Surface00"
    },
    {
      "x": -2,
      "y": 22,
      "z": -3,
      "name": "BO_Floor00"
    },
    {
      "x": -2,
      "y": 23,
      "z": -3,
      "name": "Empty"
    },
    {
      "x": -2,
      "y": 24,
      "z": -3,
      "name": "Empty"
    },
    {
      "x": -2,
      "y": 25,
      "z": -3,
      "name": "Empty"
    },
    {
      "x": -2,
      "y": 26,
      "z": -3,
      "name": "Empty"
    },
    {
      "x": -2,
      "y": 27,
      "z": -3,
      "name": "Empty"
    },
    {
      "x": -2,
      "y": 28,
      "z": -3,
      "name": "BO_Ceiling00",
      "rotation": 10
    },
    {
      "x": -2,
      "y": 29,
      "z": -3,
      "name": "BO_Pool_Surface00",
      "rotation": 4
    },
    {
      "x": -2,
      "y": 30,
      "z": -3,
      "name": "BO_Pool_Surface00",
      "rotation": 4
    },
    {
      "x": -2,
      "y": 31,
      "z": -3,
      "name": "BO_Pool_Surface00",
      "rotation": 4
    },
    {
      "x": -2,
      "y": 32,
      "z": -3,
      "name": "BO_Pool_Surface00",
      "rotation": 4
    },
    {
      "x": -2,
      "y": 33,
      "z": -3,
      "name": "BO_Pool_Surface00",
      "rotation": 4
    },
    {
      "x": -2,
      "y": 34,
      "z": -3,
      "name": "Empty"
    },
    {
      "x": -2,
      "y": 35,
      "z": -3,
      "name": "Empty"
    },
    {
      "x": -2,
      "y": 36,
      "z": -3,
      "name": "Empty"
    },
    {
      "x": -2,
      "y": 37,
      "z": -3,
      "name": "Empty"
    },
    {
      "x": -2,
      "y": 38,
      "z": -3,
      "name": "Empty"
    },
    {
      "x": -2,
      "y": 39,
      "z": -3,
      "name": "Empty"
    },
    {
      "x": -2,
      "y": 40,
      "z": -3,
      "name": "Empty"
    },
    {
      "x": -2,
      "y": 41,
      "z": -3,
      "name": "BO_Pool_Surface00",
      "rotation": 4
    },
    {
      "x": -2,
      "y": 42,
      "z": -3,
      "name": "*BO_Lightsource_Cycle_State_Definitions_Day",
      "components": {
        "Components": {
          "BlackoutCycleState": {
            "OnState": "Day",
            "OffState": "Night"
          }
        }
      },
      "rotation": 2
    },
    {
      "x": -2,
      "y": 46,
      "z": -3,
      "name": "BO_Pool_Surface00",
      "rotation": 2
    },
    {
      "x": -2,
      "y": 47,
      "z": -3,
      "name": "Empty"
    },
    {
      "x": -2,
      "y": 0,
      "z": -2,
      "name": "BO_Parking_Blacktop",
      "rotation": 4
    },
    {
      "x": -2,
      "y": 1,
      "z": -2,
      "name": "BO_Parking_Blacktop",
      "rotation": 4
    },
    {
      "x": -2,
      "y": 2,
      "z": -2,
      "name": "BO_Parking_Blacktop",
      "rotation": 4
    },
    {
      "x": -2,
      "y": 3,
      "z": -2,
      "name": "BO_Parking_Blacktop",
      "rotation": 4
    },
    {
      "x": -2,
      "y": 9,
      "z": -2,
      "name": "Prototype_Rock_Concrete_Brick_Half",
      "rotation": 8
    },
    {
      "x": -2,
      "y": 10,
      "z": -2,
      "name": "Prototype_Rock_Concrete_Brick"
    },
    {
      "x": -2,
      "y": 11,
      "z": -2,
      "name": "BO_Pool_Surface00"
    },
    {
      "x": -2,
      "y": 12,
      "z": -2,
      "name": "BO_Pool_Surface00"
    },
    {
      "x": -2,
      "y": 13,
      "z": -2,
      "name": "BO_Pool_Surface00"
    },
    {
      "x": -2,
      "y": 14,
      "z": -2,
      "name": "BO_Pool_Surface00"
    },
    {
      "x": -2,
      "y": 15,
      "z": -2,
      "name": "BO_Pool_Surface00"
    },
    {
      "x": -2,
      "y": 16,
      "z": -2,
      "name": "BO_Pool_Surface00"
    },
    {
      "x": -2,
      "y": 17,
      "z": -2,
      "name": "BO_Pool_Surface00"
    },
    {
      "x": -2,
      "y": 18,
      "z": -2,
      "name": "BO_Pool_Surface00"
    },
    {
      "x": -2,
      "y": 19,
      "z": -2,
      "name": "BO_Pool_Surface00"
    },
    {
      "x": -2,
      "y": 20,
      "z": -2,
      "name": "BO_Pool_Surface00"
    },
    {
      "x": -2,
      "y": 21,
      "z": -2,
      "name": "BO_Pool_Surface00"
    },
    {
      "x": -2,
      "y": 22,
      "z": -2,
      "name": "BO_Floor00"
    },
    {
      "x": -2,
      "y": 23,
      "z": -2,
      "name": "Empty"
    },
    {
      "x": -2,
      "y": 24,
      "z": -2,
      "name": "Empty"
    },
    {
      "x": -2,
      "y": 25,
      "z": -2,
      "name": "Empty"
    },
    {
      "x": -2,
      "y": 26,
      "z": -2,
      "name": "Empty"
    },
    {
      "x": -2,
      "y": 27,
      "z": -2,
      "name": "Empty"
    },
    {
      "x": -2,
      "y": 28,
      "z": -2,
      "name": "BO_Ceiling00",
      "rotation": 10
    },
    {
      "x": -2,
      "y": 29,
      "z": -2,
      "name": "BO_Pool_Surface00"
    },
    {
      "x": -2,
      "y": 30,
      "z": -2,
      "name": "BO_Pool_Surface00"
    },
    {
      "x": -2,
      "y": 31,
      "z": -2,
      "name": "BO_Pool_Surface00"
    },
    {
      "x": -2,
      "y": 32,
      "z": -2,
      "name": "BO_Pool_Surface00"
    },
    {
      "x": -2,
      "y": 33,
      "z": -2,
      "name": "BO_Pool_Surface00",
      "rotation": 4
    },
    {
      "x": -2,
      "y": 34,
      "z": -2,
      "name": "Empty"
    },
    {
      "x": -2,
      "y": 35,
      "z": -2,
      "name": "Empty"
    },
    {
      "x": -2,
      "y": 36,
      "z": -2,
      "name": "Empty"
    },
    {
      "x": -2,
      "y": 37,
      "z": -2,
      "name": "Empty"
    },
    {
      "x": -2,
      "y": 38,
      "z": -2,
      "name": "Empty"
    },
    {
      "x": -2,
      "y": 39,
      "z": -2,
      "name": "Empty"
    },
    {
      "x": -2,
      "y": 40,
      "z": -2,
      "name": "Empty"
    },
    {
      "x": -2,
      "y": 41,
      "z": -2,
      "name": "BO_Pool_Surface00",
      "rotation": 4
    },
    {
      "x": -2,
      "y": 42,
      "z": -2,
      "name": "*BO_Lightsource_Cycle_State_Definitions_Day",
      "components": {
        "Components": {
          "BlackoutCycleState": {
            "OnState": "Day",
            "OffState": "Night"
          }
        }
      },
      "rotation": 2
    },
    {
      "x": -2,
      "y": 46,
      "z": -2,
      "name": "BO_Pool_Surface00",
      "rotation": 2
    },
    {
      "x": -2,
      "y": 47,
      "z": -2,
      "name": "Empty"
    },
    {
      "x": -2,
      "y": 0,
      "z": -1,
      "name": "BO_Parking_Blacktop",
      "rotation": 4
    },
    {
      "x": -2,
      "y": 1,
      "z": -1,
      "name": "BO_Parking_Blacktop",
      "rotation": 4
    },
    {
      "x": -2,
      "y": 2,
      "z": -1,
      "name": "BO_Parking_Blacktop",
      "rotation": 4
    },
    {
      "x": -2,
      "y": 3,
      "z": -1,
      "name": "BO_Parking_Blacktop",
      "rotation": 4
    },
    {
      "x": -2,
      "y": 9,
      "z": -1,
      "name": "Prototype_Rock_Concrete_Brick_Half",
      "rotation": 8
    },
    {
      "x": -2,
      "y": 10,
      "z": -1,
      "name": "Prototype_Rock_Concrete_Brick"
    },
    {
      "x": -2,
      "y": 11,
      "z": -1,
      "name": "BO_Pool_Surface00"
    },
    {
      "x": -2,
      "y": 12,
      "z": -1,
      "name": "BO_Pool_Surface00"
    },
    {
      "x": -2,
      "y": 13,
      "z": -1,
      "name": "BO_Pool_Surface00"
    },
    {
      "x": -2,
      "y": 14,
      "z": -1,
      "name": "BO_Pool_Surface00"
    },
    {
      "x": -2,
      "y": 15,
      "z": -1,
      "name": "BO_Pool_Surface00"
    },
    {
      "x": -2,
      "y": 16,
      "z": -1,
      "name": "BO_Pool_Surface00"
    },
    {
      "x": -2,
      "y": 17,
      "z": -1,
      "name": "BO_Pool_Surface00"
    },
    {
      "x": -2,
      "y": 18,
      "z": -1,
      "name": "BO_Pool_Surface00"
    },
    {
      "x": -2,
      "y": 19,
      "z": -1,
      "name": "BO_Pool_Surface00"
    },
    {
      "x": -2,
      "y": 20,
      "z": -1,
      "name": "BO_Pool_Surface00"
    },
    {
      "x": -2,
      "y": 21,
      "z": -1,
      "name": "BO_Pool_Surface00"
    },
    {
      "x": -2,
      "y": 22,
      "z": -1,
      "name": "BO_Pool_Surface00",
      "support": 15
    },
    {
      "x": -2,
      "y": 23,
      "z": -1,
      "name": "BO_Wallpaper00",
      "rotation": 2
    },
    {
      "x": -2,
      "y": 24,
      "z": -1,
      "name": "BO_Wallpaper00",
      "rotation": 2
    },
    {
      "x": -2,
      "y": 25,
      "z": -1,
      "name": "BO_Wallpaper00",
      "rotation": 2
    },
    {
      "x": -2,
      "y": 26,
      "z": -1,
      "name": "BO_Wallpaper00",
      "rotation": 2
    },
    {
      "x": -2,
      "y": 27,
      "z": -1,
      "name": "BO_Wallpaper00",
      "rotation": 2
    },
    {
      "x": -2,
      "y": 28,
      "z": -1,
      "name": "BO_Ceiling00",
      "rotation": 10
    },
    {
      "x": -2,
      "y": 34,
      "z": -1,
      "name": "Empty"
    },
    {
      "x": -2,
      "y": 35,
      "z": -1,
      "name": "Empty"
    },
    {
      "x": -2,
      "y": 36,
      "z": -1,
      "name": "Empty"
    },
    {
      "x": -2,
      "y": 37,
      "z": -1,
      "name": "Empty"
    },
    {
      "x": -2,
      "y": 38,
      "z": -1,
      "name": "Empty"
    },
    {
      "x": -2,
      "y": 39,
      "z": -1,
      "name": "Empty"
    },
    {
      "x": -2,
      "y": 40,
      "z": -1,
      "name": "Empty"
    },
    {
      "x": -2,
      "y": 41,
      "z": -1,
      "name": "BO_Pool_Surface00",
      "rotation": 4
    },
    {
      "x": -2,
      "y": 42,
      "z": -1,
      "name": "*BO_Lightsource_Cycle_State_Definitions_Day",
      "components": {
        "Components": {
          "BlackoutCycleState": {
            "OnState": "Day",
            "OffState": "Night"
          }
        }
      },
      "rotation": 2
    },
    {
      "x": -2,
      "y": 46,
      "z": -1,
      "name": "BO_Pool_Surface00",
      "rotation": 2
    },
    {
      "x": -2,
      "y": 47,
      "z": -1,
      "name": "Empty"
    },
    {
      "x": -2,
      "y": 0,
      "z": 0,
      "name": "BO_Parking_Blacktop",
      "rotation": 4
    },
    {
      "x": -2,
      "y": 1,
      "z": 0,
      "name": "BO_Parking_Blacktop",
      "rotation": 4
    },
    {
      "x": -2,
      "y": 2,
      "z": 0,
      "name": "BO_Parking_Blacktop",
      "rotation": 4
    },
    {
      "x": -2,
      "y": 3,
      "z": 0,
      "name": "BO_Parking_Blacktop",
      "rotation": 4
    },
    {
      "x": -2,
      "y": 9,
      "z": 0,
      "name": "Prototype_Rock_Concrete_Brick_Half",
      "support": 15,
      "rotation": 8
    },
    {
      "x": -2,
      "y": 10,
      "z": 0,
      "name": "Prototype_Rock_Concrete_Brick"
    },
    {
      "x": -2,
      "y": 11,
      "z": 0,
      "name": "BO_Pool_Surface00"
    },
    {
      "x": -2,
      "y": 12,
      "z": 0,
      "name": "BO_Pool_Surface00"
    },
    {
      "x": -2,
      "y": 13,
      "z": 0,
      "name": "BO_Pool_Surface00"
    },
    {
      "x": -2,
      "y": 14,
      "z": 0,
      "name": "BO_Pool_Surface00"
    },
    {
      "x": -2,
      "y": 15,
      "z": 0,
      "name": "BO_Pool_Surface00"
    },
    {
      "x": -2,
      "y": 16,
      "z": 0,
      "name": "BO_Pool_Surface00"
    },
    {
      "x": -2,
      "y": 17,
      "z": 0,
      "name": "BO_Pool_Surface00"
    },
    {
      "x": -2,
      "y": 18,
      "z": 0,
      "name": "BO_Pool_Surface00"
    },
    {
      "x": -2,
      "y": 19,
      "z": 0,
      "name": "BO_Pool_Surface00"
    },
    {
      "x": -2,
      "y": 20,
      "z": 0,
      "name": "BO_Pool_Surface00"
    },
    {
      "x": -2,
      "y": 23,
      "z": 0,
      "name": "BO_Pool_Surface00",
      "support": 15
    },
    {
      "x": -2,
      "y": 24,
      "z": 0,
      "name": "BO_Floor00"
    },
    {
      "x": -2,
      "y": 25,
      "z": 0,
      "name": "BO_Wallpaper00",
      "rotation": 3
    },
    {
      "x": -2,
      "y": 26,
      "z": 0,
      "name": "BO_Wallpaper00",
      "rotation": 3
